{"created": 1754775232.0701995, "duration": 207.30973529815674, "exitcode": 1, "root": "C:\\Projects\\building-os-platform\\tests\\api", "environment": {}, "summary": {"passed": 11, "failed": 22, "total": 33, "collected": 33}, "collectors": [{"nodeid": "", "outcome": "passed", "result": [{"nodeid": "__init__.py", "type": "Package"}]}, {"nodeid": "test_endpoints.py::TestPayloads", "outcome": "passed", "result": []}, {"nodeid": "test_endpoints.py::TestHealthEndpoint", "outcome": "passed", "result": [{"nodeid": "test_endpoints.py::TestHealthEndpoint::test_health_check_success", "type": "Function", "lineno": 14}, {"nodeid": "test_endpoints.py::TestHealthEndpoint::test_health_check_performance", "type": "Function", "lineno": 23}]}, {"nodeid": "test_endpoints.py::TestDirectorEndpoint", "outcome": "passed", "result": [{"nodeid": "test_endpoints.py::TestDirectorEndpoint::test_director_basic_request", "type": "Function", "lineno": 37}, {"nodeid": "test_endpoints.py::TestDirectorEndpoint::test_director_with_user_request", "type": "Function", "lineno": 46}, {"nodeid": "test_endpoints.py::TestDirectorEndpoint::test_director_with_user_id", "type": "Function", "lineno": 56}]}, {"nodeid": "test_endpoints.py::TestPersonaEndpoint", "outcome": "passed", "result": [{"nodeid": "test_endpoints.py::TestPersonaEndpoint::test_persona_valid_message", "type": "Function", "lineno": 68}, {"nodeid": "test_endpoints.py::TestPersonaEndpoint::test_persona_missing_user_id", "type": "Function", "lineno": 81}, {"nodeid": "test_endpoints.py::TestPersonaEndpoint::test_persona_missing_message", "type": "Function", "lineno": 89}, {"nodeid": "test_endpoints.py::TestPersonaEndpoint::test_persona_conversations", "type": "Function", "lineno": 97}]}, {"nodeid": "test_endpoints.py::TestElevatorEndpoint", "outcome": "passed", "result": [{"nodeid": "test_endpoints.py::TestElevatorEndpoint::test_elevator_call_basic", "type": "Function", "lineno": 109}, {"nodeid": "test_endpoints.py::TestElevatorEndpoint::test_elevator_missing_mission_id", "type": "Function", "lineno": 120}]}, {"nodeid": "test_endpoints.py::TestPSIMEndpoint", "outcome": "passed", "result": [{"nodeid": "test_endpoints.py::TestPSIMEndpoint::test_psim_search_basic", "type": "Function", "lineno": 132}, {"nodeid": "test_endpoints.py::TestPSIMEndpoint::test_psim_search_with_custom_query", "type": "Function", "lineno": 142}]}, {"nodeid": "test_endpoints.py::TestCoordinatorEndpoint", "outcome": "passed", "result": [{"nodeid": "test_endpoints.py::TestCoordinatorEndpoint::test_coordinator_mission_status", "type": "Function", "lineno": 155}, {"nodeid": "test_endpoints.py::TestCoordinatorEndpoint::test_coordinator_different_mission_id", "type": "Function", "lineno": 166}]}, {"nodeid": "test_endpoints.py::TestCORSHeaders", "outcome": "passed", "result": [{"nodeid": "test_endpoints.py::TestCORSHeaders::test_cors_headers_present[/health]", "type": "Function", "lineno": 178}, {"nodeid": "test_endpoints.py::TestCORSHeaders::test_cors_headers_present[/director]", "type": "Function", "lineno": 178}, {"nodeid": "test_endpoints.py::TestCORSHeaders::test_cors_headers_present[/persona]", "type": "Function", "lineno": 178}, {"nodeid": "test_endpoints.py::TestCORSHeaders::test_cors_headers_present[/elevator/call]", "type": "Function", "lineno": 178}, {"nodeid": "test_endpoints.py::TestCORSHeaders::test_cors_headers_present[/psim/search]", "type": "Function", "lineno": 178}, {"nodeid": "test_endpoints.py::TestCORSHeaders::test_cors_headers_present[/coordinator/missions/test-123]", "type": "Function", "lineno": 178}]}, {"nodeid": "test_endpoints.py::TestErrorHandling", "outcome": "passed", "result": [{"nodeid": "test_endpoints.py::TestErrorHandling::test_invalid_endpoint", "type": "Function", "lineno": 220}, {"nodeid": "test_endpoints.py::TestErrorHandling::test_invalid_method", "type": "Function", "lineno": 225}, {"nodeid": "test_endpoints.py::TestErrorHandling::test_malformed_json", "type": "Function", "lineno": 235}]}, {"nodeid": "test_endpoints.py", "outcome": "passed", "result": [{"nodeid": "test_endpoints.py::TestPayloads", "type": "Class"}, {"nodeid": "test_endpoints.py::TestHealthEndpoint", "type": "Class"}, {"nodeid": "test_endpoints.py::TestDirectorEndpoint", "type": "Class"}, {"nodeid": "test_endpoints.py::TestPersonaEndpoint", "type": "Class"}, {"nodeid": "test_endpoints.py::TestElevatorEndpoint", "type": "Class"}, {"nodeid": "test_endpoints.py::TestPSIMEndpoint", "type": "Class"}, {"nodeid": "test_endpoints.py::TestCoordinatorEndpoint", "type": "Class"}, {"nodeid": "test_endpoints.py::TestCORSHeaders", "type": "Class"}, {"nodeid": "test_endpoints.py::TestErrorHandling", "type": "Class"}]}, {"nodeid": "test_performance.py::TestPerformance", "outcome": "passed", "result": [{"nodeid": "test_performance.py::TestPerformance::test_response_time_under_threshold", "type": "Function", "lineno": 18}, {"nodeid": "test_performance.py::TestPerformance::test_concurrent_health_checks", "type": "Function", "lineno": 45}]}, {"nodeid": "test_performance.py::TestLoadTesting", "outcome": "passed", "result": [{"nodeid": "test_performance.py::TestLoadTesting::test_sustained_load_health_endpoint", "type": "Function", "lineno": 72}]}, {"nodeid": "test_performance.py::TestStressScenarios", "outcome": "passed", "result": [{"nodeid": "test_performance.py::TestStressScenarios::test_large_payload_persona", "type": "Function", "lineno": 149}, {"nodeid": "test_performance.py::TestStressScenarios::test_rapid_successive_requests", "type": "Function", "lineno": 163}, {"nodeid": "test_performance.py::TestStressScenarios::test_special_characters_in_requests", "type": "Function", "lineno": 189}]}, {"nodeid": "test_performance.py::TestBoundaryConditions", "outcome": "passed", "result": [{"nodeid": "test_performance.py::TestBoundaryConditions::test_empty_payloads", "type": "Function", "lineno": 213}, {"nodeid": "test_performance.py::TestBoundaryConditions::test_null_values_in_payload", "type": "Function", "lineno": 224}, {"nodeid": "test_performance.py::TestBoundaryConditions::test_extremely_long_mission_id", "type": "Function", "lineno": 233}]}, {"nodeid": "test_performance.py", "outcome": "passed", "result": [{"nodeid": "test_performance.py::TestPerformance", "type": "Class"}, {"nodeid": "test_performance.py::TestLoadTesting", "type": "Class"}, {"nodeid": "test_performance.py::TestStressScenarios", "type": "Class"}, {"nodeid": "test_performance.py::TestBoundaryConditions", "type": "Class"}]}, {"nodeid": "__init__.py", "outcome": "passed", "result": [{"nodeid": "test_endpoints.py", "type": "Module"}, {"nodeid": "test_performance.py", "type": "Module"}]}], "tests": [{"nodeid": "test_endpoints.py::TestHealthEndpoint::test_health_check_success", "lineno": 14, "outcome": "passed", "keywords": ["test_health_check_success", "TestHealthEndpoint", "test_endpoints.py", "__init__.py", "api"], "setup": {"duration": 0.01414659999863943, "outcome": "passed", "stdout": "\n\ud83e\uddea Starting BuildingOS API Test Suite\n\ud83c\udf10 Base URL: https://pj4vlvxrg7.execute-api.us-east-1.amazonaws.com/dev\n\ud83c\udff7\ufe0f  Environment: dev\n"}, "call": {"duration": 1.591930999995384, "outcome": "passed", "stdout": "\n\ud83d\ude80 GET /health\n\ud83d\udcca Status: 200 | \u23f1\ufe0f  Time: 1589.12ms | \ud83d\udce6 Size: 60 bytes\n"}, "teardown": {"duration": 0.000887700000021141, "outcome": "passed", "stdout": "\n"}}, {"nodeid": "test_endpoints.py::TestHealthEndpoint::test_health_check_performance", "lineno": 23, "outcome": "passed", "keywords": ["test_health_check_performance", "TestHealthEndpoint", "test_endpoints.py", "__init__.py", "api"], "setup": {"duration": 0.0004964999970979989, "outcome": "passed"}, "call": {"duration": 0.2094957000008435, "outcome": "passed", "stdout": "\n\ud83d\ude80 GET /health\n\ud83d\udcca Status: 200 | \u23f1\ufe0f  Time: 207.24ms | \ud83d\udce6 Size: 60 bytes\n"}, "teardown": {"duration": 0.0009862999941105954, "outcome": "passed", "stdout": "\n"}}, {"nodeid": "test_endpoints.py::TestDirectorEndpoint::test_director_basic_request", "lineno": 37, "outcome": "passed", "keywords": ["test_director_basic_request", "TestDirectorEndpoint", "test_endpoints.py", "__init__.py", "api"], "setup": {"duration": 0.0005184999972698279, "outcome": "passed"}, "call": {"duration": 4.660583500000939, "outcome": "passed", "stdout": "\n\ud83d\ude80 GET /director\n\ud83d\udcca Status: 200 | \u23f1\ufe0f  Time: 4658.21ms | \ud83d\udce6 Size: 128 bytes\n"}, "teardown": {"duration": 0.0011185999974259175, "outcome": "passed", "stdout": "\n"}}, {"nodeid": "test_endpoints.py::TestDirectorEndpoint::test_director_with_user_request", "lineno": 46, "outcome": "passed", "keywords": ["test_director_with_user_request", "TestDirectorEndpoint", "test_endpoints.py", "__init__.py", "api"], "setup": {"duration": 0.0007009000037214719, "outcome": "passed"}, "call": {"duration": 6.9462351000038325, "outcome": "passed", "stdout": "\n\ud83d\ude80 GET /director?user_request=Test mission from Python API tests\n\ud83d\udcca Status: 200 | \u23f1\ufe0f  Time: 6943.37ms | \ud83d\udce6 Size: 128 bytes\n"}, "teardown": {"duration": 0.0010085999965667725, "outcome": "passed", "stdout": "\n"}}, {"nodeid": "test_endpoints.py::TestDirectorEndpoint::test_director_with_user_id", "lineno": 56, "outcome": "passed", "keywords": ["test_director_with_user_id", "TestDirectorEndpoint", "test_endpoints.py", "__init__.py", "api"], "setup": {"duration": 0.0005927000020164996, "outcome": "passed"}, "call": {"duration": 3.5740603000012925, "outcome": "passed", "stdout": "\n\ud83d\ude80 GET /director?user_id=api-test-user\n\ud83d\udcca Status: 200 | \u23f1\ufe0f  Time: 3571.70ms | \ud83d\udce6 Size: 128 bytes\n"}, "teardown": {"duration": 0.0008059999963734299, "outcome": "passed", "stdout": "\n"}}, {"nodeid": "test_endpoints.py::TestPersonaEndpoint::test_persona_valid_message", "lineno": 68, "outcome": "failed", "keywords": ["test_persona_valid_message", "TestPersonaEndpoint", "test_endpoints.py", "__init__.py", "api"], "setup": {"duration": 0.0005104999945615418, "outcome": "passed"}, "call": {"duration": 8.892644300001848, "outcome": "failed", "crash": {"path": "C:\\Projects\\building-os-platform\\.venv\\Lib\\site-packages\\requests\\adapters.py", "lineno": 510, "message": "requests.exceptions.RetryError: HTTPSConnectionPool(host='pj4vlvxrg7.execute-api.us-east-1.amazonaws.com', port=443): Max retries exceeded with url: /dev/persona (Caused by ResponseError('too many 500 error responses'))"}, "stdout": "\n\ud83d\ude80 POST /persona\n\u274c Request failed: \nHTTPSConnectionPool(host='pj4vlvxrg7.execute-api.us-east-1.amazonaws.com', \nport=443): Max retries exceeded with url: /dev/persona (Caused by \nResponseError('too many 500 error responses'))\n", "longrepr": "urllib3.exceptions.ResponseError: too many 500 error responses\n\nThe above exception was the direct cause of the following exception:\nE   urllib3.exceptions.MaxRetryError: HTTPSConnectionPool(host='pj4vlvxrg7.execute-api.us-east-1.amazonaws.com', port=443): Max retries exceeded with url: /dev/persona (Caused by ResponseError('too many 500 error responses'))\n\nDuring handling of the above exception, another exception occurred:\nE   requests.exceptions.RetryError: HTTPSConnectionPool(host='pj4vlvxrg7.execute-api.us-east-1.amazonaws.com', port=443): Max retries exceeded with url: /dev/persona (Caused by ResponseError('too many 500 error responses'))"}, "teardown": {"duration": 0.0011257000005571172, "outcome": "passed", "stdout": "\n"}}, {"nodeid": "test_endpoints.py::TestPersonaEndpoint::test_persona_missing_user_id", "lineno": 81, "outcome": "failed", "keywords": ["test_persona_missing_user_id", "TestPersonaEndpoint", "test_endpoints.py", "__init__.py", "api"], "setup": {"duration": 0.0006465999977081083, "outcome": "passed"}, "call": {"duration": 8.215080000001763, "outcome": "failed", "crash": {"path": "C:\\Projects\\building-os-platform\\.venv\\Lib\\site-packages\\requests\\adapters.py", "lineno": 510, "message": "requests.exceptions.RetryError: HTTPSConnectionPool(host='pj4vlvxrg7.execute-api.us-east-1.amazonaws.com', port=443): Max retries exceeded with url: /dev/persona (Caused by ResponseError('too many 500 error responses'))"}, "stdout": "\n\ud83d\ude80 POST /persona\n\u274c Request failed: \nHTTPSConnectionPool(host='pj4vlvxrg7.execute-api.us-east-1.amazonaws.com', \nport=443): Max retries exceeded with url: /dev/persona (Caused by \nResponseError('too many 500 error responses'))\n", "longrepr": "urllib3.exceptions.ResponseError: too many 500 error responses\n\nThe above exception was the direct cause of the following exception:\nE   urllib3.exceptions.MaxRetryError: HTTPSConnectionPool(host='pj4vlvxrg7.execute-api.us-east-1.amazonaws.com', port=443): Max retries exceeded with url: /dev/persona (Caused by ResponseError('too many 500 error responses'))\n\nDuring handling of the above exception, another exception occurred:\nE   requests.exceptions.RetryError: HTTPSConnectionPool(host='pj4vlvxrg7.execute-api.us-east-1.amazonaws.com', port=443): Max retries exceeded with url: /dev/persona (Caused by ResponseError('too many 500 error responses'))"}, "teardown": {"duration": 0.0009706999990157783, "outcome": "passed", "stdout": "\n"}}, {"nodeid": "test_endpoints.py::TestPersonaEndpoint::test_persona_missing_message", "lineno": 89, "outcome": "failed", "keywords": ["test_persona_missing_message", "TestPersonaEndpoint", "test_endpoints.py", "__init__.py", "api"], "setup": {"duration": 0.0005537999968510121, "outcome": "passed"}, "call": {"duration": 8.175539799995022, "outcome": "failed", "crash": {"path": "C:\\Projects\\building-os-platform\\.venv\\Lib\\site-packages\\requests\\adapters.py", "lineno": 510, "message": "requests.exceptions.RetryError: HTTPSConnectionPool(host='pj4vlvxrg7.execute-api.us-east-1.amazonaws.com', port=443): Max retries exceeded with url: /dev/persona (Caused by ResponseError('too many 500 error responses'))"}, "stdout": "\n\ud83d\ude80 POST /persona\n\u274c Request failed: \nHTTPSConnectionPool(host='pj4vlvxrg7.execute-api.us-east-1.amazonaws.com', \nport=443): Max retries exceeded with url: /dev/persona (Caused by \nResponseError('too many 500 error responses'))\n", "longrepr": "urllib3.exceptions.ResponseError: too many 500 error responses\n\nThe above exception was the direct cause of the following exception:\nE   urllib3.exceptions.MaxRetryError: HTTPSConnectionPool(host='pj4vlvxrg7.execute-api.us-east-1.amazonaws.com', port=443): Max retries exceeded with url: /dev/persona (Caused by ResponseError('too many 500 error responses'))\n\nDuring handling of the above exception, another exception occurred:\nE   requests.exceptions.RetryError: HTTPSConnectionPool(host='pj4vlvxrg7.execute-api.us-east-1.amazonaws.com', port=443): Max retries exceeded with url: /dev/persona (Caused by ResponseError('too many 500 error responses'))"}, "teardown": {"duration": 0.0009178999971481971, "outcome": "passed", "stdout": "\n"}}, {"nodeid": "test_endpoints.py::TestPersonaEndpoint::test_persona_conversations", "lineno": 97, "outcome": "failed", "keywords": ["test_persona_conversations", "TestPersonaEndpoint", "test_endpoints.py", "__init__.py", "api"], "setup": {"duration": 0.0004892999932053499, "outcome": "passed"}, "call": {"duration": 8.069432600001164, "outcome": "failed", "crash": {"path": "C:\\Projects\\building-os-platform\\.venv\\Lib\\site-packages\\requests\\adapters.py", "lineno": 510, "message": "requests.exceptions.RetryError: HTTPSConnectionPool(host='pj4vlvxrg7.execute-api.us-east-1.amazonaws.com', port=443): Max retries exceeded with url: /dev/persona/conversations?user_id=api-test-user (Caused by ResponseError('too many 500 error responses'))"}, "stdout": "\n\ud83d\ude80 GET /persona/conversations?user_id=api-test-user\n\u274c Request failed: \nHTTPSConnectionPool(host='pj4vlvxrg7.execute-api.us-east-1.amazonaws.com', \nport=443): Max retries exceeded with url: \n/dev/persona/conversations?user_id=api-test-user (Caused by ResponseError('too \nmany 500 error responses'))\n", "longrepr": "urllib3.exceptions.ResponseError: too many 500 error responses\n\nThe above exception was the direct cause of the following exception:\nE   urllib3.exceptions.MaxRetryError: HTTPSConnectionPool(host='pj4vlvxrg7.execute-api.us-east-1.amazonaws.com', port=443): Max retries exceeded with url: /dev/persona/conversations?user_id=api-test-user (Caused by ResponseError('too many 500 error responses'))\n\nDuring handling of the above exception, another exception occurred:\nE   requests.exceptions.RetryError: HTTPSConnectionPool(host='pj4vlvxrg7.execute-api.us-east-1.amazonaws.com', port=443): Max retries exceeded with url: /dev/persona/conversations?user_id=api-test-user (Caused by ResponseError('too many 500 error responses'))"}, "teardown": {"duration": 0.0009065999984159134, "outcome": "passed", "stdout": "\n"}}, {"nodeid": "test_endpoints.py::TestElevatorEndpoint::test_elevator_call_basic", "lineno": 109, "outcome": "failed", "keywords": ["test_elevator_call_basic", "TestElevatorEndpoint", "test_endpoints.py", "__init__.py", "api"], "setup": {"duration": 0.0004961999948136508, "outcome": "passed"}, "call": {"duration": 8.405251899996074, "outcome": "failed", "crash": {"path": "C:\\Projects\\building-os-platform\\.venv\\Lib\\site-packages\\requests\\adapters.py", "lineno": 510, "message": "requests.exceptions.RetryError: HTTPSConnectionPool(host='pj4vlvxrg7.execute-api.us-east-1.amazonaws.com', port=443): Max retries exceeded with url: /dev/elevator/call (Caused by ResponseError('too many 500 error responses'))"}, "stdout": "\n\ud83d\ude80 POST /elevator/call\n\u274c Request failed: \nHTTPSConnectionPool(host='pj4vlvxrg7.execute-api.us-east-1.amazonaws.com', \nport=443): Max retries exceeded with url: /dev/elevator/call (Caused by \nResponseError('too many 500 error responses'))\n", "longrepr": "urllib3.exceptions.ResponseError: too many 500 error responses\n\nThe above exception was the direct cause of the following exception:\nE   urllib3.exceptions.MaxRetryError: HTTPSConnectionPool(host='pj4vlvxrg7.execute-api.us-east-1.amazonaws.com', port=443): Max retries exceeded with url: /dev/elevator/call (Caused by ResponseError('too many 500 error responses'))\n\nDuring handling of the above exception, another exception occurred:\nE   requests.exceptions.RetryError: HTTPSConnectionPool(host='pj4vlvxrg7.execute-api.us-east-1.amazonaws.com', port=443): Max retries exceeded with url: /dev/elevator/call (Caused by ResponseError('too many 500 error responses'))"}, "teardown": {"duration": 0.0009253999960492365, "outcome": "passed", "stdout": "\n"}}, {"nodeid": "test_endpoints.py::TestElevatorEndpoint::test_elevator_missing_mission_id", "lineno": 120, "outcome": "failed", "keywords": ["test_elevator_missing_mission_id", "TestElevatorEndpoint", "test_endpoints.py", "__init__.py", "api"], "setup": {"duration": 0.0005228000009083189, "outcome": "passed"}, "call": {"duration": 7.780882999999449, "outcome": "failed", "crash": {"path": "C:\\Projects\\building-os-platform\\.venv\\Lib\\site-packages\\requests\\adapters.py", "lineno": 510, "message": "requests.exceptions.RetryError: HTTPSConnectionPool(host='pj4vlvxrg7.execute-api.us-east-1.amazonaws.com', port=443): Max retries exceeded with url: /dev/elevator/call (Caused by ResponseError('too many 500 error responses'))"}, "stdout": "\n\ud83d\ude80 POST /elevator/call\n\u274c Request failed: \nHTTPSConnectionPool(host='pj4vlvxrg7.execute-api.us-east-1.amazonaws.com', \nport=443): Max retries exceeded with url: /dev/elevator/call (Caused by \nResponseError('too many 500 error responses'))\n", "longrepr": "urllib3.exceptions.ResponseError: too many 500 error responses\n\nThe above exception was the direct cause of the following exception:\nE   urllib3.exceptions.MaxRetryError: HTTPSConnectionPool(host='pj4vlvxrg7.execute-api.us-east-1.amazonaws.com', port=443): Max retries exceeded with url: /dev/elevator/call (Caused by ResponseError('too many 500 error responses'))\n\nDuring handling of the above exception, another exception occurred:\nE   requests.exceptions.RetryError: HTTPSConnectionPool(host='pj4vlvxrg7.execute-api.us-east-1.amazonaws.com', port=443): Max retries exceeded with url: /dev/elevator/call (Caused by ResponseError('too many 500 error responses'))"}, "teardown": {"duration": 0.0009374000001116656, "outcome": "passed", "stdout": "\n"}}, {"nodeid": "test_endpoints.py::TestPSIMEndpoint::test_psim_search_basic", "lineno": 132, "outcome": "failed", "keywords": ["test_psim_search_basic", "TestPSIMEndpoint", "test_endpoints.py", "__init__.py", "api"], "setup": {"duration": 0.0005515000011655502, "outcome": "passed"}, "call": {"duration": 8.26931859999604, "outcome": "failed", "crash": {"path": "C:\\Projects\\building-os-platform\\.venv\\Lib\\site-packages\\requests\\adapters.py", "lineno": 510, "message": "requests.exceptions.RetryError: HTTPSConnectionPool(host='pj4vlvxrg7.execute-api.us-east-1.amazonaws.com', port=443): Max retries exceeded with url: /dev/psim/search (Caused by ResponseError('too many 500 error responses'))"}, "stdout": "\n\ud83d\ude80 POST /psim/search\n\u274c Request failed: \nHTTPSConnectionPool(host='pj4vlvxrg7.execute-api.us-east-1.amazonaws.com', \nport=443): Max retries exceeded with url: /dev/psim/search (Caused by \nResponseError('too many 500 error responses'))\n", "longrepr": "urllib3.exceptions.ResponseError: too many 500 error responses\n\nThe above exception was the direct cause of the following exception:\nE   urllib3.exceptions.MaxRetryError: HTTPSConnectionPool(host='pj4vlvxrg7.execute-api.us-east-1.amazonaws.com', port=443): Max retries exceeded with url: /dev/psim/search (Caused by ResponseError('too many 500 error responses'))\n\nDuring handling of the above exception, another exception occurred:\nE   requests.exceptions.RetryError: HTTPSConnectionPool(host='pj4vlvxrg7.execute-api.us-east-1.amazonaws.com', port=443): Max retries exceeded with url: /dev/psim/search (Caused by ResponseError('too many 500 error responses'))"}, "teardown": {"duration": 0.0009141000045929104, "outcome": "passed", "stdout": "\n"}}, {"nodeid": "test_endpoints.py::TestPSIMEndpoint::test_psim_search_with_custom_query", "lineno": 142, "outcome": "failed", "keywords": ["test_psim_search_with_custom_query", "TestPSIMEndpoint", "test_endpoints.py", "__init__.py", "api"], "setup": {"duration": 0.0005618999930447899, "outcome": "passed"}, "call": {"duration": 7.728459900004964, "outcome": "failed", "crash": {"path": "C:\\Projects\\building-os-platform\\.venv\\Lib\\site-packages\\requests\\adapters.py", "lineno": 510, "message": "requests.exceptions.RetryError: HTTPSConnectionPool(host='pj4vlvxrg7.execute-api.us-east-1.amazonaws.com', port=443): Max retries exceeded with url: /dev/psim/search (Caused by ResponseError('too many 500 error responses'))"}, "stdout": "\n\ud83d\ude80 POST /psim/search\n\u274c Request failed: \nHTTPSConnectionPool(host='pj4vlvxrg7.execute-api.us-east-1.amazonaws.com', \nport=443): Max retries exceeded with url: /dev/psim/search (Caused by \nResponseError('too many 500 error responses'))\n", "longrepr": "urllib3.exceptions.ResponseError: too many 500 error responses\n\nThe above exception was the direct cause of the following exception:\nE   urllib3.exceptions.MaxRetryError: HTTPSConnectionPool(host='pj4vlvxrg7.execute-api.us-east-1.amazonaws.com', port=443): Max retries exceeded with url: /dev/psim/search (Caused by ResponseError('too many 500 error responses'))\n\nDuring handling of the above exception, another exception occurred:\nE   requests.exceptions.RetryError: HTTPSConnectionPool(host='pj4vlvxrg7.execute-api.us-east-1.amazonaws.com', port=443): Max retries exceeded with url: /dev/psim/search (Caused by ResponseError('too many 500 error responses'))"}, "teardown": {"duration": 0.0009628999978303909, "outcome": "passed", "stdout": "\n"}}, {"nodeid": "test_endpoints.py::TestCoordinatorEndpoint::test_coordinator_mission_status", "lineno": 155, "outcome": "failed", "keywords": ["test_coordinator_mission_status", "TestCoordinatorEndpoint", "test_endpoints.py", "__init__.py", "api"], "setup": {"duration": 0.0005560999998124316, "outcome": "passed"}, "call": {"duration": 8.344471500000509, "outcome": "failed", "crash": {"path": "C:\\Projects\\building-os-platform\\.venv\\Lib\\site-packages\\requests\\adapters.py", "lineno": 510, "message": "requests.exceptions.RetryError: HTTPSConnectionPool(host='pj4vlvxrg7.execute-api.us-east-1.amazonaws.com', port=443): Max retries exceeded with url: /dev/coordinator/missions/test-mission-123 (Caused by ResponseError('too many 500 error responses'))"}, "stdout": "\n\ud83d\ude80 GET /coordinator/missions/test-mission-123\n\u274c Request failed: \nHTTPSConnectionPool(host='pj4vlvxrg7.execute-api.us-east-1.amazonaws.com', \nport=443): Max retries exceeded with url: \n/dev/coordinator/missions/test-mission-123 (Caused by ResponseError('too many \n500 error responses'))\n", "longrepr": "urllib3.exceptions.ResponseError: too many 500 error responses\n\nThe above exception was the direct cause of the following exception:\nE   urllib3.exceptions.MaxRetryError: HTTPSConnectionPool(host='pj4vlvxrg7.execute-api.us-east-1.amazonaws.com', port=443): Max retries exceeded with url: /dev/coordinator/missions/test-mission-123 (Caused by ResponseError('too many 500 error responses'))\n\nDuring handling of the above exception, another exception occurred:\nE   requests.exceptions.RetryError: HTTPSConnectionPool(host='pj4vlvxrg7.execute-api.us-east-1.amazonaws.com', port=443): Max retries exceeded with url: /dev/coordinator/missions/test-mission-123 (Caused by ResponseError('too many 500 error responses'))"}, "teardown": {"duration": 0.0008933999997680075, "outcome": "passed", "stdout": "\n"}}, {"nodeid": "test_endpoints.py::TestCoordinatorEndpoint::test_coordinator_different_mission_id", "lineno": 166, "outcome": "failed", "keywords": ["test_coordinator_different_mission_id", "TestCoordinatorEndpoint", "test_endpoints.py", "__init__.py", "api"], "setup": {"duration": 0.000487600002088584, "outcome": "passed"}, "call": {"duration": 8.769157000002451, "outcome": "failed", "crash": {"path": "C:\\Projects\\building-os-platform\\.venv\\Lib\\site-packages\\requests\\adapters.py", "lineno": 510, "message": "requests.exceptions.RetryError: HTTPSConnectionPool(host='pj4vlvxrg7.execute-api.us-east-1.amazonaws.com', port=443): Max retries exceeded with url: /dev/coordinator/missions/python-test-1754775116 (Caused by ResponseError('too many 500 error responses'))"}, "stdout": "\n\ud83d\ude80 GET /coordinator/missions/python-test-1754775116\n\u274c Request failed: \nHTTPSConnectionPool(host='pj4vlvxrg7.execute-api.us-east-1.amazonaws.com', \nport=443): Max retries exceeded with url: \n/dev/coordinator/missions/python-test-1754775116 (Caused by ResponseError('too \nmany 500 error responses'))\n", "longrepr": "urllib3.exceptions.ResponseError: too many 500 error responses\n\nThe above exception was the direct cause of the following exception:\nE   urllib3.exceptions.MaxRetryError: HTTPSConnectionPool(host='pj4vlvxrg7.execute-api.us-east-1.amazonaws.com', port=443): Max retries exceeded with url: /dev/coordinator/missions/python-test-1754775116 (Caused by ResponseError('too many 500 error responses'))\n\nDuring handling of the above exception, another exception occurred:\nE   requests.exceptions.RetryError: HTTPSConnectionPool(host='pj4vlvxrg7.execute-api.us-east-1.amazonaws.com', port=443): Max retries exceeded with url: /dev/coordinator/missions/python-test-1754775116 (Caused by ResponseError('too many 500 error responses'))"}, "teardown": {"duration": 0.0010151000024052337, "outcome": "passed", "stdout": "\n"}}, {"nodeid": "test_endpoints.py::TestCORSHeaders::test_cors_headers_present[/health]", "lineno": 178, "outcome": "failed", "keywords": ["test_cors_headers_present[/health]", "parametrize", "pytestmark", "/health", "TestCORSHeaders", "test_endpoints.py", "__init__.py", "api"], "setup": {"duration": 0.0007438999964506365, "outcome": "passed"}, "call": {"duration": 0.19444080000539543, "outcome": "failed", "crash": {"path": "c:\\Projects\\building-os-platform\\tests\\api\\test_endpoints.py", "lineno": 215, "message": "AssertionError: No CORS headers found in response for /health\nassert False"}, "stdout": "\n\ud83d\ude80 GET /health\n\ud83d\udcca Status: 200 | \u23f1\ufe0f  Time: 191.69ms | \ud83d\udce6 Size: 60 bytes\n", "longrepr": "E   AssertionError: No CORS headers found in response for /health\n    assert False"}, "teardown": {"duration": 0.0009194000012939796, "outcome": "passed", "stdout": "\n"}}, {"nodeid": "test_endpoints.py::TestCORSHeaders::test_cors_headers_present[/director]", "lineno": 178, "outcome": "failed", "keywords": ["test_cors_headers_present[/director]", "parametrize", "pytestmark", "/director", "TestCORSHeaders", "test_endpoints.py", "__init__.py", "api"], "setup": {"duration": 0.0005549999987124465, "outcome": "passed"}, "call": {"duration": 4.52990580000187, "outcome": "failed", "crash": {"path": "c:\\Projects\\building-os-platform\\tests\\api\\test_endpoints.py", "lineno": 215, "message": "AssertionError: No CORS headers found in response for /director\nassert False"}, "stdout": "\n\ud83d\ude80 GET /director\n\ud83d\udcca Status: 200 | \u23f1\ufe0f  Time: 4527.64ms | \ud83d\udce6 Size: 128 bytes\n", "longrepr": "E   AssertionError: No CORS headers found in response for /director\n    assert False"}, "teardown": {"duration": 0.0009503000037511811, "outcome": "passed", "stdout": "\n"}}, {"nodeid": "test_endpoints.py::TestCORSHeaders::test_cors_headers_present[/persona]", "lineno": 178, "outcome": "failed", "keywords": ["test_cors_headers_present[/persona]", "parametrize", "pytestmark", "/persona", "TestCORSHeaders", "test_endpoints.py", "__init__.py", "api"], "setup": {"duration": 0.0006410999994841404, "outcome": "passed"}, "call": {"duration": 8.269130000000587, "outcome": "failed", "crash": {"path": "C:\\Projects\\building-os-platform\\.venv\\Lib\\site-packages\\requests\\adapters.py", "lineno": 510, "message": "requests.exceptions.RetryError: HTTPSConnectionPool(host='pj4vlvxrg7.execute-api.us-east-1.amazonaws.com', port=443): Max retries exceeded with url: /dev/persona (Caused by ResponseError('too many 500 error responses'))"}, "stdout": "\n\ud83d\ude80 POST /persona\n\u274c Request failed: \nHTTPSConnectionPool(host='pj4vlvxrg7.execute-api.us-east-1.amazonaws.com', \nport=443): Max retries exceeded with url: /dev/persona (Caused by \nResponseError('too many 500 error responses'))\n", "longrepr": "urllib3.exceptions.ResponseError: too many 500 error responses\n\nThe above exception was the direct cause of the following exception:\nE   urllib3.exceptions.MaxRetryError: HTTPSConnectionPool(host='pj4vlvxrg7.execute-api.us-east-1.amazonaws.com', port=443): Max retries exceeded with url: /dev/persona (Caused by ResponseError('too many 500 error responses'))\n\nDuring handling of the above exception, another exception occurred:\nE   requests.exceptions.RetryError: HTTPSConnectionPool(host='pj4vlvxrg7.execute-api.us-east-1.amazonaws.com', port=443): Max retries exceeded with url: /dev/persona (Caused by ResponseError('too many 500 error responses'))"}, "teardown": {"duration": 0.0009871000002021901, "outcome": "passed", "stdout": "\n"}}, {"nodeid": "test_endpoints.py::TestCORSHeaders::test_cors_headers_present[/elevator/call]", "lineno": 178, "outcome": "failed", "keywords": ["test_cors_headers_present[/elevator/call]", "parametrize", "pytestmark", "/elevator/call", "TestCORSHeaders", "test_endpoints.py", "__init__.py", "api"], "setup": {"duration": 0.0006171999993966892, "outcome": "passed"}, "call": {"duration": 7.7777845000018715, "outcome": "failed", "crash": {"path": "C:\\Projects\\building-os-platform\\.venv\\Lib\\site-packages\\requests\\adapters.py", "lineno": 510, "message": "requests.exceptions.RetryError: HTTPSConnectionPool(host='pj4vlvxrg7.execute-api.us-east-1.amazonaws.com', port=443): Max retries exceeded with url: /dev/elevator/call (Caused by ResponseError('too many 500 error responses'))"}, "stdout": "\n\ud83d\ude80 POST /elevator/call\n\u274c Request failed: \nHTTPSConnectionPool(host='pj4vlvxrg7.execute-api.us-east-1.amazonaws.com', \nport=443): Max retries exceeded with url: /dev/elevator/call (Caused by \nResponseError('too many 500 error responses'))\n", "longrepr": "urllib3.exceptions.ResponseError: too many 500 error responses\n\nThe above exception was the direct cause of the following exception:\nE   urllib3.exceptions.MaxRetryError: HTTPSConnectionPool(host='pj4vlvxrg7.execute-api.us-east-1.amazonaws.com', port=443): Max retries exceeded with url: /dev/elevator/call (Caused by ResponseError('too many 500 error responses'))\n\nDuring handling of the above exception, another exception occurred:\nE   requests.exceptions.RetryError: HTTPSConnectionPool(host='pj4vlvxrg7.execute-api.us-east-1.amazonaws.com', port=443): Max retries exceeded with url: /dev/elevator/call (Caused by ResponseError('too many 500 error responses'))"}, "teardown": {"duration": 0.0009153000064543448, "outcome": "passed", "stdout": "\n"}}, {"nodeid": "test_endpoints.py::TestCORSHeaders::test_cors_headers_present[/psim/search]", "lineno": 178, "outcome": "failed", "keywords": ["test_cors_headers_present[/psim/search]", "parametrize", "pytestmark", "/psim/search", "TestCORSHeaders", "test_endpoints.py", "__init__.py", "api"], "setup": {"duration": 0.001302700002270285, "outcome": "passed"}, "call": {"duration": 7.715915700006008, "outcome": "failed", "crash": {"path": "C:\\Projects\\building-os-platform\\.venv\\Lib\\site-packages\\requests\\adapters.py", "lineno": 510, "message": "requests.exceptions.RetryError: HTTPSConnectionPool(host='pj4vlvxrg7.execute-api.us-east-1.amazonaws.com', port=443): Max retries exceeded with url: /dev/psim/search (Caused by ResponseError('too many 500 error responses'))"}, "stdout": "\n\ud83d\ude80 POST /psim/search\n\u274c Request failed: \nHTTPSConnectionPool(host='pj4vlvxrg7.execute-api.us-east-1.amazonaws.com', \nport=443): Max retries exceeded with url: /dev/psim/search (Caused by \nResponseError('too many 500 error responses'))\n", "longrepr": "urllib3.exceptions.ResponseError: too many 500 error responses\n\nThe above exception was the direct cause of the following exception:\nE   urllib3.exceptions.MaxRetryError: HTTPSConnectionPool(host='pj4vlvxrg7.execute-api.us-east-1.amazonaws.com', port=443): Max retries exceeded with url: /dev/psim/search (Caused by ResponseError('too many 500 error responses'))\n\nDuring handling of the above exception, another exception occurred:\nE   requests.exceptions.RetryError: HTTPSConnectionPool(host='pj4vlvxrg7.execute-api.us-east-1.amazonaws.com', port=443): Max retries exceeded with url: /dev/psim/search (Caused by ResponseError('too many 500 error responses'))"}, "teardown": {"duration": 0.0010619000022416003, "outcome": "passed", "stdout": "\n"}}, {"nodeid": "test_endpoints.py::TestCORSHeaders::test_cors_headers_present[/coordinator/missions/test-123]", "lineno": 178, "outcome": "failed", "keywords": ["test_cors_headers_present[/coordinator/missions/test-123]", "parametrize", "pytestmark", "/coordinator/missions/test-123", "TestCORSHeaders", "test_endpoints.py", "__init__.py", "api"], "setup": {"duration": 0.0006375000011757948, "outcome": "passed"}, "call": {"duration": 8.282799799999339, "outcome": "failed", "crash": {"path": "C:\\Projects\\building-os-platform\\.venv\\Lib\\site-packages\\requests\\adapters.py", "lineno": 510, "message": "requests.exceptions.RetryError: HTTPSConnectionPool(host='pj4vlvxrg7.execute-api.us-east-1.amazonaws.com', port=443): Max retries exceeded with url: /dev/coordinator/missions/test-123 (Caused by ResponseError('too many 500 error responses'))"}, "stdout": "\n\ud83d\ude80 GET /coordinator/missions/test-123\n\u274c Request failed: \nHTTPSConnectionPool(host='pj4vlvxrg7.execute-api.us-east-1.amazonaws.com', \nport=443): Max retries exceeded with url: /dev/coordinator/missions/test-123 \n(Caused by ResponseError('too many 500 error responses'))\n", "longrepr": "urllib3.exceptions.ResponseError: too many 500 error responses\n\nThe above exception was the direct cause of the following exception:\nE   urllib3.exceptions.MaxRetryError: HTTPSConnectionPool(host='pj4vlvxrg7.execute-api.us-east-1.amazonaws.com', port=443): Max retries exceeded with url: /dev/coordinator/missions/test-123 (Caused by ResponseError('too many 500 error responses'))\n\nDuring handling of the above exception, another exception occurred:\nE   requests.exceptions.RetryError: HTTPSConnectionPool(host='pj4vlvxrg7.execute-api.us-east-1.amazonaws.com', port=443): Max retries exceeded with url: /dev/coordinator/missions/test-123 (Caused by ResponseError('too many 500 error responses'))"}, "teardown": {"duration": 0.0010999000005540438, "outcome": "passed", "stdout": "\n"}}, {"nodeid": "test_endpoints.py::TestErrorHandling::test_invalid_endpoint", "lineno": 220, "outcome": "passed", "keywords": ["test_invalid_endpoint", "TestErrorHandling", "test_endpoints.py", "__init__.py", "api"], "setup": {"duration": 0.0006227999983821064, "outcome": "passed"}, "call": {"duration": 0.1675669999967795, "outcome": "passed", "stdout": "\n\ud83d\ude80 GET /invalid-endpoint\n\ud83d\udcca Status: 404 | \u23f1\ufe0f  Time: 165.26ms | \ud83d\udce6 Size: 23 bytes\n"}, "teardown": {"duration": 0.0009083999975700863, "outcome": "passed", "stdout": "\n"}}, {"nodeid": "test_endpoints.py::TestErrorHandling::test_invalid_method", "lineno": 225, "outcome": "passed", "keywords": ["test_invalid_method", "TestErrorHandling", "test_endpoints.py", "__init__.py", "api"], "setup": {"duration": 0.0004805999997188337, "outcome": "passed"}, "call": {"duration": 0.17526079999515787, "outcome": "passed", "stdout": "\n\ud83d\ude80 DELETE /health\n\ud83d\udcca Status: 404 | \u23f1\ufe0f  Time: 173.03ms | \ud83d\udce6 Size: 23 bytes\n"}, "teardown": {"duration": 0.0008338000043295324, "outcome": "passed", "stdout": "\n"}}, {"nodeid": "test_endpoints.py::TestErrorHandling::test_malformed_json", "lineno": 235, "outcome": "passed", "keywords": ["test_malformed_json", "TestErrorHandling", "test_endpoints.py", "__init__.py", "api"], "setup": {"duration": 0.0005185999980312772, "outcome": "passed"}, "call": {"duration": 8.047607500004233, "outcome": "passed"}, "teardown": {"duration": 0.0009075000052689575, "outcome": "passed", "stdout": "\n"}}, {"nodeid": "test_performance.py::TestPerformance::test_response_time_under_threshold", "lineno": 18, "outcome": "failed", "keywords": ["test_response_time_under_threshold", "TestPerformance", "test_performance.py", "__init__.py", "api"], "setup": {"duration": 0.0003804000007221475, "outcome": "passed"}, "call": {"duration": 3.339031100003922, "outcome": "failed", "crash": {"path": "c:\\Projects\\building-os-platform\\tests\\api\\test_performance.py", "lineno": 42, "message": "AssertionError: /director took 3153.83ms (threshold: 3000ms)\nassert 3153.8331508636475 < 3000"}, "stdout": "\n\ud83d\ude80 GET /health\n\ud83d\udcca Status: 200 | \u23f1\ufe0f  Time: 182.86ms | \ud83d\udce6 Size: 60 bytes\n\n\ud83d\ude80 GET /director\n\ud83d\udcca Status: 200 | \u23f1\ufe0f  Time: 3152.37ms | \ud83d\udce6 Size: 128 bytes\n", "longrepr": "E   AssertionError: /director took 3153.83ms (threshold: 3000ms)\n    assert 3153.8331508636475 < 3000"}, "teardown": {"duration": 0.0005127999975229613, "outcome": "passed"}}, {"nodeid": "test_performance.py::TestPerformance::test_concurrent_health_checks", "lineno": 45, "outcome": "passed", "keywords": ["test_concurrent_health_checks", "TestPerformance", "test_performance.py", "__init__.py", "api"], "setup": {"duration": 0.0005281999983708374, "outcome": "passed"}, "call": {"duration": 1.6526907999941614, "outcome": "passed", "stdout": "\n\ud83d\ude80 GET /health\n\n\ud83d\ude80 GET /health\n\n\ud83d\ude80 GET /health\n\n\ud83d\ude80 GET /health\n\n\ud83d\ude80 GET /health\n\ud83d\udcca Status: 200 | \u23f1\ufe0f  Time: 199.07ms | \ud83d\udce6 Size: 60 bytes\n\ud83d\udcca Status: 200 | \u23f1\ufe0f  Time: 1537.93ms | \ud83d\udce6 Size: 60 bytes\n\ud83d\udcca Status: 200 | \u23f1\ufe0f  Time: 1589.76ms | \ud83d\udce6 Size: 60 bytes\n\ud83d\udcca Status: 200 | \u23f1\ufe0f  Time: 1624.70ms | \ud83d\udce6 Size: 60 bytes\n\ud83d\udcca Status: 200 | \u23f1\ufe0f  Time: 1641.77ms | \ud83d\udce6 Size: 60 bytes\n"}, "teardown": {"duration": 0.0004228999969200231, "outcome": "passed"}}, {"nodeid": "test_performance.py::TestLoadTesting::test_sustained_load_health_endpoint", "lineno": 72, "outcome": "passed", "keywords": ["test_sustained_load_health_endpoint", "slow", "pytestmark", "TestLoadTesting", "test_performance.py", "__init__.py", "api"], "setup": {"duration": 0.00035659999412018806, "outcome": "passed"}, "call": {"duration": 13.2899694000007, "outcome": "passed", "stdout": "\n\ud83d\udd25 Running sustained load test...\n\n\ud83d\ude80 GET /health\n\ud83d\udcca Status: 200 | \u23f1\ufe0f  Time: 178.42ms | \ud83d\udce6 Size: 60 bytes\n\n\ud83d\ude80 GET /health\n\ud83d\udcca Status: 200 | \u23f1\ufe0f  Time: 176.00ms | \ud83d\udce6 Size: 60 bytes\n\n\ud83d\ude80 GET /health\n\ud83d\udcca Status: 200 | \u23f1\ufe0f  Time: 194.90ms | \ud83d\udce6 Size: 60 bytes\n\n\ud83d\ude80 GET /health\n\ud83d\udcca Status: 200 | \u23f1\ufe0f  Time: 186.30ms | \ud83d\udce6 Size: 60 bytes\n\n\ud83d\ude80 GET /health\n\ud83d\udcca Status: 200 | \u23f1\ufe0f  Time: 177.93ms | \ud83d\udce6 Size: 60 bytes\n\n\ud83d\ude80 GET /health\n\ud83d\udcca Status: 200 | \u23f1\ufe0f  Time: 288.96ms | \ud83d\udce6 Size: 60 bytes\n\n\ud83d\ude80 GET /health\n\ud83d\udcca Status: 200 | \u23f1\ufe0f  Time: 179.65ms | \ud83d\udce6 Size: 60 bytes\n\n\ud83d\ude80 GET /health\n\ud83d\udcca Status: 200 | \u23f1\ufe0f  Time: 176.47ms | \ud83d\udce6 Size: 60 bytes\n\n\ud83d\ude80 GET /health\n\ud83d\udcca Status: 200 | \u23f1\ufe0f  Time: 194.22ms | \ud83d\udce6 Size: 60 bytes\n\n\ud83d\ude80 GET /health\n\ud83d\udcca Status: 200 | \u23f1\ufe0f  Time: 175.45ms | \ud83d\udce6 Size: 60 bytes\n\n\ud83d\ude80 GET /health\n\ud83d\udcca Status: 200 | \u23f1\ufe0f  Time: 183.24ms | \ud83d\udce6 Size: 60 bytes\n\n\ud83d\ude80 GET /health\n\ud83d\udcca Status: 200 | \u23f1\ufe0f  Time: 181.95ms | \ud83d\udce6 Size: 60 bytes\n\n\ud83d\ude80 GET /health\n\ud83d\udcca Status: 200 | \u23f1\ufe0f  Time: 183.95ms | \ud83d\udce6 Size: 60 bytes\n\n\ud83d\ude80 GET /health\n\ud83d\udcca Status: 200 | \u23f1\ufe0f  Time: 172.96ms | \ud83d\udce6 Size: 60 bytes\n\n\ud83d\ude80 GET /health\n\ud83d\udcca Status: 200 | \u23f1\ufe0f  Time: 184.26ms | \ud83d\udce6 Size: 60 bytes\n\n\ud83d\ude80 GET /health\n\ud83d\udcca Status: 200 | \u23f1\ufe0f  Time: 178.27ms | \ud83d\udce6 Size: 60 bytes\n\n\ud83d\ude80 GET /health\n\ud83d\udcca Status: 200 | \u23f1\ufe0f  Time: 188.04ms | \ud83d\udce6 Size: 60 bytes\n\n\ud83d\ude80 GET /health\n\ud83d\udcca Status: 200 | \u23f1\ufe0f  Time: 175.19ms | \ud83d\udce6 Size: 60 bytes\n\n\ud83d\ude80 GET /health\n\ud83d\udcca Status: 200 | \u23f1\ufe0f  Time: 178.63ms | \ud83d\udce6 Size: 60 bytes\n\n\ud83d\ude80 GET /health\n\ud83d\udcca Status: 200 | \u23f1\ufe0f  Time: 181.12ms | \ud83d\udce6 Size: 60 bytes\n  Making 20 requests... 0:00:13\n\u2705 Success rate: 100.0% (20/20)\n\u23f1\ufe0f  Avg response: 188.59ms\n\ud83d\udc0c Max response: 290.87ms\n\u26a1 Min response: 174.66ms\n"}, "teardown": {"duration": 0.0005025999998906627, "outcome": "passed"}}, {"nodeid": "test_performance.py::TestStressScenarios::test_large_payload_persona", "lineno": 149, "outcome": "failed", "keywords": ["test_large_payload_persona", "TestStressScenarios", "test_performance.py", "__init__.py", "api"], "setup": {"duration": 0.00042300000495743006, "outcome": "passed"}, "call": {"duration": 8.555240199995751, "outcome": "failed", "crash": {"path": "C:\\Projects\\building-os-platform\\.venv\\Lib\\site-packages\\requests\\adapters.py", "lineno": 510, "message": "requests.exceptions.RetryError: HTTPSConnectionPool(host='pj4vlvxrg7.execute-api.us-east-1.amazonaws.com', port=443): Max retries exceeded with url: /dev/persona (Caused by ResponseError('too many 500 error responses'))"}, "stdout": "\n\ud83d\ude80 POST /persona\n\u274c Request failed: \nHTTPSConnectionPool(host='pj4vlvxrg7.execute-api.us-east-1.amazonaws.com', \nport=443): Max retries exceeded with url: /dev/persona (Caused by \nResponseError('too many 500 error responses'))\n", "longrepr": "urllib3.exceptions.ResponseError: too many 500 error responses\n\nThe above exception was the direct cause of the following exception:\nE   urllib3.exceptions.MaxRetryError: HTTPSConnectionPool(host='pj4vlvxrg7.execute-api.us-east-1.amazonaws.com', port=443): Max retries exceeded with url: /dev/persona (Caused by ResponseError('too many 500 error responses'))\n\nDuring handling of the above exception, another exception occurred:\nE   requests.exceptions.RetryError: HTTPSConnectionPool(host='pj4vlvxrg7.execute-api.us-east-1.amazonaws.com', port=443): Max retries exceeded with url: /dev/persona (Caused by ResponseError('too many 500 error responses'))"}, "teardown": {"duration": 0.0004215000008116476, "outcome": "passed"}}, {"nodeid": "test_performance.py::TestStressScenarios::test_rapid_successive_requests", "lineno": 163, "outcome": "passed", "keywords": ["test_rapid_successive_requests", "TestStressScenarios", "test_performance.py", "__init__.py", "api"], "setup": {"duration": 0.00036330000148154795, "outcome": "passed"}, "call": {"duration": 1.831399299997429, "outcome": "passed", "stdout": "\n\ud83d\ude80 GET /health\n\ud83d\udcca Status: 200 | \u23f1\ufe0f  Time: 179.83ms | \ud83d\udce6 Size: 60 bytes\n\n\ud83d\ude80 GET /health\n\ud83d\udcca Status: 200 | \u23f1\ufe0f  Time: 178.19ms | \ud83d\udce6 Size: 60 bytes\n\n\ud83d\ude80 GET /health\n\ud83d\udcca Status: 200 | \u23f1\ufe0f  Time: 177.75ms | \ud83d\udce6 Size: 60 bytes\n\n\ud83d\ude80 GET /health\n\ud83d\udcca Status: 200 | \u23f1\ufe0f  Time: 195.57ms | \ud83d\udce6 Size: 60 bytes\n\n\ud83d\ude80 GET /health\n\ud83d\udcca Status: 200 | \u23f1\ufe0f  Time: 178.76ms | \ud83d\udce6 Size: 60 bytes\n\n\ud83d\ude80 GET /health\n\ud83d\udcca Status: 200 | \u23f1\ufe0f  Time: 177.37ms | \ud83d\udce6 Size: 60 bytes\n\n\ud83d\ude80 GET /health\n\ud83d\udcca Status: 200 | \u23f1\ufe0f  Time: 177.10ms | \ud83d\udce6 Size: 60 bytes\n\n\ud83d\ude80 GET /health\n\ud83d\udcca Status: 200 | \u23f1\ufe0f  Time: 183.76ms | \ud83d\udce6 Size: 60 bytes\n\n\ud83d\ude80 GET /health\n\ud83d\udcca Status: 200 | \u23f1\ufe0f  Time: 187.39ms | \ud83d\udce6 Size: 60 bytes\n\n\ud83d\ude80 GET /health\n\ud83d\udcca Status: 200 | \u23f1\ufe0f  Time: 178.66ms | \ud83d\udce6 Size: 60 bytes\n\ud83d\ude80 Rapid requests: 10 in 1.83s\n\u2705 Success rate: 100.0%\n"}, "teardown": {"duration": 0.0004279000058886595, "outcome": "passed"}}, {"nodeid": "test_performance.py::TestStressScenarios::test_special_characters_in_requests", "lineno": 189, "outcome": "failed", "keywords": ["test_special_characters_in_requests", "TestStressScenarios", "test_performance.py", "__init__.py", "api"], "setup": {"duration": 0.0003938000008929521, "outcome": "passed"}, "call": {"duration": 8.032357199997932, "outcome": "failed", "crash": {"path": "C:\\Projects\\building-os-platform\\.venv\\Lib\\site-packages\\requests\\adapters.py", "lineno": 510, "message": "requests.exceptions.RetryError: HTTPSConnectionPool(host='pj4vlvxrg7.execute-api.us-east-1.amazonaws.com', port=443): Max retries exceeded with url: /dev/persona (Caused by ResponseError('too many 500 error responses'))"}, "stdout": "\n\ud83d\ude80 POST /persona\n\u274c Request failed: \nHTTPSConnectionPool(host='pj4vlvxrg7.execute-api.us-east-1.amazonaws.com', \nport=443): Max retries exceeded with url: /dev/persona (Caused by \nResponseError('too many 500 error responses'))\n", "longrepr": "urllib3.exceptions.ResponseError: too many 500 error responses\n\nThe above exception was the direct cause of the following exception:\nE   urllib3.exceptions.MaxRetryError: HTTPSConnectionPool(host='pj4vlvxrg7.execute-api.us-east-1.amazonaws.com', port=443): Max retries exceeded with url: /dev/persona (Caused by ResponseError('too many 500 error responses'))\n\nDuring handling of the above exception, another exception occurred:\nE   requests.exceptions.RetryError: HTTPSConnectionPool(host='pj4vlvxrg7.execute-api.us-east-1.amazonaws.com', port=443): Max retries exceeded with url: /dev/persona (Caused by ResponseError('too many 500 error responses'))"}, "teardown": {"duration": 0.0004278999986127019, "outcome": "passed"}}, {"nodeid": "test_performance.py::TestBoundaryConditions::test_empty_payloads", "lineno": 213, "outcome": "failed", "keywords": ["test_empty_payloads", "TestBoundaryConditions", "test_performance.py", "__init__.py", "api"], "setup": {"duration": 0.0006685000043944456, "outcome": "passed"}, "call": {"duration": 8.037420199994813, "outcome": "failed", "crash": {"path": "C:\\Projects\\building-os-platform\\.venv\\Lib\\site-packages\\requests\\adapters.py", "lineno": 510, "message": "requests.exceptions.RetryError: HTTPSConnectionPool(host='pj4vlvxrg7.execute-api.us-east-1.amazonaws.com', port=443): Max retries exceeded with url: /dev/persona (Caused by ResponseError('too many 500 error responses'))"}, "stdout": "\n\ud83d\ude80 POST /persona\n\u274c Request failed: \nHTTPSConnectionPool(host='pj4vlvxrg7.execute-api.us-east-1.amazonaws.com', \nport=443): Max retries exceeded with url: /dev/persona (Caused by \nResponseError('too many 500 error responses'))\n", "longrepr": "urllib3.exceptions.ResponseError: too many 500 error responses\n\nThe above exception was the direct cause of the following exception:\nE   urllib3.exceptions.MaxRetryError: HTTPSConnectionPool(host='pj4vlvxrg7.execute-api.us-east-1.amazonaws.com', port=443): Max retries exceeded with url: /dev/persona (Caused by ResponseError('too many 500 error responses'))\n\nDuring handling of the above exception, another exception occurred:\nE   requests.exceptions.RetryError: HTTPSConnectionPool(host='pj4vlvxrg7.execute-api.us-east-1.amazonaws.com', port=443): Max retries exceeded with url: /dev/persona (Caused by ResponseError('too many 500 error responses'))"}, "teardown": {"duration": 0.00044829999387729913, "outcome": "passed"}}, {"nodeid": "test_performance.py::TestBoundaryConditions::test_null_values_in_payload", "lineno": 224, "outcome": "failed", "keywords": ["test_null_values_in_payload", "TestBoundaryConditions", "test_performance.py", "__init__.py", "api"], "setup": {"duration": 0.00041739999869605526, "outcome": "passed"}, "call": {"duration": 8.046196499999496, "outcome": "failed", "crash": {"path": "C:\\Projects\\building-os-platform\\.venv\\Lib\\site-packages\\requests\\adapters.py", "lineno": 510, "message": "requests.exceptions.RetryError: HTTPSConnectionPool(host='pj4vlvxrg7.execute-api.us-east-1.amazonaws.com', port=443): Max retries exceeded with url: /dev/persona (Caused by ResponseError('too many 500 error responses'))"}, "stdout": "\n\ud83d\ude80 POST /persona\n\u274c Request failed: \nHTTPSConnectionPool(host='pj4vlvxrg7.execute-api.us-east-1.amazonaws.com', \nport=443): Max retries exceeded with url: /dev/persona (Caused by \nResponseError('too many 500 error responses'))\n", "longrepr": "urllib3.exceptions.ResponseError: too many 500 error responses\n\nThe above exception was the direct cause of the following exception:\nE   urllib3.exceptions.MaxRetryError: HTTPSConnectionPool(host='pj4vlvxrg7.execute-api.us-east-1.amazonaws.com', port=443): Max retries exceeded with url: /dev/persona (Caused by ResponseError('too many 500 error responses'))\n\nDuring handling of the above exception, another exception occurred:\nE   requests.exceptions.RetryError: HTTPSConnectionPool(host='pj4vlvxrg7.execute-api.us-east-1.amazonaws.com', port=443): Max retries exceeded with url: /dev/persona (Caused by ResponseError('too many 500 error responses'))"}, "teardown": {"duration": 0.0010481999997864477, "outcome": "passed"}}, {"nodeid": "test_performance.py::TestBoundaryConditions::test_extremely_long_mission_id", "lineno": 233, "outcome": "failed", "keywords": ["test_extremely_long_mission_id", "TestBoundaryConditions", "test_performance.py", "__init__.py", "api"], "setup": {"duration": 0.00038640000275336206, "outcome": "passed"}, "call": {"duration": 8.272651100000076, "outcome": "failed", "crash": {"path": "C:\\Projects\\building-os-platform\\.venv\\Lib\\site-packages\\requests\\adapters.py", "lineno": 510, "message": "requests.exceptions.RetryError: HTTPSConnectionPool(host='pj4vlvxrg7.execute-api.us-east-1.amazonaws.com', port=443): Max retries exceeded with url: /dev/coordinator/missions/xxxxxxxxxxxxxxxxxxxxxxxxxxxxxxxxxxxxxxxxxxxxxxxxxxxxxxxxxxxxxxxxxxxxxxxxxxxxxxxxxxxxxxxxxxxxxxxxxxxxxxxxxxxxxxxxxxxxxxxxxxxxxxxxxxxxxxxxxxxxxxxxxxxxxxxxxxxxxxxxxxxxxxxxxxxxxxxxxxxxxxxxxxxxxxxxxxxxxxxxxxxxxxxxxxxxxxxxxxxxxxxxxxxxxxxxxxxxxxxxxxxxxxxxxxxxxxxxxxxxxxxxxxxxxxxxxxxxxxxxxxxxxxxxxxxxxxxxxxxxxxxxxxxxxxxxxxxxxxxxxxxxxxxxxxxxxxxxxxxxxxxxxxxxxxxxxxxxxxxxxxxxxxxxxxxxxxxxxxxxxxxxxxxxxxxxxxxxxxxxxxxxxxxxxxxxxxxxxxxxxxxxxxxxxxxxxxxxxxxxxxxxxxxxxxxxxxxxxxxxxxxxxxxxxxxxxxxxxxxxxxxxxxxxxxxxxxxxxxxxxxxxxxxxxxxxxxxxxxxxxxxxxxxxxxxxxxxxxxxxxxxxxxxxxxxxxxxxxxxxxxxxxxxxxxxxxxxxxxxxxxxxxxxxxxxxxxxxxxxxxxxxxxxxxxxxxxxxxxxxxxxxxxxxxxxxxxxxxxxxxxxxxxxxxxxxxxxxxxxxxxxxxxxxxxxxxxxxxxxxxxxxxxxxxxxxxxxxxxxxxxxxxxxxxxxxxxxxxxxxxxxxxxxxxxxxxxxxxxxxxxxxxxxxxxxxxxxxxxxxxxxxxxxxxxxxxxxxxxxxxxxxxxxxxxxxxxxxxxxxxxxxxxxxxxxxxxxxxxxxxxxxxxxxxxxxxxxxxxxxxxxxxxxxxxxxxxxxxxxxxxxxxxxxxxxxxxxxxxxxxxxxxxxxxxxxxxxxxxxxxxxxxxxxxxxxxxxxxxxxxxxxxxxxxxxxxxxxxxxxxxxxxxxxxxxxxxxxxxxxxxxxxxxxxxxxxxxxxxxxxxxxxxxxxxxxxxxxxxxx (Caused by ResponseError('too many 500 error responses'))"}, "stdout": "\n\ud83d\ude80 GET \n/coordinator/missions/xxxxxxxxxxxxxxxxxxxxxxxxxxxxxxxxxxxxxxxxxxxxxxxxxxxxxxxxx\nxxxxxxxxxxxxxxxxxxxxxxxxxxxxxxxxxxxxxxxxxxxxxxxxxxxxxxxxxxxxxxxxxxxxxxxxxxxxxxx\nxxxxxxxxxxxxxxxxxxxxxxxxxxxxxxxxxxxxxxxxxxxxxxxxxxxxxxxxxxxxxxxxxxxxxxxxxxxxxxx\nxxxxxxxxxxxxxxxxxxxxxxxxxxxxxxxxxxxxxxxxxxxxxxxxxxxxxxxxxxxxxxxxxxxxxxxxxxxxxxx\nxxxxxxxxxxxxxxxxxxxxxxxxxxxxxxxxxxxxxxxxxxxxxxxxxxxxxxxxxxxxxxxxxxxxxxxxxxxxxxx\nxxxxxxxxxxxxxxxxxxxxxxxxxxxxxxxxxxxxxxxxxxxxxxxxxxxxxxxxxxxxxxxxxxxxxxxxxxxxxxx\nxxxxxxxxxxxxxxxxxxxxxxxxxxxxxxxxxxxxxxxxxxxxxxxxxxxxxxxxxxxxxxxxxxxxxxxxxxxxxxx\nxxxxxxxxxxxxxxxxxxxxxxxxxxxxxxxxxxxxxxxxxxxxxxxxxxxxxxxxxxxxxxxxxxxxxxxxxxxxxxx\nxxxxxxxxxxxxxxxxxxxxxxxxxxxxxxxxxxxxxxxxxxxxxxxxxxxxxxxxxxxxxxxxxxxxxxxxxxxxxxx\nxxxxxxxxxxxxxxxxxxxxxxxxxxxxxxxxxxxxxxxxxxxxxxxxxxxxxxxxxxxxxxxxxxxxxxxxxxxxxxx\nxxxxxxxxxxxxxxxxxxxxxxxxxxxxxxxxxxxxxxxxxxxxxxxxxxxxxxxxxxxxxxxxxxxxxxxxxxxxxxx\nxxxxxxxxxxxxxxxxxxxxxxxxxxxxxxxxxxxxxxxxxxxxxxxxxxxxxxxxxxxxxxxxxxxxxxxxxxxxxxx\nxxxxxxxxxxxxxxxxxxxxxxxxxxxxxxxxxxxxxxxxxxxxxxxxxxxxxxxxxxxxxxxxxxxxxxxxxx\n\u274c Request failed: \nHTTPSConnectionPool(host='pj4vlvxrg7.execute-api.us-east-1.amazonaws.com', \nport=443): Max retries exceeded with url: \n/dev/coordinator/missions/xxxxxxxxxxxxxxxxxxxxxxxxxxxxxxxxxxxxxxxxxxxxxxxxxxxxx\nxxxxxxxxxxxxxxxxxxxxxxxxxxxxxxxxxxxxxxxxxxxxxxxxxxxxxxxxxxxxxxxxxxxxxxxxxxxxxxx\nxxxxxxxxxxxxxxxxxxxxxxxxxxxxxxxxxxxxxxxxxxxxxxxxxxxxxxxxxxxxxxxxxxxxxxxxxxxxxxx\nxxxxxxxxxxxxxxxxxxxxxxxxxxxxxxxxxxxxxxxxxxxxxxxxxxxxxxxxxxxxxxxxxxxxxxxxxxxxxxx\nxxxxxxxxxxxxxxxxxxxxxxxxxxxxxxxxxxxxxxxxxxxxxxxxxxxxxxxxxxxxxxxxxxxxxxxxxxxxxxx\nxxxxxxxxxxxxxxxxxxxxxxxxxxxxxxxxxxxxxxxxxxxxxxxxxxxxxxxxxxxxxxxxxxxxxxxxxxxxxxx\nxxxxxxxxxxxxxxxxxxxxxxxxxxxxxxxxxxxxxxxxxxxxxxxxxxxxxxxxxxxxxxxxxxxxxxxxxxxxxxx\nxxxxxxxxxxxxxxxxxxxxxxxxxxxxxxxxxxxxxxxxxxxxxxxxxxxxxxxxxxxxxxxxxxxxxxxxxxxxxxx\nxxxxxxxxxxxxxxxxxxxxxxxxxxxxxxxxxxxxxxxxxxxxxxxxxxxxxxxxxxxxxxxxxxxxxxxxxxxxxxx\nxxxxxxxxxxxxxxxxxxxxxxxxxxxxxxxxxxxxxxxxxxxxxxxxxxxxxxxxxxxxxxxxxxxxxxxxxxxxxxx\nxxxxxxxxxxxxxxxxxxxxxxxxxxxxxxxxxxxxxxxxxxxxxxxxxxxxxxxxxxxxxxxxxxxxxxxxxxxxxxx\nxxxxxxxxxxxxxxxxxxxxxxxxxxxxxxxxxxxxxxxxxxxxxxxxxxxxxxxxxxxxxxxxxxxxxxxxxxxxxxx\nxxxxxxxxxxxxxxxxxxxxxxxxxxxxxxxxxxxxxxxxxxxxxxxxxxxxxxxxxxxxxxxxxxxxxxxxxxxxxx \n(Caused by ResponseError('too many 500 error responses'))\n", "longrepr": "urllib3.exceptions.ResponseError: too many 500 error responses\n\nThe above exception was the direct cause of the following exception:\nE   urllib3.exceptions.MaxRetryError: HTTPSConnectionPool(host='pj4vlvxrg7.execute-api.us-east-1.amazonaws.com', port=443): Max retries exceeded with url: /dev/coordinator/missions/xxxxxxxxxxxxxxxxxxxxxxxxxxxxxxxxxxxxxxxxxxxxxxxxxxxxxxxxxxxxxxxxxxxxxxxxxxxxxxxxxxxxxxxxxxxxxxxxxxxxxxxxxxxxxxxxxxxxxxxxxxxxxxxxxxxxxxxxxxxxxxxxxxxxxxxxxxxxxxxxxxxxxxxxxxxxxxxxxxxxxxxxxxxxxxxxxxxxxxxxxxxxxxxxxxxxxxxxxxxxxxxxxxxxxxxxxxxxxxxxxxxxxxxxxxxxxxxxxxxxxxxxxxxxxxxxxxxxxxxxxxxxxxxxxxxxxxxxxxxxxxxxxxxxxxxxxxxxxxxxxxxxxxxxxxxxxxxxxxxxxxxxxxxxxxxxxxxxxxxxxxxxxxxxxxxxxxxxxxxxxxxxxxxxxxxxxxxxxxxxxxxxxxxxxxxxxxxxxxxxxxxxxxxxxxxxxxxxxxxxxxxxxxxxxxxxxxxxxxxxxxxxxxxxxxxxxxxxxxxxxxxxxxxxxxxxxxxxxxxxxxxxxxxxxxxxxxxxxxxxxxxxxxxxxxxxxxxxxxxxxxxxxxxxxxxxxxxxxxxxxxxxxxxxxxxxxxxxxxxxxxxxxxxxxxxxxxxxxxxxxxxxxxxxxxxxxxxxxxxxxxxxxxxxxxxxxxxxxxxxxxxxxxxxxxxxxxxxxxxxxxxxxxxxxxxxxxxxxxxxxxxxxxxxxxxxxxxxxxxxxxxxxxxxxxxxxxxxxxxxxxxxxxxxxxxxxxxxxxxxxxxxxxxxxxxxxxxxxxxxxxxxxxxxxxxxxxxxxxxxxxxxxxxxxxxxxxxxxxxxxxxxxxxxxxxxxxxxxxxxxxxxxxxxxxxxxxxxxxxxxxxxxxxxxxxxxxxxxxxxxxxxxxxxxxxxxxxxxxxxxxxxxxxxxxxxxxxxxxxxxxxxxxxxxxxxxxxxxxxxxxxxxxxxxxxxxxxxxxxxxxxxxxxxxxxxxxxxxxxxxxxxxxxxxxxxxxxxxxxxxxxxxxxxxxxxxxxxxxxx (Caused by ResponseError('too many 500 error responses'))\n\nDuring handling of the above exception, another exception occurred:\nE   requests.exceptions.RetryError: HTTPSConnectionPool(host='pj4vlvxrg7.execute-api.us-east-1.amazonaws.com', port=443): Max retries exceeded with url: /dev/coordinator/missions/xxxxxxxxxxxxxxxxxxxxxxxxxxxxxxxxxxxxxxxxxxxxxxxxxxxxxxxxxxxxxxxxxxxxxxxxxxxxxxxxxxxxxxxxxxxxxxxxxxxxxxxxxxxxxxxxxxxxxxxxxxxxxxxxxxxxxxxxxxxxxxxxxxxxxxxxxxxxxxxxxxxxxxxxxxxxxxxxxxxxxxxxxxxxxxxxxxxxxxxxxxxxxxxxxxxxxxxxxxxxxxxxxxxxxxxxxxxxxxxxxxxxxxxxxxxxxxxxxxxxxxxxxxxxxxxxxxxxxxxxxxxxxxxxxxxxxxxxxxxxxxxxxxxxxxxxxxxxxxxxxxxxxxxxxxxxxxxxxxxxxxxxxxxxxxxxxxxxxxxxxxxxxxxxxxxxxxxxxxxxxxxxxxxxxxxxxxxxxxxxxxxxxxxxxxxxxxxxxxxxxxxxxxxxxxxxxxxxxxxxxxxxxxxxxxxxxxxxxxxxxxxxxxxxxxxxxxxxxxxxxxxxxxxxxxxxxxxxxxxxxxxxxxxxxxxxxxxxxxxxxxxxxxxxxxxxxxxxxxxxxxxxxxxxxxxxxxxxxxxxxxxxxxxxxxxxxxxxxxxxxxxxxxxxxxxxxxxxxxxxxxxxxxxxxxxxxxxxxxxxxxxxxxxxxxxxxxxxxxxxxxxxxxxxxxxxxxxxxxxxxxxxxxxxxxxxxxxxxxxxxxxxxxxxxxxxxxxxxxxxxxxxxxxxxxxxxxxxxxxxxxxxxxxxxxxxxxxxxxxxxxxxxxxxxxxxxxxxxxxxxxxxxxxxxxxxxxxxxxxxxxxxxxxxxxxxxxxxxxxxxxxxxxxxxxxxxxxxxxxxxxxxxxxxxxxxxxxxxxxxxxxxxxxxxxxxxxxxxxxxxxxxxxxxxxxxxxxxxxxxxxxxxxxxxxxxxxxxxxxxxxxxxxxxxxxxxxxxxxxxxxxxxxxxxxxxxxxxxxxxxxxxxxxxxxxxxxxxxxxxxxxxxxxxxxxxxxxxxxxxxxxxxxxxxxxxxxxxxxxx (Caused by ResponseError('too many 500 error responses'))"}, "teardown": {"duration": 0.17531310000049416, "outcome": "passed", "stdout": "\n\ud83d\udcca Test Session Complete\n                              \ud83d\udd0d Request Summary                               \n\u250c\u2500\u2500\u2500\u2500\u2500\u2500\u2500\u2500\u252c\u2500\u2500\u2500\u2500\u2500\u2500\u2500\u2500\u2500\u2500\u2500\u2500\u2500\u2500\u2500\u2500\u2500\u2500\u2500\u2500\u2500\u2500\u2500\u2500\u2500\u2500\u2500\u2500\u2500\u2500\u2500\u2500\u2500\u2500\u2500\u2500\u2500\u252c\u2500\u2500\u2500\u2500\u2500\u2500\u2500\u2500\u252c\u2500\u2500\u2500\u2500\u2500\u2500\u2500\u2500\u2500\u2500\u2500\u252c\u2500\u2500\u2500\u2500\u2500\u2500\u2500\u2500\u2500\u2510\n\u2502 Method \u2502 Endpoint                            \u2502 Status \u2502 Time (ms) \u2502 Success \u2502\n\u251c\u2500\u2500\u2500\u2500\u2500\u2500\u2500\u2500\u253c\u2500\u2500\u2500\u2500\u2500\u2500\u2500\u2500\u2500\u2500\u2500\u2500\u2500\u2500\u2500\u2500\u2500\u2500\u2500\u2500\u2500\u2500\u2500\u2500\u2500\u2500\u2500\u2500\u2500\u2500\u2500\u2500\u2500\u2500\u2500\u2500\u2500\u253c\u2500\u2500\u2500\u2500\u2500\u2500\u2500\u2500\u253c\u2500\u2500\u2500\u2500\u2500\u2500\u2500\u2500\u2500\u2500\u2500\u253c\u2500\u2500\u2500\u2500\u2500\u2500\u2500\u2500\u2500\u2524\n\u2502 GET    \u2502 /health                             \u2502 200    \u2502 1589.12   \u2502 \u2705      \u2502\n\u2502 GET    \u2502 /health                             \u2502 200    \u2502 207.24    \u2502 \u2705      \u2502\n\u2502 GET    \u2502 /director                           \u2502 200    \u2502 4658.21   \u2502 \u2705      \u2502\n\u2502 GET    \u2502 /director?user_request=Test mission \u2502 200    \u2502 6943.37   \u2502 \u2705      \u2502\n\u2502        \u2502 from Python API tests               \u2502        \u2502           \u2502         \u2502\n\u2502 GET    \u2502 /director?user_id=api-test-user     \u2502 200    \u2502 3571.7    \u2502 \u2705      \u2502\n\u2502 POST   \u2502 /persona                            \u2502 0      \u2502 8889.66   \u2502 \u274c      \u2502\n\u2502 POST   \u2502 /persona                            \u2502 0      \u2502 8212.29   \u2502 \u274c      \u2502\n\u2502 POST   \u2502 /persona                            \u2502 0      \u2502 8172.61   \u2502 \u274c      \u2502\n\u2502 GET    \u2502 /persona/conversations?user_id=api\u2026 \u2502 0      \u2502 8065.73   \u2502 \u274c      \u2502\n\u2502 POST   \u2502 /elevator/call                      \u2502 0      \u2502 8402.6    \u2502 \u274c      \u2502\n\u2502 POST   \u2502 /elevator/call                      \u2502 0      \u2502 7778.21   \u2502 \u274c      \u2502\n\u2502 POST   \u2502 /psim/search                        \u2502 0      \u2502 8266.48   \u2502 \u274c      \u2502\n\u2502 POST   \u2502 /psim/search                        \u2502 0      \u2502 7725.66   \u2502 \u274c      \u2502\n\u2502 GET    \u2502 /coordinator/missions/test-mission\u2026 \u2502 0      \u2502 8341.59   \u2502 \u274c      \u2502\n\u2502 GET    \u2502 /coordinator/missions/python-test-\u2026 \u2502 0      \u2502 8766.4    \u2502 \u274c      \u2502\n\u2502 GET    \u2502 /health                             \u2502 200    \u2502 191.69    \u2502 \u2705      \u2502\n\u2502 GET    \u2502 /director                           \u2502 200    \u2502 4527.64   \u2502 \u2705      \u2502\n\u2502 POST   \u2502 /persona                            \u2502 0      \u2502 8265.89   \u2502 \u274c      \u2502\n\u2502 POST   \u2502 /elevator/call                      \u2502 0      \u2502 7774.91   \u2502 \u274c      \u2502\n\u2502 POST   \u2502 /psim/search                        \u2502 0      \u2502 7713.27   \u2502 \u274c      \u2502\n\u2502 GET    \u2502 /coordinator/missions/test-123      \u2502 0      \u2502 8280.04   \u2502 \u274c      \u2502\n\u2502 GET    \u2502 /invalid-endpoint                   \u2502 404    \u2502 165.26    \u2502 \u274c      \u2502\n\u2502 DELETE \u2502 /health                             \u2502 404    \u2502 173.03    \u2502 \u274c      \u2502\n\u2502 GET    \u2502 /health                             \u2502 200    \u2502 182.86    \u2502 \u2705      \u2502\n\u2502 GET    \u2502 /director                           \u2502 200    \u2502 3152.37   \u2502 \u2705      \u2502\n\u2502 GET    \u2502 /health                             \u2502 200    \u2502 199.07    \u2502 \u2705      \u2502\n\u2502 GET    \u2502 /health                             \u2502 200    \u2502 1537.93   \u2502 \u2705      \u2502\n\u2502 GET    \u2502 /health                             \u2502 200    \u2502 1589.76   \u2502 \u2705      \u2502\n\u2502 GET    \u2502 /health                             \u2502 200    \u2502 1624.7    \u2502 \u2705      \u2502\n\u2502 GET    \u2502 /health                             \u2502 200    \u2502 1641.77   \u2502 \u2705      \u2502\n\u2502 GET    \u2502 /health                             \u2502 200    \u2502 178.42    \u2502 \u2705      \u2502\n\u2502 GET    \u2502 /health                             \u2502 200    \u2502 176.0     \u2502 \u2705      \u2502\n\u2502 GET    \u2502 /health                             \u2502 200    \u2502 194.9     \u2502 \u2705      \u2502\n\u2502 GET    \u2502 /health                             \u2502 200    \u2502 186.3     \u2502 \u2705      \u2502\n\u2502 GET    \u2502 /health                             \u2502 200    \u2502 177.93    \u2502 \u2705      \u2502\n\u2502 GET    \u2502 /health                             \u2502 200    \u2502 288.96    \u2502 \u2705      \u2502\n\u2502 GET    \u2502 /health                             \u2502 200    \u2502 179.65    \u2502 \u2705      \u2502\n\u2502 GET    \u2502 /health                             \u2502 200    \u2502 176.47    \u2502 \u2705      \u2502\n\u2502 GET    \u2502 /health                             \u2502 200    \u2502 194.22    \u2502 \u2705      \u2502\n\u2502 GET    \u2502 /health                             \u2502 200    \u2502 175.45    \u2502 \u2705      \u2502\n\u2502 GET    \u2502 /health                             \u2502 200    \u2502 183.24    \u2502 \u2705      \u2502\n\u2502 GET    \u2502 /health                             \u2502 200    \u2502 181.95    \u2502 \u2705      \u2502\n\u2502 GET    \u2502 /health                             \u2502 200    \u2502 183.95    \u2502 \u2705      \u2502\n\u2502 GET    \u2502 /health                             \u2502 200    \u2502 172.96    \u2502 \u2705      \u2502\n\u2502 GET    \u2502 /health                             \u2502 200    \u2502 184.26    \u2502 \u2705      \u2502\n\u2502 GET    \u2502 /health                             \u2502 200    \u2502 178.27    \u2502 \u2705      \u2502\n\u2502 GET    \u2502 /health                             \u2502 200    \u2502 188.04    \u2502 \u2705      \u2502\n\u2502 GET    \u2502 /health                             \u2502 200    \u2502 175.19    \u2502 \u2705      \u2502\n\u2502 GET    \u2502 /health                             \u2502 200    \u2502 178.63    \u2502 \u2705      \u2502\n\u2502 GET    \u2502 /health                             \u2502 200    \u2502 181.12    \u2502 \u2705      \u2502\n\u2502 POST   \u2502 /persona                            \u2502 0      \u2502 8552.47   \u2502 \u274c      \u2502\n\u2502 GET    \u2502 /health                             \u2502 200    \u2502 179.83    \u2502 \u2705      \u2502\n\u2502 GET    \u2502 /health                             \u2502 200    \u2502 178.19    \u2502 \u2705      \u2502\n\u2502 GET    \u2502 /health                             \u2502 200    \u2502 177.75    \u2502 \u2705      \u2502\n\u2502 GET    \u2502 /health                             \u2502 200    \u2502 195.57    \u2502 \u2705      \u2502\n\u2502 GET    \u2502 /health                             \u2502 200    \u2502 178.76    \u2502 \u2705      \u2502\n\u2502 GET    \u2502 /health                             \u2502 200    \u2502 177.37    \u2502 \u2705      \u2502\n\u2502 GET    \u2502 /health                             \u2502 200    \u2502 177.1     \u2502 \u2705      \u2502\n\u2502 GET    \u2502 /health                             \u2502 200    \u2502 183.76    \u2502 \u2705      \u2502\n\u2502 GET    \u2502 /health                             \u2502 200    \u2502 187.39    \u2502 \u2705      \u2502\n\u2502 GET    \u2502 /health                             \u2502 200    \u2502 178.66    \u2502 \u2705      \u2502\n\u2502 POST   \u2502 /persona                            \u2502 0      \u2502 8029.67   \u2502 \u274c      \u2502\n\u2502 POST   \u2502 /persona                            \u2502 0      \u2502 8033.49   \u2502 \u274c      \u2502\n\u2502 POST   \u2502 /persona                            \u2502 0      \u2502 8043.42   \u2502 \u274c      \u2502\n\u2502 GET    \u2502 /coordinator/missions/xxxxxxxxxxxx\u2026 \u2502 0      \u2502 8263.22   \u2502 \u274c      \u2502\n\u2514\u2500\u2500\u2500\u2500\u2500\u2500\u2500\u2500\u2534\u2500\u2500\u2500\u2500\u2500\u2500\u2500\u2500\u2500\u2500\u2500\u2500\u2500\u2500\u2500\u2500\u2500\u2500\u2500\u2500\u2500\u2500\u2500\u2500\u2500\u2500\u2500\u2500\u2500\u2500\u2500\u2500\u2500\u2500\u2500\u2500\u2500\u2534\u2500\u2500\u2500\u2500\u2500\u2500\u2500\u2500\u2534\u2500\u2500\u2500\u2500\u2500\u2500\u2500\u2500\u2500\u2500\u2500\u2534\u2500\u2500\u2500\u2500\u2500\u2500\u2500\u2500\u2500\u2518\n\u250c\u2500\u2500\u2500\u2500\u2500\u2500\u2500\u2500\u2500\u2500\u2500\u2500\u2500\u2500\u2500\u2500\u2500\u2500\u2500\u2500\u2500\u2500\u2500\u2500\u2500\u2500\u2500\u2500 Performance Metrics \u2500\u2500\u2500\u2500\u2500\u2500\u2500\u2500\u2500\u2500\u2500\u2500\u2500\u2500\u2500\u2500\u2500\u2500\u2500\u2500\u2500\u2500\u2500\u2500\u2500\u2500\u2500\u2500\u2510\n\u2502 \ud83d\udcc8 Avg: 844.72ms | \u26a1 Min: 172.96ms | \ud83d\udc0c Max: 6943.37ms                     \u2502\n\u2514\u2500\u2500\u2500\u2500\u2500\u2500\u2500\u2500\u2500\u2500\u2500\u2500\u2500\u2500\u2500\u2500\u2500\u2500\u2500\u2500\u2500\u2500\u2500\u2500\u2500\u2500\u2500\u2500\u2500\u2500\u2500\u2500\u2500\u2500\u2500\u2500\u2500\u2500\u2500\u2500\u2500\u2500\u2500\u2500\u2500\u2500\u2500\u2500\u2500\u2500\u2500\u2500\u2500\u2500\u2500\u2500\u2500\u2500\u2500\u2500\u2500\u2500\u2500\u2500\u2500\u2500\u2500\u2500\u2500\u2500\u2500\u2500\u2500\u2500\u2500\u2500\u2500\u2518\n\ud83d\udcbe Results exported to: api-test-results-20250809-183352.json\n"}}], "warnings": [{"message": "Unknown pytest.mark.slow - is this a typo?  You can register custom marks to avoid this warning - for details, see https://docs.pytest.org/en/stable/how-to/mark.html", "category": "PytestUnknownMarkWarning", "when": "collect", "filename": "c:\\Projects\\building-os-platform\\tests\\api\\test_performance.py", "lineno": 73}, {"message": "Unknown pytest.mark.slow - is this a typo?  You can register custom marks to avoid this warning - for details, see https://docs.pytest.org/en/stable/how-to/mark.html", "category": "PytestUnknownMarkWarning", "when": "collect", "filename": "c:\\Projects\\building-os-platform\\tests\\api\\test_performance.py", "lineno": 245}, {"message": "Unknown pytest.mark.load - is this a typo?  You can register custom marks to avoid this warning - for details, see https://docs.pytest.org/en/stable/how-to/mark.html", "category": "PytestUnknownMarkWarning", "when": "collect", "filename": "c:\\Projects\\building-os-platform\\tests\\api\\test_performance.py", "lineno": 246}]}