{"created": 1754785062.4714582, "duration": 1229.150420665741, "exitcode": 1, "root": "C:\\Projects\\building-os-platform\\tests\\api", "environment": {}, "summary": {"passed": 15, "failed": 18, "total": 33, "collected": 33}, "collectors": [{"nodeid": "", "outcome": "passed", "result": [{"nodeid": "__init__.py", "type": "Package"}]}, {"nodeid": "test_endpoints.py::TestPayloads", "outcome": "passed", "result": []}, {"nodeid": "test_endpoints.py::TestHealthEndpoint", "outcome": "passed", "result": [{"nodeid": "test_endpoints.py::TestHealthEndpoint::test_health_check_success", "type": "Function", "lineno": 14}, {"nodeid": "test_endpoints.py::TestHealthEndpoint::test_health_check_performance", "type": "Function", "lineno": 23}]}, {"nodeid": "test_endpoints.py::TestDirectorEndpoint", "outcome": "passed", "result": [{"nodeid": "test_endpoints.py::TestDirectorEndpoint::test_director_basic_request", "type": "Function", "lineno": 37}, {"nodeid": "test_endpoints.py::TestDirectorEndpoint::test_director_with_user_request", "type": "Function", "lineno": 46}, {"nodeid": "test_endpoints.py::TestDirectorEndpoint::test_director_with_user_id", "type": "Function", "lineno": 56}]}, {"nodeid": "test_endpoints.py::TestPersonaEndpoint", "outcome": "passed", "result": [{"nodeid": "test_endpoints.py::TestPersonaEndpoint::test_persona_valid_message", "type": "Function", "lineno": 68}, {"nodeid": "test_endpoints.py::TestPersonaEndpoint::test_persona_missing_user_id", "type": "Function", "lineno": 81}, {"nodeid": "test_endpoints.py::TestPersonaEndpoint::test_persona_missing_message", "type": "Function", "lineno": 89}, {"nodeid": "test_endpoints.py::TestPersonaEndpoint::test_persona_conversations", "type": "Function", "lineno": 97}]}, {"nodeid": "test_endpoints.py::TestElevatorEndpoint", "outcome": "passed", "result": [{"nodeid": "test_endpoints.py::TestElevatorEndpoint::test_elevator_call_basic", "type": "Function", "lineno": 109}, {"nodeid": "test_endpoints.py::TestElevatorEndpoint::test_elevator_missing_mission_id", "type": "Function", "lineno": 120}]}, {"nodeid": "test_endpoints.py::TestPSIMEndpoint", "outcome": "passed", "result": [{"nodeid": "test_endpoints.py::TestPSIMEndpoint::test_psim_search_basic", "type": "Function", "lineno": 132}, {"nodeid": "test_endpoints.py::TestPSIMEndpoint::test_psim_search_with_custom_query", "type": "Function", "lineno": 142}]}, {"nodeid": "test_endpoints.py::TestCoordinatorEndpoint", "outcome": "passed", "result": [{"nodeid": "test_endpoints.py::TestCoordinatorEndpoint::test_coordinator_mission_status", "type": "Function", "lineno": 155}, {"nodeid": "test_endpoints.py::TestCoordinatorEndpoint::test_coordinator_different_mission_id", "type": "Function", "lineno": 166}]}, {"nodeid": "test_endpoints.py::TestCORSHeaders", "outcome": "passed", "result": [{"nodeid": "test_endpoints.py::TestCORSHeaders::test_cors_headers_present[/health]", "type": "Function", "lineno": 178}, {"nodeid": "test_endpoints.py::TestCORSHeaders::test_cors_headers_present[/director]", "type": "Function", "lineno": 178}, {"nodeid": "test_endpoints.py::TestCORSHeaders::test_cors_headers_present[/persona]", "type": "Function", "lineno": 178}, {"nodeid": "test_endpoints.py::TestCORSHeaders::test_cors_headers_present[/elevator/call]", "type": "Function", "lineno": 178}, {"nodeid": "test_endpoints.py::TestCORSHeaders::test_cors_headers_present[/psim/search]", "type": "Function", "lineno": 178}, {"nodeid": "test_endpoints.py::TestCORSHeaders::test_cors_headers_present[/coordinator/missions/test-123]", "type": "Function", "lineno": 178}]}, {"nodeid": "test_endpoints.py::TestErrorHandling", "outcome": "passed", "result": [{"nodeid": "test_endpoints.py::TestErrorHandling::test_invalid_endpoint", "type": "Function", "lineno": 220}, {"nodeid": "test_endpoints.py::TestErrorHandling::test_invalid_method", "type": "Function", "lineno": 225}, {"nodeid": "test_endpoints.py::TestErrorHandling::test_malformed_json", "type": "Function", "lineno": 235}]}, {"nodeid": "test_endpoints.py", "outcome": "passed", "result": [{"nodeid": "test_endpoints.py::TestPayloads", "type": "Class"}, {"nodeid": "test_endpoints.py::TestHealthEndpoint", "type": "Class"}, {"nodeid": "test_endpoints.py::TestDirectorEndpoint", "type": "Class"}, {"nodeid": "test_endpoints.py::TestPersonaEndpoint", "type": "Class"}, {"nodeid": "test_endpoints.py::TestElevatorEndpoint", "type": "Class"}, {"nodeid": "test_endpoints.py::TestPSIMEndpoint", "type": "Class"}, {"nodeid": "test_endpoints.py::TestCoordinatorEndpoint", "type": "Class"}, {"nodeid": "test_endpoints.py::TestCORSHeaders", "type": "Class"}, {"nodeid": "test_endpoints.py::TestErrorHandling", "type": "Class"}]}, {"nodeid": "test_performance.py::TestPerformance", "outcome": "passed", "result": [{"nodeid": "test_performance.py::TestPerformance::test_response_time_under_threshold", "type": "Function", "lineno": 18}, {"nodeid": "test_performance.py::TestPerformance::test_concurrent_health_checks", "type": "Function", "lineno": 45}]}, {"nodeid": "test_performance.py::TestLoadTesting", "outcome": "passed", "result": [{"nodeid": "test_performance.py::TestLoadTesting::test_sustained_load_health_endpoint", "type": "Function", "lineno": 72}]}, {"nodeid": "test_performance.py::TestStressScenarios", "outcome": "passed", "result": [{"nodeid": "test_performance.py::TestStressScenarios::test_large_payload_persona", "type": "Function", "lineno": 149}, {"nodeid": "test_performance.py::TestStressScenarios::test_rapid_successive_requests", "type": "Function", "lineno": 163}, {"nodeid": "test_performance.py::TestStressScenarios::test_special_characters_in_requests", "type": "Function", "lineno": 189}]}, {"nodeid": "test_performance.py::TestBoundaryConditions", "outcome": "passed", "result": [{"nodeid": "test_performance.py::TestBoundaryConditions::test_empty_payloads", "type": "Function", "lineno": 213}, {"nodeid": "test_performance.py::TestBoundaryConditions::test_null_values_in_payload", "type": "Function", "lineno": 224}, {"nodeid": "test_performance.py::TestBoundaryConditions::test_extremely_long_mission_id", "type": "Function", "lineno": 233}]}, {"nodeid": "test_performance.py", "outcome": "passed", "result": [{"nodeid": "test_performance.py::TestPerformance", "type": "Class"}, {"nodeid": "test_performance.py::TestLoadTesting", "type": "Class"}, {"nodeid": "test_performance.py::TestStressScenarios", "type": "Class"}, {"nodeid": "test_performance.py::TestBoundaryConditions", "type": "Class"}]}, {"nodeid": "__init__.py", "outcome": "passed", "result": [{"nodeid": "test_endpoints.py", "type": "Module"}, {"nodeid": "test_performance.py", "type": "Module"}]}], "tests": [{"nodeid": "test_endpoints.py::TestHealthEndpoint::test_health_check_success", "lineno": 14, "outcome": "passed", "keywords": ["test_health_check_success", "TestHealthEndpoint", "test_endpoints.py", "__init__.py", "api"], "setup": {"duration": 0.009329000000434462, "outcome": "passed", "stdout": "\n\ud83e\uddea Starting BuildingOS API Test Suite\n\ud83c\udf10 Base URL: https://pj4vlvxrg7.execute-api.us-east-1.amazonaws.com/dev\n\ud83c\udff7\ufe0f  Environment: dev\n"}, "call": {"duration": 1.527426699998614, "outcome": "passed", "stdout": "\n\ud83d\ude80 GET /health\n\ud83d\udcca Status: 200 | \u23f1\ufe0f  Time: 1524.26ms | \ud83d\udce6 Size: 60 bytes\n"}, "teardown": {"duration": 0.0009057999996002764, "outcome": "passed", "stdout": "\n"}}, {"nodeid": "test_endpoints.py::TestHealthEndpoint::test_health_check_performance", "lineno": 23, "outcome": "passed", "keywords": ["test_health_check_performance", "TestHealthEndpoint", "test_endpoints.py", "__init__.py", "api"], "setup": {"duration": 0.0005718999964301474, "outcome": "passed"}, "call": {"duration": 0.22189619999699062, "outcome": "passed", "stdout": "\n\ud83d\ude80 GET /health\n\ud83d\udcca Status: 200 | \u23f1\ufe0f  Time: 218.74ms | \ud83d\udce6 Size: 60 bytes\n"}, "teardown": {"duration": 0.0011709000027622096, "outcome": "passed", "stdout": "\n"}}, {"nodeid": "test_endpoints.py::TestDirectorEndpoint::test_director_basic_request", "lineno": 37, "outcome": "failed", "keywords": ["test_director_basic_request", "TestDirectorEndpoint", "test_endpoints.py", "__init__.py", "api"], "setup": {"duration": 0.0006424000021070242, "outcome": "passed"}, "call": {"duration": 128.9307772999964, "outcome": "failed", "crash": {"path": "C:\\Projects\\building-os-platform\\.venv\\Lib\\site-packages\\requests\\adapters.py", "lineno": 519, "message": "requests.exceptions.ConnectionError: HTTPSConnectionPool(host='pj4vlvxrg7.execute-api.us-east-1.amazonaws.com', port=443): Max retries exceeded with url: /dev/director (Caused by ReadTimeoutError(\"HTTPSConnectionPool(host='pj4vlvxrg7.execute-api.us-east-1.amazonaws.com', port=443): Read timed out. (read timeout=30)\"))"}, "stdout": "\n\ud83d\ude80 GET /director\n\u274c Request failed: \nHTTPSConnectionPool(host='pj4vlvxrg7.execute-api.us-east-1.amazonaws.com', \nport=443): Max retries exceeded with url: /dev/director (Caused by \nReadTimeoutError(\"HTTPSConnectionPool(host='pj4vlvxrg7.execute-api.us-east-1.am\nazonaws.com', port=443): Read timed out. (read timeout=30)\"))\n", "log": [{"name": "urllib3.connectionpool", "msg": "Retrying (Retry(total=2, connect=None, read=None, redirect=None, status=None)) after connection broken by 'ReadTimeoutError(\"HTTPSConnectionPool(host='pj4vlvxrg7.execute-api.us-east-1.amazonaws.com', port=443): Read timed out. (read timeout=30)\")': /dev/director", "args": null, "levelname": "WARNING", "levelno": 30, "pathname": "C:\\Projects\\building-os-platform\\.venv\\Lib\\site-packages\\urllib3\\connectionpool.py", "filename": "connectionpool.py", "module": "connectionpool", "exc_info": null, "exc_text": null, "stack_info": null, "lineno": 868, "funcName": "urlopen", "created": 1754783866.0706913, "msecs": 70.0, "relativeCreated": 33242.9497, "thread": 15912, "threadName": "MainThread", "processName": "MainProcess", "process": 10740, "taskName": null}, {"name": "urllib3.connectionpool", "msg": "Retrying (Retry(total=1, connect=None, read=None, redirect=None, status=None)) after connection broken by 'ReadTimeoutError(\"HTTPSConnectionPool(host='pj4vlvxrg7.execute-api.us-east-1.amazonaws.com', port=443): Read timed out. (read timeout=30)\")': /dev/director", "args": null, "levelname": "WARNING", "levelno": 30, "pathname": "C:\\Projects\\building-os-platform\\.venv\\Lib\\site-packages\\urllib3\\connectionpool.py", "filename": "connectionpool.py", "module": "connectionpool", "exc_info": null, "exc_text": null, "stack_info": null, "lineno": 868, "funcName": "urlopen", "created": 1754783899.0558019, "msecs": 55.0, "relativeCreated": 66228.0603, "thread": 15912, "threadName": "MainThread", "processName": "MainProcess", "process": 10740, "taskName": null}, {"name": "urllib3.connectionpool", "msg": "Retrying (Retry(total=0, connect=None, read=None, redirect=None, status=None)) after connection broken by 'ReadTimeoutError(\"HTTPSConnectionPool(host='pj4vlvxrg7.execute-api.us-east-1.amazonaws.com', port=443): Read timed out. (read timeout=30)\")': /dev/director", "args": null, "levelname": "WARNING", "levelno": 30, "pathname": "C:\\Projects\\building-os-platform\\.venv\\Lib\\site-packages\\urllib3\\connectionpool.py", "filename": "connectionpool.py", "module": "connectionpool", "exc_info": null, "exc_text": null, "stack_info": null, "lineno": 868, "funcName": "urlopen", "created": 1754783934.0244877, "msecs": 24.0, "relativeCreated": 101196.7461, "thread": 15912, "threadName": "MainThread", "processName": "MainProcess", "process": 10740, "taskName": null}], "longrepr": "E   TimeoutError: The read operation timed out\n\nThe above exception was the direct cause of the following exception:\nE   urllib3.exceptions.ReadTimeoutError: HTTPSConnectionPool(host='pj4vlvxrg7.execute-api.us-east-1.amazonaws.com', port=443): Read timed out. (read timeout=30)\n\nThe above exception was the direct cause of the following exception:\nE   urllib3.exceptions.MaxRetryError: HTTPSConnectionPool(host='pj4vlvxrg7.execute-api.us-east-1.amazonaws.com', port=443): Max retries exceeded with url: /dev/director (Caused by ReadTimeoutError(\"HTTPSConnectionPool(host='pj4vlvxrg7.execute-api.us-east-1.amazonaws.com', port=443): Read timed out. (read timeout=30)\"))\n\nDuring handling of the above exception, another exception occurred:\nE   requests.exceptions.ConnectionError: HTTPSConnectionPool(host='pj4vlvxrg7.execute-api.us-east-1.amazonaws.com', port=443): Max retries exceeded with url: /dev/director (Caused by ReadTimeoutError(\"HTTPSConnectionPool(host='pj4vlvxrg7.execute-api.us-east-1.amazonaws.com', port=443): Read timed out. (read timeout=30)\"))"}, "teardown": {"duration": 0.0009325999999418855, "outcome": "passed", "stdout": "\n"}}, {"nodeid": "test_endpoints.py::TestDirectorEndpoint::test_director_with_user_request", "lineno": 46, "outcome": "failed", "keywords": ["test_director_with_user_request", "TestDirectorEndpoint", "test_endpoints.py", "__init__.py", "api"], "setup": {"duration": 0.0005791000003227964, "outcome": "passed"}, "call": {"duration": 129.9175991000011, "outcome": "failed", "crash": {"path": "C:\\Projects\\building-os-platform\\.venv\\Lib\\site-packages\\requests\\adapters.py", "lineno": 519, "message": "requests.exceptions.ConnectionError: HTTPSConnectionPool(host='pj4vlvxrg7.execute-api.us-east-1.amazonaws.com', port=443): Max retries exceeded with url: /dev/director?user_request=Test%20mission%20from%20Python%20API%20tests (Caused by ReadTimeoutError(\"HTTPSConnectionPool(host='pj4vlvxrg7.execute-api.us-east-1.amazonaws.com', port=443): Read timed out. (read timeout=30)\"))"}, "stdout": "\n\ud83d\ude80 GET /director?user_request=Test mission from Python API tests\n\u274c Request failed: \nHTTPSConnectionPool(host='pj4vlvxrg7.execute-api.us-east-1.amazonaws.com', \nport=443): Max retries exceeded with url: \n/dev/director?user_request=Test%20mission%20from%20Python%20API%20tests (Caused\nby \nReadTimeoutError(\"HTTPSConnectionPool(host='pj4vlvxrg7.execute-api.us-east-1.am\nazonaws.com', port=443): Read timed out. (read timeout=30)\"))\n", "log": [{"name": "urllib3.connectionpool", "msg": "Retrying (Retry(total=2, connect=None, read=None, redirect=None, status=None)) after connection broken by 'ReadTimeoutError(\"HTTPSConnectionPool(host='pj4vlvxrg7.execute-api.us-east-1.amazonaws.com', port=443): Read timed out. (read timeout=30)\")': /dev/director?user_request=Test%20mission%20from%20Python%20API%20tests", "args": null, "levelname": "WARNING", "levelno": 30, "pathname": "C:\\Projects\\building-os-platform\\.venv\\Lib\\site-packages\\urllib3\\connectionpool.py", "filename": "connectionpool.py", "module": "connectionpool", "exc_info": null, "exc_text": null, "stack_info": null, "lineno": 868, "funcName": "urlopen", "created": 1754783995.9957151, "msecs": 995.0, "relativeCreated": 163167.9737, "thread": 15912, "threadName": "MainThread", "processName": "MainProcess", "process": 10740, "taskName": null}, {"name": "urllib3.connectionpool", "msg": "Retrying (Retry(total=1, connect=None, read=None, redirect=None, status=None)) after connection broken by 'ReadTimeoutError(\"HTTPSConnectionPool(host='pj4vlvxrg7.execute-api.us-east-1.amazonaws.com', port=443): Read timed out. (read timeout=30)\")': /dev/director?user_request=Test%20mission%20from%20Python%20API%20tests", "args": null, "levelname": "WARNING", "levelno": 30, "pathname": "C:\\Projects\\building-os-platform\\.venv\\Lib\\site-packages\\urllib3\\connectionpool.py", "filename": "connectionpool.py", "module": "connectionpool", "exc_info": null, "exc_text": null, "stack_info": null, "lineno": 868, "funcName": "urlopen", "created": 1754784028.9555256, "msecs": 955.0, "relativeCreated": 196127.7842, "thread": 15912, "threadName": "MainThread", "processName": "MainProcess", "process": 10740, "taskName": null}, {"name": "urllib3.connectionpool", "msg": "Retrying (Retry(total=0, connect=None, read=None, redirect=None, status=None)) after connection broken by 'ReadTimeoutError(\"HTTPSConnectionPool(host='pj4vlvxrg7.execute-api.us-east-1.amazonaws.com', port=443): Read timed out. (read timeout=30)\")': /dev/director?user_request=Test%20mission%20from%20Python%20API%20tests", "args": null, "levelname": "WARNING", "levelno": 30, "pathname": "C:\\Projects\\building-os-platform\\.venv\\Lib\\site-packages\\urllib3\\connectionpool.py", "filename": "connectionpool.py", "module": "connectionpool", "exc_info": null, "exc_text": null, "stack_info": null, "lineno": 868, "funcName": "urlopen", "created": 1754784063.96143, "msecs": 961.0, "relativeCreated": 231133.6884, "thread": 15912, "threadName": "MainThread", "processName": "MainProcess", "process": 10740, "taskName": null}], "longrepr": "E   TimeoutError: The read operation timed out\n\nThe above exception was the direct cause of the following exception:\nE   urllib3.exceptions.ReadTimeoutError: HTTPSConnectionPool(host='pj4vlvxrg7.execute-api.us-east-1.amazonaws.com', port=443): Read timed out. (read timeout=30)\n\nThe above exception was the direct cause of the following exception:\nE   urllib3.exceptions.MaxRetryError: HTTPSConnectionPool(host='pj4vlvxrg7.execute-api.us-east-1.amazonaws.com', port=443): Max retries exceeded with url: /dev/director?user_request=Test%20mission%20from%20Python%20API%20tests (Caused by ReadTimeoutError(\"HTTPSConnectionPool(host='pj4vlvxrg7.execute-api.us-east-1.amazonaws.com', port=443): Read timed out. (read timeout=30)\"))\n\nDuring handling of the above exception, another exception occurred:\nE   requests.exceptions.ConnectionError: HTTPSConnectionPool(host='pj4vlvxrg7.execute-api.us-east-1.amazonaws.com', port=443): Max retries exceeded with url: /dev/director?user_request=Test%20mission%20from%20Python%20API%20tests (Caused by ReadTimeoutError(\"HTTPSConnectionPool(host='pj4vlvxrg7.execute-api.us-east-1.amazonaws.com', port=443): Read timed out. (read timeout=30)\"))"}, "teardown": {"duration": 0.0009108000012929551, "outcome": "passed", "stdout": "\n"}}, {"nodeid": "test_endpoints.py::TestDirectorEndpoint::test_director_with_user_id", "lineno": 56, "outcome": "failed", "keywords": ["test_director_with_user_id", "TestDirectorEndpoint", "test_endpoints.py", "__init__.py", "api"], "setup": {"duration": 0.0005005999992135912, "outcome": "passed"}, "call": {"duration": 130.13657450000028, "outcome": "failed", "crash": {"path": "C:\\Projects\\building-os-platform\\.venv\\Lib\\site-packages\\requests\\adapters.py", "lineno": 519, "message": "requests.exceptions.ConnectionError: HTTPSConnectionPool(host='pj4vlvxrg7.execute-api.us-east-1.amazonaws.com', port=443): Max retries exceeded with url: /dev/director?user_id=api-test-user (Caused by ReadTimeoutError(\"HTTPSConnectionPool(host='pj4vlvxrg7.execute-api.us-east-1.amazonaws.com', port=443): Read timed out. (read timeout=30)\"))"}, "stdout": "\n\ud83d\ude80 GET /director?user_id=api-test-user\n\u274c Request failed: \nHTTPSConnectionPool(host='pj4vlvxrg7.execute-api.us-east-1.amazonaws.com', \nport=443): Max retries exceeded with url: /dev/director?user_id=api-test-user \n(Caused by \nReadTimeoutError(\"HTTPSConnectionPool(host='pj4vlvxrg7.execute-api.us-east-1.am\nazonaws.com', port=443): Read timed out. (read timeout=30)\"))\n", "log": [{"name": "urllib3.connectionpool", "msg": "Retrying (Retry(total=2, connect=None, read=None, redirect=None, status=None)) after connection broken by 'ReadTimeoutError(\"HTTPSConnectionPool(host='pj4vlvxrg7.execute-api.us-east-1.amazonaws.com', port=443): Read timed out. (read timeout=30)\")': /dev/director?user_id=api-test-user", "args": null, "levelname": "WARNING", "levelno": 30, "pathname": "C:\\Projects\\building-os-platform\\.venv\\Lib\\site-packages\\urllib3\\connectionpool.py", "filename": "connectionpool.py", "module": "connectionpool", "exc_info": null, "exc_text": null, "stack_info": null, "lineno": 868, "funcName": "urlopen", "created": 1754784125.990421, "msecs": 990.0, "relativeCreated": 293162.6794, "thread": 15912, "threadName": "MainThread", "processName": "MainProcess", "process": 10740, "taskName": null}, {"name": "urllib3.connectionpool", "msg": "Retrying (Retry(total=1, connect=None, read=None, redirect=None, status=None)) after connection broken by 'ReadTimeoutError(\"HTTPSConnectionPool(host='pj4vlvxrg7.execute-api.us-east-1.amazonaws.com', port=443): Read timed out. (read timeout=30)\")': /dev/director?user_id=api-test-user", "args": null, "levelname": "WARNING", "levelno": 30, "pathname": "C:\\Projects\\building-os-platform\\.venv\\Lib\\site-packages\\urllib3\\connectionpool.py", "filename": "connectionpool.py", "module": "connectionpool", "exc_info": null, "exc_text": null, "stack_info": null, "lineno": 868, "funcName": "urlopen", "created": 1754784159.006667, "msecs": 6.0, "relativeCreated": 326178.9255, "thread": 15912, "threadName": "MainThread", "processName": "MainProcess", "process": 10740, "taskName": null}, {"name": "urllib3.connectionpool", "msg": "Retrying (Retry(total=0, connect=None, read=None, redirect=None, status=None)) after connection broken by 'ReadTimeoutError(\"HTTPSConnectionPool(host='pj4vlvxrg7.execute-api.us-east-1.amazonaws.com', port=443): Read timed out. (read timeout=30)\")': /dev/director?user_id=api-test-user", "args": null, "levelname": "WARNING", "levelno": 30, "pathname": "C:\\Projects\\building-os-platform\\.venv\\Lib\\site-packages\\urllib3\\connectionpool.py", "filename": "connectionpool.py", "module": "connectionpool", "exc_info": null, "exc_text": null, "stack_info": null, "lineno": 868, "funcName": "urlopen", "created": 1754784194.0620332, "msecs": 62.0, "relativeCreated": 361234.2916, "thread": 15912, "threadName": "MainThread", "processName": "MainProcess", "process": 10740, "taskName": null}], "longrepr": "E   TimeoutError: The read operation timed out\n\nThe above exception was the direct cause of the following exception:\nE   urllib3.exceptions.ReadTimeoutError: HTTPSConnectionPool(host='pj4vlvxrg7.execute-api.us-east-1.amazonaws.com', port=443): Read timed out. (read timeout=30)\n\nThe above exception was the direct cause of the following exception:\nE   urllib3.exceptions.MaxRetryError: HTTPSConnectionPool(host='pj4vlvxrg7.execute-api.us-east-1.amazonaws.com', port=443): Max retries exceeded with url: /dev/director?user_id=api-test-user (Caused by ReadTimeoutError(\"HTTPSConnectionPool(host='pj4vlvxrg7.execute-api.us-east-1.amazonaws.com', port=443): Read timed out. (read timeout=30)\"))\n\nDuring handling of the above exception, another exception occurred:\nE   requests.exceptions.ConnectionError: HTTPSConnectionPool(host='pj4vlvxrg7.execute-api.us-east-1.amazonaws.com', port=443): Max retries exceeded with url: /dev/director?user_id=api-test-user (Caused by ReadTimeoutError(\"HTTPSConnectionPool(host='pj4vlvxrg7.execute-api.us-east-1.amazonaws.com', port=443): Read timed out. (read timeout=30)\"))"}, "teardown": {"duration": 0.0009561000042594969, "outcome": "passed", "stdout": "\n"}}, {"nodeid": "test_endpoints.py::TestPersonaEndpoint::test_persona_valid_message", "lineno": 68, "outcome": "failed", "keywords": ["test_persona_valid_message", "TestPersonaEndpoint", "test_endpoints.py", "__init__.py", "api"], "setup": {"duration": 0.0005336999965948053, "outcome": "passed"}, "call": {"duration": 8.571656700005406, "outcome": "failed", "crash": {"path": "C:\\Projects\\building-os-platform\\.venv\\Lib\\site-packages\\requests\\adapters.py", "lineno": 510, "message": "requests.exceptions.RetryError: HTTPSConnectionPool(host='pj4vlvxrg7.execute-api.us-east-1.amazonaws.com', port=443): Max retries exceeded with url: /dev/persona (Caused by ResponseError('too many 500 error responses'))"}, "stdout": "\n\ud83d\ude80 POST /persona\n\u274c Request failed: \nHTTPSConnectionPool(host='pj4vlvxrg7.execute-api.us-east-1.amazonaws.com', \nport=443): Max retries exceeded with url: /dev/persona (Caused by \nResponseError('too many 500 error responses'))\n", "longrepr": "urllib3.exceptions.ResponseError: too many 500 error responses\n\nThe above exception was the direct cause of the following exception:\nE   urllib3.exceptions.MaxRetryError: HTTPSConnectionPool(host='pj4vlvxrg7.execute-api.us-east-1.amazonaws.com', port=443): Max retries exceeded with url: /dev/persona (Caused by ResponseError('too many 500 error responses'))\n\nDuring handling of the above exception, another exception occurred:\nE   requests.exceptions.RetryError: HTTPSConnectionPool(host='pj4vlvxrg7.execute-api.us-east-1.amazonaws.com', port=443): Max retries exceeded with url: /dev/persona (Caused by ResponseError('too many 500 error responses'))"}, "teardown": {"duration": 0.0020414999962667935, "outcome": "passed", "stdout": "\n"}}, {"nodeid": "test_endpoints.py::TestPersonaEndpoint::test_persona_missing_user_id", "lineno": 81, "outcome": "passed", "keywords": ["test_persona_missing_user_id", "TestPersonaEndpoint", "test_endpoints.py", "__init__.py", "api"], "setup": {"duration": 0.0009607999963918701, "outcome": "passed"}, "call": {"duration": 0.1959839999981341, "outcome": "passed", "stdout": "\n\ud83d\ude80 POST /persona\n\ud83d\udcca Status: 400 | \u23f1\ufe0f  Time: 193.72ms | \ud83d\udce6 Size: 45 bytes\n"}, "teardown": {"duration": 0.0011329999979352579, "outcome": "passed", "stdout": "\n"}}, {"nodeid": "test_endpoints.py::TestPersonaEndpoint::test_persona_missing_message", "lineno": 89, "outcome": "passed", "keywords": ["test_persona_missing_message", "TestPersonaEndpoint", "test_endpoints.py", "__init__.py", "api"], "setup": {"duration": 0.0009021000005304813, "outcome": "passed"}, "call": {"duration": 0.19650040000124136, "outcome": "passed", "stdout": "\n\ud83d\ude80 POST /persona\n\ud83d\udcca Status: 400 | \u23f1\ufe0f  Time: 193.80ms | \ud83d\udce6 Size: 45 bytes\n"}, "teardown": {"duration": 0.001152099997852929, "outcome": "passed", "stdout": "\n"}}, {"nodeid": "test_endpoints.py::TestPersonaEndpoint::test_persona_conversations", "lineno": 97, "outcome": "passed", "keywords": ["test_persona_conversations", "TestPersonaEndpoint", "test_endpoints.py", "__init__.py", "api"], "setup": {"duration": 0.0008770999993430451, "outcome": "passed"}, "call": {"duration": 0.23129559999506455, "outcome": "passed", "stdout": "\n\ud83d\ude80 GET /persona/conversations?user_id=api-test-user\n\ud83d\udcca Status: 200 | \u23f1\ufe0f  Time: 228.41ms | \ud83d\udce6 Size: 64 bytes\n"}, "teardown": {"duration": 0.0010770000008051284, "outcome": "passed", "stdout": "\n"}}, {"nodeid": "test_endpoints.py::TestElevatorEndpoint::test_elevator_call_basic", "lineno": 109, "outcome": "failed", "keywords": ["test_elevator_call_basic", "TestElevatorEndpoint", "test_endpoints.py", "__init__.py", "api"], "setup": {"duration": 0.0005527999965124764, "outcome": "passed"}, "call": {"duration": 129.28792689999682, "outcome": "failed", "crash": {"path": "C:\\Projects\\building-os-platform\\.venv\\Lib\\site-packages\\requests\\adapters.py", "lineno": 519, "message": "requests.exceptions.ConnectionError: HTTPSConnectionPool(host='pj4vlvxrg7.execute-api.us-east-1.amazonaws.com', port=443): Max retries exceeded with url: /dev/elevator/call (Caused by ReadTimeoutError(\"HTTPSConnectionPool(host='pj4vlvxrg7.execute-api.us-east-1.amazonaws.com', port=443): Read timed out. (read timeout=30)\"))"}, "stdout": "\n\ud83d\ude80 POST /elevator/call\n\u274c Request failed: \nHTTPSConnectionPool(host='pj4vlvxrg7.execute-api.us-east-1.amazonaws.com', \nport=443): Max retries exceeded with url: /dev/elevator/call (Caused by \nReadTimeoutError(\"HTTPSConnectionPool(host='pj4vlvxrg7.execute-api.us-east-1.am\nazonaws.com', port=443): Read timed out. (read timeout=30)\"))\n", "log": [{"name": "urllib3.connectionpool", "msg": "Retrying (Retry(total=2, connect=None, read=None, redirect=None, status=None)) after connection broken by 'ReadTimeoutError(\"HTTPSConnectionPool(host='pj4vlvxrg7.execute-api.us-east-1.amazonaws.com', port=443): Read timed out. (read timeout=30)\")': /dev/elevator/call", "args": null, "levelname": "WARNING", "levelno": 30, "pathname": "C:\\Projects\\building-os-platform\\.venv\\Lib\\site-packages\\urllib3\\connectionpool.py", "filename": "connectionpool.py", "module": "connectionpool", "exc_info": null, "exc_text": null, "stack_info": null, "lineno": 868, "funcName": "urlopen", "created": 1754784264.467406, "msecs": 467.0, "relativeCreated": 431639.6645, "thread": 15912, "threadName": "MainThread", "processName": "MainProcess", "process": 10740, "taskName": null}, {"name": "urllib3.connectionpool", "msg": "Retrying (Retry(total=1, connect=None, read=None, redirect=None, status=None)) after connection broken by 'ReadTimeoutError(\"HTTPSConnectionPool(host='pj4vlvxrg7.execute-api.us-east-1.amazonaws.com', port=443): Read timed out. (read timeout=30)\")': /dev/elevator/call", "args": null, "levelname": "WARNING", "levelno": 30, "pathname": "C:\\Projects\\building-os-platform\\.venv\\Lib\\site-packages\\urllib3\\connectionpool.py", "filename": "connectionpool.py", "module": "connectionpool", "exc_info": null, "exc_text": null, "stack_info": null, "lineno": 868, "funcName": "urlopen", "created": 1754784297.4902127, "msecs": 490.0, "relativeCreated": 464662.4711, "thread": 15912, "threadName": "MainThread", "processName": "MainProcess", "process": 10740, "taskName": null}, {"name": "urllib3.connectionpool", "msg": "Retrying (Retry(total=0, connect=None, read=None, redirect=None, status=None)) after connection broken by 'ReadTimeoutError(\"HTTPSConnectionPool(host='pj4vlvxrg7.execute-api.us-east-1.amazonaws.com', port=443): Read timed out. (read timeout=30)\")': /dev/elevator/call", "args": null, "levelname": "WARNING", "levelno": 30, "pathname": "C:\\Projects\\building-os-platform\\.venv\\Lib\\site-packages\\urllib3\\connectionpool.py", "filename": "connectionpool.py", "module": "connectionpool", "exc_info": null, "exc_text": null, "stack_info": null, "lineno": 868, "funcName": "urlopen", "created": 1754784332.77457, "msecs": 774.0, "relativeCreated": 499946.8286, "thread": 15912, "threadName": "MainThread", "processName": "MainProcess", "process": 10740, "taskName": null}], "longrepr": "E   TimeoutError: The read operation timed out\n\nThe above exception was the direct cause of the following exception:\nE   urllib3.exceptions.ReadTimeoutError: HTTPSConnectionPool(host='pj4vlvxrg7.execute-api.us-east-1.amazonaws.com', port=443): Read timed out. (read timeout=30)\n\nThe above exception was the direct cause of the following exception:\nE   urllib3.exceptions.MaxRetryError: HTTPSConnectionPool(host='pj4vlvxrg7.execute-api.us-east-1.amazonaws.com', port=443): Max retries exceeded with url: /dev/elevator/call (Caused by ReadTimeoutError(\"HTTPSConnectionPool(host='pj4vlvxrg7.execute-api.us-east-1.amazonaws.com', port=443): Read timed out. (read timeout=30)\"))\n\nDuring handling of the above exception, another exception occurred:\nE   requests.exceptions.ConnectionError: HTTPSConnectionPool(host='pj4vlvxrg7.execute-api.us-east-1.amazonaws.com', port=443): Max retries exceeded with url: /dev/elevator/call (Caused by ReadTimeoutError(\"HTTPSConnectionPool(host='pj4vlvxrg7.execute-api.us-east-1.amazonaws.com', port=443): Read timed out. (read timeout=30)\"))"}, "teardown": {"duration": 0.0008974999946076423, "outcome": "passed", "stdout": "\n"}}, {"nodeid": "test_endpoints.py::TestElevatorEndpoint::test_elevator_missing_mission_id", "lineno": 120, "outcome": "failed", "keywords": ["test_elevator_missing_mission_id", "TestElevatorEndpoint", "test_endpoints.py", "__init__.py", "api"], "setup": {"duration": 0.0004931999937980436, "outcome": "passed"}, "call": {"duration": 130.12042569999903, "outcome": "failed", "crash": {"path": "C:\\Projects\\building-os-platform\\.venv\\Lib\\site-packages\\requests\\adapters.py", "lineno": 519, "message": "requests.exceptions.ConnectionError: HTTPSConnectionPool(host='pj4vlvxrg7.execute-api.us-east-1.amazonaws.com', port=443): Max retries exceeded with url: /dev/elevator/call (Caused by ReadTimeoutError(\"HTTPSConnectionPool(host='pj4vlvxrg7.execute-api.us-east-1.amazonaws.com', port=443): Read timed out. (read timeout=30)\"))"}, "stdout": "\n\ud83d\ude80 POST /elevator/call\n\u274c Request failed: \nHTTPSConnectionPool(host='pj4vlvxrg7.execute-api.us-east-1.amazonaws.com', \nport=443): Max retries exceeded with url: /dev/elevator/call (Caused by \nReadTimeoutError(\"HTTPSConnectionPool(host='pj4vlvxrg7.execute-api.us-east-1.am\nazonaws.com', port=443): Read timed out. (read timeout=30)\"))\n", "log": [{"name": "urllib3.connectionpool", "msg": "Retrying (Retry(total=2, connect=None, read=None, redirect=None, status=None)) after connection broken by 'ReadTimeoutError(\"HTTPSConnectionPool(host='pj4vlvxrg7.execute-api.us-east-1.amazonaws.com', port=443): Read timed out. (read timeout=30)\")': /dev/elevator/call", "args": null, "levelname": "WARNING", "levelno": 30, "pathname": "C:\\Projects\\building-os-platform\\.venv\\Lib\\site-packages\\urllib3\\connectionpool.py", "filename": "connectionpool.py", "module": "connectionpool", "exc_info": null, "exc_text": null, "stack_info": null, "lineno": 868, "funcName": "urlopen", "created": 1754784394.85537, "msecs": 855.0, "relativeCreated": 562027.6286, "thread": 15912, "threadName": "MainThread", "processName": "MainProcess", "process": 10740, "taskName": null}, {"name": "urllib3.connectionpool", "msg": "Retrying (Retry(total=1, connect=None, read=None, redirect=None, status=None)) after connection broken by 'ReadTimeoutError(\"HTTPSConnectionPool(host='pj4vlvxrg7.execute-api.us-east-1.amazonaws.com', port=443): Read timed out. (read timeout=30)\")': /dev/elevator/call", "args": null, "levelname": "WARNING", "levelno": 30, "pathname": "C:\\Projects\\building-os-platform\\.venv\\Lib\\site-packages\\urllib3\\connectionpool.py", "filename": "connectionpool.py", "module": "connectionpool", "exc_info": null, "exc_text": null, "stack_info": null, "lineno": 868, "funcName": "urlopen", "created": 1754784427.8556387, "msecs": 855.0, "relativeCreated": 595027.8973, "thread": 15912, "threadName": "MainThread", "processName": "MainProcess", "process": 10740, "taskName": null}, {"name": "urllib3.connectionpool", "msg": "Retrying (Retry(total=0, connect=None, read=None, redirect=None, status=None)) after connection broken by 'ReadTimeoutError(\"HTTPSConnectionPool(host='pj4vlvxrg7.execute-api.us-east-1.amazonaws.com', port=443): Read timed out. (read timeout=30)\")': /dev/elevator/call", "args": null, "levelname": "WARNING", "levelno": 30, "pathname": "C:\\Projects\\building-os-platform\\.venv\\Lib\\site-packages\\urllib3\\connectionpool.py", "filename": "connectionpool.py", "module": "connectionpool", "exc_info": null, "exc_text": null, "stack_info": null, "lineno": 868, "funcName": "urlopen", "created": 1754784462.8801672, "msecs": 880.0, "relativeCreated": 630052.4256, "thread": 15912, "threadName": "MainThread", "processName": "MainProcess", "process": 10740, "taskName": null}], "longrepr": "E   TimeoutError: The read operation timed out\n\nThe above exception was the direct cause of the following exception:\nE   urllib3.exceptions.ReadTimeoutError: HTTPSConnectionPool(host='pj4vlvxrg7.execute-api.us-east-1.amazonaws.com', port=443): Read timed out. (read timeout=30)\n\nThe above exception was the direct cause of the following exception:\nE   urllib3.exceptions.MaxRetryError: HTTPSConnectionPool(host='pj4vlvxrg7.execute-api.us-east-1.amazonaws.com', port=443): Max retries exceeded with url: /dev/elevator/call (Caused by ReadTimeoutError(\"HTTPSConnectionPool(host='pj4vlvxrg7.execute-api.us-east-1.amazonaws.com', port=443): Read timed out. (read timeout=30)\"))\n\nDuring handling of the above exception, another exception occurred:\nE   requests.exceptions.ConnectionError: HTTPSConnectionPool(host='pj4vlvxrg7.execute-api.us-east-1.amazonaws.com', port=443): Max retries exceeded with url: /dev/elevator/call (Caused by ReadTimeoutError(\"HTTPSConnectionPool(host='pj4vlvxrg7.execute-api.us-east-1.amazonaws.com', port=443): Read timed out. (read timeout=30)\"))"}, "teardown": {"duration": 0.0011184000031789765, "outcome": "passed", "stdout": "\n"}}, {"nodeid": "test_endpoints.py::TestPSIMEndpoint::test_psim_search_basic", "lineno": 132, "outcome": "passed", "keywords": ["test_psim_search_basic", "TestPSIMEndpoint", "test_endpoints.py", "__init__.py", "api"], "setup": {"duration": 0.0009140000038314611, "outcome": "passed"}, "call": {"duration": 2.639324299998407, "outcome": "passed", "stdout": "\n\ud83d\ude80 POST /psim/search\n\ud83d\udcca Status: 200 | \u23f1\ufe0f  Time: 2624.57ms | \ud83d\udce6 Size: 223 bytes\n"}, "teardown": {"duration": 0.0008973000003607012, "outcome": "passed", "stdout": "\n"}}, {"nodeid": "test_endpoints.py::TestPSIMEndpoint::test_psim_search_with_custom_query", "lineno": 142, "outcome": "passed", "keywords": ["test_psim_search_with_custom_query", "TestPSIMEndpoint", "test_endpoints.py", "__init__.py", "api"], "setup": {"duration": 0.0006308000010903925, "outcome": "passed"}, "call": {"duration": 0.32955000000220025, "outcome": "passed", "stdout": "\n\ud83d\ude80 POST /psim/search\n\ud83d\udcca Status: 200 | \u23f1\ufe0f  Time: 327.13ms | \ud83d\udce6 Size: 223 bytes\n"}, "teardown": {"duration": 0.0009066999991773628, "outcome": "passed", "stdout": "\n"}}, {"nodeid": "test_endpoints.py::TestCoordinatorEndpoint::test_coordinator_mission_status", "lineno": 155, "outcome": "failed", "keywords": ["test_coordinator_mission_status", "TestCoordinatorEndpoint", "test_endpoints.py", "__init__.py", "api"], "setup": {"duration": 0.0007369999948423356, "outcome": "passed"}, "call": {"duration": 2.5222242000018014, "outcome": "failed", "crash": {"path": "c:\\Projects\\building-os-platform\\tests\\api\\test_endpoints.py", "lineno": 161, "message": "assert 404 == 200\n +  where 404 = <Response [404]>.status_code"}, "stdout": "\n\ud83d\ude80 GET /coordinator/missions/test-mission-123\n\ud83d\udcca Status: 404 | \u23f1\ufe0f  Time: 2519.72ms | \ud83d\udce6 Size: 47 bytes\n", "longrepr": "E   assert 404 == 200\n     +  where 404 = <Response [404]>.status_code"}, "teardown": {"duration": 0.000945399995543994, "outcome": "passed", "stdout": "\n"}}, {"nodeid": "test_endpoints.py::TestCoordinatorEndpoint::test_coordinator_different_mission_id", "lineno": 166, "outcome": "failed", "keywords": ["test_coordinator_different_mission_id", "TestCoordinatorEndpoint", "test_endpoints.py", "__init__.py", "api"], "setup": {"duration": 0.0005595000038738362, "outcome": "passed"}, "call": {"duration": 0.2568734999949811, "outcome": "failed", "crash": {"path": "c:\\Projects\\building-os-platform\\tests\\api\\test_endpoints.py", "lineno": 172, "message": "assert 404 == 200\n +  where 404 = <Response [404]>.status_code"}, "stdout": "\n\ud83d\ude80 GET /coordinator/missions/python-test-1754784499\n\ud83d\udcca Status: 404 | \u23f1\ufe0f  Time: 254.44ms | \ud83d\udce6 Size: 53 bytes\n", "longrepr": "E   assert 404 == 200\n     +  where 404 = <Response [404]>.status_code"}, "teardown": {"duration": 0.0009189000047626905, "outcome": "passed", "stdout": "\n"}}, {"nodeid": "test_endpoints.py::TestCORSHeaders::test_cors_headers_present[/health]", "lineno": 178, "outcome": "failed", "keywords": ["test_cors_headers_present[/health]", "parametrize", "pytestmark", "/health", "TestCORSHeaders", "test_endpoints.py", "__init__.py", "api"], "setup": {"duration": 0.0007104000032995827, "outcome": "passed"}, "call": {"duration": 0.5208788000018103, "outcome": "failed", "crash": {"path": "c:\\Projects\\building-os-platform\\tests\\api\\test_endpoints.py", "lineno": 215, "message": "AssertionError: No CORS headers found in response for /health\nassert False"}, "stdout": "\n\ud83d\ude80 GET /health\n\ud83d\udcca Status: 200 | \u23f1\ufe0f  Time: 518.15ms | \ud83d\udce6 Size: 60 bytes\n", "longrepr": "E   AssertionError: No CORS headers found in response for /health\n    assert False"}, "teardown": {"duration": 0.000915999997232575, "outcome": "passed", "stdout": "\n"}}, {"nodeid": "test_endpoints.py::TestCORSHeaders::test_cors_headers_present[/director]", "lineno": 178, "outcome": "failed", "keywords": ["test_cors_headers_present[/director]", "parametrize", "pytestmark", "/director", "TestCORSHeaders", "test_endpoints.py", "__init__.py", "api"], "setup": {"duration": 0.0005976999964332208, "outcome": "passed"}, "call": {"duration": 129.01812500000233, "outcome": "failed", "crash": {"path": "C:\\Projects\\building-os-platform\\.venv\\Lib\\site-packages\\requests\\adapters.py", "lineno": 519, "message": "requests.exceptions.ConnectionError: HTTPSConnectionPool(host='pj4vlvxrg7.execute-api.us-east-1.amazonaws.com', port=443): Max retries exceeded with url: /dev/director (Caused by ReadTimeoutError(\"HTTPSConnectionPool(host='pj4vlvxrg7.execute-api.us-east-1.amazonaws.com', port=443): Read timed out. (read timeout=30)\"))"}, "stdout": "\n\ud83d\ude80 GET /director\n\u274c Request failed: \nHTTPSConnectionPool(host='pj4vlvxrg7.execute-api.us-east-1.amazonaws.com', \nport=443): Max retries exceeded with url: /dev/director (Caused by \nReadTimeoutError(\"HTTPSConnectionPool(host='pj4vlvxrg7.execute-api.us-east-1.am\nazonaws.com', port=443): Read timed out. (read timeout=30)\"))\n", "log": [{"name": "urllib3.connectionpool", "msg": "Retrying (Retry(total=2, connect=None, read=None, redirect=None, status=None)) after connection broken by 'ReadTimeoutError(\"HTTPSConnectionPool(host='pj4vlvxrg7.execute-api.us-east-1.amazonaws.com', port=443): Read timed out. (read timeout=30)\")': /dev/director", "args": null, "levelname": "WARNING", "levelno": 30, "pathname": "C:\\Projects\\building-os-platform\\.venv\\Lib\\site-packages\\urllib3\\connectionpool.py", "filename": "connectionpool.py", "module": "connectionpool", "exc_info": null, "exc_text": null, "stack_info": null, "lineno": 868, "funcName": "urlopen", "created": 1754784530.2325115, "msecs": 232.0, "relativeCreated": 697404.77, "thread": 15912, "threadName": "MainThread", "processName": "MainProcess", "process": 10740, "taskName": null}, {"name": "urllib3.connectionpool", "msg": "Retrying (Retry(total=1, connect=None, read=None, redirect=None, status=None)) after connection broken by 'ReadTimeoutError(\"HTTPSConnectionPool(host='pj4vlvxrg7.execute-api.us-east-1.amazonaws.com', port=443): Read timed out. (read timeout=30)\")': /dev/director", "args": null, "levelname": "WARNING", "levelno": 30, "pathname": "C:\\Projects\\building-os-platform\\.venv\\Lib\\site-packages\\urllib3\\connectionpool.py", "filename": "connectionpool.py", "module": "connectionpool", "exc_info": null, "exc_text": null, "stack_info": null, "lineno": 868, "funcName": "urlopen", "created": 1754784563.1991682, "msecs": 199.0, "relativeCreated": 730371.4268, "thread": 15912, "threadName": "MainThread", "processName": "MainProcess", "process": 10740, "taskName": null}, {"name": "urllib3.connectionpool", "msg": "Retrying (Retry(total=0, connect=None, read=None, redirect=None, status=None)) after connection broken by 'ReadTimeoutError(\"HTTPSConnectionPool(host='pj4vlvxrg7.execute-api.us-east-1.amazonaws.com', port=443): Read timed out. (read timeout=30)\")': /dev/director", "args": null, "levelname": "WARNING", "levelno": 30, "pathname": "C:\\Projects\\building-os-platform\\.venv\\Lib\\site-packages\\urllib3\\connectionpool.py", "filename": "connectionpool.py", "module": "connectionpool", "exc_info": null, "exc_text": null, "stack_info": null, "lineno": 868, "funcName": "urlopen", "created": 1754784598.2342174, "msecs": 234.0, "relativeCreated": 765406.4761, "thread": 15912, "threadName": "MainThread", "processName": "MainProcess", "process": 10740, "taskName": null}], "longrepr": "E   TimeoutError: The read operation timed out\n\nThe above exception was the direct cause of the following exception:\nE   urllib3.exceptions.ReadTimeoutError: HTTPSConnectionPool(host='pj4vlvxrg7.execute-api.us-east-1.amazonaws.com', port=443): Read timed out. (read timeout=30)\n\nThe above exception was the direct cause of the following exception:\nE   urllib3.exceptions.MaxRetryError: HTTPSConnectionPool(host='pj4vlvxrg7.execute-api.us-east-1.amazonaws.com', port=443): Max retries exceeded with url: /dev/director (Caused by ReadTimeoutError(\"HTTPSConnectionPool(host='pj4vlvxrg7.execute-api.us-east-1.amazonaws.com', port=443): Read timed out. (read timeout=30)\"))\n\nDuring handling of the above exception, another exception occurred:\nE   requests.exceptions.ConnectionError: HTTPSConnectionPool(host='pj4vlvxrg7.execute-api.us-east-1.amazonaws.com', port=443): Max retries exceeded with url: /dev/director (Caused by ReadTimeoutError(\"HTTPSConnectionPool(host='pj4vlvxrg7.execute-api.us-east-1.amazonaws.com', port=443): Read timed out. (read timeout=30)\"))"}, "teardown": {"duration": 0.0009374000001116656, "outcome": "passed", "stdout": "\n"}}, {"nodeid": "test_endpoints.py::TestCORSHeaders::test_cors_headers_present[/persona]", "lineno": 178, "outcome": "failed", "keywords": ["test_cors_headers_present[/persona]", "parametrize", "pytestmark", "/persona", "TestCORSHeaders", "test_endpoints.py", "__init__.py", "api"], "setup": {"duration": 0.0005974000014248304, "outcome": "passed"}, "call": {"duration": 1.9026723999995738, "outcome": "failed", "crash": {"path": "c:\\Projects\\building-os-platform\\tests\\api\\test_endpoints.py", "lineno": 215, "message": "AssertionError: No CORS headers found in response for /persona\nassert False"}, "stdout": "\n\ud83d\ude80 POST /persona\n\ud83d\udcca Status: 400 | \u23f1\ufe0f  Time: 1900.39ms | \ud83d\udce6 Size: 45 bytes\n", "longrepr": "E   AssertionError: No CORS headers found in response for /persona\n    assert False"}, "teardown": {"duration": 0.0009895999974105507, "outcome": "passed", "stdout": "\n"}}, {"nodeid": "test_endpoints.py::TestCORSHeaders::test_cors_headers_present[/elevator/call]", "lineno": 178, "outcome": "failed", "keywords": ["test_cors_headers_present[/elevator/call]", "parametrize", "pytestmark", "/elevator/call", "TestCORSHeaders", "test_endpoints.py", "__init__.py", "api"], "setup": {"duration": 0.0006546000004163943, "outcome": "passed"}, "call": {"duration": 129.30478289999883, "outcome": "failed", "crash": {"path": "C:\\Projects\\building-os-platform\\.venv\\Lib\\site-packages\\requests\\adapters.py", "lineno": 519, "message": "requests.exceptions.ConnectionError: HTTPSConnectionPool(host='pj4vlvxrg7.execute-api.us-east-1.amazonaws.com', port=443): Max retries exceeded with url: /dev/elevator/call (Caused by ReadTimeoutError(\"HTTPSConnectionPool(host='pj4vlvxrg7.execute-api.us-east-1.amazonaws.com', port=443): Read timed out. (read timeout=30)\"))"}, "stdout": "\n\ud83d\ude80 POST /elevator/call\n\u274c Request failed: \nHTTPSConnectionPool(host='pj4vlvxrg7.execute-api.us-east-1.amazonaws.com', \nport=443): Max retries exceeded with url: /dev/elevator/call (Caused by \nReadTimeoutError(\"HTTPSConnectionPool(host='pj4vlvxrg7.execute-api.us-east-1.am\nazonaws.com', port=443): Read timed out. (read timeout=30)\"))\n", "log": [{"name": "urllib3.connectionpool", "msg": "Retrying (Retry(total=2, connect=None, read=None, redirect=None, status=None)) after connection broken by 'ReadTimeoutError(\"HTTPSConnectionPool(host='pj4vlvxrg7.execute-api.us-east-1.amazonaws.com', port=443): Read timed out. (read timeout=30)\")': /dev/elevator/call", "args": null, "levelname": "WARNING", "levelno": 30, "pathname": "C:\\Projects\\building-os-platform\\.venv\\Lib\\site-packages\\urllib3\\connectionpool.py", "filename": "connectionpool.py", "module": "connectionpool", "exc_info": null, "exc_text": null, "stack_info": null, "lineno": 868, "funcName": "urlopen", "created": 1754784661.1803136, "msecs": 180.0, "relativeCreated": 828352.572, "thread": 15912, "threadName": "MainThread", "processName": "MainProcess", "process": 10740, "taskName": null}, {"name": "urllib3.connectionpool", "msg": "Retrying (Retry(total=1, connect=None, read=None, redirect=None, status=None)) after connection broken by 'ReadTimeoutError(\"HTTPSConnectionPool(host='pj4vlvxrg7.execute-api.us-east-1.amazonaws.com', port=443): Read timed out. (read timeout=30)\")': /dev/elevator/call", "args": null, "levelname": "WARNING", "levelno": 30, "pathname": "C:\\Projects\\building-os-platform\\.venv\\Lib\\site-packages\\urllib3\\connectionpool.py", "filename": "connectionpool.py", "module": "connectionpool", "exc_info": null, "exc_text": null, "stack_info": null, "lineno": 868, "funcName": "urlopen", "created": 1754784694.1419678, "msecs": 141.0, "relativeCreated": 861314.2263, "thread": 15912, "threadName": "MainThread", "processName": "MainProcess", "process": 10740, "taskName": null}, {"name": "urllib3.connectionpool", "msg": "Retrying (Retry(total=0, connect=None, read=None, redirect=None, status=None)) after connection broken by 'ReadTimeoutError(\"HTTPSConnectionPool(host='pj4vlvxrg7.execute-api.us-east-1.amazonaws.com', port=443): Read timed out. (read timeout=30)\")': /dev/elevator/call", "args": null, "levelname": "WARNING", "levelno": 30, "pathname": "C:\\Projects\\building-os-platform\\.venv\\Lib\\site-packages\\urllib3\\connectionpool.py", "filename": "connectionpool.py", "module": "connectionpool", "exc_info": null, "exc_text": null, "stack_info": null, "lineno": 868, "funcName": "urlopen", "created": 1754784729.2403, "msecs": 240.0, "relativeCreated": 896412.5586, "thread": 15912, "threadName": "MainThread", "processName": "MainProcess", "process": 10740, "taskName": null}], "longrepr": "E   TimeoutError: The read operation timed out\n\nThe above exception was the direct cause of the following exception:\nE   urllib3.exceptions.ReadTimeoutError: HTTPSConnectionPool(host='pj4vlvxrg7.execute-api.us-east-1.amazonaws.com', port=443): Read timed out. (read timeout=30)\n\nThe above exception was the direct cause of the following exception:\nE   urllib3.exceptions.MaxRetryError: HTTPSConnectionPool(host='pj4vlvxrg7.execute-api.us-east-1.amazonaws.com', port=443): Max retries exceeded with url: /dev/elevator/call (Caused by ReadTimeoutError(\"HTTPSConnectionPool(host='pj4vlvxrg7.execute-api.us-east-1.amazonaws.com', port=443): Read timed out. (read timeout=30)\"))\n\nDuring handling of the above exception, another exception occurred:\nE   requests.exceptions.ConnectionError: HTTPSConnectionPool(host='pj4vlvxrg7.execute-api.us-east-1.amazonaws.com', port=443): Max retries exceeded with url: /dev/elevator/call (Caused by ReadTimeoutError(\"HTTPSConnectionPool(host='pj4vlvxrg7.execute-api.us-east-1.amazonaws.com', port=443): Read timed out. (read timeout=30)\"))"}, "teardown": {"duration": 0.0009797999955480918, "outcome": "passed", "stdout": "\n"}}, {"nodeid": "test_endpoints.py::TestCORSHeaders::test_cors_headers_present[/psim/search]", "lineno": 178, "outcome": "failed", "keywords": ["test_cors_headers_present[/psim/search]", "parametrize", "pytestmark", "/psim/search", "TestCORSHeaders", "test_endpoints.py", "__init__.py", "api"], "setup": {"duration": 0.0005718999964301474, "outcome": "passed"}, "call": {"duration": 1.271028600000136, "outcome": "failed", "crash": {"path": "c:\\Projects\\building-os-platform\\tests\\api\\test_endpoints.py", "lineno": 215, "message": "AssertionError: No CORS headers found in response for /psim/search\nassert False"}, "stdout": "\n\ud83d\ude80 POST /psim/search\n\ud83d\udcca Status: 400 | \u23f1\ufe0f  Time: 1268.49ms | \ud83d\udce6 Size: 43 bytes\n", "longrepr": "E   AssertionError: No CORS headers found in response for /psim/search\n    assert False"}, "teardown": {"duration": 0.0009242000014637597, "outcome": "passed", "stdout": "\n"}}, {"nodeid": "test_endpoints.py::TestCORSHeaders::test_cors_headers_present[/coordinator/missions/test-123]", "lineno": 178, "outcome": "failed", "keywords": ["test_cors_headers_present[/coordinator/missions/test-123]", "parametrize", "pytestmark", "/coordinator/missions/test-123", "TestCORSHeaders", "test_endpoints.py", "__init__.py", "api"], "setup": {"duration": 0.000567100003536325, "outcome": "passed"}, "call": {"duration": 0.40826430000015534, "outcome": "failed", "crash": {"path": "c:\\Projects\\building-os-platform\\tests\\api\\test_endpoints.py", "lineno": 215, "message": "AssertionError: No CORS headers found in response for /coordinator/missions/test-123\nassert False"}, "stdout": "\n\ud83d\ude80 GET /coordinator/missions/test-123\n\ud83d\udcca Status: 404 | \u23f1\ufe0f  Time: 405.94ms | \ud83d\udce6 Size: 39 bytes\n", "longrepr": "E   AssertionError: No CORS headers found in response for /coordinator/missions/test-123\n    assert False"}, "teardown": {"duration": 0.001011099993775133, "outcome": "passed", "stdout": "\n"}}, {"nodeid": "test_endpoints.py::TestErrorHandling::test_invalid_endpoint", "lineno": 220, "outcome": "passed", "keywords": ["test_invalid_endpoint", "TestErrorHandling", "test_endpoints.py", "__init__.py", "api"], "setup": {"duration": 0.000633299998298753, "outcome": "passed"}, "call": {"duration": 0.1919823999996879, "outcome": "passed", "stdout": "\n\ud83d\ude80 GET /invalid-endpoint\n\ud83d\udcca Status: 404 | \u23f1\ufe0f  Time: 189.70ms | \ud83d\udce6 Size: 23 bytes\n"}, "teardown": {"duration": 0.0010515999965718947, "outcome": "passed", "stdout": "\n"}}, {"nodeid": "test_endpoints.py::TestErrorHandling::test_invalid_method", "lineno": 225, "outcome": "passed", "keywords": ["test_invalid_method", "TestErrorHandling", "test_endpoints.py", "__init__.py", "api"], "setup": {"duration": 0.0005373999956646003, "outcome": "passed"}, "call": {"duration": 0.19096809999609832, "outcome": "passed", "stdout": "\n\ud83d\ude80 DELETE /health\n\ud83d\udcca Status: 404 | \u23f1\ufe0f  Time: 188.80ms | \ud83d\udce6 Size: 23 bytes\n"}, "teardown": {"duration": 0.0008015000057639554, "outcome": "passed", "stdout": "\n"}}, {"nodeid": "test_endpoints.py::TestErrorHandling::test_malformed_json", "lineno": 235, "outcome": "passed", "keywords": ["test_malformed_json", "TestErrorHandling", "test_endpoints.py", "__init__.py", "api"], "setup": {"duration": 0.000519599998369813, "outcome": "passed"}, "call": {"duration": 7.522507699999551, "outcome": "passed"}, "teardown": {"duration": 0.001007500002742745, "outcome": "passed", "stdout": "\n"}}, {"nodeid": "test_performance.py::TestPerformance::test_response_time_under_threshold", "lineno": 18, "outcome": "failed", "keywords": ["test_response_time_under_threshold", "TestPerformance", "test_performance.py", "__init__.py", "api"], "setup": {"duration": 0.0004059000057168305, "outcome": "passed"}, "call": {"duration": 129.54371289999835, "outcome": "failed", "crash": {"path": "C:\\Projects\\building-os-platform\\.venv\\Lib\\site-packages\\requests\\adapters.py", "lineno": 519, "message": "requests.exceptions.ConnectionError: HTTPSConnectionPool(host='pj4vlvxrg7.execute-api.us-east-1.amazonaws.com', port=443): Max retries exceeded with url: /dev/director (Caused by ReadTimeoutError(\"HTTPSConnectionPool(host='pj4vlvxrg7.execute-api.us-east-1.amazonaws.com', port=443): Read timed out. (read timeout=30)\"))"}, "stdout": "\n\ud83d\ude80 GET /health\n\ud83d\udcca Status: 200 | \u23f1\ufe0f  Time: 513.92ms | \ud83d\udce6 Size: 60 bytes\n\n\ud83d\ude80 GET /director\n\u274c Request failed: \nHTTPSConnectionPool(host='pj4vlvxrg7.execute-api.us-east-1.amazonaws.com', \nport=443): Max retries exceeded with url: /dev/director (Caused by \nReadTimeoutError(\"HTTPSConnectionPool(host='pj4vlvxrg7.execute-api.us-east-1.am\nazonaws.com', port=443): Read timed out. (read timeout=30)\"))\n", "log": [{"name": "urllib3.connectionpool", "msg": "Retrying (Retry(total=2, connect=None, read=None, redirect=None, status=None)) after connection broken by 'ReadTimeoutError(\"HTTPSConnectionPool(host='pj4vlvxrg7.execute-api.us-east-1.amazonaws.com', port=443): Read timed out. (read timeout=30)\")': /dev/director", "args": null, "levelname": "WARNING", "levelno": 30, "pathname": "C:\\Projects\\building-os-platform\\.venv\\Lib\\site-packages\\urllib3\\connectionpool.py", "filename": "connectionpool.py", "module": "connectionpool", "exc_info": null, "exc_text": null, "stack_info": null, "lineno": 868, "funcName": "urlopen", "created": 1754784800.6337986, "msecs": 633.0, "relativeCreated": 967806.0572, "thread": 15912, "threadName": "MainThread", "processName": "MainProcess", "process": 10740, "taskName": null}, {"name": "urllib3.connectionpool", "msg": "Retrying (Retry(total=1, connect=None, read=None, redirect=None, status=None)) after connection broken by 'ReadTimeoutError(\"HTTPSConnectionPool(host='pj4vlvxrg7.execute-api.us-east-1.amazonaws.com', port=443): Read timed out. (read timeout=30)\")': /dev/director", "args": null, "levelname": "WARNING", "levelno": 30, "pathname": "C:\\Projects\\building-os-platform\\.venv\\Lib\\site-packages\\urllib3\\connectionpool.py", "filename": "connectionpool.py", "module": "connectionpool", "exc_info": null, "exc_text": null, "stack_info": null, "lineno": 868, "funcName": "urlopen", "created": 1754784833.6274438, "msecs": 627.0, "relativeCreated": 1000799.7022, "thread": 15912, "threadName": "MainThread", "processName": "MainProcess", "process": 10740, "taskName": null}, {"name": "urllib3.connectionpool", "msg": "Retrying (Retry(total=0, connect=None, read=None, redirect=None, status=None)) after connection broken by 'ReadTimeoutError(\"HTTPSConnectionPool(host='pj4vlvxrg7.execute-api.us-east-1.amazonaws.com', port=443): Read timed out. (read timeout=30)\")': /dev/director", "args": null, "levelname": "WARNING", "levelno": 30, "pathname": "C:\\Projects\\building-os-platform\\.venv\\Lib\\site-packages\\urllib3\\connectionpool.py", "filename": "connectionpool.py", "module": "connectionpool", "exc_info": null, "exc_text": null, "stack_info": null, "lineno": 868, "funcName": "urlopen", "created": 1754784868.658783, "msecs": 658.0, "relativeCreated": 1035831.0414, "thread": 15912, "threadName": "MainThread", "processName": "MainProcess", "process": 10740, "taskName": null}], "longrepr": "E   TimeoutError: The read operation timed out\n\nThe above exception was the direct cause of the following exception:\nE   urllib3.exceptions.ReadTimeoutError: HTTPSConnectionPool(host='pj4vlvxrg7.execute-api.us-east-1.amazonaws.com', port=443): Read timed out. (read timeout=30)\n\nThe above exception was the direct cause of the following exception:\nE   urllib3.exceptions.MaxRetryError: HTTPSConnectionPool(host='pj4vlvxrg7.execute-api.us-east-1.amazonaws.com', port=443): Max retries exceeded with url: /dev/director (Caused by ReadTimeoutError(\"HTTPSConnectionPool(host='pj4vlvxrg7.execute-api.us-east-1.amazonaws.com', port=443): Read timed out. (read timeout=30)\"))\n\nDuring handling of the above exception, another exception occurred:\nE   requests.exceptions.ConnectionError: HTTPSConnectionPool(host='pj4vlvxrg7.execute-api.us-east-1.amazonaws.com', port=443): Max retries exceeded with url: /dev/director (Caused by ReadTimeoutError(\"HTTPSConnectionPool(host='pj4vlvxrg7.execute-api.us-east-1.amazonaws.com', port=443): Read timed out. (read timeout=30)\"))"}, "teardown": {"duration": 0.00042300000495743006, "outcome": "passed"}}, {"nodeid": "test_performance.py::TestPerformance::test_concurrent_health_checks", "lineno": 45, "outcome": "passed", "keywords": ["test_concurrent_health_checks", "TestPerformance", "test_performance.py", "__init__.py", "api"], "setup": {"duration": 0.00044830000115325674, "outcome": "passed"}, "call": {"duration": 2.0057775000022957, "outcome": "passed", "stdout": "\n\ud83d\ude80 GET /health\n\n\ud83d\ude80 GET /health\n\n\ud83d\ude80 GET /health\n\n\ud83d\ude80 GET /health\n\n\ud83d\ude80 GET /health\n\ud83d\udcca Status: 200 | \u23f1\ufe0f  Time: 1904.54ms | \ud83d\udce6 Size: 60 bytes\n\ud83d\udcca Status: 200 | \u23f1\ufe0f  Time: 1917.21ms | \ud83d\udce6 Size: 60 bytes\n\ud83d\udcca Status: 200 | \u23f1\ufe0f  Time: 1950.75ms | \ud83d\udce6 Size: 60 bytes\n\ud83d\udcca Status: 200 | \u23f1\ufe0f  Time: 1998.10ms | \ud83d\udce6 Size: 60 bytes\n\ud83d\udcca Status: 200 | \u23f1\ufe0f  Time: 1998.06ms | \ud83d\udce6 Size: 60 bytes\n"}, "teardown": {"duration": 0.00046129999827826396, "outcome": "passed"}}, {"nodeid": "test_performance.py::TestLoadTesting::test_sustained_load_health_endpoint", "lineno": 72, "outcome": "passed", "keywords": ["test_sustained_load_health_endpoint", "slow", "pytestmark", "TestLoadTesting", "test_performance.py", "__init__.py", "api"], "setup": {"duration": 0.000742000003810972, "outcome": "passed"}, "call": {"duration": 13.848628900006588, "outcome": "passed", "stdout": "\n\ud83d\udd25 Running sustained load test...\n\n\ud83d\ude80 GET /health\n\ud83d\udcca Status: 200 | \u23f1\ufe0f  Time: 594.46ms | \ud83d\udce6 Size: 60 bytes\n\n\ud83d\ude80 GET /health\n\ud83d\udcca Status: 200 | \u23f1\ufe0f  Time: 187.34ms | \ud83d\udce6 Size: 60 bytes\n\n\ud83d\ude80 GET /health\n\ud83d\udcca Status: 200 | \u23f1\ufe0f  Time: 180.01ms | \ud83d\udce6 Size: 60 bytes\n\n\ud83d\ude80 GET /health\n\ud83d\udcca Status: 200 | \u23f1\ufe0f  Time: 197.85ms | \ud83d\udce6 Size: 60 bytes\n\n\ud83d\ude80 GET /health\n\ud83d\udcca Status: 200 | \u23f1\ufe0f  Time: 202.39ms | \ud83d\udce6 Size: 60 bytes\n\n\ud83d\ude80 GET /health\n\ud83d\udcca Status: 200 | \u23f1\ufe0f  Time: 214.14ms | \ud83d\udce6 Size: 60 bytes\n\n\ud83d\ude80 GET /health\n\ud83d\udcca Status: 200 | \u23f1\ufe0f  Time: 196.35ms | \ud83d\udce6 Size: 60 bytes\n\n\ud83d\ude80 GET /health\n\ud83d\udcca Status: 200 | \u23f1\ufe0f  Time: 193.30ms | \ud83d\udce6 Size: 60 bytes\n\n\ud83d\ude80 GET /health\n\ud83d\udcca Status: 200 | \u23f1\ufe0f  Time: 196.68ms | \ud83d\udce6 Size: 60 bytes\n\n\ud83d\ude80 GET /health\n\ud83d\udcca Status: 200 | \u23f1\ufe0f  Time: 197.87ms | \ud83d\udce6 Size: 60 bytes\n\n\ud83d\ude80 GET /health\n\ud83d\udcca Status: 200 | \u23f1\ufe0f  Time: 190.84ms | \ud83d\udce6 Size: 60 bytes\n\n\ud83d\ude80 GET /health\n\ud83d\udcca Status: 200 | \u23f1\ufe0f  Time: 187.19ms | \ud83d\udce6 Size: 60 bytes\n\n\ud83d\ude80 GET /health\n\ud83d\udcca Status: 200 | \u23f1\ufe0f  Time: 212.46ms | \ud83d\udce6 Size: 60 bytes\n\n\ud83d\ude80 GET /health\n\ud83d\udcca Status: 200 | \u23f1\ufe0f  Time: 182.19ms | \ud83d\udce6 Size: 60 bytes\n\n\ud83d\ude80 GET /health\n\ud83d\udcca Status: 200 | \u23f1\ufe0f  Time: 183.73ms | \ud83d\udce6 Size: 60 bytes\n\n\ud83d\ude80 GET /health\n\ud83d\udcca Status: 200 | \u23f1\ufe0f  Time: 204.71ms | \ud83d\udce6 Size: 60 bytes\n\n\ud83d\ude80 GET /health\n\ud83d\udcca Status: 200 | \u23f1\ufe0f  Time: 202.21ms | \ud83d\udce6 Size: 60 bytes\n\n\ud83d\ude80 GET /health\n\ud83d\udcca Status: 200 | \u23f1\ufe0f  Time: 179.45ms | \ud83d\udce6 Size: 60 bytes\n\n\ud83d\ude80 GET /health\n\ud83d\udcca Status: 200 | \u23f1\ufe0f  Time: 197.94ms | \ud83d\udce6 Size: 60 bytes\n\n\ud83d\ude80 GET /health\n\ud83d\udcca Status: 200 | \u23f1\ufe0f  Time: 187.06ms | \ud83d\udce6 Size: 60 bytes\n  Making 20 requests... 0:00:13\n\u2705 Success rate: 100.0% (20/20)\n\u23f1\ufe0f  Avg response: 216.38ms\n\ud83d\udc0c Max response: 596.12ms\n\u26a1 Min response: 181.16ms\n"}, "teardown": {"duration": 0.0004091000009793788, "outcome": "passed"}}, {"nodeid": "test_performance.py::TestStressScenarios::test_large_payload_persona", "lineno": 149, "outcome": "failed", "keywords": ["test_large_payload_persona", "TestStressScenarios", "test_performance.py", "__init__.py", "api"], "setup": {"duration": 0.0004239999980200082, "outcome": "passed"}, "call": {"duration": 7.150777599999856, "outcome": "failed", "crash": {"path": "C:\\Projects\\building-os-platform\\.venv\\Lib\\site-packages\\requests\\adapters.py", "lineno": 510, "message": "requests.exceptions.RetryError: HTTPSConnectionPool(host='pj4vlvxrg7.execute-api.us-east-1.amazonaws.com', port=443): Max retries exceeded with url: /dev/persona (Caused by ResponseError('too many 500 error responses'))"}, "stdout": "\n\ud83d\ude80 POST /persona\n\u274c Request failed: \nHTTPSConnectionPool(host='pj4vlvxrg7.execute-api.us-east-1.amazonaws.com', \nport=443): Max retries exceeded with url: /dev/persona (Caused by \nResponseError('too many 500 error responses'))\n", "longrepr": "urllib3.exceptions.ResponseError: too many 500 error responses\n\nThe above exception was the direct cause of the following exception:\nE   urllib3.exceptions.MaxRetryError: HTTPSConnectionPool(host='pj4vlvxrg7.execute-api.us-east-1.amazonaws.com', port=443): Max retries exceeded with url: /dev/persona (Caused by ResponseError('too many 500 error responses'))\n\nDuring handling of the above exception, another exception occurred:\nE   requests.exceptions.RetryError: HTTPSConnectionPool(host='pj4vlvxrg7.execute-api.us-east-1.amazonaws.com', port=443): Max retries exceeded with url: /dev/persona (Caused by ResponseError('too many 500 error responses'))"}, "teardown": {"duration": 0.0005071999985375442, "outcome": "passed"}}, {"nodeid": "test_performance.py::TestStressScenarios::test_rapid_successive_requests", "lineno": 163, "outcome": "passed", "keywords": ["test_rapid_successive_requests", "TestStressScenarios", "test_performance.py", "__init__.py", "api"], "setup": {"duration": 0.00039399999513989314, "outcome": "passed"}, "call": {"duration": 1.948349500002223, "outcome": "passed", "stdout": "\n\ud83d\ude80 GET /health\n\ud83d\udcca Status: 200 | \u23f1\ufe0f  Time: 202.03ms | \ud83d\udce6 Size: 60 bytes\n\n\ud83d\ude80 GET /health\n\ud83d\udcca Status: 200 | \u23f1\ufe0f  Time: 184.31ms | \ud83d\udce6 Size: 60 bytes\n\n\ud83d\ude80 GET /health\n\ud83d\udcca Status: 200 | \u23f1\ufe0f  Time: 188.70ms | \ud83d\udce6 Size: 60 bytes\n\n\ud83d\ude80 GET /health\n\ud83d\udcca Status: 200 | \u23f1\ufe0f  Time: 191.75ms | \ud83d\udce6 Size: 60 bytes\n\n\ud83d\ude80 GET /health\n\ud83d\udcca Status: 200 | \u23f1\ufe0f  Time: 215.73ms | \ud83d\udce6 Size: 60 bytes\n\n\ud83d\ude80 GET /health\n\ud83d\udcca Status: 200 | \u23f1\ufe0f  Time: 188.91ms | \ud83d\udce6 Size: 60 bytes\n\n\ud83d\ude80 GET /health\n\ud83d\udcca Status: 200 | \u23f1\ufe0f  Time: 188.07ms | \ud83d\udce6 Size: 60 bytes\n\n\ud83d\ude80 GET /health\n\ud83d\udcca Status: 200 | \u23f1\ufe0f  Time: 203.35ms | \ud83d\udce6 Size: 60 bytes\n\n\ud83d\ude80 GET /health\n\ud83d\udcca Status: 200 | \u23f1\ufe0f  Time: 178.11ms | \ud83d\udce6 Size: 60 bytes\n\n\ud83d\ude80 GET /health\n\ud83d\udcca Status: 200 | \u23f1\ufe0f  Time: 191.29ms | \ud83d\udce6 Size: 60 bytes\n\ud83d\ude80 Rapid requests: 10 in 1.95s\n\u2705 Success rate: 100.0%\n"}, "teardown": {"duration": 0.00043000000005122274, "outcome": "passed"}}, {"nodeid": "test_performance.py::TestStressScenarios::test_special_characters_in_requests", "lineno": 189, "outcome": "failed", "keywords": ["test_special_characters_in_requests", "TestStressScenarios", "test_performance.py", "__init__.py", "api"], "setup": {"duration": 0.0004282000008970499, "outcome": "passed"}, "call": {"duration": 6.814790299999004, "outcome": "failed", "crash": {"path": "C:\\Projects\\building-os-platform\\.venv\\Lib\\site-packages\\requests\\adapters.py", "lineno": 510, "message": "requests.exceptions.RetryError: HTTPSConnectionPool(host='pj4vlvxrg7.execute-api.us-east-1.amazonaws.com', port=443): Max retries exceeded with url: /dev/persona (Caused by ResponseError('too many 500 error responses'))"}, "stdout": "\n\ud83d\ude80 POST /persona\n\u274c Request failed: \nHTTPSConnectionPool(host='pj4vlvxrg7.execute-api.us-east-1.amazonaws.com', \nport=443): Max retries exceeded with url: /dev/persona (Caused by \nResponseError('too many 500 error responses'))\n", "longrepr": "urllib3.exceptions.ResponseError: too many 500 error responses\n\nThe above exception was the direct cause of the following exception:\nE   urllib3.exceptions.MaxRetryError: HTTPSConnectionPool(host='pj4vlvxrg7.execute-api.us-east-1.amazonaws.com', port=443): Max retries exceeded with url: /dev/persona (Caused by ResponseError('too many 500 error responses'))\n\nDuring handling of the above exception, another exception occurred:\nE   requests.exceptions.RetryError: HTTPSConnectionPool(host='pj4vlvxrg7.execute-api.us-east-1.amazonaws.com', port=443): Max retries exceeded with url: /dev/persona (Caused by ResponseError('too many 500 error responses'))"}, "teardown": {"duration": 0.00046519999887095764, "outcome": "passed"}}, {"nodeid": "test_performance.py::TestBoundaryConditions::test_empty_payloads", "lineno": 213, "outcome": "failed", "keywords": ["test_empty_payloads", "TestBoundaryConditions", "test_performance.py", "__init__.py", "api"], "setup": {"duration": 0.00045030000183032826, "outcome": "passed"}, "call": {"duration": 129.33685700000206, "outcome": "failed", "crash": {"path": "C:\\Projects\\building-os-platform\\.venv\\Lib\\site-packages\\requests\\adapters.py", "lineno": 519, "message": "requests.exceptions.ConnectionError: HTTPSConnectionPool(host='pj4vlvxrg7.execute-api.us-east-1.amazonaws.com', port=443): Max retries exceeded with url: /dev/elevator/call (Caused by ReadTimeoutError(\"HTTPSConnectionPool(host='pj4vlvxrg7.execute-api.us-east-1.amazonaws.com', port=443): Read timed out. (read timeout=30)\"))"}, "stdout": "\n\ud83d\ude80 POST /persona\n\ud83d\udcca Status: 400 | \u23f1\ufe0f  Time: 184.27ms | \ud83d\udce6 Size: 45 bytes\n\n\ud83d\ude80 POST /elevator/call\n\u274c Request failed: \nHTTPSConnectionPool(host='pj4vlvxrg7.execute-api.us-east-1.amazonaws.com', \nport=443): Max retries exceeded with url: /dev/elevator/call (Caused by \nReadTimeoutError(\"HTTPSConnectionPool(host='pj4vlvxrg7.execute-api.us-east-1.am\nazonaws.com', port=443): Read timed out. (read timeout=30)\"))\n", "log": [{"name": "urllib3.connectionpool", "msg": "Retrying (Retry(total=2, connect=None, read=None, redirect=None, status=None)) after connection broken by 'ReadTimeoutError(\"HTTPSConnectionPool(host='pj4vlvxrg7.execute-api.us-east-1.amazonaws.com', port=443): Read timed out. (read timeout=30)\")': /dev/elevator/call", "args": null, "levelname": "WARNING", "levelno": 30, "pathname": "C:\\Projects\\building-os-platform\\.venv\\Lib\\site-packages\\urllib3\\connectionpool.py", "filename": "connectionpool.py", "module": "connectionpool", "exc_info": null, "exc_text": null, "stack_info": null, "lineno": 868, "funcName": "urlopen", "created": 1754784961.6723485, "msecs": 672.0, "relativeCreated": 1128844.6068, "thread": 15912, "threadName": "MainThread", "processName": "MainProcess", "process": 10740, "taskName": null}, {"name": "urllib3.connectionpool", "msg": "Retrying (Retry(total=1, connect=None, read=None, redirect=None, status=None)) after connection broken by 'ReadTimeoutError(\"HTTPSConnectionPool(host='pj4vlvxrg7.execute-api.us-east-1.amazonaws.com', port=443): Read timed out. (read timeout=30)\")': /dev/elevator/call", "args": null, "levelname": "WARNING", "levelno": 30, "pathname": "C:\\Projects\\building-os-platform\\.venv\\Lib\\site-packages\\urllib3\\connectionpool.py", "filename": "connectionpool.py", "module": "connectionpool", "exc_info": null, "exc_text": null, "stack_info": null, "lineno": 868, "funcName": "urlopen", "created": 1754784994.7053597, "msecs": 705.0, "relativeCreated": 1161877.618, "thread": 15912, "threadName": "MainThread", "processName": "MainProcess", "process": 10740, "taskName": null}, {"name": "urllib3.connectionpool", "msg": "Retrying (Retry(total=0, connect=None, read=None, redirect=None, status=None)) after connection broken by 'ReadTimeoutError(\"HTTPSConnectionPool(host='pj4vlvxrg7.execute-api.us-east-1.amazonaws.com', port=443): Read timed out. (read timeout=30)\")': /dev/elevator/call", "args": null, "levelname": "WARNING", "levelno": 30, "pathname": "C:\\Projects\\building-os-platform\\.venv\\Lib\\site-packages\\urllib3\\connectionpool.py", "filename": "connectionpool.py", "module": "connectionpool", "exc_info": null, "exc_text": null, "stack_info": null, "lineno": 868, "funcName": "urlopen", "created": 1754785029.7428906, "msecs": 742.0, "relativeCreated": 1196915.149, "thread": 15912, "threadName": "MainThread", "processName": "MainProcess", "process": 10740, "taskName": null}], "longrepr": "E   TimeoutError: The read operation timed out\n\nThe above exception was the direct cause of the following exception:\nE   urllib3.exceptions.ReadTimeoutError: HTTPSConnectionPool(host='pj4vlvxrg7.execute-api.us-east-1.amazonaws.com', port=443): Read timed out. (read timeout=30)\n\nThe above exception was the direct cause of the following exception:\nE   urllib3.exceptions.MaxRetryError: HTTPSConnectionPool(host='pj4vlvxrg7.execute-api.us-east-1.amazonaws.com', port=443): Max retries exceeded with url: /dev/elevator/call (Caused by ReadTimeoutError(\"HTTPSConnectionPool(host='pj4vlvxrg7.execute-api.us-east-1.amazonaws.com', port=443): Read timed out. (read timeout=30)\"))\n\nDuring handling of the above exception, another exception occurred:\nE   requests.exceptions.ConnectionError: HTTPSConnectionPool(host='pj4vlvxrg7.execute-api.us-east-1.amazonaws.com', port=443): Max retries exceeded with url: /dev/elevator/call (Caused by ReadTimeoutError(\"HTTPSConnectionPool(host='pj4vlvxrg7.execute-api.us-east-1.amazonaws.com', port=443): Read timed out. (read timeout=30)\"))"}, "teardown": {"duration": 0.0004995999988750555, "outcome": "passed"}}, {"nodeid": "test_performance.py::TestBoundaryConditions::test_null_values_in_payload", "lineno": 224, "outcome": "passed", "keywords": ["test_null_values_in_payload", "TestBoundaryConditions", "test_performance.py", "__init__.py", "api"], "setup": {"duration": 0.000705599995853845, "outcome": "passed"}, "call": {"duration": 1.1786159000039333, "outcome": "passed", "stdout": "\n\ud83d\ude80 POST /persona\n\ud83d\udcca Status: 400 | \u23f1\ufe0f  Time: 1175.99ms | \ud83d\udce6 Size: 45 bytes\n"}, "teardown": {"duration": 0.00043900000309804454, "outcome": "passed"}}, {"nodeid": "test_performance.py::TestBoundaryConditions::test_extremely_long_mission_id", "lineno": 233, "outcome": "passed", "keywords": ["test_extremely_long_mission_id", "TestBoundaryConditions", "test_performance.py", "__init__.py", "api"], "setup": {"duration": 0.0004169000021647662, "outcome": "passed"}, "call": {"duration": 0.32544740000594174, "outcome": "passed", "stdout": "\n\ud83d\ude80 GET \n/coordinator/missions/xxxxxxxxxxxxxxxxxxxxxxxxxxxxxxxxxxxxxxxxxxxxxxxxxxxxxxxxx\nxxxxxxxxxxxxxxxxxxxxxxxxxxxxxxxxxxxxxxxxxxxxxxxxxxxxxxxxxxxxxxxxxxxxxxxxxxxxxxx\nxxxxxxxxxxxxxxxxxxxxxxxxxxxxxxxxxxxxxxxxxxxxxxxxxxxxxxxxxxxxxxxxxxxxxxxxxxxxxxx\nxxxxxxxxxxxxxxxxxxxxxxxxxxxxxxxxxxxxxxxxxxxxxxxxxxxxxxxxxxxxxxxxxxxxxxxxxxxxxxx\nxxxxxxxxxxxxxxxxxxxxxxxxxxxxxxxxxxxxxxxxxxxxxxxxxxxxxxxxxxxxxxxxxxxxxxxxxxxxxxx\nxxxxxxxxxxxxxxxxxxxxxxxxxxxxxxxxxxxxxxxxxxxxxxxxxxxxxxxxxxxxxxxxxxxxxxxxxxxxxxx\nxxxxxxxxxxxxxxxxxxxxxxxxxxxxxxxxxxxxxxxxxxxxxxxxxxxxxxxxxxxxxxxxxxxxxxxxxxxxxxx\nxxxxxxxxxxxxxxxxxxxxxxxxxxxxxxxxxxxxxxxxxxxxxxxxxxxxxxxxxxxxxxxxxxxxxxxxxxxxxxx\nxxxxxxxxxxxxxxxxxxxxxxxxxxxxxxxxxxxxxxxxxxxxxxxxxxxxxxxxxxxxxxxxxxxxxxxxxxxxxxx\nxxxxxxxxxxxxxxxxxxxxxxxxxxxxxxxxxxxxxxxxxxxxxxxxxxxxxxxxxxxxxxxxxxxxxxxxxxxxxxx\nxxxxxxxxxxxxxxxxxxxxxxxxxxxxxxxxxxxxxxxxxxxxxxxxxxxxxxxxxxxxxxxxxxxxxxxxxxxxxxx\nxxxxxxxxxxxxxxxxxxxxxxxxxxxxxxxxxxxxxxxxxxxxxxxxxxxxxxxxxxxxxxxxxxxxxxxxxxxxxxx\nxxxxxxxxxxxxxxxxxxxxxxxxxxxxxxxxxxxxxxxxxxxxxxxxxxxxxxxxxxxxxxxxxxxxxxxxxx\n\ud83d\udcca Status: 404 | \u23f1\ufe0f  Time: 320.10ms | \ud83d\udce6 Size: 1031 bytes\n"}, "teardown": {"duration": 0.1307851999954437, "outcome": "passed", "stdout": "\n\ud83d\udcca Test Session Complete\n                              \ud83d\udd0d Request Summary                               \n\u250c\u2500\u2500\u2500\u2500\u2500\u2500\u2500\u2500\u252c\u2500\u2500\u2500\u2500\u2500\u2500\u2500\u2500\u2500\u2500\u2500\u2500\u2500\u2500\u2500\u2500\u2500\u2500\u2500\u2500\u2500\u2500\u2500\u2500\u2500\u2500\u2500\u2500\u2500\u2500\u2500\u2500\u2500\u2500\u2500\u2500\u2500\u252c\u2500\u2500\u2500\u2500\u2500\u2500\u2500\u2500\u252c\u2500\u2500\u2500\u2500\u2500\u2500\u2500\u2500\u2500\u2500\u2500\u252c\u2500\u2500\u2500\u2500\u2500\u2500\u2500\u2500\u2500\u2510\n\u2502 Method \u2502 Endpoint                            \u2502 Status \u2502 Time (ms) \u2502 Success \u2502\n\u251c\u2500\u2500\u2500\u2500\u2500\u2500\u2500\u2500\u253c\u2500\u2500\u2500\u2500\u2500\u2500\u2500\u2500\u2500\u2500\u2500\u2500\u2500\u2500\u2500\u2500\u2500\u2500\u2500\u2500\u2500\u2500\u2500\u2500\u2500\u2500\u2500\u2500\u2500\u2500\u2500\u2500\u2500\u2500\u2500\u2500\u2500\u253c\u2500\u2500\u2500\u2500\u2500\u2500\u2500\u2500\u253c\u2500\u2500\u2500\u2500\u2500\u2500\u2500\u2500\u2500\u2500\u2500\u253c\u2500\u2500\u2500\u2500\u2500\u2500\u2500\u2500\u2500\u2524\n\u2502 GET    \u2502 /health                             \u2502 200    \u2502 1524.26   \u2502 \u2705      \u2502\n\u2502 GET    \u2502 /health                             \u2502 200    \u2502 218.74    \u2502 \u2705      \u2502\n\u2502 GET    \u2502 /director                           \u2502 0      \u2502 128926.82 \u2502 \u274c      \u2502\n\u2502 GET    \u2502 /director?user_request=Test mission \u2502 0      \u2502 129913.69 \u2502 \u274c      \u2502\n\u2502        \u2502 from Python API tests               \u2502        \u2502           \u2502         \u2502\n\u2502 GET    \u2502 /director?user_id=api-test-user     \u2502 0      \u2502 130120.5  \u2502 \u274c      \u2502\n\u2502 POST   \u2502 /persona                            \u2502 0      \u2502 8568.7    \u2502 \u274c      \u2502\n\u2502 POST   \u2502 /persona                            \u2502 400    \u2502 193.72    \u2502 \u274c      \u2502\n\u2502 POST   \u2502 /persona                            \u2502 400    \u2502 193.8     \u2502 \u274c      \u2502\n\u2502 GET    \u2502 /persona/conversations?user_id=api\u2026 \u2502 200    \u2502 228.41    \u2502 \u2705      \u2502\n\u2502 POST   \u2502 /elevator/call                      \u2502 0      \u2502 129284.5  \u2502 \u274c      \u2502\n\u2502 POST   \u2502 /elevator/call                      \u2502 0      \u2502 130117.21 \u2502 \u274c      \u2502\n\u2502 POST   \u2502 /psim/search                        \u2502 200    \u2502 2624.57   \u2502 \u2705      \u2502\n\u2502 POST   \u2502 /psim/search                        \u2502 200    \u2502 327.13    \u2502 \u2705      \u2502\n\u2502 GET    \u2502 /coordinator/missions/test-mission\u2026 \u2502 404    \u2502 2519.72   \u2502 \u274c      \u2502\n\u2502 GET    \u2502 /coordinator/missions/python-test-\u2026 \u2502 404    \u2502 254.44    \u2502 \u274c      \u2502\n\u2502 GET    \u2502 /health                             \u2502 200    \u2502 518.15    \u2502 \u2705      \u2502\n\u2502 GET    \u2502 /director                           \u2502 0      \u2502 129015.1  \u2502 \u274c      \u2502\n\u2502 POST   \u2502 /persona                            \u2502 400    \u2502 1900.39   \u2502 \u274c      \u2502\n\u2502 POST   \u2502 /elevator/call                      \u2502 0      \u2502 129295.91 \u2502 \u274c      \u2502\n\u2502 POST   \u2502 /psim/search                        \u2502 400    \u2502 1268.49   \u2502 \u274c      \u2502\n\u2502 GET    \u2502 /coordinator/missions/test-123      \u2502 404    \u2502 405.94    \u2502 \u274c      \u2502\n\u2502 GET    \u2502 /invalid-endpoint                   \u2502 404    \u2502 189.7     \u2502 \u274c      \u2502\n\u2502 DELETE \u2502 /health                             \u2502 404    \u2502 188.8     \u2502 \u274c      \u2502\n\u2502 GET    \u2502 /health                             \u2502 200    \u2502 513.92    \u2502 \u2705      \u2502\n\u2502 GET    \u2502 /director                           \u2502 0      \u2502 129025.1  \u2502 \u274c      \u2502\n\u2502 GET    \u2502 /health                             \u2502 200    \u2502 1904.54   \u2502 \u2705      \u2502\n\u2502 GET    \u2502 /health                             \u2502 200    \u2502 1917.21   \u2502 \u2705      \u2502\n\u2502 GET    \u2502 /health                             \u2502 200    \u2502 1950.75   \u2502 \u2705      \u2502\n\u2502 GET    \u2502 /health                             \u2502 200    \u2502 1998.1    \u2502 \u2705      \u2502\n\u2502 GET    \u2502 /health                             \u2502 200    \u2502 1998.06   \u2502 \u2705      \u2502\n\u2502 GET    \u2502 /health                             \u2502 200    \u2502 594.46    \u2502 \u2705      \u2502\n\u2502 GET    \u2502 /health                             \u2502 200    \u2502 187.34    \u2502 \u2705      \u2502\n\u2502 GET    \u2502 /health                             \u2502 200    \u2502 180.01    \u2502 \u2705      \u2502\n\u2502 GET    \u2502 /health                             \u2502 200    \u2502 197.85    \u2502 \u2705      \u2502\n\u2502 GET    \u2502 /health                             \u2502 200    \u2502 202.39    \u2502 \u2705      \u2502\n\u2502 GET    \u2502 /health                             \u2502 200    \u2502 214.14    \u2502 \u2705      \u2502\n\u2502 GET    \u2502 /health                             \u2502 200    \u2502 196.35    \u2502 \u2705      \u2502\n\u2502 GET    \u2502 /health                             \u2502 200    \u2502 193.3     \u2502 \u2705      \u2502\n\u2502 GET    \u2502 /health                             \u2502 200    \u2502 196.68    \u2502 \u2705      \u2502\n\u2502 GET    \u2502 /health                             \u2502 200    \u2502 197.87    \u2502 \u2705      \u2502\n\u2502 GET    \u2502 /health                             \u2502 200    \u2502 190.84    \u2502 \u2705      \u2502\n\u2502 GET    \u2502 /health                             \u2502 200    \u2502 187.19    \u2502 \u2705      \u2502\n\u2502 GET    \u2502 /health                             \u2502 200    \u2502 212.46    \u2502 \u2705      \u2502\n\u2502 GET    \u2502 /health                             \u2502 200    \u2502 182.19    \u2502 \u2705      \u2502\n\u2502 GET    \u2502 /health                             \u2502 200    \u2502 183.73    \u2502 \u2705      \u2502\n\u2502 GET    \u2502 /health                             \u2502 200    \u2502 204.71    \u2502 \u2705      \u2502\n\u2502 GET    \u2502 /health                             \u2502 200    \u2502 202.21    \u2502 \u2705      \u2502\n\u2502 GET    \u2502 /health                             \u2502 200    \u2502 179.45    \u2502 \u2705      \u2502\n\u2502 GET    \u2502 /health                             \u2502 200    \u2502 197.94    \u2502 \u2705      \u2502\n\u2502 GET    \u2502 /health                             \u2502 200    \u2502 187.06    \u2502 \u2705      \u2502\n\u2502 POST   \u2502 /persona                            \u2502 0      \u2502 7148.02   \u2502 \u274c      \u2502\n\u2502 GET    \u2502 /health                             \u2502 200    \u2502 202.03    \u2502 \u2705      \u2502\n\u2502 GET    \u2502 /health                             \u2502 200    \u2502 184.31    \u2502 \u2705      \u2502\n\u2502 GET    \u2502 /health                             \u2502 200    \u2502 188.7     \u2502 \u2705      \u2502\n\u2502 GET    \u2502 /health                             \u2502 200    \u2502 191.75    \u2502 \u2705      \u2502\n\u2502 GET    \u2502 /health                             \u2502 200    \u2502 215.73    \u2502 \u2705      \u2502\n\u2502 GET    \u2502 /health                             \u2502 200    \u2502 188.91    \u2502 \u2705      \u2502\n\u2502 GET    \u2502 /health                             \u2502 200    \u2502 188.07    \u2502 \u2705      \u2502\n\u2502 GET    \u2502 /health                             \u2502 200    \u2502 203.35    \u2502 \u2705      \u2502\n\u2502 GET    \u2502 /health                             \u2502 200    \u2502 178.11    \u2502 \u2705      \u2502\n\u2502 GET    \u2502 /health                             \u2502 200    \u2502 191.29    \u2502 \u2705      \u2502\n\u2502 POST   \u2502 /persona                            \u2502 0      \u2502 6812.14   \u2502 \u274c      \u2502\n\u2502 POST   \u2502 /persona                            \u2502 400    \u2502 184.27    \u2502 \u274c      \u2502\n\u2502 POST   \u2502 /elevator/call                      \u2502 0      \u2502 129147.79 \u2502 \u274c      \u2502\n\u2502 POST   \u2502 /persona                            \u2502 400    \u2502 1175.99   \u2502 \u274c      \u2502\n\u2502 GET    \u2502 /coordinator/missions/xxxxxxxxxxxx\u2026 \u2502 404    \u2502 320.1     \u2502 \u274c      \u2502\n\u2514\u2500\u2500\u2500\u2500\u2500\u2500\u2500\u2500\u2534\u2500\u2500\u2500\u2500\u2500\u2500\u2500\u2500\u2500\u2500\u2500\u2500\u2500\u2500\u2500\u2500\u2500\u2500\u2500\u2500\u2500\u2500\u2500\u2500\u2500\u2500\u2500\u2500\u2500\u2500\u2500\u2500\u2500\u2500\u2500\u2500\u2500\u2534\u2500\u2500\u2500\u2500\u2500\u2500\u2500\u2500\u2534\u2500\u2500\u2500\u2500\u2500\u2500\u2500\u2500\u2500\u2500\u2500\u2534\u2500\u2500\u2500\u2500\u2500\u2500\u2500\u2500\u2500\u2518\n\u250c\u2500\u2500\u2500\u2500\u2500\u2500\u2500\u2500\u2500\u2500\u2500\u2500\u2500\u2500\u2500\u2500\u2500\u2500\u2500\u2500\u2500\u2500\u2500\u2500\u2500\u2500\u2500\u2500 Performance Metrics \u2500\u2500\u2500\u2500\u2500\u2500\u2500\u2500\u2500\u2500\u2500\u2500\u2500\u2500\u2500\u2500\u2500\u2500\u2500\u2500\u2500\u2500\u2500\u2500\u2500\u2500\u2500\u2500\u2510\n\u2502 \ud83d\udcc8 Avg: 522.48ms | \u26a1 Min: 178.11ms | \ud83d\udc0c Max: 2624.57ms                     \u2502\n\u2514\u2500\u2500\u2500\u2500\u2500\u2500\u2500\u2500\u2500\u2500\u2500\u2500\u2500\u2500\u2500\u2500\u2500\u2500\u2500\u2500\u2500\u2500\u2500\u2500\u2500\u2500\u2500\u2500\u2500\u2500\u2500\u2500\u2500\u2500\u2500\u2500\u2500\u2500\u2500\u2500\u2500\u2500\u2500\u2500\u2500\u2500\u2500\u2500\u2500\u2500\u2500\u2500\u2500\u2500\u2500\u2500\u2500\u2500\u2500\u2500\u2500\u2500\u2500\u2500\u2500\u2500\u2500\u2500\u2500\u2500\u2500\u2500\u2500\u2500\u2500\u2500\u2500\u2518\n\ud83d\udcbe Results exported to: api-test-results-20250809-211742.json\n"}}], "warnings": [{"message": "Unknown pytest.mark.slow - is this a typo?  You can register custom marks to avoid this warning - for details, see https://docs.pytest.org/en/stable/how-to/mark.html", "category": "PytestUnknownMarkWarning", "when": "collect", "filename": "c:\\Projects\\building-os-platform\\tests\\api\\test_performance.py", "lineno": 73}, {"message": "Unknown pytest.mark.slow - is this a typo?  You can register custom marks to avoid this warning - for details, see https://docs.pytest.org/en/stable/how-to/mark.html", "category": "PytestUnknownMarkWarning", "when": "collect", "filename": "c:\\Projects\\building-os-platform\\tests\\api\\test_performance.py", "lineno": 245}, {"message": "Unknown pytest.mark.load - is this a typo?  You can register custom marks to avoid this warning - for details, see https://docs.pytest.org/en/stable/how-to/mark.html", "category": "PytestUnknownMarkWarning", "when": "collect", "filename": "c:\\Projects\\building-os-platform\\tests\\api\\test_performance.py", "lineno": 246}]}