{"created": 1754781900.302825, "duration": 1227.099440574646, "exitcode": 1, "root": "C:\\Projects\\building-os-platform\\tests\\api", "environment": {}, "summary": {"passed": 15, "failed": 18, "total": 33, "collected": 33}, "collectors": [{"nodeid": "", "outcome": "passed", "result": [{"nodeid": "__init__.py", "type": "Package"}]}, {"nodeid": "test_endpoints.py::TestPayloads", "outcome": "passed", "result": []}, {"nodeid": "test_endpoints.py::TestHealthEndpoint", "outcome": "passed", "result": [{"nodeid": "test_endpoints.py::TestHealthEndpoint::test_health_check_success", "type": "Function", "lineno": 14}, {"nodeid": "test_endpoints.py::TestHealthEndpoint::test_health_check_performance", "type": "Function", "lineno": 23}]}, {"nodeid": "test_endpoints.py::TestDirectorEndpoint", "outcome": "passed", "result": [{"nodeid": "test_endpoints.py::TestDirectorEndpoint::test_director_basic_request", "type": "Function", "lineno": 37}, {"nodeid": "test_endpoints.py::TestDirectorEndpoint::test_director_with_user_request", "type": "Function", "lineno": 46}, {"nodeid": "test_endpoints.py::TestDirectorEndpoint::test_director_with_user_id", "type": "Function", "lineno": 56}]}, {"nodeid": "test_endpoints.py::TestPersonaEndpoint", "outcome": "passed", "result": [{"nodeid": "test_endpoints.py::TestPersonaEndpoint::test_persona_valid_message", "type": "Function", "lineno": 68}, {"nodeid": "test_endpoints.py::TestPersonaEndpoint::test_persona_missing_user_id", "type": "Function", "lineno": 81}, {"nodeid": "test_endpoints.py::TestPersonaEndpoint::test_persona_missing_message", "type": "Function", "lineno": 89}, {"nodeid": "test_endpoints.py::TestPersonaEndpoint::test_persona_conversations", "type": "Function", "lineno": 97}]}, {"nodeid": "test_endpoints.py::TestElevatorEndpoint", "outcome": "passed", "result": [{"nodeid": "test_endpoints.py::TestElevatorEndpoint::test_elevator_call_basic", "type": "Function", "lineno": 109}, {"nodeid": "test_endpoints.py::TestElevatorEndpoint::test_elevator_missing_mission_id", "type": "Function", "lineno": 120}]}, {"nodeid": "test_endpoints.py::TestPSIMEndpoint", "outcome": "passed", "result": [{"nodeid": "test_endpoints.py::TestPSIMEndpoint::test_psim_search_basic", "type": "Function", "lineno": 132}, {"nodeid": "test_endpoints.py::TestPSIMEndpoint::test_psim_search_with_custom_query", "type": "Function", "lineno": 142}]}, {"nodeid": "test_endpoints.py::TestCoordinatorEndpoint", "outcome": "passed", "result": [{"nodeid": "test_endpoints.py::TestCoordinatorEndpoint::test_coordinator_mission_status", "type": "Function", "lineno": 155}, {"nodeid": "test_endpoints.py::TestCoordinatorEndpoint::test_coordinator_different_mission_id", "type": "Function", "lineno": 166}]}, {"nodeid": "test_endpoints.py::TestCORSHeaders", "outcome": "passed", "result": [{"nodeid": "test_endpoints.py::TestCORSHeaders::test_cors_headers_present[/health]", "type": "Function", "lineno": 178}, {"nodeid": "test_endpoints.py::TestCORSHeaders::test_cors_headers_present[/director]", "type": "Function", "lineno": 178}, {"nodeid": "test_endpoints.py::TestCORSHeaders::test_cors_headers_present[/persona]", "type": "Function", "lineno": 178}, {"nodeid": "test_endpoints.py::TestCORSHeaders::test_cors_headers_present[/elevator/call]", "type": "Function", "lineno": 178}, {"nodeid": "test_endpoints.py::TestCORSHeaders::test_cors_headers_present[/psim/search]", "type": "Function", "lineno": 178}, {"nodeid": "test_endpoints.py::TestCORSHeaders::test_cors_headers_present[/coordinator/missions/test-123]", "type": "Function", "lineno": 178}]}, {"nodeid": "test_endpoints.py::TestErrorHandling", "outcome": "passed", "result": [{"nodeid": "test_endpoints.py::TestErrorHandling::test_invalid_endpoint", "type": "Function", "lineno": 220}, {"nodeid": "test_endpoints.py::TestErrorHandling::test_invalid_method", "type": "Function", "lineno": 225}, {"nodeid": "test_endpoints.py::TestErrorHandling::test_malformed_json", "type": "Function", "lineno": 235}]}, {"nodeid": "test_endpoints.py", "outcome": "passed", "result": [{"nodeid": "test_endpoints.py::TestPayloads", "type": "Class"}, {"nodeid": "test_endpoints.py::TestHealthEndpoint", "type": "Class"}, {"nodeid": "test_endpoints.py::TestDirectorEndpoint", "type": "Class"}, {"nodeid": "test_endpoints.py::TestPersonaEndpoint", "type": "Class"}, {"nodeid": "test_endpoints.py::TestElevatorEndpoint", "type": "Class"}, {"nodeid": "test_endpoints.py::TestPSIMEndpoint", "type": "Class"}, {"nodeid": "test_endpoints.py::TestCoordinatorEndpoint", "type": "Class"}, {"nodeid": "test_endpoints.py::TestCORSHeaders", "type": "Class"}, {"nodeid": "test_endpoints.py::TestErrorHandling", "type": "Class"}]}, {"nodeid": "test_performance.py::TestPerformance", "outcome": "passed", "result": [{"nodeid": "test_performance.py::TestPerformance::test_response_time_under_threshold", "type": "Function", "lineno": 18}, {"nodeid": "test_performance.py::TestPerformance::test_concurrent_health_checks", "type": "Function", "lineno": 45}]}, {"nodeid": "test_performance.py::TestLoadTesting", "outcome": "passed", "result": [{"nodeid": "test_performance.py::TestLoadTesting::test_sustained_load_health_endpoint", "type": "Function", "lineno": 72}]}, {"nodeid": "test_performance.py::TestStressScenarios", "outcome": "passed", "result": [{"nodeid": "test_performance.py::TestStressScenarios::test_large_payload_persona", "type": "Function", "lineno": 149}, {"nodeid": "test_performance.py::TestStressScenarios::test_rapid_successive_requests", "type": "Function", "lineno": 163}, {"nodeid": "test_performance.py::TestStressScenarios::test_special_characters_in_requests", "type": "Function", "lineno": 189}]}, {"nodeid": "test_performance.py::TestBoundaryConditions", "outcome": "passed", "result": [{"nodeid": "test_performance.py::TestBoundaryConditions::test_empty_payloads", "type": "Function", "lineno": 213}, {"nodeid": "test_performance.py::TestBoundaryConditions::test_null_values_in_payload", "type": "Function", "lineno": 224}, {"nodeid": "test_performance.py::TestBoundaryConditions::test_extremely_long_mission_id", "type": "Function", "lineno": 233}]}, {"nodeid": "test_performance.py", "outcome": "passed", "result": [{"nodeid": "test_performance.py::TestPerformance", "type": "Class"}, {"nodeid": "test_performance.py::TestLoadTesting", "type": "Class"}, {"nodeid": "test_performance.py::TestStressScenarios", "type": "Class"}, {"nodeid": "test_performance.py::TestBoundaryConditions", "type": "Class"}]}, {"nodeid": "__init__.py", "outcome": "passed", "result": [{"nodeid": "test_endpoints.py", "type": "Module"}, {"nodeid": "test_performance.py", "type": "Module"}]}], "tests": [{"nodeid": "test_endpoints.py::TestHealthEndpoint::test_health_check_success", "lineno": 14, "outcome": "passed", "keywords": ["test_health_check_success", "TestHealthEndpoint", "test_endpoints.py", "__init__.py", "api"], "setup": {"duration": 0.009234899996954482, "outcome": "passed", "stdout": "\n\ud83e\uddea Starting BuildingOS API Test Suite\n\ud83c\udf10 Base URL: https://pj4vlvxrg7.execute-api.us-east-1.amazonaws.com/dev\n\ud83c\udff7\ufe0f  Environment: dev\n"}, "call": {"duration": 1.528072200002498, "outcome": "passed", "stdout": "\n\ud83d\ude80 GET /health\n\ud83d\udcca Status: 200 | \u23f1\ufe0f  Time: 1525.47ms | \ud83d\udce6 Size: 60 bytes\n"}, "teardown": {"duration": 0.0009835999953793362, "outcome": "passed", "stdout": "\n"}}, {"nodeid": "test_endpoints.py::TestHealthEndpoint::test_health_check_performance", "lineno": 23, "outcome": "passed", "keywords": ["test_health_check_performance", "TestHealthEndpoint", "test_endpoints.py", "__init__.py", "api"], "setup": {"duration": 0.0005578999989666045, "outcome": "passed"}, "call": {"duration": 0.197888900001999, "outcome": "passed", "stdout": "\n\ud83d\ude80 GET /health\n\ud83d\udcca Status: 200 | \u23f1\ufe0f  Time: 195.53ms | \ud83d\udce6 Size: 60 bytes\n"}, "teardown": {"duration": 0.0011206000053789467, "outcome": "passed", "stdout": "\n"}}, {"nodeid": "test_endpoints.py::TestDirectorEndpoint::test_director_basic_request", "lineno": 37, "outcome": "failed", "keywords": ["test_director_basic_request", "TestDirectorEndpoint", "test_endpoints.py", "__init__.py", "api"], "setup": {"duration": 0.0005028000014135614, "outcome": "passed"}, "call": {"duration": 128.92459560000134, "outcome": "failed", "crash": {"path": "C:\\Projects\\building-os-platform\\.venv\\Lib\\site-packages\\requests\\adapters.py", "lineno": 519, "message": "requests.exceptions.ConnectionError: HTTPSConnectionPool(host='pj4vlvxrg7.execute-api.us-east-1.amazonaws.com', port=443): Max retries exceeded with url: /dev/director (Caused by ReadTimeoutError(\"HTTPSConnectionPool(host='pj4vlvxrg7.execute-api.us-east-1.amazonaws.com', port=443): Read timed out. (read timeout=30)\"))"}, "stdout": "\n\ud83d\ude80 GET /director\n\u274c Request failed: \nHTTPSConnectionPool(host='pj4vlvxrg7.execute-api.us-east-1.amazonaws.com', \nport=443): Max retries exceeded with url: /dev/director (Caused by \nReadTimeoutError(\"HTTPSConnectionPool(host='pj4vlvxrg7.execute-api.us-east-1.am\nazonaws.com', port=443): Read timed out. (read timeout=30)\"))\n", "log": [{"name": "urllib3.connectionpool", "msg": "Retrying (Retry(total=2, connect=None, read=None, redirect=None, status=None)) after connection broken by 'ReadTimeoutError(\"HTTPSConnectionPool(host='pj4vlvxrg7.execute-api.us-east-1.amazonaws.com', port=443): Read timed out. (read timeout=30)\")': /dev/director", "args": null, "levelname": "WARNING", "levelno": 30, "pathname": "C:\\Projects\\building-os-platform\\.venv\\Lib\\site-packages\\urllib3\\connectionpool.py", "filename": "connectionpool.py", "module": "connectionpool", "exc_info": null, "exc_text": null, "stack_info": null, "lineno": 868, "funcName": "urlopen", "created": 1754780705.9401355, "msecs": 940.0, "relativeCreated": 33242.5715, "thread": 5176, "threadName": "MainThread", "processName": "MainProcess", "process": 15148, "taskName": null}, {"name": "urllib3.connectionpool", "msg": "Retrying (Retry(total=1, connect=None, read=None, redirect=None, status=None)) after connection broken by 'ReadTimeoutError(\"HTTPSConnectionPool(host='pj4vlvxrg7.execute-api.us-east-1.amazonaws.com', port=443): Read timed out. (read timeout=30)\")': /dev/director", "args": null, "levelname": "WARNING", "levelno": 30, "pathname": "C:\\Projects\\building-os-platform\\.venv\\Lib\\site-packages\\urllib3\\connectionpool.py", "filename": "connectionpool.py", "module": "connectionpool", "exc_info": null, "exc_text": null, "stack_info": null, "lineno": 868, "funcName": "urlopen", "created": 1754780738.9105792, "msecs": 910.0, "relativeCreated": 66213.0151, "thread": 5176, "threadName": "MainThread", "processName": "MainProcess", "process": 15148, "taskName": null}, {"name": "urllib3.connectionpool", "msg": "Retrying (Retry(total=0, connect=None, read=None, redirect=None, status=None)) after connection broken by 'ReadTimeoutError(\"HTTPSConnectionPool(host='pj4vlvxrg7.execute-api.us-east-1.amazonaws.com', port=443): Read timed out. (read timeout=30)\")': /dev/director", "args": null, "levelname": "WARNING", "levelno": 30, "pathname": "C:\\Projects\\building-os-platform\\.venv\\Lib\\site-packages\\urllib3\\connectionpool.py", "filename": "connectionpool.py", "module": "connectionpool", "exc_info": null, "exc_text": null, "stack_info": null, "lineno": 868, "funcName": "urlopen", "created": 1754780773.9011247, "msecs": 901.0, "relativeCreated": 101203.5607, "thread": 5176, "threadName": "MainThread", "processName": "MainProcess", "process": 15148, "taskName": null}], "longrepr": "E   TimeoutError: The read operation timed out\n\nThe above exception was the direct cause of the following exception:\nE   urllib3.exceptions.ReadTimeoutError: HTTPSConnectionPool(host='pj4vlvxrg7.execute-api.us-east-1.amazonaws.com', port=443): Read timed out. (read timeout=30)\n\nThe above exception was the direct cause of the following exception:\nE   urllib3.exceptions.MaxRetryError: HTTPSConnectionPool(host='pj4vlvxrg7.execute-api.us-east-1.amazonaws.com', port=443): Max retries exceeded with url: /dev/director (Caused by ReadTimeoutError(\"HTTPSConnectionPool(host='pj4vlvxrg7.execute-api.us-east-1.amazonaws.com', port=443): Read timed out. (read timeout=30)\"))\n\nDuring handling of the above exception, another exception occurred:\nE   requests.exceptions.ConnectionError: HTTPSConnectionPool(host='pj4vlvxrg7.execute-api.us-east-1.amazonaws.com', port=443): Max retries exceeded with url: /dev/director (Caused by ReadTimeoutError(\"HTTPSConnectionPool(host='pj4vlvxrg7.execute-api.us-east-1.amazonaws.com', port=443): Read timed out. (read timeout=30)\"))"}, "teardown": {"duration": 0.000967200001468882, "outcome": "passed", "stdout": "\n"}}, {"nodeid": "test_endpoints.py::TestDirectorEndpoint::test_director_with_user_request", "lineno": 46, "outcome": "failed", "keywords": ["test_director_with_user_request", "TestDirectorEndpoint", "test_endpoints.py", "__init__.py", "api"], "setup": {"duration": 0.000588800001423806, "outcome": "passed"}, "call": {"duration": 130.53329269999813, "outcome": "failed", "crash": {"path": "C:\\Projects\\building-os-platform\\.venv\\Lib\\site-packages\\requests\\adapters.py", "lineno": 519, "message": "requests.exceptions.ConnectionError: HTTPSConnectionPool(host='pj4vlvxrg7.execute-api.us-east-1.amazonaws.com', port=443): Max retries exceeded with url: /dev/director?user_request=Test%20mission%20from%20Python%20API%20tests (Caused by ReadTimeoutError(\"HTTPSConnectionPool(host='pj4vlvxrg7.execute-api.us-east-1.amazonaws.com', port=443): Read timed out. (read timeout=30)\"))"}, "stdout": "\n\ud83d\ude80 GET /director?user_request=Test mission from Python API tests\n\u274c Request failed: \nHTTPSConnectionPool(host='pj4vlvxrg7.execute-api.us-east-1.amazonaws.com', \nport=443): Max retries exceeded with url: \n/dev/director?user_request=Test%20mission%20from%20Python%20API%20tests (Caused\nby \nReadTimeoutError(\"HTTPSConnectionPool(host='pj4vlvxrg7.execute-api.us-east-1.am\nazonaws.com', port=443): Read timed out. (read timeout=30)\"))\n", "log": [{"name": "urllib3.connectionpool", "msg": "Retrying (Retry(total=2, connect=None, read=None, redirect=None, status=None)) after connection broken by 'ReadTimeoutError(\"HTTPSConnectionPool(host='pj4vlvxrg7.execute-api.us-east-1.amazonaws.com', port=443): Read timed out. (read timeout=30)\")': /dev/director?user_request=Test%20mission%20from%20Python%20API%20tests", "args": null, "levelname": "WARNING", "levelno": 30, "pathname": "C:\\Projects\\building-os-platform\\.venv\\Lib\\site-packages\\urllib3\\connectionpool.py", "filename": "connectionpool.py", "module": "connectionpool", "exc_info": null, "exc_text": null, "stack_info": null, "lineno": 868, "funcName": "urlopen", "created": 1754780835.8773022, "msecs": 877.0, "relativeCreated": 163179.7383, "thread": 5176, "threadName": "MainThread", "processName": "MainProcess", "process": 15148, "taskName": null}, {"name": "urllib3.connectionpool", "msg": "Retrying (Retry(total=1, connect=None, read=None, redirect=None, status=None)) after connection broken by 'ReadTimeoutError(\"HTTPSConnectionPool(host='pj4vlvxrg7.execute-api.us-east-1.amazonaws.com', port=443): Read timed out. (read timeout=30)\")': /dev/director?user_request=Test%20mission%20from%20Python%20API%20tests", "args": null, "levelname": "WARNING", "levelno": 30, "pathname": "C:\\Projects\\building-os-platform\\.venv\\Lib\\site-packages\\urllib3\\connectionpool.py", "filename": "connectionpool.py", "module": "connectionpool", "exc_info": null, "exc_text": null, "stack_info": null, "lineno": 868, "funcName": "urlopen", "created": 1754780869.4213052, "msecs": 421.0, "relativeCreated": 196723.7412, "thread": 5176, "threadName": "MainThread", "processName": "MainProcess", "process": 15148, "taskName": null}, {"name": "urllib3.connectionpool", "msg": "Retrying (Retry(total=0, connect=None, read=None, redirect=None, status=None)) after connection broken by 'ReadTimeoutError(\"HTTPSConnectionPool(host='pj4vlvxrg7.execute-api.us-east-1.amazonaws.com', port=443): Read timed out. (read timeout=30)\")': /dev/director?user_request=Test%20mission%20from%20Python%20API%20tests", "args": null, "levelname": "WARNING", "levelno": 30, "pathname": "C:\\Projects\\building-os-platform\\.venv\\Lib\\site-packages\\urllib3\\connectionpool.py", "filename": "connectionpool.py", "module": "connectionpool", "exc_info": null, "exc_text": null, "stack_info": null, "lineno": 868, "funcName": "urlopen", "created": 1754780904.4456375, "msecs": 445.0, "relativeCreated": 231748.0735, "thread": 5176, "threadName": "MainThread", "processName": "MainProcess", "process": 15148, "taskName": null}], "longrepr": "E   TimeoutError: The read operation timed out\n\nThe above exception was the direct cause of the following exception:\nE   urllib3.exceptions.ReadTimeoutError: HTTPSConnectionPool(host='pj4vlvxrg7.execute-api.us-east-1.amazonaws.com', port=443): Read timed out. (read timeout=30)\n\nThe above exception was the direct cause of the following exception:\nE   urllib3.exceptions.MaxRetryError: HTTPSConnectionPool(host='pj4vlvxrg7.execute-api.us-east-1.amazonaws.com', port=443): Max retries exceeded with url: /dev/director?user_request=Test%20mission%20from%20Python%20API%20tests (Caused by ReadTimeoutError(\"HTTPSConnectionPool(host='pj4vlvxrg7.execute-api.us-east-1.amazonaws.com', port=443): Read timed out. (read timeout=30)\"))\n\nDuring handling of the above exception, another exception occurred:\nE   requests.exceptions.ConnectionError: HTTPSConnectionPool(host='pj4vlvxrg7.execute-api.us-east-1.amazonaws.com', port=443): Max retries exceeded with url: /dev/director?user_request=Test%20mission%20from%20Python%20API%20tests (Caused by ReadTimeoutError(\"HTTPSConnectionPool(host='pj4vlvxrg7.execute-api.us-east-1.amazonaws.com', port=443): Read timed out. (read timeout=30)\"))"}, "teardown": {"duration": 0.0009184000009554438, "outcome": "passed", "stdout": "\n"}}, {"nodeid": "test_endpoints.py::TestDirectorEndpoint::test_director_with_user_id", "lineno": 56, "outcome": "failed", "keywords": ["test_director_with_user_id", "TestDirectorEndpoint", "test_endpoints.py", "__init__.py", "api"], "setup": {"duration": 0.0016761000006226823, "outcome": "passed"}, "call": {"duration": 131.5359965000025, "outcome": "failed", "crash": {"path": "C:\\Projects\\building-os-platform\\.venv\\Lib\\site-packages\\requests\\adapters.py", "lineno": 519, "message": "requests.exceptions.ConnectionError: HTTPSConnectionPool(host='pj4vlvxrg7.execute-api.us-east-1.amazonaws.com', port=443): Max retries exceeded with url: /dev/director?user_id=api-test-user (Caused by ReadTimeoutError(\"HTTPSConnectionPool(host='pj4vlvxrg7.execute-api.us-east-1.amazonaws.com', port=443): Read timed out. (read timeout=30)\"))"}, "stdout": "\n\ud83d\ude80 GET /director?user_id=api-test-user\n\u274c Request failed: \nHTTPSConnectionPool(host='pj4vlvxrg7.execute-api.us-east-1.amazonaws.com', \nport=443): Max retries exceeded with url: /dev/director?user_id=api-test-user \n(Caused by \nReadTimeoutError(\"HTTPSConnectionPool(host='pj4vlvxrg7.execute-api.us-east-1.am\nazonaws.com', port=443): Read timed out. (read timeout=30)\"))\n", "log": [{"name": "urllib3.connectionpool", "msg": "Retrying (Retry(total=2, connect=None, read=None, redirect=None, status=None)) after connection broken by 'ReadTimeoutError(\"HTTPSConnectionPool(host='pj4vlvxrg7.execute-api.us-east-1.amazonaws.com', port=443): Read timed out. (read timeout=30)\")': /dev/director?user_id=api-test-user", "args": null, "levelname": "WARNING", "levelno": 30, "pathname": "C:\\Projects\\building-os-platform\\.venv\\Lib\\site-packages\\urllib3\\connectionpool.py", "filename": "connectionpool.py", "module": "connectionpool", "exc_info": null, "exc_text": null, "stack_info": null, "lineno": 868, "funcName": "urlopen", "created": 1754780966.6465955, "msecs": 646.0, "relativeCreated": 293949.0316, "thread": 5176, "threadName": "MainThread", "processName": "MainProcess", "process": 15148, "taskName": null}, {"name": "urllib3.connectionpool", "msg": "Retrying (Retry(total=1, connect=None, read=None, redirect=None, status=None)) after connection broken by 'ReadTimeoutError(\"HTTPSConnectionPool(host='pj4vlvxrg7.execute-api.us-east-1.amazonaws.com', port=443): Read timed out. (read timeout=30)\")': /dev/director?user_id=api-test-user", "args": null, "levelname": "WARNING", "levelno": 30, "pathname": "C:\\Projects\\building-os-platform\\.venv\\Lib\\site-packages\\urllib3\\connectionpool.py", "filename": "connectionpool.py", "module": "connectionpool", "exc_info": null, "exc_text": null, "stack_info": null, "lineno": 868, "funcName": "urlopen", "created": 1754780999.6076944, "msecs": 607.0, "relativeCreated": 326910.1304, "thread": 5176, "threadName": "MainThread", "processName": "MainProcess", "process": 15148, "taskName": null}, {"name": "urllib3.connectionpool", "msg": "Retrying (Retry(total=0, connect=None, read=None, redirect=None, status=None)) after connection broken by 'ReadTimeoutError(\"HTTPSConnectionPool(host='pj4vlvxrg7.execute-api.us-east-1.amazonaws.com', port=443): Read timed out. (read timeout=30)\")': /dev/director?user_id=api-test-user", "args": null, "levelname": "WARNING", "levelno": 30, "pathname": "C:\\Projects\\building-os-platform\\.venv\\Lib\\site-packages\\urllib3\\connectionpool.py", "filename": "connectionpool.py", "module": "connectionpool", "exc_info": null, "exc_text": null, "stack_info": null, "lineno": 868, "funcName": "urlopen", "created": 1754781034.6528842, "msecs": 652.0, "relativeCreated": 361955.3201, "thread": 5176, "threadName": "MainThread", "processName": "MainProcess", "process": 15148, "taskName": null}], "longrepr": "E   TimeoutError: The read operation timed out\n\nThe above exception was the direct cause of the following exception:\nE   urllib3.exceptions.ReadTimeoutError: HTTPSConnectionPool(host='pj4vlvxrg7.execute-api.us-east-1.amazonaws.com', port=443): Read timed out. (read timeout=30)\n\nThe above exception was the direct cause of the following exception:\nE   urllib3.exceptions.MaxRetryError: HTTPSConnectionPool(host='pj4vlvxrg7.execute-api.us-east-1.amazonaws.com', port=443): Max retries exceeded with url: /dev/director?user_id=api-test-user (Caused by ReadTimeoutError(\"HTTPSConnectionPool(host='pj4vlvxrg7.execute-api.us-east-1.amazonaws.com', port=443): Read timed out. (read timeout=30)\"))\n\nDuring handling of the above exception, another exception occurred:\nE   requests.exceptions.ConnectionError: HTTPSConnectionPool(host='pj4vlvxrg7.execute-api.us-east-1.amazonaws.com', port=443): Max retries exceeded with url: /dev/director?user_id=api-test-user (Caused by ReadTimeoutError(\"HTTPSConnectionPool(host='pj4vlvxrg7.execute-api.us-east-1.amazonaws.com', port=443): Read timed out. (read timeout=30)\"))"}, "teardown": {"duration": 0.0009049000000231899, "outcome": "passed", "stdout": "\n"}}, {"nodeid": "test_endpoints.py::TestPersonaEndpoint::test_persona_valid_message", "lineno": 68, "outcome": "failed", "keywords": ["test_persona_valid_message", "TestPersonaEndpoint", "test_endpoints.py", "__init__.py", "api"], "setup": {"duration": 0.0004923000014969148, "outcome": "passed"}, "call": {"duration": 8.600843699998222, "outcome": "failed", "crash": {"path": "C:\\Projects\\building-os-platform\\.venv\\Lib\\site-packages\\requests\\adapters.py", "lineno": 510, "message": "requests.exceptions.RetryError: HTTPSConnectionPool(host='pj4vlvxrg7.execute-api.us-east-1.amazonaws.com', port=443): Max retries exceeded with url: /dev/persona (Caused by ResponseError('too many 500 error responses'))"}, "stdout": "\n\ud83d\ude80 POST /persona\n\u274c Request failed: \nHTTPSConnectionPool(host='pj4vlvxrg7.execute-api.us-east-1.amazonaws.com', \nport=443): Max retries exceeded with url: /dev/persona (Caused by \nResponseError('too many 500 error responses'))\n", "longrepr": "urllib3.exceptions.ResponseError: too many 500 error responses\n\nThe above exception was the direct cause of the following exception:\nE   urllib3.exceptions.MaxRetryError: HTTPSConnectionPool(host='pj4vlvxrg7.execute-api.us-east-1.amazonaws.com', port=443): Max retries exceeded with url: /dev/persona (Caused by ResponseError('too many 500 error responses'))\n\nDuring handling of the above exception, another exception occurred:\nE   requests.exceptions.RetryError: HTTPSConnectionPool(host='pj4vlvxrg7.execute-api.us-east-1.amazonaws.com', port=443): Max retries exceeded with url: /dev/persona (Caused by ResponseError('too many 500 error responses'))"}, "teardown": {"duration": 0.0009425000025657937, "outcome": "passed", "stdout": "\n"}}, {"nodeid": "test_endpoints.py::TestPersonaEndpoint::test_persona_missing_user_id", "lineno": 81, "outcome": "passed", "keywords": ["test_persona_missing_user_id", "TestPersonaEndpoint", "test_endpoints.py", "__init__.py", "api"], "setup": {"duration": 0.0005385999975260347, "outcome": "passed"}, "call": {"duration": 0.19365239999751793, "outcome": "passed", "stdout": "\n\ud83d\ude80 POST /persona\n\ud83d\udcca Status: 400 | \u23f1\ufe0f  Time: 191.29ms | \ud83d\udce6 Size: 45 bytes\n"}, "teardown": {"duration": 0.0009513999975752085, "outcome": "passed", "stdout": "\n"}}, {"nodeid": "test_endpoints.py::TestPersonaEndpoint::test_persona_missing_message", "lineno": 89, "outcome": "passed", "keywords": ["test_persona_missing_message", "TestPersonaEndpoint", "test_endpoints.py", "__init__.py", "api"], "setup": {"duration": 0.0005223999978625216, "outcome": "passed"}, "call": {"duration": 0.19022810000024037, "outcome": "passed", "stdout": "\n\ud83d\ude80 POST /persona\n\ud83d\udcca Status: 400 | \u23f1\ufe0f  Time: 187.37ms | \ud83d\udce6 Size: 45 bytes\n"}, "teardown": {"duration": 0.0008194999973056838, "outcome": "passed", "stdout": "\n"}}, {"nodeid": "test_endpoints.py::TestPersonaEndpoint::test_persona_conversations", "lineno": 97, "outcome": "passed", "keywords": ["test_persona_conversations", "TestPersonaEndpoint", "test_endpoints.py", "__init__.py", "api"], "setup": {"duration": 0.0004636999947251752, "outcome": "passed"}, "call": {"duration": 0.22377399999822956, "outcome": "passed", "stdout": "\n\ud83d\ude80 GET /persona/conversations?user_id=api-test-user\n\ud83d\udcca Status: 200 | \u23f1\ufe0f  Time: 221.44ms | \ud83d\udce6 Size: 64 bytes\n"}, "teardown": {"duration": 0.0008398999998462386, "outcome": "passed", "stdout": "\n"}}, {"nodeid": "test_endpoints.py::TestElevatorEndpoint::test_elevator_call_basic", "lineno": 109, "outcome": "failed", "keywords": ["test_elevator_call_basic", "TestElevatorEndpoint", "test_endpoints.py", "__init__.py", "api"], "setup": {"duration": 0.0005870000022696331, "outcome": "passed"}, "call": {"duration": 128.99084170000424, "outcome": "failed", "crash": {"path": "C:\\Projects\\building-os-platform\\.venv\\Lib\\site-packages\\requests\\adapters.py", "lineno": 519, "message": "requests.exceptions.ConnectionError: HTTPSConnectionPool(host='pj4vlvxrg7.execute-api.us-east-1.amazonaws.com', port=443): Max retries exceeded with url: /dev/elevator/call (Caused by ReadTimeoutError(\"HTTPSConnectionPool(host='pj4vlvxrg7.execute-api.us-east-1.amazonaws.com', port=443): Read timed out. (read timeout=30)\"))"}, "stdout": "\n\ud83d\ude80 POST /elevator/call\n\u274c Request failed: \nHTTPSConnectionPool(host='pj4vlvxrg7.execute-api.us-east-1.amazonaws.com', \nport=443): Max retries exceeded with url: /dev/elevator/call (Caused by \nReadTimeoutError(\"HTTPSConnectionPool(host='pj4vlvxrg7.execute-api.us-east-1.am\nazonaws.com', port=443): Read timed out. (read timeout=30)\"))\n", "log": [{"name": "urllib3.connectionpool", "msg": "Retrying (Retry(total=2, connect=None, read=None, redirect=None, status=None)) after connection broken by 'ReadTimeoutError(\"HTTPSConnectionPool(host='pj4vlvxrg7.execute-api.us-east-1.amazonaws.com', port=443): Read timed out. (read timeout=30)\")': /dev/elevator/call", "args": null, "levelname": "WARNING", "levelno": 30, "pathname": "C:\\Projects\\building-os-platform\\.venv\\Lib\\site-packages\\urllib3\\connectionpool.py", "filename": "connectionpool.py", "module": "connectionpool", "exc_info": null, "exc_text": null, "stack_info": null, "lineno": 868, "funcName": "urlopen", "created": 1754781106.2478971, "msecs": 247.0, "relativeCreated": 433550.3332, "thread": 5176, "threadName": "MainThread", "processName": "MainProcess", "process": 15148, "taskName": null}, {"name": "urllib3.connectionpool", "msg": "Retrying (Retry(total=1, connect=None, read=None, redirect=None, status=None)) after connection broken by 'ReadTimeoutError(\"HTTPSConnectionPool(host='pj4vlvxrg7.execute-api.us-east-1.amazonaws.com', port=443): Read timed out. (read timeout=30)\")': /dev/elevator/call", "args": null, "levelname": "WARNING", "levelno": 30, "pathname": "C:\\Projects\\building-os-platform\\.venv\\Lib\\site-packages\\urllib3\\connectionpool.py", "filename": "connectionpool.py", "module": "connectionpool", "exc_info": null, "exc_text": null, "stack_info": null, "lineno": 868, "funcName": "urlopen", "created": 1754781139.2102723, "msecs": 210.0, "relativeCreated": 466512.7083, "thread": 5176, "threadName": "MainThread", "processName": "MainProcess", "process": 15148, "taskName": null}, {"name": "urllib3.connectionpool", "msg": "Retrying (Retry(total=0, connect=None, read=None, redirect=None, status=None)) after connection broken by 'ReadTimeoutError(\"HTTPSConnectionPool(host='pj4vlvxrg7.execute-api.us-east-1.amazonaws.com', port=443): Read timed out. (read timeout=30)\")': /dev/elevator/call", "args": null, "levelname": "WARNING", "levelno": 30, "pathname": "C:\\Projects\\building-os-platform\\.venv\\Lib\\site-packages\\urllib3\\connectionpool.py", "filename": "connectionpool.py", "module": "connectionpool", "exc_info": null, "exc_text": null, "stack_info": null, "lineno": 868, "funcName": "urlopen", "created": 1754781174.2590823, "msecs": 259.0, "relativeCreated": 501561.5182, "thread": 5176, "threadName": "MainThread", "processName": "MainProcess", "process": 15148, "taskName": null}], "longrepr": "E   TimeoutError: The read operation timed out\n\nThe above exception was the direct cause of the following exception:\nE   urllib3.exceptions.ReadTimeoutError: HTTPSConnectionPool(host='pj4vlvxrg7.execute-api.us-east-1.amazonaws.com', port=443): Read timed out. (read timeout=30)\n\nThe above exception was the direct cause of the following exception:\nE   urllib3.exceptions.MaxRetryError: HTTPSConnectionPool(host='pj4vlvxrg7.execute-api.us-east-1.amazonaws.com', port=443): Max retries exceeded with url: /dev/elevator/call (Caused by ReadTimeoutError(\"HTTPSConnectionPool(host='pj4vlvxrg7.execute-api.us-east-1.amazonaws.com', port=443): Read timed out. (read timeout=30)\"))\n\nDuring handling of the above exception, another exception occurred:\nE   requests.exceptions.ConnectionError: HTTPSConnectionPool(host='pj4vlvxrg7.execute-api.us-east-1.amazonaws.com', port=443): Max retries exceeded with url: /dev/elevator/call (Caused by ReadTimeoutError(\"HTTPSConnectionPool(host='pj4vlvxrg7.execute-api.us-east-1.amazonaws.com', port=443): Read timed out. (read timeout=30)\"))"}, "teardown": {"duration": 0.0009378999966429546, "outcome": "passed", "stdout": "\n"}}, {"nodeid": "test_endpoints.py::TestElevatorEndpoint::test_elevator_missing_mission_id", "lineno": 120, "outcome": "failed", "keywords": ["test_elevator_missing_mission_id", "TestElevatorEndpoint", "test_endpoints.py", "__init__.py", "api"], "setup": {"duration": 0.0005320999989635311, "outcome": "passed"}, "call": {"duration": 130.02045029999863, "outcome": "failed", "crash": {"path": "C:\\Projects\\building-os-platform\\.venv\\Lib\\site-packages\\requests\\adapters.py", "lineno": 519, "message": "requests.exceptions.ConnectionError: HTTPSConnectionPool(host='pj4vlvxrg7.execute-api.us-east-1.amazonaws.com', port=443): Max retries exceeded with url: /dev/elevator/call (Caused by ReadTimeoutError(\"HTTPSConnectionPool(host='pj4vlvxrg7.execute-api.us-east-1.amazonaws.com', port=443): Read timed out. (read timeout=30)\"))"}, "stdout": "\n\ud83d\ude80 POST /elevator/call\n\u274c Request failed: \nHTTPSConnectionPool(host='pj4vlvxrg7.execute-api.us-east-1.amazonaws.com', \nport=443): Max retries exceeded with url: /dev/elevator/call (Caused by \nReadTimeoutError(\"HTTPSConnectionPool(host='pj4vlvxrg7.execute-api.us-east-1.am\nazonaws.com', port=443): Read timed out. (read timeout=30)\"))\n", "log": [{"name": "urllib3.connectionpool", "msg": "Retrying (Retry(total=2, connect=None, read=None, redirect=None, status=None)) after connection broken by 'ReadTimeoutError(\"HTTPSConnectionPool(host='pj4vlvxrg7.execute-api.us-east-1.amazonaws.com', port=443): Read timed out. (read timeout=30)\")': /dev/elevator/call", "args": null, "levelname": "WARNING", "levelno": 30, "pathname": "C:\\Projects\\building-os-platform\\.venv\\Lib\\site-packages\\urllib3\\connectionpool.py", "filename": "connectionpool.py", "module": "connectionpool", "exc_info": null, "exc_text": null, "stack_info": null, "lineno": 868, "funcName": "urlopen", "created": 1754781236.237631, "msecs": 237.0, "relativeCreated": 563540.0669, "thread": 5176, "threadName": "MainThread", "processName": "MainProcess", "process": 15148, "taskName": null}, {"name": "urllib3.connectionpool", "msg": "Retrying (Retry(total=1, connect=None, read=None, redirect=None, status=None)) after connection broken by 'ReadTimeoutError(\"HTTPSConnectionPool(host='pj4vlvxrg7.execute-api.us-east-1.amazonaws.com', port=443): Read timed out. (read timeout=30)\")': /dev/elevator/call", "args": null, "levelname": "WARNING", "levelno": 30, "pathname": "C:\\Projects\\building-os-platform\\.venv\\Lib\\site-packages\\urllib3\\connectionpool.py", "filename": "connectionpool.py", "module": "connectionpool", "exc_info": null, "exc_text": null, "stack_info": null, "lineno": 868, "funcName": "urlopen", "created": 1754781269.286791, "msecs": 286.0, "relativeCreated": 596589.2272, "thread": 5176, "threadName": "MainThread", "processName": "MainProcess", "process": 15148, "taskName": null}, {"name": "urllib3.connectionpool", "msg": "Retrying (Retry(total=0, connect=None, read=None, redirect=None, status=None)) after connection broken by 'ReadTimeoutError(\"HTTPSConnectionPool(host='pj4vlvxrg7.execute-api.us-east-1.amazonaws.com', port=443): Read timed out. (read timeout=30)\")': /dev/elevator/call", "args": null, "levelname": "WARNING", "levelno": 30, "pathname": "C:\\Projects\\building-os-platform\\.venv\\Lib\\site-packages\\urllib3\\connectionpool.py", "filename": "connectionpool.py", "module": "connectionpool", "exc_info": null, "exc_text": null, "stack_info": null, "lineno": 868, "funcName": "urlopen", "created": 1754781304.3068888, "msecs": 306.0, "relativeCreated": 631609.3247, "thread": 5176, "threadName": "MainThread", "processName": "MainProcess", "process": 15148, "taskName": null}], "longrepr": "E   TimeoutError: The read operation timed out\n\nThe above exception was the direct cause of the following exception:\nE   urllib3.exceptions.ReadTimeoutError: HTTPSConnectionPool(host='pj4vlvxrg7.execute-api.us-east-1.amazonaws.com', port=443): Read timed out. (read timeout=30)\n\nThe above exception was the direct cause of the following exception:\nE   urllib3.exceptions.MaxRetryError: HTTPSConnectionPool(host='pj4vlvxrg7.execute-api.us-east-1.amazonaws.com', port=443): Max retries exceeded with url: /dev/elevator/call (Caused by ReadTimeoutError(\"HTTPSConnectionPool(host='pj4vlvxrg7.execute-api.us-east-1.amazonaws.com', port=443): Read timed out. (read timeout=30)\"))\n\nDuring handling of the above exception, another exception occurred:\nE   requests.exceptions.ConnectionError: HTTPSConnectionPool(host='pj4vlvxrg7.execute-api.us-east-1.amazonaws.com', port=443): Max retries exceeded with url: /dev/elevator/call (Caused by ReadTimeoutError(\"HTTPSConnectionPool(host='pj4vlvxrg7.execute-api.us-east-1.amazonaws.com', port=443): Read timed out. (read timeout=30)\"))"}, "teardown": {"duration": 0.001036599998769816, "outcome": "passed", "stdout": "\n"}}, {"nodeid": "test_endpoints.py::TestPSIMEndpoint::test_psim_search_basic", "lineno": 132, "outcome": "passed", "keywords": ["test_psim_search_basic", "TestPSIMEndpoint", "test_endpoints.py", "__init__.py", "api"], "setup": {"duration": 0.0005468000017572194, "outcome": "passed"}, "call": {"duration": 2.620616300002439, "outcome": "passed", "stdout": "\n\ud83d\ude80 POST /psim/search\n\ud83d\udcca Status: 200 | \u23f1\ufe0f  Time: 2606.72ms | \ud83d\udce6 Size: 223 bytes\n"}, "teardown": {"duration": 0.0007947000049171038, "outcome": "passed", "stdout": "\n"}}, {"nodeid": "test_endpoints.py::TestPSIMEndpoint::test_psim_search_with_custom_query", "lineno": 142, "outcome": "passed", "keywords": ["test_psim_search_with_custom_query", "TestPSIMEndpoint", "test_endpoints.py", "__init__.py", "api"], "setup": {"duration": 0.0005301999990479089, "outcome": "passed"}, "call": {"duration": 0.3177040999944438, "outcome": "passed", "stdout": "\n\ud83d\ude80 POST /psim/search\n\ud83d\udcca Status: 200 | \u23f1\ufe0f  Time: 315.49ms | \ud83d\udce6 Size: 223 bytes\n"}, "teardown": {"duration": 0.0008961999992607161, "outcome": "passed", "stdout": "\n"}}, {"nodeid": "test_endpoints.py::TestCoordinatorEndpoint::test_coordinator_mission_status", "lineno": 155, "outcome": "failed", "keywords": ["test_coordinator_mission_status", "TestCoordinatorEndpoint", "test_endpoints.py", "__init__.py", "api"], "setup": {"duration": 0.0006221999938134104, "outcome": "passed"}, "call": {"duration": 1.053431999993336, "outcome": "failed", "crash": {"path": "c:\\Projects\\building-os-platform\\tests\\api\\test_endpoints.py", "lineno": 161, "message": "assert 404 == 200\n +  where 404 = <Response [404]>.status_code"}, "stdout": "\n\ud83d\ude80 GET /coordinator/missions/test-mission-123\n\ud83d\udcca Status: 404 | \u23f1\ufe0f  Time: 1050.83ms | \ud83d\udce6 Size: 47 bytes\n", "longrepr": "E   assert 404 == 200\n     +  where 404 = <Response [404]>.status_code"}, "teardown": {"duration": 0.0008842000024742447, "outcome": "passed", "stdout": "\n"}}, {"nodeid": "test_endpoints.py::TestCoordinatorEndpoint::test_coordinator_different_mission_id", "lineno": 166, "outcome": "failed", "keywords": ["test_coordinator_different_mission_id", "TestCoordinatorEndpoint", "test_endpoints.py", "__init__.py", "api"], "setup": {"duration": 0.0004780000017490238, "outcome": "passed"}, "call": {"duration": 0.22417329999734648, "outcome": "failed", "crash": {"path": "c:\\Projects\\building-os-platform\\tests\\api\\test_endpoints.py", "lineno": 172, "message": "assert 404 == 200\n +  where 404 = <Response [404]>.status_code"}, "stdout": "\n\ud83d\ude80 GET /coordinator/missions/python-test-1754781339\n\ud83d\udcca Status: 404 | \u23f1\ufe0f  Time: 220.91ms | \ud83d\udce6 Size: 53 bytes\n", "longrepr": "E   assert 404 == 200\n     +  where 404 = <Response [404]>.status_code"}, "teardown": {"duration": 0.000931399998080451, "outcome": "passed", "stdout": "\n"}}, {"nodeid": "test_endpoints.py::TestCORSHeaders::test_cors_headers_present[/health]", "lineno": 178, "outcome": "failed", "keywords": ["test_cors_headers_present[/health]", "parametrize", "pytestmark", "/health", "TestCORSHeaders", "test_endpoints.py", "__init__.py", "api"], "setup": {"duration": 0.0006298000007518567, "outcome": "passed"}, "call": {"duration": 0.5297179000044707, "outcome": "failed", "crash": {"path": "c:\\Projects\\building-os-platform\\tests\\api\\test_endpoints.py", "lineno": 215, "message": "AssertionError: No CORS headers found in response for /health\nassert False"}, "stdout": "\n\ud83d\ude80 GET /health\n\ud83d\udcca Status: 200 | \u23f1\ufe0f  Time: 527.18ms | \ud83d\udce6 Size: 60 bytes\n", "longrepr": "E   AssertionError: No CORS headers found in response for /health\n    assert False"}, "teardown": {"duration": 0.0009935999987646937, "outcome": "passed", "stdout": "\n"}}, {"nodeid": "test_endpoints.py::TestCORSHeaders::test_cors_headers_present[/director]", "lineno": 178, "outcome": "failed", "keywords": ["test_cors_headers_present[/director]", "parametrize", "pytestmark", "/director", "TestCORSHeaders", "test_endpoints.py", "__init__.py", "api"], "setup": {"duration": 0.0005901999975321814, "outcome": "passed"}, "call": {"duration": 128.90210790000128, "outcome": "failed", "crash": {"path": "C:\\Projects\\building-os-platform\\.venv\\Lib\\site-packages\\requests\\adapters.py", "lineno": 519, "message": "requests.exceptions.ConnectionError: HTTPSConnectionPool(host='pj4vlvxrg7.execute-api.us-east-1.amazonaws.com', port=443): Max retries exceeded with url: /dev/director (Caused by ReadTimeoutError(\"HTTPSConnectionPool(host='pj4vlvxrg7.execute-api.us-east-1.amazonaws.com', port=443): Read timed out. (read timeout=30)\"))"}, "stdout": "\n\ud83d\ude80 GET /director\n\u274c Request failed: \nHTTPSConnectionPool(host='pj4vlvxrg7.execute-api.us-east-1.amazonaws.com', \nport=443): Max retries exceeded with url: /dev/director (Caused by \nReadTimeoutError(\"HTTPSConnectionPool(host='pj4vlvxrg7.execute-api.us-east-1.am\nazonaws.com', port=443): Read timed out. (read timeout=30)\"))\n", "log": [{"name": "urllib3.connectionpool", "msg": "Retrying (Retry(total=2, connect=None, read=None, redirect=None, status=None)) after connection broken by 'ReadTimeoutError(\"HTTPSConnectionPool(host='pj4vlvxrg7.execute-api.us-east-1.amazonaws.com', port=443): Read timed out. (read timeout=30)\")': /dev/director", "args": null, "levelname": "WARNING", "levelno": 30, "pathname": "C:\\Projects\\building-os-platform\\.venv\\Lib\\site-packages\\urllib3\\connectionpool.py", "filename": "connectionpool.py", "module": "connectionpool", "exc_info": null, "exc_text": null, "stack_info": null, "lineno": 868, "funcName": "urlopen", "created": 1754781370.0736036, "msecs": 73.0, "relativeCreated": 697376.0396, "thread": 5176, "threadName": "MainThread", "processName": "MainProcess", "process": 15148, "taskName": null}, {"name": "urllib3.connectionpool", "msg": "Retrying (Retry(total=1, connect=None, read=None, redirect=None, status=None)) after connection broken by 'ReadTimeoutError(\"HTTPSConnectionPool(host='pj4vlvxrg7.execute-api.us-east-1.amazonaws.com', port=443): Read timed out. (read timeout=30)\")': /dev/director", "args": null, "levelname": "WARNING", "levelno": 30, "pathname": "C:\\Projects\\building-os-platform\\.venv\\Lib\\site-packages\\urllib3\\connectionpool.py", "filename": "connectionpool.py", "module": "connectionpool", "exc_info": null, "exc_text": null, "stack_info": null, "lineno": 868, "funcName": "urlopen", "created": 1754781403.0424194, "msecs": 42.0, "relativeCreated": 730344.8555, "thread": 5176, "threadName": "MainThread", "processName": "MainProcess", "process": 15148, "taskName": null}, {"name": "urllib3.connectionpool", "msg": "Retrying (Retry(total=0, connect=None, read=None, redirect=None, status=None)) after connection broken by 'ReadTimeoutError(\"HTTPSConnectionPool(host='pj4vlvxrg7.execute-api.us-east-1.amazonaws.com', port=443): Read timed out. (read timeout=30)\")': /dev/director", "args": null, "levelname": "WARNING", "levelno": 30, "pathname": "C:\\Projects\\building-os-platform\\.venv\\Lib\\site-packages\\urllib3\\connectionpool.py", "filename": "connectionpool.py", "module": "connectionpool", "exc_info": null, "exc_text": null, "stack_info": null, "lineno": 868, "funcName": "urlopen", "created": 1754781438.0228488, "msecs": 22.0, "relativeCreated": 765325.2848, "thread": 5176, "threadName": "MainThread", "processName": "MainProcess", "process": 15148, "taskName": null}], "longrepr": "E   TimeoutError: The read operation timed out\n\nThe above exception was the direct cause of the following exception:\nE   urllib3.exceptions.ReadTimeoutError: HTTPSConnectionPool(host='pj4vlvxrg7.execute-api.us-east-1.amazonaws.com', port=443): Read timed out. (read timeout=30)\n\nThe above exception was the direct cause of the following exception:\nE   urllib3.exceptions.MaxRetryError: HTTPSConnectionPool(host='pj4vlvxrg7.execute-api.us-east-1.amazonaws.com', port=443): Max retries exceeded with url: /dev/director (Caused by ReadTimeoutError(\"HTTPSConnectionPool(host='pj4vlvxrg7.execute-api.us-east-1.amazonaws.com', port=443): Read timed out. (read timeout=30)\"))\n\nDuring handling of the above exception, another exception occurred:\nE   requests.exceptions.ConnectionError: HTTPSConnectionPool(host='pj4vlvxrg7.execute-api.us-east-1.amazonaws.com', port=443): Max retries exceeded with url: /dev/director (Caused by ReadTimeoutError(\"HTTPSConnectionPool(host='pj4vlvxrg7.execute-api.us-east-1.amazonaws.com', port=443): Read timed out. (read timeout=30)\"))"}, "teardown": {"duration": 0.0010372999968240038, "outcome": "passed", "stdout": "\n"}}, {"nodeid": "test_endpoints.py::TestCORSHeaders::test_cors_headers_present[/persona]", "lineno": 178, "outcome": "failed", "keywords": ["test_cors_headers_present[/persona]", "parametrize", "pytestmark", "/persona", "TestCORSHeaders", "test_endpoints.py", "__init__.py", "api"], "setup": {"duration": 0.0006673000025330111, "outcome": "passed"}, "call": {"duration": 1.8011248000038904, "outcome": "failed", "crash": {"path": "c:\\Projects\\building-os-platform\\tests\\api\\test_endpoints.py", "lineno": 215, "message": "AssertionError: No CORS headers found in response for /persona\nassert False"}, "stdout": "\n\ud83d\ude80 POST /persona\n\ud83d\udcca Status: 400 | \u23f1\ufe0f  Time: 1798.17ms | \ud83d\udce6 Size: 45 bytes\n", "longrepr": "E   AssertionError: No CORS headers found in response for /persona\n    assert False"}, "teardown": {"duration": 0.0009413000007043593, "outcome": "passed", "stdout": "\n"}}, {"nodeid": "test_endpoints.py::TestCORSHeaders::test_cors_headers_present[/elevator/call]", "lineno": 178, "outcome": "failed", "keywords": ["test_cors_headers_present[/elevator/call]", "parametrize", "pytestmark", "/elevator/call", "TestCORSHeaders", "test_endpoints.py", "__init__.py", "api"], "setup": {"duration": 0.0006062999964342453, "outcome": "passed"}, "call": {"duration": 128.9769069000031, "outcome": "failed", "crash": {"path": "C:\\Projects\\building-os-platform\\.venv\\Lib\\site-packages\\requests\\adapters.py", "lineno": 519, "message": "requests.exceptions.ConnectionError: HTTPSConnectionPool(host='pj4vlvxrg7.execute-api.us-east-1.amazonaws.com', port=443): Max retries exceeded with url: /dev/elevator/call (Caused by ReadTimeoutError(\"HTTPSConnectionPool(host='pj4vlvxrg7.execute-api.us-east-1.amazonaws.com', port=443): Read timed out. (read timeout=30)\"))"}, "stdout": "\n\ud83d\ude80 POST /elevator/call\n\u274c Request failed: \nHTTPSConnectionPool(host='pj4vlvxrg7.execute-api.us-east-1.amazonaws.com', \nport=443): Max retries exceeded with url: /dev/elevator/call (Caused by \nReadTimeoutError(\"HTTPSConnectionPool(host='pj4vlvxrg7.execute-api.us-east-1.am\nazonaws.com', port=443): Read timed out. (read timeout=30)\"))\n", "log": [{"name": "urllib3.connectionpool", "msg": "Retrying (Retry(total=2, connect=None, read=None, redirect=None, status=None)) after connection broken by 'ReadTimeoutError(\"HTTPSConnectionPool(host='pj4vlvxrg7.execute-api.us-east-1.amazonaws.com', port=443): Read timed out. (read timeout=30)\")': /dev/elevator/call", "args": null, "levelname": "WARNING", "levelno": 30, "pathname": "C:\\Projects\\building-os-platform\\.venv\\Lib\\site-packages\\urllib3\\connectionpool.py", "filename": "connectionpool.py", "module": "connectionpool", "exc_info": null, "exc_text": null, "stack_info": null, "lineno": 868, "funcName": "urlopen", "created": 1754781500.8116152, "msecs": 811.0, "relativeCreated": 828114.0513, "thread": 5176, "threadName": "MainThread", "processName": "MainProcess", "process": 15148, "taskName": null}, {"name": "urllib3.connectionpool", "msg": "Retrying (Retry(total=1, connect=None, read=None, redirect=None, status=None)) after connection broken by 'ReadTimeoutError(\"HTTPSConnectionPool(host='pj4vlvxrg7.execute-api.us-east-1.amazonaws.com', port=443): Read timed out. (read timeout=30)\")': /dev/elevator/call", "args": null, "levelname": "WARNING", "levelno": 30, "pathname": "C:\\Projects\\building-os-platform\\.venv\\Lib\\site-packages\\urllib3\\connectionpool.py", "filename": "connectionpool.py", "module": "connectionpool", "exc_info": null, "exc_text": null, "stack_info": null, "lineno": 868, "funcName": "urlopen", "created": 1754781533.7707574, "msecs": 770.0, "relativeCreated": 861073.1935, "thread": 5176, "threadName": "MainThread", "processName": "MainProcess", "process": 15148, "taskName": null}, {"name": "urllib3.connectionpool", "msg": "Retrying (Retry(total=0, connect=None, read=None, redirect=None, status=None)) after connection broken by 'ReadTimeoutError(\"HTTPSConnectionPool(host='pj4vlvxrg7.execute-api.us-east-1.amazonaws.com', port=443): Read timed out. (read timeout=30)\")': /dev/elevator/call", "args": null, "levelname": "WARNING", "levelno": 30, "pathname": "C:\\Projects\\building-os-platform\\.venv\\Lib\\site-packages\\urllib3\\connectionpool.py", "filename": "connectionpool.py", "module": "connectionpool", "exc_info": null, "exc_text": null, "stack_info": null, "lineno": 868, "funcName": "urlopen", "created": 1754781568.7917578, "msecs": 791.0, "relativeCreated": 896094.1938, "thread": 5176, "threadName": "MainThread", "processName": "MainProcess", "process": 15148, "taskName": null}], "longrepr": "E   TimeoutError: The read operation timed out\n\nThe above exception was the direct cause of the following exception:\nE   urllib3.exceptions.ReadTimeoutError: HTTPSConnectionPool(host='pj4vlvxrg7.execute-api.us-east-1.amazonaws.com', port=443): Read timed out. (read timeout=30)\n\nThe above exception was the direct cause of the following exception:\nE   urllib3.exceptions.MaxRetryError: HTTPSConnectionPool(host='pj4vlvxrg7.execute-api.us-east-1.amazonaws.com', port=443): Max retries exceeded with url: /dev/elevator/call (Caused by ReadTimeoutError(\"HTTPSConnectionPool(host='pj4vlvxrg7.execute-api.us-east-1.amazonaws.com', port=443): Read timed out. (read timeout=30)\"))\n\nDuring handling of the above exception, another exception occurred:\nE   requests.exceptions.ConnectionError: HTTPSConnectionPool(host='pj4vlvxrg7.execute-api.us-east-1.amazonaws.com', port=443): Max retries exceeded with url: /dev/elevator/call (Caused by ReadTimeoutError(\"HTTPSConnectionPool(host='pj4vlvxrg7.execute-api.us-east-1.amazonaws.com', port=443): Read timed out. (read timeout=30)\"))"}, "teardown": {"duration": 0.0009577000018907711, "outcome": "passed", "stdout": "\n"}}, {"nodeid": "test_endpoints.py::TestCORSHeaders::test_cors_headers_present[/psim/search]", "lineno": 178, "outcome": "failed", "keywords": ["test_cors_headers_present[/psim/search]", "parametrize", "pytestmark", "/psim/search", "TestCORSHeaders", "test_endpoints.py", "__init__.py", "api"], "setup": {"duration": 0.0006460000004153699, "outcome": "passed"}, "call": {"duration": 1.2141199999969103, "outcome": "failed", "crash": {"path": "c:\\Projects\\building-os-platform\\tests\\api\\test_endpoints.py", "lineno": 215, "message": "AssertionError: No CORS headers found in response for /psim/search\nassert False"}, "stdout": "\n\ud83d\ude80 POST /psim/search\n\ud83d\udcca Status: 400 | \u23f1\ufe0f  Time: 1211.75ms | \ud83d\udce6 Size: 43 bytes\n", "longrepr": "E   AssertionError: No CORS headers found in response for /psim/search\n    assert False"}, "teardown": {"duration": 0.0009352999986731447, "outcome": "passed", "stdout": "\n"}}, {"nodeid": "test_endpoints.py::TestCORSHeaders::test_cors_headers_present[/coordinator/missions/test-123]", "lineno": 178, "outcome": "failed", "keywords": ["test_cors_headers_present[/coordinator/missions/test-123]", "parametrize", "pytestmark", "/coordinator/missions/test-123", "TestCORSHeaders", "test_endpoints.py", "__init__.py", "api"], "setup": {"duration": 0.0006424000021070242, "outcome": "passed"}, "call": {"duration": 0.3197045999986585, "outcome": "failed", "crash": {"path": "c:\\Projects\\building-os-platform\\tests\\api\\test_endpoints.py", "lineno": 215, "message": "AssertionError: No CORS headers found in response for /coordinator/missions/test-123\nassert False"}, "stdout": "\n\ud83d\ude80 GET /coordinator/missions/test-123\n\ud83d\udcca Status: 404 | \u23f1\ufe0f  Time: 317.32ms | \ud83d\udce6 Size: 39 bytes\n", "longrepr": "E   AssertionError: No CORS headers found in response for /coordinator/missions/test-123\n    assert False"}, "teardown": {"duration": 0.0009366000012960285, "outcome": "passed", "stdout": "\n"}}, {"nodeid": "test_endpoints.py::TestErrorHandling::test_invalid_endpoint", "lineno": 220, "outcome": "passed", "keywords": ["test_invalid_endpoint", "TestErrorHandling", "test_endpoints.py", "__init__.py", "api"], "setup": {"duration": 0.0005703999995603226, "outcome": "passed"}, "call": {"duration": 0.16083459999936167, "outcome": "passed", "stdout": "\n\ud83d\ude80 GET /invalid-endpoint\n\ud83d\udcca Status: 404 | \u23f1\ufe0f  Time: 158.46ms | \ud83d\udce6 Size: 23 bytes\n"}, "teardown": {"duration": 0.0011330999986967072, "outcome": "passed", "stdout": "\n"}}, {"nodeid": "test_endpoints.py::TestErrorHandling::test_invalid_method", "lineno": 225, "outcome": "passed", "keywords": ["test_invalid_method", "TestErrorHandling", "test_endpoints.py", "__init__.py", "api"], "setup": {"duration": 0.0006989999965298921, "outcome": "passed"}, "call": {"duration": 0.16263630000321427, "outcome": "passed", "stdout": "\n\ud83d\ude80 DELETE /health\n\ud83d\udcca Status: 404 | \u23f1\ufe0f  Time: 160.02ms | \ud83d\udce6 Size: 23 bytes\n"}, "teardown": {"duration": 0.0009303999977419153, "outcome": "passed", "stdout": "\n"}}, {"nodeid": "test_endpoints.py::TestErrorHandling::test_malformed_json", "lineno": 235, "outcome": "passed", "keywords": ["test_malformed_json", "TestErrorHandling", "test_endpoints.py", "__init__.py", "api"], "setup": {"duration": 0.000586200003453996, "outcome": "passed"}, "call": {"duration": 6.884893499998725, "outcome": "passed"}, "teardown": {"duration": 0.001414500002283603, "outcome": "passed", "stdout": "\n"}}, {"nodeid": "test_performance.py::TestPerformance::test_response_time_under_threshold", "lineno": 18, "outcome": "failed", "keywords": ["test_response_time_under_threshold", "TestPerformance", "test_performance.py", "__init__.py", "api"], "setup": {"duration": 0.0008450999957858585, "outcome": "passed"}, "call": {"duration": 129.44843910000054, "outcome": "failed", "crash": {"path": "C:\\Projects\\building-os-platform\\.venv\\Lib\\site-packages\\requests\\adapters.py", "lineno": 519, "message": "requests.exceptions.ConnectionError: HTTPSConnectionPool(host='pj4vlvxrg7.execute-api.us-east-1.amazonaws.com', port=443): Max retries exceeded with url: /dev/director (Caused by ReadTimeoutError(\"HTTPSConnectionPool(host='pj4vlvxrg7.execute-api.us-east-1.amazonaws.com', port=443): Read timed out. (read timeout=30)\"))"}, "stdout": "\n\ud83d\ude80 GET /health\n\ud83d\udcca Status: 200 | \u23f1\ufe0f  Time: 498.41ms | \ud83d\udce6 Size: 60 bytes\n\n\ud83d\ude80 GET /director\n\u274c Request failed: \nHTTPSConnectionPool(host='pj4vlvxrg7.execute-api.us-east-1.amazonaws.com', \nport=443): Max retries exceeded with url: /dev/director (Caused by \nReadTimeoutError(\"HTTPSConnectionPool(host='pj4vlvxrg7.execute-api.us-east-1.am\nazonaws.com', port=443): Read timed out. (read timeout=30)\"))\n", "log": [{"name": "urllib3.connectionpool", "msg": "Retrying (Retry(total=2, connect=None, read=None, redirect=None, status=None)) after connection broken by 'ReadTimeoutError(\"HTTPSConnectionPool(host='pj4vlvxrg7.execute-api.us-east-1.amazonaws.com', port=443): Read timed out. (read timeout=30)\")': /dev/director", "args": null, "levelname": "WARNING", "levelno": 30, "pathname": "C:\\Projects\\building-os-platform\\.venv\\Lib\\site-packages\\urllib3\\connectionpool.py", "filename": "connectionpool.py", "module": "connectionpool", "exc_info": null, "exc_text": null, "stack_info": null, "lineno": 868, "funcName": "urlopen", "created": 1754781639.4348457, "msecs": 434.0, "relativeCreated": 966737.2817, "thread": 5176, "threadName": "MainThread", "processName": "MainProcess", "process": 15148, "taskName": null}, {"name": "urllib3.connectionpool", "msg": "Retrying (Retry(total=1, connect=None, read=None, redirect=None, status=None)) after connection broken by 'ReadTimeoutError(\"HTTPSConnectionPool(host='pj4vlvxrg7.execute-api.us-east-1.amazonaws.com', port=443): Read timed out. (read timeout=30)\")': /dev/director", "args": null, "levelname": "WARNING", "levelno": 30, "pathname": "C:\\Projects\\building-os-platform\\.venv\\Lib\\site-packages\\urllib3\\connectionpool.py", "filename": "connectionpool.py", "module": "connectionpool", "exc_info": null, "exc_text": null, "stack_info": null, "lineno": 868, "funcName": "urlopen", "created": 1754781672.3968763, "msecs": 396.0, "relativeCreated": 999699.3123, "thread": 5176, "threadName": "MainThread", "processName": "MainProcess", "process": 15148, "taskName": null}, {"name": "urllib3.connectionpool", "msg": "Retrying (Retry(total=0, connect=None, read=None, redirect=None, status=None)) after connection broken by 'ReadTimeoutError(\"HTTPSConnectionPool(host='pj4vlvxrg7.execute-api.us-east-1.amazonaws.com', port=443): Read timed out. (read timeout=30)\")': /dev/director", "args": null, "levelname": "WARNING", "levelno": 30, "pathname": "C:\\Projects\\building-os-platform\\.venv\\Lib\\site-packages\\urllib3\\connectionpool.py", "filename": "connectionpool.py", "module": "connectionpool", "exc_info": null, "exc_text": null, "stack_info": null, "lineno": 868, "funcName": "urlopen", "created": 1754781707.3907979, "msecs": 390.0, "relativeCreated": 1034693.2337, "thread": 5176, "threadName": "MainThread", "processName": "MainProcess", "process": 15148, "taskName": null}], "longrepr": "E   TimeoutError: The read operation timed out\n\nThe above exception was the direct cause of the following exception:\nE   urllib3.exceptions.ReadTimeoutError: HTTPSConnectionPool(host='pj4vlvxrg7.execute-api.us-east-1.amazonaws.com', port=443): Read timed out. (read timeout=30)\n\nThe above exception was the direct cause of the following exception:\nE   urllib3.exceptions.MaxRetryError: HTTPSConnectionPool(host='pj4vlvxrg7.execute-api.us-east-1.amazonaws.com', port=443): Max retries exceeded with url: /dev/director (Caused by ReadTimeoutError(\"HTTPSConnectionPool(host='pj4vlvxrg7.execute-api.us-east-1.amazonaws.com', port=443): Read timed out. (read timeout=30)\"))\n\nDuring handling of the above exception, another exception occurred:\nE   requests.exceptions.ConnectionError: HTTPSConnectionPool(host='pj4vlvxrg7.execute-api.us-east-1.amazonaws.com', port=443): Max retries exceeded with url: /dev/director (Caused by ReadTimeoutError(\"HTTPSConnectionPool(host='pj4vlvxrg7.execute-api.us-east-1.amazonaws.com', port=443): Read timed out. (read timeout=30)\"))"}, "teardown": {"duration": 0.0005720999979530461, "outcome": "passed"}}, {"nodeid": "test_performance.py::TestPerformance::test_concurrent_health_checks", "lineno": 45, "outcome": "passed", "keywords": ["test_concurrent_health_checks", "TestPerformance", "test_performance.py", "__init__.py", "api"], "setup": {"duration": 0.0005590999935520813, "outcome": "passed"}, "call": {"duration": 1.9441044999985024, "outcome": "passed", "stdout": "\n\ud83d\ude80 GET /health\n\n\ud83d\ude80 GET /health\n\n\ud83d\ude80 GET /health\n\n\ud83d\ude80 GET /health\n\n\ud83d\ude80 GET /health\n\ud83d\udcca Status: 200 | \u23f1\ufe0f  Time: 1829.64ms | \ud83d\udce6 Size: 60 bytes\n\ud83d\udcca Status: 200 | \u23f1\ufe0f  Time: 1848.87ms | \ud83d\udce6 Size: 60 bytes\n\ud83d\udcca Status: 200 | \u23f1\ufe0f  Time: 1902.60ms | \ud83d\udce6 Size: 60 bytes\n\ud83d\udcca Status: 200 | \u23f1\ufe0f  Time: 1926.44ms | \ud83d\udce6 Size: 60 bytes\n\ud83d\udcca Status: 200 | \u23f1\ufe0f  Time: 1934.48ms | \ud83d\udce6 Size: 60 bytes\n"}, "teardown": {"duration": 0.0004702000005636364, "outcome": "passed"}}, {"nodeid": "test_performance.py::TestLoadTesting::test_sustained_load_health_endpoint", "lineno": 72, "outcome": "passed", "keywords": ["test_sustained_load_health_endpoint", "slow", "pytestmark", "TestLoadTesting", "test_performance.py", "__init__.py", "api"], "setup": {"duration": 0.0006003000016789883, "outcome": "passed"}, "call": {"duration": 13.365638600000239, "outcome": "passed", "stdout": "\n\ud83d\udd25 Running sustained load test...\n\n\ud83d\ude80 GET /health\n\ud83d\udcca Status: 200 | \u23f1\ufe0f  Time: 192.35ms | \ud83d\udce6 Size: 60 bytes\n\n\ud83d\ude80 GET /health\n\ud83d\udcca Status: 200 | \u23f1\ufe0f  Time: 185.34ms | \ud83d\udce6 Size: 60 bytes\n\n\ud83d\ude80 GET /health\n\ud83d\udcca Status: 200 | \u23f1\ufe0f  Time: 183.71ms | \ud83d\udce6 Size: 60 bytes\n\n\ud83d\ude80 GET /health\n\ud83d\udcca Status: 200 | \u23f1\ufe0f  Time: 177.13ms | \ud83d\udce6 Size: 60 bytes\n\n\ud83d\ude80 GET /health\n\ud83d\udcca Status: 200 | \u23f1\ufe0f  Time: 191.54ms | \ud83d\udce6 Size: 60 bytes\n\n\ud83d\ude80 GET /health\n\ud83d\udcca Status: 200 | \u23f1\ufe0f  Time: 290.65ms | \ud83d\udce6 Size: 60 bytes\n\n\ud83d\ude80 GET /health\n\ud83d\udcca Status: 200 | \u23f1\ufe0f  Time: 174.65ms | \ud83d\udce6 Size: 60 bytes\n\n\ud83d\ude80 GET /health\n\ud83d\udcca Status: 200 | \u23f1\ufe0f  Time: 178.43ms | \ud83d\udce6 Size: 60 bytes\n\n\ud83d\ude80 GET /health\n\ud83d\udcca Status: 200 | \u23f1\ufe0f  Time: 189.74ms | \ud83d\udce6 Size: 60 bytes\n\n\ud83d\ude80 GET /health\n\ud83d\udcca Status: 200 | \u23f1\ufe0f  Time: 178.18ms | \ud83d\udce6 Size: 60 bytes\n\n\ud83d\ude80 GET /health\n\ud83d\udcca Status: 200 | \u23f1\ufe0f  Time: 191.81ms | \ud83d\udce6 Size: 60 bytes\n\n\ud83d\ude80 GET /health\n\ud83d\udcca Status: 200 | \u23f1\ufe0f  Time: 192.34ms | \ud83d\udce6 Size: 60 bytes\n\n\ud83d\ude80 GET /health\n\ud83d\udcca Status: 200 | \u23f1\ufe0f  Time: 196.10ms | \ud83d\udce6 Size: 60 bytes\n\n\ud83d\ude80 GET /health\n\ud83d\udcca Status: 200 | \u23f1\ufe0f  Time: 172.18ms | \ud83d\udce6 Size: 60 bytes\n\n\ud83d\ude80 GET /health\n\ud83d\udcca Status: 200 | \u23f1\ufe0f  Time: 186.50ms | \ud83d\udce6 Size: 60 bytes\n\n\ud83d\ude80 GET /health\n\ud83d\udcca Status: 200 | \u23f1\ufe0f  Time: 172.50ms | \ud83d\udce6 Size: 60 bytes\n\n\ud83d\ude80 GET /health\n\ud83d\udcca Status: 200 | \u23f1\ufe0f  Time: 185.55ms | \ud83d\udce6 Size: 60 bytes\n\n\ud83d\ude80 GET /health\n\ud83d\udcca Status: 200 | \u23f1\ufe0f  Time: 199.22ms | \ud83d\udce6 Size: 60 bytes\n\n\ud83d\ude80 GET /health\n\ud83d\udcca Status: 200 | \u23f1\ufe0f  Time: 198.62ms | \ud83d\udce6 Size: 60 bytes\n\n\ud83d\ude80 GET /health\n\ud83d\udcca Status: 200 | \u23f1\ufe0f  Time: 174.97ms | \ud83d\udce6 Size: 60 bytes\n  Making 20 requests... 0:00:13\n\u2705 Success rate: 100.0% (20/20)\n\u23f1\ufe0f  Avg response: 192.40ms\n\ud83d\udc0c Max response: 292.56ms\n\u26a1 Min response: 173.90ms\n"}, "teardown": {"duration": 0.0004158999945502728, "outcome": "passed"}}, {"nodeid": "test_performance.py::TestStressScenarios::test_large_payload_persona", "lineno": 149, "outcome": "failed", "keywords": ["test_large_payload_persona", "TestStressScenarios", "test_performance.py", "__init__.py", "api"], "setup": {"duration": 0.0004199999966658652, "outcome": "passed"}, "call": {"duration": 7.020551299996441, "outcome": "failed", "crash": {"path": "C:\\Projects\\building-os-platform\\.venv\\Lib\\site-packages\\requests\\adapters.py", "lineno": 510, "message": "requests.exceptions.RetryError: HTTPSConnectionPool(host='pj4vlvxrg7.execute-api.us-east-1.amazonaws.com', port=443): Max retries exceeded with url: /dev/persona (Caused by ResponseError('too many 500 error responses'))"}, "stdout": "\n\ud83d\ude80 POST /persona\n\u274c Request failed: \nHTTPSConnectionPool(host='pj4vlvxrg7.execute-api.us-east-1.amazonaws.com', \nport=443): Max retries exceeded with url: /dev/persona (Caused by \nResponseError('too many 500 error responses'))\n", "longrepr": "urllib3.exceptions.ResponseError: too many 500 error responses\n\nThe above exception was the direct cause of the following exception:\nE   urllib3.exceptions.MaxRetryError: HTTPSConnectionPool(host='pj4vlvxrg7.execute-api.us-east-1.amazonaws.com', port=443): Max retries exceeded with url: /dev/persona (Caused by ResponseError('too many 500 error responses'))\n\nDuring handling of the above exception, another exception occurred:\nE   requests.exceptions.RetryError: HTTPSConnectionPool(host='pj4vlvxrg7.execute-api.us-east-1.amazonaws.com', port=443): Max retries exceeded with url: /dev/persona (Caused by ResponseError('too many 500 error responses'))"}, "teardown": {"duration": 0.00045339999633142725, "outcome": "passed"}}, {"nodeid": "test_performance.py::TestStressScenarios::test_rapid_successive_requests", "lineno": 163, "outcome": "passed", "keywords": ["test_rapid_successive_requests", "TestStressScenarios", "test_performance.py", "__init__.py", "api"], "setup": {"duration": 0.0003910000014002435, "outcome": "passed"}, "call": {"duration": 1.8509148999946774, "outcome": "passed", "stdout": "\n\ud83d\ude80 GET /health\n\ud83d\udcca Status: 200 | \u23f1\ufe0f  Time: 190.06ms | \ud83d\udce6 Size: 60 bytes\n\n\ud83d\ude80 GET /health\n\ud83d\udcca Status: 200 | \u23f1\ufe0f  Time: 177.73ms | \ud83d\udce6 Size: 60 bytes\n\n\ud83d\ude80 GET /health\n\ud83d\udcca Status: 200 | \u23f1\ufe0f  Time: 180.34ms | \ud83d\udce6 Size: 60 bytes\n\n\ud83d\ude80 GET /health\n\ud83d\udcca Status: 200 | \u23f1\ufe0f  Time: 183.08ms | \ud83d\udce6 Size: 60 bytes\n\n\ud83d\ude80 GET /health\n\ud83d\udcca Status: 200 | \u23f1\ufe0f  Time: 191.42ms | \ud83d\udce6 Size: 60 bytes\n\n\ud83d\ude80 GET /health\n\ud83d\udcca Status: 200 | \u23f1\ufe0f  Time: 180.47ms | \ud83d\udce6 Size: 60 bytes\n\n\ud83d\ude80 GET /health\n\ud83d\udcca Status: 200 | \u23f1\ufe0f  Time: 189.62ms | \ud83d\udce6 Size: 60 bytes\n\n\ud83d\ude80 GET /health\n\ud83d\udcca Status: 200 | \u23f1\ufe0f  Time: 179.64ms | \ud83d\udce6 Size: 60 bytes\n\n\ud83d\ude80 GET /health\n\ud83d\udcca Status: 200 | \u23f1\ufe0f  Time: 177.24ms | \ud83d\udce6 Size: 60 bytes\n\n\ud83d\ude80 GET /health\n\ud83d\udcca Status: 200 | \u23f1\ufe0f  Time: 183.98ms | \ud83d\udce6 Size: 60 bytes\n\ud83d\ude80 Rapid requests: 10 in 1.85s\n\u2705 Success rate: 100.0%\n"}, "teardown": {"duration": 0.00038640000275336206, "outcome": "passed"}}, {"nodeid": "test_performance.py::TestStressScenarios::test_special_characters_in_requests", "lineno": 189, "outcome": "failed", "keywords": ["test_special_characters_in_requests", "TestStressScenarios", "test_performance.py", "__init__.py", "api"], "setup": {"duration": 0.00038050000148359686, "outcome": "passed"}, "call": {"duration": 6.771879200001422, "outcome": "failed", "crash": {"path": "C:\\Projects\\building-os-platform\\.venv\\Lib\\site-packages\\requests\\adapters.py", "lineno": 510, "message": "requests.exceptions.RetryError: HTTPSConnectionPool(host='pj4vlvxrg7.execute-api.us-east-1.amazonaws.com', port=443): Max retries exceeded with url: /dev/persona (Caused by ResponseError('too many 500 error responses'))"}, "stdout": "\n\ud83d\ude80 POST /persona\n\u274c Request failed: \nHTTPSConnectionPool(host='pj4vlvxrg7.execute-api.us-east-1.amazonaws.com', \nport=443): Max retries exceeded with url: /dev/persona (Caused by \nResponseError('too many 500 error responses'))\n", "longrepr": "urllib3.exceptions.ResponseError: too many 500 error responses\n\nThe above exception was the direct cause of the following exception:\nE   urllib3.exceptions.MaxRetryError: HTTPSConnectionPool(host='pj4vlvxrg7.execute-api.us-east-1.amazonaws.com', port=443): Max retries exceeded with url: /dev/persona (Caused by ResponseError('too many 500 error responses'))\n\nDuring handling of the above exception, another exception occurred:\nE   requests.exceptions.RetryError: HTTPSConnectionPool(host='pj4vlvxrg7.execute-api.us-east-1.amazonaws.com', port=443): Max retries exceeded with url: /dev/persona (Caused by ResponseError('too many 500 error responses'))"}, "teardown": {"duration": 0.0004744000034406781, "outcome": "passed"}}, {"nodeid": "test_performance.py::TestBoundaryConditions::test_empty_payloads", "lineno": 213, "outcome": "failed", "keywords": ["test_empty_payloads", "TestBoundaryConditions", "test_performance.py", "__init__.py", "api"], "setup": {"duration": 0.00036750000435858965, "outcome": "passed"}, "call": {"duration": 129.25058489999356, "outcome": "failed", "crash": {"path": "C:\\Projects\\building-os-platform\\.venv\\Lib\\site-packages\\requests\\adapters.py", "lineno": 519, "message": "requests.exceptions.ConnectionError: HTTPSConnectionPool(host='pj4vlvxrg7.execute-api.us-east-1.amazonaws.com', port=443): Max retries exceeded with url: /dev/elevator/call (Caused by ReadTimeoutError(\"HTTPSConnectionPool(host='pj4vlvxrg7.execute-api.us-east-1.amazonaws.com', port=443): Read timed out. (read timeout=30)\"))"}, "stdout": "\n\ud83d\ude80 POST /persona\n\ud83d\udcca Status: 400 | \u23f1\ufe0f  Time: 219.89ms | \ud83d\udce6 Size: 45 bytes\n\n\ud83d\ude80 POST /elevator/call\n\u274c Request failed: \nHTTPSConnectionPool(host='pj4vlvxrg7.execute-api.us-east-1.amazonaws.com', \nport=443): Max retries exceeded with url: /dev/elevator/call (Caused by \nReadTimeoutError(\"HTTPSConnectionPool(host='pj4vlvxrg7.execute-api.us-east-1.am\nazonaws.com', port=443): Read timed out. (read timeout=30)\"))\n", "log": [{"name": "urllib3.connectionpool", "msg": "Retrying (Retry(total=2, connect=None, read=None, redirect=None, status=None)) after connection broken by 'ReadTimeoutError(\"HTTPSConnectionPool(host='pj4vlvxrg7.execute-api.us-east-1.amazonaws.com', port=443): Read timed out. (read timeout=30)\")': /dev/elevator/call", "args": null, "levelname": "WARNING", "levelno": 30, "pathname": "C:\\Projects\\building-os-platform\\.venv\\Lib\\site-packages\\urllib3\\connectionpool.py", "filename": "connectionpool.py", "module": "connectionpool", "exc_info": null, "exc_text": null, "stack_info": null, "lineno": 868, "funcName": "urlopen", "created": 1754781799.5985985, "msecs": 598.0, "relativeCreated": 1126901.0343, "thread": 5176, "threadName": "MainThread", "processName": "MainProcess", "process": 15148, "taskName": null}, {"name": "urllib3.connectionpool", "msg": "Retrying (Retry(total=1, connect=None, read=None, redirect=None, status=None)) after connection broken by 'ReadTimeoutError(\"HTTPSConnectionPool(host='pj4vlvxrg7.execute-api.us-east-1.amazonaws.com', port=443): Read timed out. (read timeout=30)\")': /dev/elevator/call", "args": null, "levelname": "WARNING", "levelno": 30, "pathname": "C:\\Projects\\building-os-platform\\.venv\\Lib\\site-packages\\urllib3\\connectionpool.py", "filename": "connectionpool.py", "module": "connectionpool", "exc_info": null, "exc_text": null, "stack_info": null, "lineno": 868, "funcName": "urlopen", "created": 1754781832.6188962, "msecs": 618.0, "relativeCreated": 1159921.3321, "thread": 5176, "threadName": "MainThread", "processName": "MainProcess", "process": 15148, "taskName": null}, {"name": "urllib3.connectionpool", "msg": "Retrying (Retry(total=0, connect=None, read=None, redirect=None, status=None)) after connection broken by 'ReadTimeoutError(\"HTTPSConnectionPool(host='pj4vlvxrg7.execute-api.us-east-1.amazonaws.com', port=443): Read timed out. (read timeout=30)\")': /dev/elevator/call", "args": null, "levelname": "WARNING", "levelno": 30, "pathname": "C:\\Projects\\building-os-platform\\.venv\\Lib\\site-packages\\urllib3\\connectionpool.py", "filename": "connectionpool.py", "module": "connectionpool", "exc_info": null, "exc_text": null, "stack_info": null, "lineno": 868, "funcName": "urlopen", "created": 1754781867.6150162, "msecs": 615.0, "relativeCreated": 1194917.4522, "thread": 5176, "threadName": "MainThread", "processName": "MainProcess", "process": 15148, "taskName": null}], "longrepr": "E   TimeoutError: The read operation timed out\n\nThe above exception was the direct cause of the following exception:\nE   urllib3.exceptions.ReadTimeoutError: HTTPSConnectionPool(host='pj4vlvxrg7.execute-api.us-east-1.amazonaws.com', port=443): Read timed out. (read timeout=30)\n\nThe above exception was the direct cause of the following exception:\nE   urllib3.exceptions.MaxRetryError: HTTPSConnectionPool(host='pj4vlvxrg7.execute-api.us-east-1.amazonaws.com', port=443): Max retries exceeded with url: /dev/elevator/call (Caused by ReadTimeoutError(\"HTTPSConnectionPool(host='pj4vlvxrg7.execute-api.us-east-1.amazonaws.com', port=443): Read timed out. (read timeout=30)\"))\n\nDuring handling of the above exception, another exception occurred:\nE   requests.exceptions.ConnectionError: HTTPSConnectionPool(host='pj4vlvxrg7.execute-api.us-east-1.amazonaws.com', port=443): Max retries exceeded with url: /dev/elevator/call (Caused by ReadTimeoutError(\"HTTPSConnectionPool(host='pj4vlvxrg7.execute-api.us-east-1.amazonaws.com', port=443): Read timed out. (read timeout=30)\"))"}, "teardown": {"duration": 0.0004410999972606078, "outcome": "passed"}}, {"nodeid": "test_performance.py::TestBoundaryConditions::test_null_values_in_payload", "lineno": 224, "outcome": "passed", "keywords": ["test_null_values_in_payload", "TestBoundaryConditions", "test_performance.py", "__init__.py", "api"], "setup": {"duration": 0.0004437000025063753, "outcome": "passed"}, "call": {"duration": 1.2071545999933733, "outcome": "passed", "stdout": "\n\ud83d\ude80 POST /persona\n\ud83d\udcca Status: 400 | \u23f1\ufe0f  Time: 1204.86ms | \ud83d\udce6 Size: 45 bytes\n"}, "teardown": {"duration": 0.0005850000015925616, "outcome": "passed"}}, {"nodeid": "test_performance.py::TestBoundaryConditions::test_extremely_long_mission_id", "lineno": 233, "outcome": "passed", "keywords": ["test_extremely_long_mission_id", "TestBoundaryConditions", "test_performance.py", "__init__.py", "api"], "setup": {"duration": 0.0004365999993751757, "outcome": "passed"}, "call": {"duration": 0.3142342999999528, "outcome": "passed", "stdout": "\n\ud83d\ude80 GET \n/coordinator/missions/xxxxxxxxxxxxxxxxxxxxxxxxxxxxxxxxxxxxxxxxxxxxxxxxxxxxxxxxx\nxxxxxxxxxxxxxxxxxxxxxxxxxxxxxxxxxxxxxxxxxxxxxxxxxxxxxxxxxxxxxxxxxxxxxxxxxxxxxxx\nxxxxxxxxxxxxxxxxxxxxxxxxxxxxxxxxxxxxxxxxxxxxxxxxxxxxxxxxxxxxxxxxxxxxxxxxxxxxxxx\nxxxxxxxxxxxxxxxxxxxxxxxxxxxxxxxxxxxxxxxxxxxxxxxxxxxxxxxxxxxxxxxxxxxxxxxxxxxxxxx\nxxxxxxxxxxxxxxxxxxxxxxxxxxxxxxxxxxxxxxxxxxxxxxxxxxxxxxxxxxxxxxxxxxxxxxxxxxxxxxx\nxxxxxxxxxxxxxxxxxxxxxxxxxxxxxxxxxxxxxxxxxxxxxxxxxxxxxxxxxxxxxxxxxxxxxxxxxxxxxxx\nxxxxxxxxxxxxxxxxxxxxxxxxxxxxxxxxxxxxxxxxxxxxxxxxxxxxxxxxxxxxxxxxxxxxxxxxxxxxxxx\nxxxxxxxxxxxxxxxxxxxxxxxxxxxxxxxxxxxxxxxxxxxxxxxxxxxxxxxxxxxxxxxxxxxxxxxxxxxxxxx\nxxxxxxxxxxxxxxxxxxxxxxxxxxxxxxxxxxxxxxxxxxxxxxxxxxxxxxxxxxxxxxxxxxxxxxxxxxxxxxx\nxxxxxxxxxxxxxxxxxxxxxxxxxxxxxxxxxxxxxxxxxxxxxxxxxxxxxxxxxxxxxxxxxxxxxxxxxxxxxxx\nxxxxxxxxxxxxxxxxxxxxxxxxxxxxxxxxxxxxxxxxxxxxxxxxxxxxxxxxxxxxxxxxxxxxxxxxxxxxxxx\nxxxxxxxxxxxxxxxxxxxxxxxxxxxxxxxxxxxxxxxxxxxxxxxxxxxxxxxxxxxxxxxxxxxxxxxxxxxxxxx\nxxxxxxxxxxxxxxxxxxxxxxxxxxxxxxxxxxxxxxxxxxxxxxxxxxxxxxxxxxxxxxxxxxxxxxxxxx\n\ud83d\udcca Status: 404 | \u23f1\ufe0f  Time: 308.88ms | \ud83d\udce6 Size: 1031 bytes\n"}, "teardown": {"duration": 0.1317170999973314, "outcome": "passed", "stdout": "\n\ud83d\udcca Test Session Complete\n                              \ud83d\udd0d Request Summary                               \n\u250c\u2500\u2500\u2500\u2500\u2500\u2500\u2500\u2500\u252c\u2500\u2500\u2500\u2500\u2500\u2500\u2500\u2500\u2500\u2500\u2500\u2500\u2500\u2500\u2500\u2500\u2500\u2500\u2500\u2500\u2500\u2500\u2500\u2500\u2500\u2500\u2500\u2500\u2500\u2500\u2500\u2500\u2500\u2500\u2500\u2500\u2500\u252c\u2500\u2500\u2500\u2500\u2500\u2500\u2500\u2500\u252c\u2500\u2500\u2500\u2500\u2500\u2500\u2500\u2500\u2500\u2500\u2500\u252c\u2500\u2500\u2500\u2500\u2500\u2500\u2500\u2500\u2500\u2510\n\u2502 Method \u2502 Endpoint                            \u2502 Status \u2502 Time (ms) \u2502 Success \u2502\n\u251c\u2500\u2500\u2500\u2500\u2500\u2500\u2500\u2500\u253c\u2500\u2500\u2500\u2500\u2500\u2500\u2500\u2500\u2500\u2500\u2500\u2500\u2500\u2500\u2500\u2500\u2500\u2500\u2500\u2500\u2500\u2500\u2500\u2500\u2500\u2500\u2500\u2500\u2500\u2500\u2500\u2500\u2500\u2500\u2500\u2500\u2500\u253c\u2500\u2500\u2500\u2500\u2500\u2500\u2500\u2500\u253c\u2500\u2500\u2500\u2500\u2500\u2500\u2500\u2500\u2500\u2500\u2500\u253c\u2500\u2500\u2500\u2500\u2500\u2500\u2500\u2500\u2500\u2524\n\u2502 GET    \u2502 /health                             \u2502 200    \u2502 1525.47   \u2502 \u2705      \u2502\n\u2502 GET    \u2502 /health                             \u2502 200    \u2502 195.53    \u2502 \u2705      \u2502\n\u2502 GET    \u2502 /director                           \u2502 0      \u2502 128921.06 \u2502 \u274c      \u2502\n\u2502 GET    \u2502 /director?user_request=Test mission \u2502 0      \u2502 130529.01 \u2502 \u274c      \u2502\n\u2502        \u2502 from Python API tests               \u2502        \u2502           \u2502         \u2502\n\u2502 GET    \u2502 /director?user_id=api-test-user     \u2502 0      \u2502 131519.24 \u2502 \u274c      \u2502\n\u2502 POST   \u2502 /persona                            \u2502 0      \u2502 8598.06   \u2502 \u274c      \u2502\n\u2502 POST   \u2502 /persona                            \u2502 400    \u2502 191.29    \u2502 \u274c      \u2502\n\u2502 POST   \u2502 /persona                            \u2502 400    \u2502 187.37    \u2502 \u274c      \u2502\n\u2502 GET    \u2502 /persona/conversations?user_id=api\u2026 \u2502 200    \u2502 221.44    \u2502 \u2705      \u2502\n\u2502 POST   \u2502 /elevator/call                      \u2502 0      \u2502 128987.67 \u2502 \u274c      \u2502\n\u2502 POST   \u2502 /elevator/call                      \u2502 0      \u2502 130017.47 \u2502 \u274c      \u2502\n\u2502 POST   \u2502 /psim/search                        \u2502 200    \u2502 2606.72   \u2502 \u2705      \u2502\n\u2502 POST   \u2502 /psim/search                        \u2502 200    \u2502 315.49    \u2502 \u2705      \u2502\n\u2502 GET    \u2502 /coordinator/missions/test-mission\u2026 \u2502 404    \u2502 1050.83   \u2502 \u274c      \u2502\n\u2502 GET    \u2502 /coordinator/missions/python-test-\u2026 \u2502 404    \u2502 220.91    \u2502 \u274c      \u2502\n\u2502 GET    \u2502 /health                             \u2502 200    \u2502 527.18    \u2502 \u2705      \u2502\n\u2502 GET    \u2502 /director                           \u2502 0      \u2502 128898.71 \u2502 \u274c      \u2502\n\u2502 POST   \u2502 /persona                            \u2502 400    \u2502 1798.17   \u2502 \u274c      \u2502\n\u2502 POST   \u2502 /elevator/call                      \u2502 0      \u2502 128967.96 \u2502 \u274c      \u2502\n\u2502 POST   \u2502 /psim/search                        \u2502 400    \u2502 1211.75   \u2502 \u274c      \u2502\n\u2502 GET    \u2502 /coordinator/missions/test-123      \u2502 404    \u2502 317.32    \u2502 \u274c      \u2502\n\u2502 GET    \u2502 /invalid-endpoint                   \u2502 404    \u2502 158.46    \u2502 \u274c      \u2502\n\u2502 DELETE \u2502 /health                             \u2502 404    \u2502 160.02    \u2502 \u274c      \u2502\n\u2502 GET    \u2502 /health                             \u2502 200    \u2502 498.41    \u2502 \u2705      \u2502\n\u2502 GET    \u2502 /director                           \u2502 0      \u2502 128944.37 \u2502 \u274c      \u2502\n\u2502 GET    \u2502 /health                             \u2502 200    \u2502 1829.64   \u2502 \u2705      \u2502\n\u2502 GET    \u2502 /health                             \u2502 200    \u2502 1848.87   \u2502 \u2705      \u2502\n\u2502 GET    \u2502 /health                             \u2502 200    \u2502 1902.6    \u2502 \u2705      \u2502\n\u2502 GET    \u2502 /health                             \u2502 200    \u2502 1926.44   \u2502 \u2705      \u2502\n\u2502 GET    \u2502 /health                             \u2502 200    \u2502 1934.48   \u2502 \u2705      \u2502\n\u2502 GET    \u2502 /health                             \u2502 200    \u2502 192.35    \u2502 \u2705      \u2502\n\u2502 GET    \u2502 /health                             \u2502 200    \u2502 185.34    \u2502 \u2705      \u2502\n\u2502 GET    \u2502 /health                             \u2502 200    \u2502 183.71    \u2502 \u2705      \u2502\n\u2502 GET    \u2502 /health                             \u2502 200    \u2502 177.13    \u2502 \u2705      \u2502\n\u2502 GET    \u2502 /health                             \u2502 200    \u2502 191.54    \u2502 \u2705      \u2502\n\u2502 GET    \u2502 /health                             \u2502 200    \u2502 290.65    \u2502 \u2705      \u2502\n\u2502 GET    \u2502 /health                             \u2502 200    \u2502 174.65    \u2502 \u2705      \u2502\n\u2502 GET    \u2502 /health                             \u2502 200    \u2502 178.43    \u2502 \u2705      \u2502\n\u2502 GET    \u2502 /health                             \u2502 200    \u2502 189.74    \u2502 \u2705      \u2502\n\u2502 GET    \u2502 /health                             \u2502 200    \u2502 178.18    \u2502 \u2705      \u2502\n\u2502 GET    \u2502 /health                             \u2502 200    \u2502 191.81    \u2502 \u2705      \u2502\n\u2502 GET    \u2502 /health                             \u2502 200    \u2502 192.34    \u2502 \u2705      \u2502\n\u2502 GET    \u2502 /health                             \u2502 200    \u2502 196.1     \u2502 \u2705      \u2502\n\u2502 GET    \u2502 /health                             \u2502 200    \u2502 172.18    \u2502 \u2705      \u2502\n\u2502 GET    \u2502 /health                             \u2502 200    \u2502 186.5     \u2502 \u2705      \u2502\n\u2502 GET    \u2502 /health                             \u2502 200    \u2502 172.5     \u2502 \u2705      \u2502\n\u2502 GET    \u2502 /health                             \u2502 200    \u2502 185.55    \u2502 \u2705      \u2502\n\u2502 GET    \u2502 /health                             \u2502 200    \u2502 199.22    \u2502 \u2705      \u2502\n\u2502 GET    \u2502 /health                             \u2502 200    \u2502 198.62    \u2502 \u2705      \u2502\n\u2502 GET    \u2502 /health                             \u2502 200    \u2502 174.97    \u2502 \u2705      \u2502\n\u2502 POST   \u2502 /persona                            \u2502 0      \u2502 7017.78   \u2502 \u274c      \u2502\n\u2502 GET    \u2502 /health                             \u2502 200    \u2502 190.06    \u2502 \u2705      \u2502\n\u2502 GET    \u2502 /health                             \u2502 200    \u2502 177.73    \u2502 \u2705      \u2502\n\u2502 GET    \u2502 /health                             \u2502 200    \u2502 180.34    \u2502 \u2705      \u2502\n\u2502 GET    \u2502 /health                             \u2502 200    \u2502 183.08    \u2502 \u2705      \u2502\n\u2502 GET    \u2502 /health                             \u2502 200    \u2502 191.42    \u2502 \u2705      \u2502\n\u2502 GET    \u2502 /health                             \u2502 200    \u2502 180.47    \u2502 \u2705      \u2502\n\u2502 GET    \u2502 /health                             \u2502 200    \u2502 189.62    \u2502 \u2705      \u2502\n\u2502 GET    \u2502 /health                             \u2502 200    \u2502 179.64    \u2502 \u2705      \u2502\n\u2502 GET    \u2502 /health                             \u2502 200    \u2502 177.24    \u2502 \u2705      \u2502\n\u2502 GET    \u2502 /health                             \u2502 200    \u2502 183.98    \u2502 \u2705      \u2502\n\u2502 POST   \u2502 /persona                            \u2502 0      \u2502 6769.1    \u2502 \u274c      \u2502\n\u2502 POST   \u2502 /persona                            \u2502 400    \u2502 219.89    \u2502 \u274c      \u2502\n\u2502 POST   \u2502 /elevator/call                      \u2502 0      \u2502 129025.57 \u2502 \u274c      \u2502\n\u2502 POST   \u2502 /persona                            \u2502 400    \u2502 1204.86   \u2502 \u274c      \u2502\n\u2502 GET    \u2502 /coordinator/missions/xxxxxxxxxxxx\u2026 \u2502 404    \u2502 308.88    \u2502 \u274c      \u2502\n\u2514\u2500\u2500\u2500\u2500\u2500\u2500\u2500\u2500\u2534\u2500\u2500\u2500\u2500\u2500\u2500\u2500\u2500\u2500\u2500\u2500\u2500\u2500\u2500\u2500\u2500\u2500\u2500\u2500\u2500\u2500\u2500\u2500\u2500\u2500\u2500\u2500\u2500\u2500\u2500\u2500\u2500\u2500\u2500\u2500\u2500\u2500\u2534\u2500\u2500\u2500\u2500\u2500\u2500\u2500\u2500\u2534\u2500\u2500\u2500\u2500\u2500\u2500\u2500\u2500\u2500\u2500\u2500\u2534\u2500\u2500\u2500\u2500\u2500\u2500\u2500\u2500\u2500\u2518\n\u250c\u2500\u2500\u2500\u2500\u2500\u2500\u2500\u2500\u2500\u2500\u2500\u2500\u2500\u2500\u2500\u2500\u2500\u2500\u2500\u2500\u2500\u2500\u2500\u2500\u2500\u2500\u2500\u2500 Performance Metrics \u2500\u2500\u2500\u2500\u2500\u2500\u2500\u2500\u2500\u2500\u2500\u2500\u2500\u2500\u2500\u2500\u2500\u2500\u2500\u2500\u2500\u2500\u2500\u2500\u2500\u2500\u2500\u2500\u2510\n\u2502 \ud83d\udcc8 Avg: 499.46ms | \u26a1 Min: 172.18ms | \ud83d\udc0c Max: 2606.72ms                     \u2502\n\u2514\u2500\u2500\u2500\u2500\u2500\u2500\u2500\u2500\u2500\u2500\u2500\u2500\u2500\u2500\u2500\u2500\u2500\u2500\u2500\u2500\u2500\u2500\u2500\u2500\u2500\u2500\u2500\u2500\u2500\u2500\u2500\u2500\u2500\u2500\u2500\u2500\u2500\u2500\u2500\u2500\u2500\u2500\u2500\u2500\u2500\u2500\u2500\u2500\u2500\u2500\u2500\u2500\u2500\u2500\u2500\u2500\u2500\u2500\u2500\u2500\u2500\u2500\u2500\u2500\u2500\u2500\u2500\u2500\u2500\u2500\u2500\u2500\u2500\u2500\u2500\u2500\u2500\u2518\n\ud83d\udcbe Results exported to: api-test-results-20250809-202500.json\n"}}], "warnings": [{"message": "Unknown pytest.mark.slow - is this a typo?  You can register custom marks to avoid this warning - for details, see https://docs.pytest.org/en/stable/how-to/mark.html", "category": "PytestUnknownMarkWarning", "when": "collect", "filename": "c:\\Projects\\building-os-platform\\tests\\api\\test_performance.py", "lineno": 73}, {"message": "Unknown pytest.mark.slow - is this a typo?  You can register custom marks to avoid this warning - for details, see https://docs.pytest.org/en/stable/how-to/mark.html", "category": "PytestUnknownMarkWarning", "when": "collect", "filename": "c:\\Projects\\building-os-platform\\tests\\api\\test_performance.py", "lineno": 245}, {"message": "Unknown pytest.mark.load - is this a typo?  You can register custom marks to avoid this warning - for details, see https://docs.pytest.org/en/stable/how-to/mark.html", "category": "PytestUnknownMarkWarning", "when": "collect", "filename": "c:\\Projects\\building-os-platform\\tests\\api\\test_performance.py", "lineno": 246}]}