{"created": 1754775613.0211842, "duration": 208.51498341560364, "exitcode": 1, "root": "C:\\Projects\\building-os-platform\\tests\\api", "environment": {}, "summary": {"passed": 11, "failed": 22, "total": 33, "collected": 33}, "collectors": [{"nodeid": "", "outcome": "passed", "result": [{"nodeid": "__init__.py", "type": "Package"}]}, {"nodeid": "test_endpoints.py::TestPayloads", "outcome": "passed", "result": []}, {"nodeid": "test_endpoints.py::TestHealthEndpoint", "outcome": "passed", "result": [{"nodeid": "test_endpoints.py::TestHealthEndpoint::test_health_check_success", "type": "Function", "lineno": 14}, {"nodeid": "test_endpoints.py::TestHealthEndpoint::test_health_check_performance", "type": "Function", "lineno": 23}]}, {"nodeid": "test_endpoints.py::TestDirectorEndpoint", "outcome": "passed", "result": [{"nodeid": "test_endpoints.py::TestDirectorEndpoint::test_director_basic_request", "type": "Function", "lineno": 37}, {"nodeid": "test_endpoints.py::TestDirectorEndpoint::test_director_with_user_request", "type": "Function", "lineno": 46}, {"nodeid": "test_endpoints.py::TestDirectorEndpoint::test_director_with_user_id", "type": "Function", "lineno": 56}]}, {"nodeid": "test_endpoints.py::TestPersonaEndpoint", "outcome": "passed", "result": [{"nodeid": "test_endpoints.py::TestPersonaEndpoint::test_persona_valid_message", "type": "Function", "lineno": 68}, {"nodeid": "test_endpoints.py::TestPersonaEndpoint::test_persona_missing_user_id", "type": "Function", "lineno": 81}, {"nodeid": "test_endpoints.py::TestPersonaEndpoint::test_persona_missing_message", "type": "Function", "lineno": 89}, {"nodeid": "test_endpoints.py::TestPersonaEndpoint::test_persona_conversations", "type": "Function", "lineno": 97}]}, {"nodeid": "test_endpoints.py::TestElevatorEndpoint", "outcome": "passed", "result": [{"nodeid": "test_endpoints.py::TestElevatorEndpoint::test_elevator_call_basic", "type": "Function", "lineno": 109}, {"nodeid": "test_endpoints.py::TestElevatorEndpoint::test_elevator_missing_mission_id", "type": "Function", "lineno": 120}]}, {"nodeid": "test_endpoints.py::TestPSIMEndpoint", "outcome": "passed", "result": [{"nodeid": "test_endpoints.py::TestPSIMEndpoint::test_psim_search_basic", "type": "Function", "lineno": 132}, {"nodeid": "test_endpoints.py::TestPSIMEndpoint::test_psim_search_with_custom_query", "type": "Function", "lineno": 142}]}, {"nodeid": "test_endpoints.py::TestCoordinatorEndpoint", "outcome": "passed", "result": [{"nodeid": "test_endpoints.py::TestCoordinatorEndpoint::test_coordinator_mission_status", "type": "Function", "lineno": 155}, {"nodeid": "test_endpoints.py::TestCoordinatorEndpoint::test_coordinator_different_mission_id", "type": "Function", "lineno": 166}]}, {"nodeid": "test_endpoints.py::TestCORSHeaders", "outcome": "passed", "result": [{"nodeid": "test_endpoints.py::TestCORSHeaders::test_cors_headers_present[/health]", "type": "Function", "lineno": 178}, {"nodeid": "test_endpoints.py::TestCORSHeaders::test_cors_headers_present[/director]", "type": "Function", "lineno": 178}, {"nodeid": "test_endpoints.py::TestCORSHeaders::test_cors_headers_present[/persona]", "type": "Function", "lineno": 178}, {"nodeid": "test_endpoints.py::TestCORSHeaders::test_cors_headers_present[/elevator/call]", "type": "Function", "lineno": 178}, {"nodeid": "test_endpoints.py::TestCORSHeaders::test_cors_headers_present[/psim/search]", "type": "Function", "lineno": 178}, {"nodeid": "test_endpoints.py::TestCORSHeaders::test_cors_headers_present[/coordinator/missions/test-123]", "type": "Function", "lineno": 178}]}, {"nodeid": "test_endpoints.py::TestErrorHandling", "outcome": "passed", "result": [{"nodeid": "test_endpoints.py::TestErrorHandling::test_invalid_endpoint", "type": "Function", "lineno": 220}, {"nodeid": "test_endpoints.py::TestErrorHandling::test_invalid_method", "type": "Function", "lineno": 225}, {"nodeid": "test_endpoints.py::TestErrorHandling::test_malformed_json", "type": "Function", "lineno": 235}]}, {"nodeid": "test_endpoints.py", "outcome": "passed", "result": [{"nodeid": "test_endpoints.py::TestPayloads", "type": "Class"}, {"nodeid": "test_endpoints.py::TestHealthEndpoint", "type": "Class"}, {"nodeid": "test_endpoints.py::TestDirectorEndpoint", "type": "Class"}, {"nodeid": "test_endpoints.py::TestPersonaEndpoint", "type": "Class"}, {"nodeid": "test_endpoints.py::TestElevatorEndpoint", "type": "Class"}, {"nodeid": "test_endpoints.py::TestPSIMEndpoint", "type": "Class"}, {"nodeid": "test_endpoints.py::TestCoordinatorEndpoint", "type": "Class"}, {"nodeid": "test_endpoints.py::TestCORSHeaders", "type": "Class"}, {"nodeid": "test_endpoints.py::TestErrorHandling", "type": "Class"}]}, {"nodeid": "test_performance.py::TestPerformance", "outcome": "passed", "result": [{"nodeid": "test_performance.py::TestPerformance::test_response_time_under_threshold", "type": "Function", "lineno": 18}, {"nodeid": "test_performance.py::TestPerformance::test_concurrent_health_checks", "type": "Function", "lineno": 45}]}, {"nodeid": "test_performance.py::TestLoadTesting", "outcome": "passed", "result": [{"nodeid": "test_performance.py::TestLoadTesting::test_sustained_load_health_endpoint", "type": "Function", "lineno": 72}]}, {"nodeid": "test_performance.py::TestStressScenarios", "outcome": "passed", "result": [{"nodeid": "test_performance.py::TestStressScenarios::test_large_payload_persona", "type": "Function", "lineno": 149}, {"nodeid": "test_performance.py::TestStressScenarios::test_rapid_successive_requests", "type": "Function", "lineno": 163}, {"nodeid": "test_performance.py::TestStressScenarios::test_special_characters_in_requests", "type": "Function", "lineno": 189}]}, {"nodeid": "test_performance.py::TestBoundaryConditions", "outcome": "passed", "result": [{"nodeid": "test_performance.py::TestBoundaryConditions::test_empty_payloads", "type": "Function", "lineno": 213}, {"nodeid": "test_performance.py::TestBoundaryConditions::test_null_values_in_payload", "type": "Function", "lineno": 224}, {"nodeid": "test_performance.py::TestBoundaryConditions::test_extremely_long_mission_id", "type": "Function", "lineno": 233}]}, {"nodeid": "test_performance.py", "outcome": "passed", "result": [{"nodeid": "test_performance.py::TestPerformance", "type": "Class"}, {"nodeid": "test_performance.py::TestLoadTesting", "type": "Class"}, {"nodeid": "test_performance.py::TestStressScenarios", "type": "Class"}, {"nodeid": "test_performance.py::TestBoundaryConditions", "type": "Class"}]}, {"nodeid": "__init__.py", "outcome": "passed", "result": [{"nodeid": "test_endpoints.py", "type": "Module"}, {"nodeid": "test_performance.py", "type": "Module"}]}], "tests": [{"nodeid": "test_endpoints.py::TestHealthEndpoint::test_health_check_success", "lineno": 14, "outcome": "passed", "keywords": ["test_health_check_success", "TestHealthEndpoint", "test_endpoints.py", "__init__.py", "api"], "setup": {"duration": 0.01643789999798173, "outcome": "passed", "stdout": "\n\ud83e\uddea Starting BuildingOS API Test Suite\n\ud83c\udf10 Base URL: https://pj4vlvxrg7.execute-api.us-east-1.amazonaws.com/dev\n\ud83c\udff7\ufe0f  Environment: dev\n"}, "call": {"duration": 1.30027870000049, "outcome": "passed", "stdout": "\n\ud83d\ude80 GET /health\n\ud83d\udcca Status: 200 | \u23f1\ufe0f  Time: 1297.31ms | \ud83d\udce6 Size: 60 bytes\n"}, "teardown": {"duration": 0.0009701999952085316, "outcome": "passed", "stdout": "\n"}}, {"nodeid": "test_endpoints.py::TestHealthEndpoint::test_health_check_performance", "lineno": 23, "outcome": "passed", "keywords": ["test_health_check_performance", "TestHealthEndpoint", "test_endpoints.py", "__init__.py", "api"], "setup": {"duration": 0.0006099000020185485, "outcome": "passed"}, "call": {"duration": 0.20092229999863775, "outcome": "passed", "stdout": "\n\ud83d\ude80 GET /health\n\ud83d\udcca Status: 200 | \u23f1\ufe0f  Time: 198.58ms | \ud83d\udce6 Size: 60 bytes\n"}, "teardown": {"duration": 0.0009573999996064231, "outcome": "passed", "stdout": "\n"}}, {"nodeid": "test_endpoints.py::TestDirectorEndpoint::test_director_basic_request", "lineno": 37, "outcome": "passed", "keywords": ["test_director_basic_request", "TestDirectorEndpoint", "test_endpoints.py", "__init__.py", "api"], "setup": {"duration": 0.000494699997943826, "outcome": "passed"}, "call": {"duration": 4.055096100004448, "outcome": "passed", "stdout": "\n\ud83d\ude80 GET /director\n\ud83d\udcca Status: 200 | \u23f1\ufe0f  Time: 4052.94ms | \ud83d\udce6 Size: 128 bytes\n"}, "teardown": {"duration": 0.001021800002490636, "outcome": "passed", "stdout": "\n"}}, {"nodeid": "test_endpoints.py::TestDirectorEndpoint::test_director_with_user_request", "lineno": 46, "outcome": "passed", "keywords": ["test_director_with_user_request", "TestDirectorEndpoint", "test_endpoints.py", "__init__.py", "api"], "setup": {"duration": 0.0006059000006644055, "outcome": "passed"}, "call": {"duration": 5.584161099999619, "outcome": "passed", "stdout": "\n\ud83d\ude80 GET /director?user_request=Test mission from Python API tests\n\ud83d\udcca Status: 200 | \u23f1\ufe0f  Time: 5581.57ms | \ud83d\udce6 Size: 128 bytes\n"}, "teardown": {"duration": 0.0008876000065356493, "outcome": "passed", "stdout": "\n"}}, {"nodeid": "test_endpoints.py::TestDirectorEndpoint::test_director_with_user_id", "lineno": 56, "outcome": "passed", "keywords": ["test_director_with_user_id", "TestDirectorEndpoint", "test_endpoints.py", "__init__.py", "api"], "setup": {"duration": 0.0005110000056447461, "outcome": "passed"}, "call": {"duration": 6.587938100004976, "outcome": "passed", "stdout": "\n\ud83d\ude80 GET /director?user_id=api-test-user\n\ud83d\udcca Status: 200 | \u23f1\ufe0f  Time: 6585.56ms | \ud83d\udce6 Size: 128 bytes\n"}, "teardown": {"duration": 0.0008908000017981976, "outcome": "passed", "stdout": "\n"}}, {"nodeid": "test_endpoints.py::TestPersonaEndpoint::test_persona_valid_message", "lineno": 68, "outcome": "failed", "keywords": ["test_persona_valid_message", "TestPersonaEndpoint", "test_endpoints.py", "__init__.py", "api"], "setup": {"duration": 0.0005252000046311878, "outcome": "passed"}, "call": {"duration": 8.909118399998988, "outcome": "failed", "crash": {"path": "C:\\Projects\\building-os-platform\\.venv\\Lib\\site-packages\\requests\\adapters.py", "lineno": 510, "message": "requests.exceptions.RetryError: HTTPSConnectionPool(host='pj4vlvxrg7.execute-api.us-east-1.amazonaws.com', port=443): Max retries exceeded with url: /dev/persona (Caused by ResponseError('too many 500 error responses'))"}, "stdout": "\n\ud83d\ude80 POST /persona\n\u274c Request failed: \nHTTPSConnectionPool(host='pj4vlvxrg7.execute-api.us-east-1.amazonaws.com', \nport=443): Max retries exceeded with url: /dev/persona (Caused by \nResponseError('too many 500 error responses'))\n", "longrepr": "urllib3.exceptions.ResponseError: too many 500 error responses\n\nThe above exception was the direct cause of the following exception:\nE   urllib3.exceptions.MaxRetryError: HTTPSConnectionPool(host='pj4vlvxrg7.execute-api.us-east-1.amazonaws.com', port=443): Max retries exceeded with url: /dev/persona (Caused by ResponseError('too many 500 error responses'))\n\nDuring handling of the above exception, another exception occurred:\nE   requests.exceptions.RetryError: HTTPSConnectionPool(host='pj4vlvxrg7.execute-api.us-east-1.amazonaws.com', port=443): Max retries exceeded with url: /dev/persona (Caused by ResponseError('too many 500 error responses'))"}, "teardown": {"duration": 0.000985999999102205, "outcome": "passed", "stdout": "\n"}}, {"nodeid": "test_endpoints.py::TestPersonaEndpoint::test_persona_missing_user_id", "lineno": 81, "outcome": "failed", "keywords": ["test_persona_missing_user_id", "TestPersonaEndpoint", "test_endpoints.py", "__init__.py", "api"], "setup": {"duration": 0.0005108999976073392, "outcome": "passed"}, "call": {"duration": 8.163320700004988, "outcome": "failed", "crash": {"path": "C:\\Projects\\building-os-platform\\.venv\\Lib\\site-packages\\requests\\adapters.py", "lineno": 510, "message": "requests.exceptions.RetryError: HTTPSConnectionPool(host='pj4vlvxrg7.execute-api.us-east-1.amazonaws.com', port=443): Max retries exceeded with url: /dev/persona (Caused by ResponseError('too many 500 error responses'))"}, "stdout": "\n\ud83d\ude80 POST /persona\n\u274c Request failed: \nHTTPSConnectionPool(host='pj4vlvxrg7.execute-api.us-east-1.amazonaws.com', \nport=443): Max retries exceeded with url: /dev/persona (Caused by \nResponseError('too many 500 error responses'))\n", "longrepr": "urllib3.exceptions.ResponseError: too many 500 error responses\n\nThe above exception was the direct cause of the following exception:\nE   urllib3.exceptions.MaxRetryError: HTTPSConnectionPool(host='pj4vlvxrg7.execute-api.us-east-1.amazonaws.com', port=443): Max retries exceeded with url: /dev/persona (Caused by ResponseError('too many 500 error responses'))\n\nDuring handling of the above exception, another exception occurred:\nE   requests.exceptions.RetryError: HTTPSConnectionPool(host='pj4vlvxrg7.execute-api.us-east-1.amazonaws.com', port=443): Max retries exceeded with url: /dev/persona (Caused by ResponseError('too many 500 error responses'))"}, "teardown": {"duration": 0.0009748000011313707, "outcome": "passed", "stdout": "\n"}}, {"nodeid": "test_endpoints.py::TestPersonaEndpoint::test_persona_missing_message", "lineno": 89, "outcome": "failed", "keywords": ["test_persona_missing_message", "TestPersonaEndpoint", "test_endpoints.py", "__init__.py", "api"], "setup": {"duration": 0.0005849000008311123, "outcome": "passed"}, "call": {"duration": 8.139110100004473, "outcome": "failed", "crash": {"path": "C:\\Projects\\building-os-platform\\.venv\\Lib\\site-packages\\requests\\adapters.py", "lineno": 510, "message": "requests.exceptions.RetryError: HTTPSConnectionPool(host='pj4vlvxrg7.execute-api.us-east-1.amazonaws.com', port=443): Max retries exceeded with url: /dev/persona (Caused by ResponseError('too many 500 error responses'))"}, "stdout": "\n\ud83d\ude80 POST /persona\n\u274c Request failed: \nHTTPSConnectionPool(host='pj4vlvxrg7.execute-api.us-east-1.amazonaws.com', \nport=443): Max retries exceeded with url: /dev/persona (Caused by \nResponseError('too many 500 error responses'))\n", "longrepr": "urllib3.exceptions.ResponseError: too many 500 error responses\n\nThe above exception was the direct cause of the following exception:\nE   urllib3.exceptions.MaxRetryError: HTTPSConnectionPool(host='pj4vlvxrg7.execute-api.us-east-1.amazonaws.com', port=443): Max retries exceeded with url: /dev/persona (Caused by ResponseError('too many 500 error responses'))\n\nDuring handling of the above exception, another exception occurred:\nE   requests.exceptions.RetryError: HTTPSConnectionPool(host='pj4vlvxrg7.execute-api.us-east-1.amazonaws.com', port=443): Max retries exceeded with url: /dev/persona (Caused by ResponseError('too many 500 error responses'))"}, "teardown": {"duration": 0.0009157000022241846, "outcome": "passed", "stdout": "\n"}}, {"nodeid": "test_endpoints.py::TestPersonaEndpoint::test_persona_conversations", "lineno": 97, "outcome": "failed", "keywords": ["test_persona_conversations", "TestPersonaEndpoint", "test_endpoints.py", "__init__.py", "api"], "setup": {"duration": 0.0004976999989594333, "outcome": "passed"}, "call": {"duration": 8.117797900005826, "outcome": "failed", "crash": {"path": "C:\\Projects\\building-os-platform\\.venv\\Lib\\site-packages\\requests\\adapters.py", "lineno": 510, "message": "requests.exceptions.RetryError: HTTPSConnectionPool(host='pj4vlvxrg7.execute-api.us-east-1.amazonaws.com', port=443): Max retries exceeded with url: /dev/persona/conversations?user_id=api-test-user (Caused by ResponseError('too many 500 error responses'))"}, "stdout": "\n\ud83d\ude80 GET /persona/conversations?user_id=api-test-user\n\u274c Request failed: \nHTTPSConnectionPool(host='pj4vlvxrg7.execute-api.us-east-1.amazonaws.com', \nport=443): Max retries exceeded with url: \n/dev/persona/conversations?user_id=api-test-user (Caused by ResponseError('too \nmany 500 error responses'))\n", "longrepr": "urllib3.exceptions.ResponseError: too many 500 error responses\n\nThe above exception was the direct cause of the following exception:\nE   urllib3.exceptions.MaxRetryError: HTTPSConnectionPool(host='pj4vlvxrg7.execute-api.us-east-1.amazonaws.com', port=443): Max retries exceeded with url: /dev/persona/conversations?user_id=api-test-user (Caused by ResponseError('too many 500 error responses'))\n\nDuring handling of the above exception, another exception occurred:\nE   requests.exceptions.RetryError: HTTPSConnectionPool(host='pj4vlvxrg7.execute-api.us-east-1.amazonaws.com', port=443): Max retries exceeded with url: /dev/persona/conversations?user_id=api-test-user (Caused by ResponseError('too many 500 error responses'))"}, "teardown": {"duration": 0.0009586000014678575, "outcome": "passed", "stdout": "\n"}}, {"nodeid": "test_endpoints.py::TestElevatorEndpoint::test_elevator_call_basic", "lineno": 109, "outcome": "failed", "keywords": ["test_elevator_call_basic", "TestElevatorEndpoint", "test_endpoints.py", "__init__.py", "api"], "setup": {"duration": 0.0005407999997260049, "outcome": "passed"}, "call": {"duration": 8.374800899997354, "outcome": "failed", "crash": {"path": "C:\\Projects\\building-os-platform\\.venv\\Lib\\site-packages\\requests\\adapters.py", "lineno": 510, "message": "requests.exceptions.RetryError: HTTPSConnectionPool(host='pj4vlvxrg7.execute-api.us-east-1.amazonaws.com', port=443): Max retries exceeded with url: /dev/elevator/call (Caused by ResponseError('too many 500 error responses'))"}, "stdout": "\n\ud83d\ude80 POST /elevator/call\n\u274c Request failed: \nHTTPSConnectionPool(host='pj4vlvxrg7.execute-api.us-east-1.amazonaws.com', \nport=443): Max retries exceeded with url: /dev/elevator/call (Caused by \nResponseError('too many 500 error responses'))\n", "longrepr": "urllib3.exceptions.ResponseError: too many 500 error responses\n\nThe above exception was the direct cause of the following exception:\nE   urllib3.exceptions.MaxRetryError: HTTPSConnectionPool(host='pj4vlvxrg7.execute-api.us-east-1.amazonaws.com', port=443): Max retries exceeded with url: /dev/elevator/call (Caused by ResponseError('too many 500 error responses'))\n\nDuring handling of the above exception, another exception occurred:\nE   requests.exceptions.RetryError: HTTPSConnectionPool(host='pj4vlvxrg7.execute-api.us-east-1.amazonaws.com', port=443): Max retries exceeded with url: /dev/elevator/call (Caused by ResponseError('too many 500 error responses'))"}, "teardown": {"duration": 0.0009300000019720756, "outcome": "passed", "stdout": "\n"}}, {"nodeid": "test_endpoints.py::TestElevatorEndpoint::test_elevator_missing_mission_id", "lineno": 120, "outcome": "failed", "keywords": ["test_elevator_missing_mission_id", "TestElevatorEndpoint", "test_endpoints.py", "__init__.py", "api"], "setup": {"duration": 0.0005807000052300282, "outcome": "passed"}, "call": {"duration": 7.780591300004744, "outcome": "failed", "crash": {"path": "C:\\Projects\\building-os-platform\\.venv\\Lib\\site-packages\\requests\\adapters.py", "lineno": 510, "message": "requests.exceptions.RetryError: HTTPSConnectionPool(host='pj4vlvxrg7.execute-api.us-east-1.amazonaws.com', port=443): Max retries exceeded with url: /dev/elevator/call (Caused by ResponseError('too many 500 error responses'))"}, "stdout": "\n\ud83d\ude80 POST /elevator/call\n\u274c Request failed: \nHTTPSConnectionPool(host='pj4vlvxrg7.execute-api.us-east-1.amazonaws.com', \nport=443): Max retries exceeded with url: /dev/elevator/call (Caused by \nResponseError('too many 500 error responses'))\n", "longrepr": "urllib3.exceptions.ResponseError: too many 500 error responses\n\nThe above exception was the direct cause of the following exception:\nE   urllib3.exceptions.MaxRetryError: HTTPSConnectionPool(host='pj4vlvxrg7.execute-api.us-east-1.amazonaws.com', port=443): Max retries exceeded with url: /dev/elevator/call (Caused by ResponseError('too many 500 error responses'))\n\nDuring handling of the above exception, another exception occurred:\nE   requests.exceptions.RetryError: HTTPSConnectionPool(host='pj4vlvxrg7.execute-api.us-east-1.amazonaws.com', port=443): Max retries exceeded with url: /dev/elevator/call (Caused by ResponseError('too many 500 error responses'))"}, "teardown": {"duration": 0.0010196000002906658, "outcome": "passed", "stdout": "\n"}}, {"nodeid": "test_endpoints.py::TestPSIMEndpoint::test_psim_search_basic", "lineno": 132, "outcome": "failed", "keywords": ["test_psim_search_basic", "TestPSIMEndpoint", "test_endpoints.py", "__init__.py", "api"], "setup": {"duration": 0.0005366999976104125, "outcome": "passed"}, "call": {"duration": 8.460375999995449, "outcome": "failed", "crash": {"path": "C:\\Projects\\building-os-platform\\.venv\\Lib\\site-packages\\requests\\adapters.py", "lineno": 510, "message": "requests.exceptions.RetryError: HTTPSConnectionPool(host='pj4vlvxrg7.execute-api.us-east-1.amazonaws.com', port=443): Max retries exceeded with url: /dev/psim/search (Caused by ResponseError('too many 500 error responses'))"}, "stdout": "\n\ud83d\ude80 POST /psim/search\n\u274c Request failed: \nHTTPSConnectionPool(host='pj4vlvxrg7.execute-api.us-east-1.amazonaws.com', \nport=443): Max retries exceeded with url: /dev/psim/search (Caused by \nResponseError('too many 500 error responses'))\n", "longrepr": "urllib3.exceptions.ResponseError: too many 500 error responses\n\nThe above exception was the direct cause of the following exception:\nE   urllib3.exceptions.MaxRetryError: HTTPSConnectionPool(host='pj4vlvxrg7.execute-api.us-east-1.amazonaws.com', port=443): Max retries exceeded with url: /dev/psim/search (Caused by ResponseError('too many 500 error responses'))\n\nDuring handling of the above exception, another exception occurred:\nE   requests.exceptions.RetryError: HTTPSConnectionPool(host='pj4vlvxrg7.execute-api.us-east-1.amazonaws.com', port=443): Max retries exceeded with url: /dev/psim/search (Caused by ResponseError('too many 500 error responses'))"}, "teardown": {"duration": 0.0009919000003719702, "outcome": "passed", "stdout": "\n"}}, {"nodeid": "test_endpoints.py::TestPSIMEndpoint::test_psim_search_with_custom_query", "lineno": 142, "outcome": "failed", "keywords": ["test_psim_search_with_custom_query", "TestPSIMEndpoint", "test_endpoints.py", "__init__.py", "api"], "setup": {"duration": 0.0004925000030198134, "outcome": "passed"}, "call": {"duration": 7.732139899999311, "outcome": "failed", "crash": {"path": "C:\\Projects\\building-os-platform\\.venv\\Lib\\site-packages\\requests\\adapters.py", "lineno": 510, "message": "requests.exceptions.RetryError: HTTPSConnectionPool(host='pj4vlvxrg7.execute-api.us-east-1.amazonaws.com', port=443): Max retries exceeded with url: /dev/psim/search (Caused by ResponseError('too many 500 error responses'))"}, "stdout": "\n\ud83d\ude80 POST /psim/search\n\u274c Request failed: \nHTTPSConnectionPool(host='pj4vlvxrg7.execute-api.us-east-1.amazonaws.com', \nport=443): Max retries exceeded with url: /dev/psim/search (Caused by \nResponseError('too many 500 error responses'))\n", "longrepr": "urllib3.exceptions.ResponseError: too many 500 error responses\n\nThe above exception was the direct cause of the following exception:\nE   urllib3.exceptions.MaxRetryError: HTTPSConnectionPool(host='pj4vlvxrg7.execute-api.us-east-1.amazonaws.com', port=443): Max retries exceeded with url: /dev/psim/search (Caused by ResponseError('too many 500 error responses'))\n\nDuring handling of the above exception, another exception occurred:\nE   requests.exceptions.RetryError: HTTPSConnectionPool(host='pj4vlvxrg7.execute-api.us-east-1.amazonaws.com', port=443): Max retries exceeded with url: /dev/psim/search (Caused by ResponseError('too many 500 error responses'))"}, "teardown": {"duration": 0.0009521999963908456, "outcome": "passed", "stdout": "\n"}}, {"nodeid": "test_endpoints.py::TestCoordinatorEndpoint::test_coordinator_mission_status", "lineno": 155, "outcome": "failed", "keywords": ["test_coordinator_mission_status", "TestCoordinatorEndpoint", "test_endpoints.py", "__init__.py", "api"], "setup": {"duration": 0.0005506000015884638, "outcome": "passed"}, "call": {"duration": 8.35725210000237, "outcome": "failed", "crash": {"path": "C:\\Projects\\building-os-platform\\.venv\\Lib\\site-packages\\requests\\adapters.py", "lineno": 510, "message": "requests.exceptions.RetryError: HTTPSConnectionPool(host='pj4vlvxrg7.execute-api.us-east-1.amazonaws.com', port=443): Max retries exceeded with url: /dev/coordinator/missions/test-mission-123 (Caused by ResponseError('too many 500 error responses'))"}, "stdout": "\n\ud83d\ude80 GET /coordinator/missions/test-mission-123\n\u274c Request failed: \nHTTPSConnectionPool(host='pj4vlvxrg7.execute-api.us-east-1.amazonaws.com', \nport=443): Max retries exceeded with url: \n/dev/coordinator/missions/test-mission-123 (Caused by ResponseError('too many \n500 error responses'))\n", "longrepr": "urllib3.exceptions.ResponseError: too many 500 error responses\n\nThe above exception was the direct cause of the following exception:\nE   urllib3.exceptions.MaxRetryError: HTTPSConnectionPool(host='pj4vlvxrg7.execute-api.us-east-1.amazonaws.com', port=443): Max retries exceeded with url: /dev/coordinator/missions/test-mission-123 (Caused by ResponseError('too many 500 error responses'))\n\nDuring handling of the above exception, another exception occurred:\nE   requests.exceptions.RetryError: HTTPSConnectionPool(host='pj4vlvxrg7.execute-api.us-east-1.amazonaws.com', port=443): Max retries exceeded with url: /dev/coordinator/missions/test-mission-123 (Caused by ResponseError('too many 500 error responses'))"}, "teardown": {"duration": 0.0010323000024072826, "outcome": "passed", "stdout": "\n"}}, {"nodeid": "test_endpoints.py::TestCoordinatorEndpoint::test_coordinator_different_mission_id", "lineno": 166, "outcome": "failed", "keywords": ["test_coordinator_different_mission_id", "TestCoordinatorEndpoint", "test_endpoints.py", "__init__.py", "api"], "setup": {"duration": 0.0006644000022788532, "outcome": "passed"}, "call": {"duration": 8.280611700000009, "outcome": "failed", "crash": {"path": "C:\\Projects\\building-os-platform\\.venv\\Lib\\site-packages\\requests\\adapters.py", "lineno": 510, "message": "requests.exceptions.RetryError: HTTPSConnectionPool(host='pj4vlvxrg7.execute-api.us-east-1.amazonaws.com', port=443): Max retries exceeded with url: /dev/coordinator/missions/python-test-1754775497 (Caused by ResponseError('too many 500 error responses'))"}, "stdout": "\n\ud83d\ude80 GET /coordinator/missions/python-test-1754775497\n\u274c Request failed: \nHTTPSConnectionPool(host='pj4vlvxrg7.execute-api.us-east-1.amazonaws.com', \nport=443): Max retries exceeded with url: \n/dev/coordinator/missions/python-test-1754775497 (Caused by ResponseError('too \nmany 500 error responses'))\n", "longrepr": "urllib3.exceptions.ResponseError: too many 500 error responses\n\nThe above exception was the direct cause of the following exception:\nE   urllib3.exceptions.MaxRetryError: HTTPSConnectionPool(host='pj4vlvxrg7.execute-api.us-east-1.amazonaws.com', port=443): Max retries exceeded with url: /dev/coordinator/missions/python-test-1754775497 (Caused by ResponseError('too many 500 error responses'))\n\nDuring handling of the above exception, another exception occurred:\nE   requests.exceptions.RetryError: HTTPSConnectionPool(host='pj4vlvxrg7.execute-api.us-east-1.amazonaws.com', port=443): Max retries exceeded with url: /dev/coordinator/missions/python-test-1754775497 (Caused by ResponseError('too many 500 error responses'))"}, "teardown": {"duration": 0.0009480000007897615, "outcome": "passed", "stdout": "\n"}}, {"nodeid": "test_endpoints.py::TestCORSHeaders::test_cors_headers_present[/health]", "lineno": 178, "outcome": "failed", "keywords": ["test_cors_headers_present[/health]", "parametrize", "pytestmark", "/health", "TestCORSHeaders", "test_endpoints.py", "__init__.py", "api"], "setup": {"duration": 0.0008060000036493875, "outcome": "passed"}, "call": {"duration": 0.20153579999896465, "outcome": "failed", "crash": {"path": "c:\\Projects\\building-os-platform\\tests\\api\\test_endpoints.py", "lineno": 215, "message": "AssertionError: No CORS headers found in response for /health\nassert False"}, "stdout": "\n\ud83d\ude80 GET /health\n\ud83d\udcca Status: 200 | \u23f1\ufe0f  Time: 198.99ms | \ud83d\udce6 Size: 60 bytes\n", "longrepr": "E   AssertionError: No CORS headers found in response for /health\n    assert False"}, "teardown": {"duration": 0.0012494999973569065, "outcome": "passed", "stdout": "\n"}}, {"nodeid": "test_endpoints.py::TestCORSHeaders::test_cors_headers_present[/director]", "lineno": 178, "outcome": "failed", "keywords": ["test_cors_headers_present[/director]", "parametrize", "pytestmark", "/director", "TestCORSHeaders", "test_endpoints.py", "__init__.py", "api"], "setup": {"duration": 0.0006905999980517663, "outcome": "passed"}, "call": {"duration": 2.9489061999993282, "outcome": "failed", "crash": {"path": "c:\\Projects\\building-os-platform\\tests\\api\\test_endpoints.py", "lineno": 215, "message": "AssertionError: No CORS headers found in response for /director\nassert False"}, "stdout": "\n\ud83d\ude80 GET /director\n\ud83d\udcca Status: 200 | \u23f1\ufe0f  Time: 2946.46ms | \ud83d\udce6 Size: 128 bytes\n", "longrepr": "E   AssertionError: No CORS headers found in response for /director\n    assert False"}, "teardown": {"duration": 0.0009674999964772724, "outcome": "passed", "stdout": "\n"}}, {"nodeid": "test_endpoints.py::TestCORSHeaders::test_cors_headers_present[/persona]", "lineno": 178, "outcome": "failed", "keywords": ["test_cors_headers_present[/persona]", "parametrize", "pytestmark", "/persona", "TestCORSHeaders", "test_endpoints.py", "__init__.py", "api"], "setup": {"duration": 0.0006352999989758246, "outcome": "passed"}, "call": {"duration": 8.075857499999984, "outcome": "failed", "crash": {"path": "C:\\Projects\\building-os-platform\\.venv\\Lib\\site-packages\\requests\\adapters.py", "lineno": 510, "message": "requests.exceptions.RetryError: HTTPSConnectionPool(host='pj4vlvxrg7.execute-api.us-east-1.amazonaws.com', port=443): Max retries exceeded with url: /dev/persona (Caused by ResponseError('too many 500 error responses'))"}, "stdout": "\n\ud83d\ude80 POST /persona\n\u274c Request failed: \nHTTPSConnectionPool(host='pj4vlvxrg7.execute-api.us-east-1.amazonaws.com', \nport=443): Max retries exceeded with url: /dev/persona (Caused by \nResponseError('too many 500 error responses'))\n", "longrepr": "urllib3.exceptions.ResponseError: too many 500 error responses\n\nThe above exception was the direct cause of the following exception:\nE   urllib3.exceptions.MaxRetryError: HTTPSConnectionPool(host='pj4vlvxrg7.execute-api.us-east-1.amazonaws.com', port=443): Max retries exceeded with url: /dev/persona (Caused by ResponseError('too many 500 error responses'))\n\nDuring handling of the above exception, another exception occurred:\nE   requests.exceptions.RetryError: HTTPSConnectionPool(host='pj4vlvxrg7.execute-api.us-east-1.amazonaws.com', port=443): Max retries exceeded with url: /dev/persona (Caused by ResponseError('too many 500 error responses'))"}, "teardown": {"duration": 0.0009063999968930148, "outcome": "passed", "stdout": "\n"}}, {"nodeid": "test_endpoints.py::TestCORSHeaders::test_cors_headers_present[/elevator/call]", "lineno": 178, "outcome": "failed", "keywords": ["test_cors_headers_present[/elevator/call]", "parametrize", "pytestmark", "/elevator/call", "TestCORSHeaders", "test_endpoints.py", "__init__.py", "api"], "setup": {"duration": 0.0005231999966781586, "outcome": "passed"}, "call": {"duration": 7.869956500006083, "outcome": "failed", "crash": {"path": "C:\\Projects\\building-os-platform\\.venv\\Lib\\site-packages\\requests\\adapters.py", "lineno": 510, "message": "requests.exceptions.RetryError: HTTPSConnectionPool(host='pj4vlvxrg7.execute-api.us-east-1.amazonaws.com', port=443): Max retries exceeded with url: /dev/elevator/call (Caused by ResponseError('too many 500 error responses'))"}, "stdout": "\n\ud83d\ude80 POST /elevator/call\n\u274c Request failed: \nHTTPSConnectionPool(host='pj4vlvxrg7.execute-api.us-east-1.amazonaws.com', \nport=443): Max retries exceeded with url: /dev/elevator/call (Caused by \nResponseError('too many 500 error responses'))\n", "longrepr": "urllib3.exceptions.ResponseError: too many 500 error responses\n\nThe above exception was the direct cause of the following exception:\nE   urllib3.exceptions.MaxRetryError: HTTPSConnectionPool(host='pj4vlvxrg7.execute-api.us-east-1.amazonaws.com', port=443): Max retries exceeded with url: /dev/elevator/call (Caused by ResponseError('too many 500 error responses'))\n\nDuring handling of the above exception, another exception occurred:\nE   requests.exceptions.RetryError: HTTPSConnectionPool(host='pj4vlvxrg7.execute-api.us-east-1.amazonaws.com', port=443): Max retries exceeded with url: /dev/elevator/call (Caused by ResponseError('too many 500 error responses'))"}, "teardown": {"duration": 0.0009662000011303462, "outcome": "passed", "stdout": "\n"}}, {"nodeid": "test_endpoints.py::TestCORSHeaders::test_cors_headers_present[/psim/search]", "lineno": 178, "outcome": "failed", "keywords": ["test_cors_headers_present[/psim/search]", "parametrize", "pytestmark", "/psim/search", "TestCORSHeaders", "test_endpoints.py", "__init__.py", "api"], "setup": {"duration": 0.001394099999743048, "outcome": "passed"}, "call": {"duration": 7.69955000000482, "outcome": "failed", "crash": {"path": "C:\\Projects\\building-os-platform\\.venv\\Lib\\site-packages\\requests\\adapters.py", "lineno": 510, "message": "requests.exceptions.RetryError: HTTPSConnectionPool(host='pj4vlvxrg7.execute-api.us-east-1.amazonaws.com', port=443): Max retries exceeded with url: /dev/psim/search (Caused by ResponseError('too many 500 error responses'))"}, "stdout": "\n\ud83d\ude80 POST /psim/search\n\u274c Request failed: \nHTTPSConnectionPool(host='pj4vlvxrg7.execute-api.us-east-1.amazonaws.com', \nport=443): Max retries exceeded with url: /dev/psim/search (Caused by \nResponseError('too many 500 error responses'))\n", "longrepr": "urllib3.exceptions.ResponseError: too many 500 error responses\n\nThe above exception was the direct cause of the following exception:\nE   urllib3.exceptions.MaxRetryError: HTTPSConnectionPool(host='pj4vlvxrg7.execute-api.us-east-1.amazonaws.com', port=443): Max retries exceeded with url: /dev/psim/search (Caused by ResponseError('too many 500 error responses'))\n\nDuring handling of the above exception, another exception occurred:\nE   requests.exceptions.RetryError: HTTPSConnectionPool(host='pj4vlvxrg7.execute-api.us-east-1.amazonaws.com', port=443): Max retries exceeded with url: /dev/psim/search (Caused by ResponseError('too many 500 error responses'))"}, "teardown": {"duration": 0.0010077000042656437, "outcome": "passed", "stdout": "\n"}}, {"nodeid": "test_endpoints.py::TestCORSHeaders::test_cors_headers_present[/coordinator/missions/test-123]", "lineno": 178, "outcome": "failed", "keywords": ["test_cors_headers_present[/coordinator/missions/test-123]", "parametrize", "pytestmark", "/coordinator/missions/test-123", "TestCORSHeaders", "test_endpoints.py", "__init__.py", "api"], "setup": {"duration": 0.0006775000001653098, "outcome": "passed"}, "call": {"duration": 8.234966700001678, "outcome": "failed", "crash": {"path": "C:\\Projects\\building-os-platform\\.venv\\Lib\\site-packages\\requests\\adapters.py", "lineno": 510, "message": "requests.exceptions.RetryError: HTTPSConnectionPool(host='pj4vlvxrg7.execute-api.us-east-1.amazonaws.com', port=443): Max retries exceeded with url: /dev/coordinator/missions/test-123 (Caused by ResponseError('too many 500 error responses'))"}, "stdout": "\n\ud83d\ude80 GET /coordinator/missions/test-123\n\u274c Request failed: \nHTTPSConnectionPool(host='pj4vlvxrg7.execute-api.us-east-1.amazonaws.com', \nport=443): Max retries exceeded with url: /dev/coordinator/missions/test-123 \n(Caused by ResponseError('too many 500 error responses'))\n", "longrepr": "urllib3.exceptions.ResponseError: too many 500 error responses\n\nThe above exception was the direct cause of the following exception:\nE   urllib3.exceptions.MaxRetryError: HTTPSConnectionPool(host='pj4vlvxrg7.execute-api.us-east-1.amazonaws.com', port=443): Max retries exceeded with url: /dev/coordinator/missions/test-123 (Caused by ResponseError('too many 500 error responses'))\n\nDuring handling of the above exception, another exception occurred:\nE   requests.exceptions.RetryError: HTTPSConnectionPool(host='pj4vlvxrg7.execute-api.us-east-1.amazonaws.com', port=443): Max retries exceeded with url: /dev/coordinator/missions/test-123 (Caused by ResponseError('too many 500 error responses'))"}, "teardown": {"duration": 0.0009138999957940541, "outcome": "passed", "stdout": "\n"}}, {"nodeid": "test_endpoints.py::TestErrorHandling::test_invalid_endpoint", "lineno": 220, "outcome": "passed", "keywords": ["test_invalid_endpoint", "TestErrorHandling", "test_endpoints.py", "__init__.py", "api"], "setup": {"duration": 0.0005213000040384941, "outcome": "passed"}, "call": {"duration": 0.16042929999821354, "outcome": "passed", "stdout": "\n\ud83d\ude80 GET /invalid-endpoint\n\ud83d\udcca Status: 404 | \u23f1\ufe0f  Time: 158.03ms | \ud83d\udce6 Size: 23 bytes\n"}, "teardown": {"duration": 0.000990000000456348, "outcome": "passed", "stdout": "\n"}}, {"nodeid": "test_endpoints.py::TestErrorHandling::test_invalid_method", "lineno": 225, "outcome": "passed", "keywords": ["test_invalid_method", "TestErrorHandling", "test_endpoints.py", "__init__.py", "api"], "setup": {"duration": 0.0005329999985406175, "outcome": "passed"}, "call": {"duration": 0.15737539999827277, "outcome": "passed", "stdout": "\n\ud83d\ude80 DELETE /health\n\ud83d\udcca Status: 404 | \u23f1\ufe0f  Time: 155.14ms | \ud83d\udce6 Size: 23 bytes\n"}, "teardown": {"duration": 0.0010557999994489364, "outcome": "passed", "stdout": "\n"}}, {"nodeid": "test_endpoints.py::TestErrorHandling::test_malformed_json", "lineno": 235, "outcome": "passed", "keywords": ["test_malformed_json", "TestErrorHandling", "test_endpoints.py", "__init__.py", "api"], "setup": {"duration": 0.0007803999978932552, "outcome": "passed"}, "call": {"duration": 8.069709999996121, "outcome": "passed"}, "teardown": {"duration": 0.0009368999963044189, "outcome": "passed", "stdout": "\n"}}, {"nodeid": "test_performance.py::TestPerformance::test_response_time_under_threshold", "lineno": 18, "outcome": "failed", "keywords": ["test_response_time_under_threshold", "TestPerformance", "test_performance.py", "__init__.py", "api"], "setup": {"duration": 0.00048660000175004825, "outcome": "passed"}, "call": {"duration": 5.743311699996411, "outcome": "failed", "crash": {"path": "c:\\Projects\\building-os-platform\\tests\\api\\test_performance.py", "lineno": 42, "message": "AssertionError: /director took 5559.37ms (threshold: 3000ms)\nassert 5559.368133544922 < 3000"}, "stdout": "\n\ud83d\ude80 GET /health\n\ud83d\udcca Status: 200 | \u23f1\ufe0f  Time: 181.41ms | \ud83d\udce6 Size: 60 bytes\n\n\ud83d\ude80 GET /director\n\ud83d\udcca Status: 200 | \u23f1\ufe0f  Time: 5557.78ms | \ud83d\udce6 Size: 128 bytes\n", "longrepr": "E   AssertionError: /director took 5559.37ms (threshold: 3000ms)\n    assert 5559.368133544922 < 3000"}, "teardown": {"duration": 0.00045449999743141234, "outcome": "passed"}}, {"nodeid": "test_performance.py::TestPerformance::test_concurrent_health_checks", "lineno": 45, "outcome": "passed", "keywords": ["test_concurrent_health_checks", "TestPerformance", "test_performance.py", "__init__.py", "api"], "setup": {"duration": 0.00041820000478764996, "outcome": "passed"}, "call": {"duration": 1.9032136000023456, "outcome": "passed", "stdout": "\n\ud83d\ude80 GET /health\n\n\ud83d\ude80 GET /health\n\n\ud83d\ude80 GET /health\n\n\ud83d\ude80 GET /health\n\n\ud83d\ude80 GET /health\n\ud83d\udcca Status: 200 | \u23f1\ufe0f  Time: 195.22ms | \ud83d\udce6 Size: 60 bytes\n\ud83d\udcca Status: 200 | \u23f1\ufe0f  Time: 1835.04ms | \ud83d\udce6 Size: 60 bytes\n\ud83d\udcca Status: 200 | \u23f1\ufe0f  Time: 1841.57ms | \ud83d\udce6 Size: 60 bytes\n\ud83d\udcca Status: 200 | \u23f1\ufe0f  Time: 1858.53ms | \ud83d\udce6 Size: 60 bytes\n\ud83d\udcca Status: 200 | \u23f1\ufe0f  Time: 1890.46ms | \ud83d\udce6 Size: 60 bytes\n"}, "teardown": {"duration": 0.0004771999956574291, "outcome": "passed"}}, {"nodeid": "test_performance.py::TestLoadTesting::test_sustained_load_health_endpoint", "lineno": 72, "outcome": "passed", "keywords": ["test_sustained_load_health_endpoint", "slow", "pytestmark", "TestLoadTesting", "test_performance.py", "__init__.py", "api"], "setup": {"duration": 0.0004298999992897734, "outcome": "passed"}, "call": {"duration": 13.33251929999824, "outcome": "passed", "stdout": "\n\ud83d\udd25 Running sustained load test...\n\n\ud83d\ude80 GET /health\n\ud83d\udcca Status: 200 | \u23f1\ufe0f  Time: 183.63ms | \ud83d\udce6 Size: 60 bytes\n\n\ud83d\ude80 GET /health\n\ud83d\udcca Status: 200 | \u23f1\ufe0f  Time: 188.03ms | \ud83d\udce6 Size: 60 bytes\n\n\ud83d\ude80 GET /health\n\ud83d\udcca Status: 200 | \u23f1\ufe0f  Time: 190.26ms | \ud83d\udce6 Size: 60 bytes\n\n\ud83d\ude80 GET /health\n\ud83d\udcca Status: 200 | \u23f1\ufe0f  Time: 189.51ms | \ud83d\udce6 Size: 60 bytes\n\n\ud83d\ude80 GET /health\n\ud83d\udcca Status: 200 | \u23f1\ufe0f  Time: 186.72ms | \ud83d\udce6 Size: 60 bytes\n\n\ud83d\ude80 GET /health\n\ud83d\udcca Status: 200 | \u23f1\ufe0f  Time: 180.63ms | \ud83d\udce6 Size: 60 bytes\n\n\ud83d\ude80 GET /health\n\ud83d\udcca Status: 200 | \u23f1\ufe0f  Time: 179.98ms | \ud83d\udce6 Size: 60 bytes\n\n\ud83d\ude80 GET /health\n\ud83d\udcca Status: 200 | \u23f1\ufe0f  Time: 180.04ms | \ud83d\udce6 Size: 60 bytes\n\n\ud83d\ude80 GET /health\n\ud83d\udcca Status: 200 | \u23f1\ufe0f  Time: 177.69ms | \ud83d\udce6 Size: 60 bytes\n\n\ud83d\ude80 GET /health\n\ud83d\udcca Status: 200 | \u23f1\ufe0f  Time: 183.17ms | \ud83d\udce6 Size: 60 bytes\n\n\ud83d\ude80 GET /health\n\ud83d\udcca Status: 200 | \u23f1\ufe0f  Time: 195.19ms | \ud83d\udce6 Size: 60 bytes\n\n\ud83d\ude80 GET /health\n\ud83d\udcca Status: 200 | \u23f1\ufe0f  Time: 190.03ms | \ud83d\udce6 Size: 60 bytes\n\n\ud83d\ude80 GET /health\n\ud83d\udcca Status: 200 | \u23f1\ufe0f  Time: 179.09ms | \ud83d\udce6 Size: 60 bytes\n\n\ud83d\ude80 GET /health\n\ud83d\udcca Status: 200 | \u23f1\ufe0f  Time: 186.27ms | \ud83d\udce6 Size: 60 bytes\n\n\ud83d\ude80 GET /health\n\ud83d\udcca Status: 200 | \u23f1\ufe0f  Time: 175.74ms | \ud83d\udce6 Size: 60 bytes\n\n\ud83d\ude80 GET /health\n\ud83d\udcca Status: 200 | \u23f1\ufe0f  Time: 175.00ms | \ud83d\udce6 Size: 60 bytes\n\n\ud83d\ude80 GET /health\n\ud83d\udcca Status: 200 | \u23f1\ufe0f  Time: 184.04ms | \ud83d\udce6 Size: 60 bytes\n\n\ud83d\ude80 GET /health\n\ud83d\udcca Status: 200 | \u23f1\ufe0f  Time: 175.95ms | \ud83d\udce6 Size: 60 bytes\n\n\ud83d\ude80 GET /health\n\ud83d\udcca Status: 200 | \u23f1\ufe0f  Time: 203.33ms | \ud83d\udce6 Size: 60 bytes\n\n\ud83d\ude80 GET /health\n\ud83d\udcca Status: 200 | \u23f1\ufe0f  Time: 268.58ms | \ud83d\udce6 Size: 60 bytes\n  Making 20 requests... 0:00:13\n\u2705 Success rate: 100.0% (20/20)\n\u23f1\ufe0f  Avg response: 190.59ms\n\ud83d\udc0c Max response: 270.52ms\n\u26a1 Min response: 176.68ms\n"}, "teardown": {"duration": 0.0004990000015823171, "outcome": "passed"}}, {"nodeid": "test_performance.py::TestStressScenarios::test_large_payload_persona", "lineno": 149, "outcome": "failed", "keywords": ["test_large_payload_persona", "TestStressScenarios", "test_performance.py", "__init__.py", "api"], "setup": {"duration": 0.00047569999878760427, "outcome": "passed"}, "call": {"duration": 8.138674599998922, "outcome": "failed", "crash": {"path": "C:\\Projects\\building-os-platform\\.venv\\Lib\\site-packages\\requests\\adapters.py", "lineno": 510, "message": "requests.exceptions.RetryError: HTTPSConnectionPool(host='pj4vlvxrg7.execute-api.us-east-1.amazonaws.com', port=443): Max retries exceeded with url: /dev/persona (Caused by ResponseError('too many 500 error responses'))"}, "stdout": "\n\ud83d\ude80 POST /persona\n\u274c Request failed: \nHTTPSConnectionPool(host='pj4vlvxrg7.execute-api.us-east-1.amazonaws.com', \nport=443): Max retries exceeded with url: /dev/persona (Caused by \nResponseError('too many 500 error responses'))\n", "longrepr": "urllib3.exceptions.ResponseError: too many 500 error responses\n\nThe above exception was the direct cause of the following exception:\nE   urllib3.exceptions.MaxRetryError: HTTPSConnectionPool(host='pj4vlvxrg7.execute-api.us-east-1.amazonaws.com', port=443): Max retries exceeded with url: /dev/persona (Caused by ResponseError('too many 500 error responses'))\n\nDuring handling of the above exception, another exception occurred:\nE   requests.exceptions.RetryError: HTTPSConnectionPool(host='pj4vlvxrg7.execute-api.us-east-1.amazonaws.com', port=443): Max retries exceeded with url: /dev/persona (Caused by ResponseError('too many 500 error responses'))"}, "teardown": {"duration": 0.00046329999895533547, "outcome": "passed"}}, {"nodeid": "test_performance.py::TestStressScenarios::test_rapid_successive_requests", "lineno": 163, "outcome": "passed", "keywords": ["test_rapid_successive_requests", "TestStressScenarios", "test_performance.py", "__init__.py", "api"], "setup": {"duration": 0.00048740000056568533, "outcome": "passed"}, "call": {"duration": 1.879501799994614, "outcome": "passed", "stdout": "\n\ud83d\ude80 GET /health\n\ud83d\udcca Status: 200 | \u23f1\ufe0f  Time: 182.65ms | \ud83d\udce6 Size: 60 bytes\n\n\ud83d\ude80 GET /health\n\ud83d\udcca Status: 200 | \u23f1\ufe0f  Time: 208.26ms | \ud83d\udce6 Size: 60 bytes\n\n\ud83d\ude80 GET /health\n\ud83d\udcca Status: 200 | \u23f1\ufe0f  Time: 182.07ms | \ud83d\udce6 Size: 60 bytes\n\n\ud83d\ude80 GET /health\n\ud83d\udcca Status: 200 | \u23f1\ufe0f  Time: 192.09ms | \ud83d\udce6 Size: 60 bytes\n\n\ud83d\ude80 GET /health\n\ud83d\udcca Status: 200 | \u23f1\ufe0f  Time: 180.92ms | \ud83d\udce6 Size: 60 bytes\n\n\ud83d\ude80 GET /health\n\ud83d\udcca Status: 200 | \u23f1\ufe0f  Time: 190.92ms | \ud83d\udce6 Size: 60 bytes\n\n\ud83d\ude80 GET /health\n\ud83d\udcca Status: 200 | \u23f1\ufe0f  Time: 185.02ms | \ud83d\udce6 Size: 60 bytes\n\n\ud83d\ude80 GET /health\n\ud83d\udcca Status: 200 | \u23f1\ufe0f  Time: 180.53ms | \ud83d\udce6 Size: 60 bytes\n\n\ud83d\ude80 GET /health\n\ud83d\udcca Status: 200 | \u23f1\ufe0f  Time: 178.45ms | \ud83d\udce6 Size: 60 bytes\n\n\ud83d\ude80 GET /health\n\ud83d\udcca Status: 200 | \u23f1\ufe0f  Time: 181.61ms | \ud83d\udce6 Size: 60 bytes\n\ud83d\ude80 Rapid requests: 10 in 1.88s\n\u2705 Success rate: 100.0%\n"}, "teardown": {"duration": 0.0004651000053854659, "outcome": "passed"}}, {"nodeid": "test_performance.py::TestStressScenarios::test_special_characters_in_requests", "lineno": 189, "outcome": "failed", "keywords": ["test_special_characters_in_requests", "TestStressScenarios", "test_performance.py", "__init__.py", "api"], "setup": {"duration": 0.00047839999751886353, "outcome": "passed"}, "call": {"duration": 8.045809700000973, "outcome": "failed", "crash": {"path": "C:\\Projects\\building-os-platform\\.venv\\Lib\\site-packages\\requests\\adapters.py", "lineno": 510, "message": "requests.exceptions.RetryError: HTTPSConnectionPool(host='pj4vlvxrg7.execute-api.us-east-1.amazonaws.com', port=443): Max retries exceeded with url: /dev/persona (Caused by ResponseError('too many 500 error responses'))"}, "stdout": "\n\ud83d\ude80 POST /persona\n\u274c Request failed: \nHTTPSConnectionPool(host='pj4vlvxrg7.execute-api.us-east-1.amazonaws.com', \nport=443): Max retries exceeded with url: /dev/persona (Caused by \nResponseError('too many 500 error responses'))\n", "longrepr": "urllib3.exceptions.ResponseError: too many 500 error responses\n\nThe above exception was the direct cause of the following exception:\nE   urllib3.exceptions.MaxRetryError: HTTPSConnectionPool(host='pj4vlvxrg7.execute-api.us-east-1.amazonaws.com', port=443): Max retries exceeded with url: /dev/persona (Caused by ResponseError('too many 500 error responses'))\n\nDuring handling of the above exception, another exception occurred:\nE   requests.exceptions.RetryError: HTTPSConnectionPool(host='pj4vlvxrg7.execute-api.us-east-1.amazonaws.com', port=443): Max retries exceeded with url: /dev/persona (Caused by ResponseError('too many 500 error responses'))"}, "teardown": {"duration": 0.0004197000016574748, "outcome": "passed"}}, {"nodeid": "test_performance.py::TestBoundaryConditions::test_empty_payloads", "lineno": 213, "outcome": "failed", "keywords": ["test_empty_payloads", "TestBoundaryConditions", "test_performance.py", "__init__.py", "api"], "setup": {"duration": 0.0003735000063898042, "outcome": "passed"}, "call": {"duration": 8.072743599994283, "outcome": "failed", "crash": {"path": "C:\\Projects\\building-os-platform\\.venv\\Lib\\site-packages\\requests\\adapters.py", "lineno": 510, "message": "requests.exceptions.RetryError: HTTPSConnectionPool(host='pj4vlvxrg7.execute-api.us-east-1.amazonaws.com', port=443): Max retries exceeded with url: /dev/persona (Caused by ResponseError('too many 500 error responses'))"}, "stdout": "\n\ud83d\ude80 POST /persona\n\u274c Request failed: \nHTTPSConnectionPool(host='pj4vlvxrg7.execute-api.us-east-1.amazonaws.com', \nport=443): Max retries exceeded with url: /dev/persona (Caused by \nResponseError('too many 500 error responses'))\n", "longrepr": "urllib3.exceptions.ResponseError: too many 500 error responses\n\nThe above exception was the direct cause of the following exception:\nE   urllib3.exceptions.MaxRetryError: HTTPSConnectionPool(host='pj4vlvxrg7.execute-api.us-east-1.amazonaws.com', port=443): Max retries exceeded with url: /dev/persona (Caused by ResponseError('too many 500 error responses'))\n\nDuring handling of the above exception, another exception occurred:\nE   requests.exceptions.RetryError: HTTPSConnectionPool(host='pj4vlvxrg7.execute-api.us-east-1.amazonaws.com', port=443): Max retries exceeded with url: /dev/persona (Caused by ResponseError('too many 500 error responses'))"}, "teardown": {"duration": 0.00044270000216783956, "outcome": "passed"}}, {"nodeid": "test_performance.py::TestBoundaryConditions::test_null_values_in_payload", "lineno": 224, "outcome": "failed", "keywords": ["test_null_values_in_payload", "TestBoundaryConditions", "test_performance.py", "__init__.py", "api"], "setup": {"duration": 0.00039540000580018386, "outcome": "passed"}, "call": {"duration": 8.073463600005198, "outcome": "failed", "crash": {"path": "C:\\Projects\\building-os-platform\\.venv\\Lib\\site-packages\\requests\\adapters.py", "lineno": 510, "message": "requests.exceptions.RetryError: HTTPSConnectionPool(host='pj4vlvxrg7.execute-api.us-east-1.amazonaws.com', port=443): Max retries exceeded with url: /dev/persona (Caused by ResponseError('too many 500 error responses'))"}, "stdout": "\n\ud83d\ude80 POST /persona\n\u274c Request failed: \nHTTPSConnectionPool(host='pj4vlvxrg7.execute-api.us-east-1.amazonaws.com', \nport=443): Max retries exceeded with url: /dev/persona (Caused by \nResponseError('too many 500 error responses'))\n", "longrepr": "urllib3.exceptions.ResponseError: too many 500 error responses\n\nThe above exception was the direct cause of the following exception:\nE   urllib3.exceptions.MaxRetryError: HTTPSConnectionPool(host='pj4vlvxrg7.execute-api.us-east-1.amazonaws.com', port=443): Max retries exceeded with url: /dev/persona (Caused by ResponseError('too many 500 error responses'))\n\nDuring handling of the above exception, another exception occurred:\nE   requests.exceptions.RetryError: HTTPSConnectionPool(host='pj4vlvxrg7.execute-api.us-east-1.amazonaws.com', port=443): Max retries exceeded with url: /dev/persona (Caused by ResponseError('too many 500 error responses'))"}, "teardown": {"duration": 0.00044839999463874847, "outcome": "passed"}}, {"nodeid": "test_performance.py::TestBoundaryConditions::test_extremely_long_mission_id", "lineno": 233, "outcome": "failed", "keywords": ["test_extremely_long_mission_id", "TestBoundaryConditions", "test_performance.py", "__init__.py", "api"], "setup": {"duration": 0.00040040000021690503, "outcome": "passed"}, "call": {"duration": 8.411846000002697, "outcome": "failed", "crash": {"path": "C:\\Projects\\building-os-platform\\.venv\\Lib\\site-packages\\requests\\adapters.py", "lineno": 510, "message": "requests.exceptions.RetryError: HTTPSConnectionPool(host='pj4vlvxrg7.execute-api.us-east-1.amazonaws.com', port=443): Max retries exceeded with url: /dev/coordinator/missions/xxxxxxxxxxxxxxxxxxxxxxxxxxxxxxxxxxxxxxxxxxxxxxxxxxxxxxxxxxxxxxxxxxxxxxxxxxxxxxxxxxxxxxxxxxxxxxxxxxxxxxxxxxxxxxxxxxxxxxxxxxxxxxxxxxxxxxxxxxxxxxxxxxxxxxxxxxxxxxxxxxxxxxxxxxxxxxxxxxxxxxxxxxxxxxxxxxxxxxxxxxxxxxxxxxxxxxxxxxxxxxxxxxxxxxxxxxxxxxxxxxxxxxxxxxxxxxxxxxxxxxxxxxxxxxxxxxxxxxxxxxxxxxxxxxxxxxxxxxxxxxxxxxxxxxxxxxxxxxxxxxxxxxxxxxxxxxxxxxxxxxxxxxxxxxxxxxxxxxxxxxxxxxxxxxxxxxxxxxxxxxxxxxxxxxxxxxxxxxxxxxxxxxxxxxxxxxxxxxxxxxxxxxxxxxxxxxxxxxxxxxxxxxxxxxxxxxxxxxxxxxxxxxxxxxxxxxxxxxxxxxxxxxxxxxxxxxxxxxxxxxxxxxxxxxxxxxxxxxxxxxxxxxxxxxxxxxxxxxxxxxxxxxxxxxxxxxxxxxxxxxxxxxxxxxxxxxxxxxxxxxxxxxxxxxxxxxxxxxxxxxxxxxxxxxxxxxxxxxxxxxxxxxxxxxxxxxxxxxxxxxxxxxxxxxxxxxxxxxxxxxxxxxxxxxxxxxxxxxxxxxxxxxxxxxxxxxxxxxxxxxxxxxxxxxxxxxxxxxxxxxxxxxxxxxxxxxxxxxxxxxxxxxxxxxxxxxxxxxxxxxxxxxxxxxxxxxxxxxxxxxxxxxxxxxxxxxxxxxxxxxxxxxxxxxxxxxxxxxxxxxxxxxxxxxxxxxxxxxxxxxxxxxxxxxxxxxxxxxxxxxxxxxxxxxxxxxxxxxxxxxxxxxxxxxxxxxxxxxxxxxxxxxxxxxxxxxxxxxxxxxxxxxxxxxxxxxxxxxxxxxxxxxxxxxxxxxxxxxxxxxxxxxxxxxxxxxxxxxxxxxxxxxxxxxxxxxxxxxxx (Caused by ResponseError('too many 500 error responses'))"}, "stdout": "\n\ud83d\ude80 GET \n/coordinator/missions/xxxxxxxxxxxxxxxxxxxxxxxxxxxxxxxxxxxxxxxxxxxxxxxxxxxxxxxxx\nxxxxxxxxxxxxxxxxxxxxxxxxxxxxxxxxxxxxxxxxxxxxxxxxxxxxxxxxxxxxxxxxxxxxxxxxxxxxxxx\nxxxxxxxxxxxxxxxxxxxxxxxxxxxxxxxxxxxxxxxxxxxxxxxxxxxxxxxxxxxxxxxxxxxxxxxxxxxxxxx\nxxxxxxxxxxxxxxxxxxxxxxxxxxxxxxxxxxxxxxxxxxxxxxxxxxxxxxxxxxxxxxxxxxxxxxxxxxxxxxx\nxxxxxxxxxxxxxxxxxxxxxxxxxxxxxxxxxxxxxxxxxxxxxxxxxxxxxxxxxxxxxxxxxxxxxxxxxxxxxxx\nxxxxxxxxxxxxxxxxxxxxxxxxxxxxxxxxxxxxxxxxxxxxxxxxxxxxxxxxxxxxxxxxxxxxxxxxxxxxxxx\nxxxxxxxxxxxxxxxxxxxxxxxxxxxxxxxxxxxxxxxxxxxxxxxxxxxxxxxxxxxxxxxxxxxxxxxxxxxxxxx\nxxxxxxxxxxxxxxxxxxxxxxxxxxxxxxxxxxxxxxxxxxxxxxxxxxxxxxxxxxxxxxxxxxxxxxxxxxxxxxx\nxxxxxxxxxxxxxxxxxxxxxxxxxxxxxxxxxxxxxxxxxxxxxxxxxxxxxxxxxxxxxxxxxxxxxxxxxxxxxxx\nxxxxxxxxxxxxxxxxxxxxxxxxxxxxxxxxxxxxxxxxxxxxxxxxxxxxxxxxxxxxxxxxxxxxxxxxxxxxxxx\nxxxxxxxxxxxxxxxxxxxxxxxxxxxxxxxxxxxxxxxxxxxxxxxxxxxxxxxxxxxxxxxxxxxxxxxxxxxxxxx\nxxxxxxxxxxxxxxxxxxxxxxxxxxxxxxxxxxxxxxxxxxxxxxxxxxxxxxxxxxxxxxxxxxxxxxxxxxxxxxx\nxxxxxxxxxxxxxxxxxxxxxxxxxxxxxxxxxxxxxxxxxxxxxxxxxxxxxxxxxxxxxxxxxxxxxxxxxx\n\u274c Request failed: \nHTTPSConnectionPool(host='pj4vlvxrg7.execute-api.us-east-1.amazonaws.com', \nport=443): Max retries exceeded with url: \n/dev/coordinator/missions/xxxxxxxxxxxxxxxxxxxxxxxxxxxxxxxxxxxxxxxxxxxxxxxxxxxxx\nxxxxxxxxxxxxxxxxxxxxxxxxxxxxxxxxxxxxxxxxxxxxxxxxxxxxxxxxxxxxxxxxxxxxxxxxxxxxxxx\nxxxxxxxxxxxxxxxxxxxxxxxxxxxxxxxxxxxxxxxxxxxxxxxxxxxxxxxxxxxxxxxxxxxxxxxxxxxxxxx\nxxxxxxxxxxxxxxxxxxxxxxxxxxxxxxxxxxxxxxxxxxxxxxxxxxxxxxxxxxxxxxxxxxxxxxxxxxxxxxx\nxxxxxxxxxxxxxxxxxxxxxxxxxxxxxxxxxxxxxxxxxxxxxxxxxxxxxxxxxxxxxxxxxxxxxxxxxxxxxxx\nxxxxxxxxxxxxxxxxxxxxxxxxxxxxxxxxxxxxxxxxxxxxxxxxxxxxxxxxxxxxxxxxxxxxxxxxxxxxxxx\nxxxxxxxxxxxxxxxxxxxxxxxxxxxxxxxxxxxxxxxxxxxxxxxxxxxxxxxxxxxxxxxxxxxxxxxxxxxxxxx\nxxxxxxxxxxxxxxxxxxxxxxxxxxxxxxxxxxxxxxxxxxxxxxxxxxxxxxxxxxxxxxxxxxxxxxxxxxxxxxx\nxxxxxxxxxxxxxxxxxxxxxxxxxxxxxxxxxxxxxxxxxxxxxxxxxxxxxxxxxxxxxxxxxxxxxxxxxxxxxxx\nxxxxxxxxxxxxxxxxxxxxxxxxxxxxxxxxxxxxxxxxxxxxxxxxxxxxxxxxxxxxxxxxxxxxxxxxxxxxxxx\nxxxxxxxxxxxxxxxxxxxxxxxxxxxxxxxxxxxxxxxxxxxxxxxxxxxxxxxxxxxxxxxxxxxxxxxxxxxxxxx\nxxxxxxxxxxxxxxxxxxxxxxxxxxxxxxxxxxxxxxxxxxxxxxxxxxxxxxxxxxxxxxxxxxxxxxxxxxxxxxx\nxxxxxxxxxxxxxxxxxxxxxxxxxxxxxxxxxxxxxxxxxxxxxxxxxxxxxxxxxxxxxxxxxxxxxxxxxxxxxx \n(Caused by ResponseError('too many 500 error responses'))\n", "longrepr": "urllib3.exceptions.ResponseError: too many 500 error responses\n\nThe above exception was the direct cause of the following exception:\nE   urllib3.exceptions.MaxRetryError: HTTPSConnectionPool(host='pj4vlvxrg7.execute-api.us-east-1.amazonaws.com', port=443): Max retries exceeded with url: /dev/coordinator/missions/xxxxxxxxxxxxxxxxxxxxxxxxxxxxxxxxxxxxxxxxxxxxxxxxxxxxxxxxxxxxxxxxxxxxxxxxxxxxxxxxxxxxxxxxxxxxxxxxxxxxxxxxxxxxxxxxxxxxxxxxxxxxxxxxxxxxxxxxxxxxxxxxxxxxxxxxxxxxxxxxxxxxxxxxxxxxxxxxxxxxxxxxxxxxxxxxxxxxxxxxxxxxxxxxxxxxxxxxxxxxxxxxxxxxxxxxxxxxxxxxxxxxxxxxxxxxxxxxxxxxxxxxxxxxxxxxxxxxxxxxxxxxxxxxxxxxxxxxxxxxxxxxxxxxxxxxxxxxxxxxxxxxxxxxxxxxxxxxxxxxxxxxxxxxxxxxxxxxxxxxxxxxxxxxxxxxxxxxxxxxxxxxxxxxxxxxxxxxxxxxxxxxxxxxxxxxxxxxxxxxxxxxxxxxxxxxxxxxxxxxxxxxxxxxxxxxxxxxxxxxxxxxxxxxxxxxxxxxxxxxxxxxxxxxxxxxxxxxxxxxxxxxxxxxxxxxxxxxxxxxxxxxxxxxxxxxxxxxxxxxxxxxxxxxxxxxxxxxxxxxxxxxxxxxxxxxxxxxxxxxxxxxxxxxxxxxxxxxxxxxxxxxxxxxxxxxxxxxxxxxxxxxxxxxxxxxxxxxxxxxxxxxxxxxxxxxxxxxxxxxxxxxxxxxxxxxxxxxxxxxxxxxxxxxxxxxxxxxxxxxxxxxxxxxxxxxxxxxxxxxxxxxxxxxxxxxxxxxxxxxxxxxxxxxxxxxxxxxxxxxxxxxxxxxxxxxxxxxxxxxxxxxxxxxxxxxxxxxxxxxxxxxxxxxxxxxxxxxxxxxxxxxxxxxxxxxxxxxxxxxxxxxxxxxxxxxxxxxxxxxxxxxxxxxxxxxxxxxxxxxxxxxxxxxxxxxxxxxxxxxxxxxxxxxxxxxxxxxxxxxxxxxxxxxxxxxxxxxxxxxxxxxxxxxxxxxxxxxxxxxxxxxxxxxxxxxxxxxxxxxxxxxxxxxxxxxxxxxxxxx (Caused by ResponseError('too many 500 error responses'))\n\nDuring handling of the above exception, another exception occurred:\nE   requests.exceptions.RetryError: HTTPSConnectionPool(host='pj4vlvxrg7.execute-api.us-east-1.amazonaws.com', port=443): Max retries exceeded with url: /dev/coordinator/missions/xxxxxxxxxxxxxxxxxxxxxxxxxxxxxxxxxxxxxxxxxxxxxxxxxxxxxxxxxxxxxxxxxxxxxxxxxxxxxxxxxxxxxxxxxxxxxxxxxxxxxxxxxxxxxxxxxxxxxxxxxxxxxxxxxxxxxxxxxxxxxxxxxxxxxxxxxxxxxxxxxxxxxxxxxxxxxxxxxxxxxxxxxxxxxxxxxxxxxxxxxxxxxxxxxxxxxxxxxxxxxxxxxxxxxxxxxxxxxxxxxxxxxxxxxxxxxxxxxxxxxxxxxxxxxxxxxxxxxxxxxxxxxxxxxxxxxxxxxxxxxxxxxxxxxxxxxxxxxxxxxxxxxxxxxxxxxxxxxxxxxxxxxxxxxxxxxxxxxxxxxxxxxxxxxxxxxxxxxxxxxxxxxxxxxxxxxxxxxxxxxxxxxxxxxxxxxxxxxxxxxxxxxxxxxxxxxxxxxxxxxxxxxxxxxxxxxxxxxxxxxxxxxxxxxxxxxxxxxxxxxxxxxxxxxxxxxxxxxxxxxxxxxxxxxxxxxxxxxxxxxxxxxxxxxxxxxxxxxxxxxxxxxxxxxxxxxxxxxxxxxxxxxxxxxxxxxxxxxxxxxxxxxxxxxxxxxxxxxxxxxxxxxxxxxxxxxxxxxxxxxxxxxxxxxxxxxxxxxxxxxxxxxxxxxxxxxxxxxxxxxxxxxxxxxxxxxxxxxxxxxxxxxxxxxxxxxxxxxxxxxxxxxxxxxxxxxxxxxxxxxxxxxxxxxxxxxxxxxxxxxxxxxxxxxxxxxxxxxxxxxxxxxxxxxxxxxxxxxxxxxxxxxxxxxxxxxxxxxxxxxxxxxxxxxxxxxxxxxxxxxxxxxxxxxxxxxxxxxxxxxxxxxxxxxxxxxxxxxxxxxxxxxxxxxxxxxxxxxxxxxxxxxxxxxxxxxxxxxxxxxxxxxxxxxxxxxxxxxxxxxxxxxxxxxxxxxxxxxxxxxxxxxxxxxxxxxxxxxxxxxxxxxxxxxxxxxxxxxxxxxxxxxxxxxxxxxxxxxxxx (Caused by ResponseError('too many 500 error responses'))"}, "teardown": {"duration": 0.14088330000231508, "outcome": "passed", "stdout": "\n\ud83d\udcca Test Session Complete\n                              \ud83d\udd0d Request Summary                               \n\u250c\u2500\u2500\u2500\u2500\u2500\u2500\u2500\u2500\u252c\u2500\u2500\u2500\u2500\u2500\u2500\u2500\u2500\u2500\u2500\u2500\u2500\u2500\u2500\u2500\u2500\u2500\u2500\u2500\u2500\u2500\u2500\u2500\u2500\u2500\u2500\u2500\u2500\u2500\u2500\u2500\u2500\u2500\u2500\u2500\u2500\u2500\u252c\u2500\u2500\u2500\u2500\u2500\u2500\u2500\u2500\u252c\u2500\u2500\u2500\u2500\u2500\u2500\u2500\u2500\u2500\u2500\u2500\u252c\u2500\u2500\u2500\u2500\u2500\u2500\u2500\u2500\u2500\u2510\n\u2502 Method \u2502 Endpoint                            \u2502 Status \u2502 Time (ms) \u2502 Success \u2502\n\u251c\u2500\u2500\u2500\u2500\u2500\u2500\u2500\u2500\u253c\u2500\u2500\u2500\u2500\u2500\u2500\u2500\u2500\u2500\u2500\u2500\u2500\u2500\u2500\u2500\u2500\u2500\u2500\u2500\u2500\u2500\u2500\u2500\u2500\u2500\u2500\u2500\u2500\u2500\u2500\u2500\u2500\u2500\u2500\u2500\u2500\u2500\u253c\u2500\u2500\u2500\u2500\u2500\u2500\u2500\u2500\u253c\u2500\u2500\u2500\u2500\u2500\u2500\u2500\u2500\u2500\u2500\u2500\u253c\u2500\u2500\u2500\u2500\u2500\u2500\u2500\u2500\u2500\u2524\n\u2502 GET    \u2502 /health                             \u2502 200    \u2502 1297.31   \u2502 \u2705      \u2502\n\u2502 GET    \u2502 /health                             \u2502 200    \u2502 198.58    \u2502 \u2705      \u2502\n\u2502 GET    \u2502 /director                           \u2502 200    \u2502 4052.94   \u2502 \u2705      \u2502\n\u2502 GET    \u2502 /director?user_request=Test mission \u2502 200    \u2502 5581.57   \u2502 \u2705      \u2502\n\u2502        \u2502 from Python API tests               \u2502        \u2502           \u2502         \u2502\n\u2502 GET    \u2502 /director?user_id=api-test-user     \u2502 200    \u2502 6585.56   \u2502 \u2705      \u2502\n\u2502 POST   \u2502 /persona                            \u2502 0      \u2502 8906.19   \u2502 \u274c      \u2502\n\u2502 POST   \u2502 /persona                            \u2502 0      \u2502 8160.71   \u2502 \u274c      \u2502\n\u2502 POST   \u2502 /persona                            \u2502 0      \u2502 8136.42   \u2502 \u274c      \u2502\n\u2502 GET    \u2502 /persona/conversations?user_id=api\u2026 \u2502 0      \u2502 8113.98   \u2502 \u274c      \u2502\n\u2502 POST   \u2502 /elevator/call                      \u2502 0      \u2502 8372.06   \u2502 \u274c      \u2502\n\u2502 POST   \u2502 /elevator/call                      \u2502 0      \u2502 7777.36   \u2502 \u274c      \u2502\n\u2502 POST   \u2502 /psim/search                        \u2502 0      \u2502 8457.51   \u2502 \u274c      \u2502\n\u2502 POST   \u2502 /psim/search                        \u2502 0      \u2502 7729.44   \u2502 \u274c      \u2502\n\u2502 GET    \u2502 /coordinator/missions/test-mission\u2026 \u2502 0      \u2502 8354.43   \u2502 \u274c      \u2502\n\u2502 GET    \u2502 /coordinator/missions/python-test-\u2026 \u2502 0      \u2502 8277.31   \u2502 \u274c      \u2502\n\u2502 GET    \u2502 /health                             \u2502 200    \u2502 198.99    \u2502 \u2705      \u2502\n\u2502 GET    \u2502 /director                           \u2502 200    \u2502 2946.46   \u2502 \u2705      \u2502\n\u2502 POST   \u2502 /persona                            \u2502 0      \u2502 8073.0    \u2502 \u274c      \u2502\n\u2502 POST   \u2502 /elevator/call                      \u2502 0      \u2502 7867.39   \u2502 \u274c      \u2502\n\u2502 POST   \u2502 /psim/search                        \u2502 0      \u2502 7696.95   \u2502 \u274c      \u2502\n\u2502 GET    \u2502 /coordinator/missions/test-123      \u2502 0      \u2502 8232.02   \u2502 \u274c      \u2502\n\u2502 GET    \u2502 /invalid-endpoint                   \u2502 404    \u2502 158.03    \u2502 \u274c      \u2502\n\u2502 DELETE \u2502 /health                             \u2502 404    \u2502 155.14    \u2502 \u274c      \u2502\n\u2502 GET    \u2502 /health                             \u2502 200    \u2502 181.41    \u2502 \u2705      \u2502\n\u2502 GET    \u2502 /director                           \u2502 200    \u2502 5557.78   \u2502 \u2705      \u2502\n\u2502 GET    \u2502 /health                             \u2502 200    \u2502 195.22    \u2502 \u2705      \u2502\n\u2502 GET    \u2502 /health                             \u2502 200    \u2502 1835.04   \u2502 \u2705      \u2502\n\u2502 GET    \u2502 /health                             \u2502 200    \u2502 1841.57   \u2502 \u2705      \u2502\n\u2502 GET    \u2502 /health                             \u2502 200    \u2502 1858.53   \u2502 \u2705      \u2502\n\u2502 GET    \u2502 /health                             \u2502 200    \u2502 1890.46   \u2502 \u2705      \u2502\n\u2502 GET    \u2502 /health                             \u2502 200    \u2502 183.63    \u2502 \u2705      \u2502\n\u2502 GET    \u2502 /health                             \u2502 200    \u2502 188.03    \u2502 \u2705      \u2502\n\u2502 GET    \u2502 /health                             \u2502 200    \u2502 190.26    \u2502 \u2705      \u2502\n\u2502 GET    \u2502 /health                             \u2502 200    \u2502 189.51    \u2502 \u2705      \u2502\n\u2502 GET    \u2502 /health                             \u2502 200    \u2502 186.72    \u2502 \u2705      \u2502\n\u2502 GET    \u2502 /health                             \u2502 200    \u2502 180.63    \u2502 \u2705      \u2502\n\u2502 GET    \u2502 /health                             \u2502 200    \u2502 179.98    \u2502 \u2705      \u2502\n\u2502 GET    \u2502 /health                             \u2502 200    \u2502 180.04    \u2502 \u2705      \u2502\n\u2502 GET    \u2502 /health                             \u2502 200    \u2502 177.69    \u2502 \u2705      \u2502\n\u2502 GET    \u2502 /health                             \u2502 200    \u2502 183.17    \u2502 \u2705      \u2502\n\u2502 GET    \u2502 /health                             \u2502 200    \u2502 195.19    \u2502 \u2705      \u2502\n\u2502 GET    \u2502 /health                             \u2502 200    \u2502 190.03    \u2502 \u2705      \u2502\n\u2502 GET    \u2502 /health                             \u2502 200    \u2502 179.09    \u2502 \u2705      \u2502\n\u2502 GET    \u2502 /health                             \u2502 200    \u2502 186.27    \u2502 \u2705      \u2502\n\u2502 GET    \u2502 /health                             \u2502 200    \u2502 175.74    \u2502 \u2705      \u2502\n\u2502 GET    \u2502 /health                             \u2502 200    \u2502 175.0     \u2502 \u2705      \u2502\n\u2502 GET    \u2502 /health                             \u2502 200    \u2502 184.04    \u2502 \u2705      \u2502\n\u2502 GET    \u2502 /health                             \u2502 200    \u2502 175.95    \u2502 \u2705      \u2502\n\u2502 GET    \u2502 /health                             \u2502 200    \u2502 203.33    \u2502 \u2705      \u2502\n\u2502 GET    \u2502 /health                             \u2502 200    \u2502 268.58    \u2502 \u2705      \u2502\n\u2502 POST   \u2502 /persona                            \u2502 0      \u2502 8135.9    \u2502 \u274c      \u2502\n\u2502 GET    \u2502 /health                             \u2502 200    \u2502 182.65    \u2502 \u2705      \u2502\n\u2502 GET    \u2502 /health                             \u2502 200    \u2502 208.26    \u2502 \u2705      \u2502\n\u2502 GET    \u2502 /health                             \u2502 200    \u2502 182.07    \u2502 \u2705      \u2502\n\u2502 GET    \u2502 /health                             \u2502 200    \u2502 192.09    \u2502 \u2705      \u2502\n\u2502 GET    \u2502 /health                             \u2502 200    \u2502 180.92    \u2502 \u2705      \u2502\n\u2502 GET    \u2502 /health                             \u2502 200    \u2502 190.92    \u2502 \u2705      \u2502\n\u2502 GET    \u2502 /health                             \u2502 200    \u2502 185.02    \u2502 \u2705      \u2502\n\u2502 GET    \u2502 /health                             \u2502 200    \u2502 180.53    \u2502 \u2705      \u2502\n\u2502 GET    \u2502 /health                             \u2502 200    \u2502 178.45    \u2502 \u2705      \u2502\n\u2502 GET    \u2502 /health                             \u2502 200    \u2502 181.61    \u2502 \u2705      \u2502\n\u2502 POST   \u2502 /persona                            \u2502 0      \u2502 8042.99   \u2502 \u274c      \u2502\n\u2502 POST   \u2502 /persona                            \u2502 0      \u2502 8069.75   \u2502 \u274c      \u2502\n\u2502 POST   \u2502 /persona                            \u2502 0      \u2502 8070.77   \u2502 \u274c      \u2502\n\u2502 GET    \u2502 /coordinator/missions/xxxxxxxxxxxx\u2026 \u2502 0      \u2502 8402.84   \u2502 \u274c      \u2502\n\u2514\u2500\u2500\u2500\u2500\u2500\u2500\u2500\u2500\u2534\u2500\u2500\u2500\u2500\u2500\u2500\u2500\u2500\u2500\u2500\u2500\u2500\u2500\u2500\u2500\u2500\u2500\u2500\u2500\u2500\u2500\u2500\u2500\u2500\u2500\u2500\u2500\u2500\u2500\u2500\u2500\u2500\u2500\u2500\u2500\u2500\u2500\u2534\u2500\u2500\u2500\u2500\u2500\u2500\u2500\u2500\u2534\u2500\u2500\u2500\u2500\u2500\u2500\u2500\u2500\u2500\u2500\u2500\u2534\u2500\u2500\u2500\u2500\u2500\u2500\u2500\u2500\u2500\u2518\n\u250c\u2500\u2500\u2500\u2500\u2500\u2500\u2500\u2500\u2500\u2500\u2500\u2500\u2500\u2500\u2500\u2500\u2500\u2500\u2500\u2500\u2500\u2500\u2500\u2500\u2500\u2500\u2500\u2500 Performance Metrics \u2500\u2500\u2500\u2500\u2500\u2500\u2500\u2500\u2500\u2500\u2500\u2500\u2500\u2500\u2500\u2500\u2500\u2500\u2500\u2500\u2500\u2500\u2500\u2500\u2500\u2500\u2500\u2500\u2510\n\u2502 \ud83d\udcc8 Avg: 905.84ms | \u26a1 Min: 175.00ms | \ud83d\udc0c Max: 6585.56ms                     \u2502\n\u2514\u2500\u2500\u2500\u2500\u2500\u2500\u2500\u2500\u2500\u2500\u2500\u2500\u2500\u2500\u2500\u2500\u2500\u2500\u2500\u2500\u2500\u2500\u2500\u2500\u2500\u2500\u2500\u2500\u2500\u2500\u2500\u2500\u2500\u2500\u2500\u2500\u2500\u2500\u2500\u2500\u2500\u2500\u2500\u2500\u2500\u2500\u2500\u2500\u2500\u2500\u2500\u2500\u2500\u2500\u2500\u2500\u2500\u2500\u2500\u2500\u2500\u2500\u2500\u2500\u2500\u2500\u2500\u2500\u2500\u2500\u2500\u2500\u2500\u2500\u2500\u2500\u2500\u2518\n\ud83d\udcbe Results exported to: api-test-results-20250809-184013.json\n"}}], "warnings": [{"message": "Unknown pytest.mark.slow - is this a typo?  You can register custom marks to avoid this warning - for details, see https://docs.pytest.org/en/stable/how-to/mark.html", "category": "PytestUnknownMarkWarning", "when": "collect", "filename": "c:\\Projects\\building-os-platform\\tests\\api\\test_performance.py", "lineno": 73}, {"message": "Unknown pytest.mark.slow - is this a typo?  You can register custom marks to avoid this warning - for details, see https://docs.pytest.org/en/stable/how-to/mark.html", "category": "PytestUnknownMarkWarning", "when": "collect", "filename": "c:\\Projects\\building-os-platform\\tests\\api\\test_performance.py", "lineno": 245}, {"message": "Unknown pytest.mark.load - is this a typo?  You can register custom marks to avoid this warning - for details, see https://docs.pytest.org/en/stable/how-to/mark.html", "category": "PytestUnknownMarkWarning", "when": "collect", "filename": "c:\\Projects\\building-os-platform\\tests\\api\\test_performance.py", "lineno": 246}]}