{"created": 1754783059.9971948, "duration": 435.35415053367615, "exitcode": 2, "root": "C:\\Projects\\building-os-platform\\tests\\api", "environment": {}, "summary": {"passed": 6, "failed": 4, "total": 10, "collected": 33}, "collectors": [{"nodeid": "", "outcome": "passed", "result": [{"nodeid": "__init__.py", "type": "Package"}]}, {"nodeid": "test_endpoints.py::TestPayloads", "outcome": "passed", "result": []}, {"nodeid": "test_endpoints.py::TestHealthEndpoint", "outcome": "passed", "result": [{"nodeid": "test_endpoints.py::TestHealthEndpoint::test_health_check_success", "type": "Function", "lineno": 14}, {"nodeid": "test_endpoints.py::TestHealthEndpoint::test_health_check_performance", "type": "Function", "lineno": 23}]}, {"nodeid": "test_endpoints.py::TestDirectorEndpoint", "outcome": "passed", "result": [{"nodeid": "test_endpoints.py::TestDirectorEndpoint::test_director_basic_request", "type": "Function", "lineno": 37}, {"nodeid": "test_endpoints.py::TestDirectorEndpoint::test_director_with_user_request", "type": "Function", "lineno": 46}, {"nodeid": "test_endpoints.py::TestDirectorEndpoint::test_director_with_user_id", "type": "Function", "lineno": 56}]}, {"nodeid": "test_endpoints.py::TestPersonaEndpoint", "outcome": "passed", "result": [{"nodeid": "test_endpoints.py::TestPersonaEndpoint::test_persona_valid_message", "type": "Function", "lineno": 68}, {"nodeid": "test_endpoints.py::TestPersonaEndpoint::test_persona_missing_user_id", "type": "Function", "lineno": 81}, {"nodeid": "test_endpoints.py::TestPersonaEndpoint::test_persona_missing_message", "type": "Function", "lineno": 89}, {"nodeid": "test_endpoints.py::TestPersonaEndpoint::test_persona_conversations", "type": "Function", "lineno": 97}]}, {"nodeid": "test_endpoints.py::TestElevatorEndpoint", "outcome": "passed", "result": [{"nodeid": "test_endpoints.py::TestElevatorEndpoint::test_elevator_call_basic", "type": "Function", "lineno": 109}, {"nodeid": "test_endpoints.py::TestElevatorEndpoint::test_elevator_missing_mission_id", "type": "Function", "lineno": 120}]}, {"nodeid": "test_endpoints.py::TestPSIMEndpoint", "outcome": "passed", "result": [{"nodeid": "test_endpoints.py::TestPSIMEndpoint::test_psim_search_basic", "type": "Function", "lineno": 132}, {"nodeid": "test_endpoints.py::TestPSIMEndpoint::test_psim_search_with_custom_query", "type": "Function", "lineno": 142}]}, {"nodeid": "test_endpoints.py::TestCoordinatorEndpoint", "outcome": "passed", "result": [{"nodeid": "test_endpoints.py::TestCoordinatorEndpoint::test_coordinator_mission_status", "type": "Function", "lineno": 155}, {"nodeid": "test_endpoints.py::TestCoordinatorEndpoint::test_coordinator_different_mission_id", "type": "Function", "lineno": 166}]}, {"nodeid": "test_endpoints.py::TestCORSHeaders", "outcome": "passed", "result": [{"nodeid": "test_endpoints.py::TestCORSHeaders::test_cors_headers_present[/health]", "type": "Function", "lineno": 178}, {"nodeid": "test_endpoints.py::TestCORSHeaders::test_cors_headers_present[/director]", "type": "Function", "lineno": 178}, {"nodeid": "test_endpoints.py::TestCORSHeaders::test_cors_headers_present[/persona]", "type": "Function", "lineno": 178}, {"nodeid": "test_endpoints.py::TestCORSHeaders::test_cors_headers_present[/elevator/call]", "type": "Function", "lineno": 178}, {"nodeid": "test_endpoints.py::TestCORSHeaders::test_cors_headers_present[/psim/search]", "type": "Function", "lineno": 178}, {"nodeid": "test_endpoints.py::TestCORSHeaders::test_cors_headers_present[/coordinator/missions/test-123]", "type": "Function", "lineno": 178}]}, {"nodeid": "test_endpoints.py::TestErrorHandling", "outcome": "passed", "result": [{"nodeid": "test_endpoints.py::TestErrorHandling::test_invalid_endpoint", "type": "Function", "lineno": 220}, {"nodeid": "test_endpoints.py::TestErrorHandling::test_invalid_method", "type": "Function", "lineno": 225}, {"nodeid": "test_endpoints.py::TestErrorHandling::test_malformed_json", "type": "Function", "lineno": 235}]}, {"nodeid": "test_endpoints.py", "outcome": "passed", "result": [{"nodeid": "test_endpoints.py::TestPayloads", "type": "Class"}, {"nodeid": "test_endpoints.py::TestHealthEndpoint", "type": "Class"}, {"nodeid": "test_endpoints.py::TestDirectorEndpoint", "type": "Class"}, {"nodeid": "test_endpoints.py::TestPersonaEndpoint", "type": "Class"}, {"nodeid": "test_endpoints.py::TestElevatorEndpoint", "type": "Class"}, {"nodeid": "test_endpoints.py::TestPSIMEndpoint", "type": "Class"}, {"nodeid": "test_endpoints.py::TestCoordinatorEndpoint", "type": "Class"}, {"nodeid": "test_endpoints.py::TestCORSHeaders", "type": "Class"}, {"nodeid": "test_endpoints.py::TestErrorHandling", "type": "Class"}]}, {"nodeid": "test_performance.py::TestPerformance", "outcome": "passed", "result": [{"nodeid": "test_performance.py::TestPerformance::test_response_time_under_threshold", "type": "Function", "lineno": 18}, {"nodeid": "test_performance.py::TestPerformance::test_concurrent_health_checks", "type": "Function", "lineno": 45}]}, {"nodeid": "test_performance.py::TestLoadTesting", "outcome": "passed", "result": [{"nodeid": "test_performance.py::TestLoadTesting::test_sustained_load_health_endpoint", "type": "Function", "lineno": 72}]}, {"nodeid": "test_performance.py::TestStressScenarios", "outcome": "passed", "result": [{"nodeid": "test_performance.py::TestStressScenarios::test_large_payload_persona", "type": "Function", "lineno": 149}, {"nodeid": "test_performance.py::TestStressScenarios::test_rapid_successive_requests", "type": "Function", "lineno": 163}, {"nodeid": "test_performance.py::TestStressScenarios::test_special_characters_in_requests", "type": "Function", "lineno": 189}]}, {"nodeid": "test_performance.py::TestBoundaryConditions", "outcome": "passed", "result": [{"nodeid": "test_performance.py::TestBoundaryConditions::test_empty_payloads", "type": "Function", "lineno": 213}, {"nodeid": "test_performance.py::TestBoundaryConditions::test_null_values_in_payload", "type": "Function", "lineno": 224}, {"nodeid": "test_performance.py::TestBoundaryConditions::test_extremely_long_mission_id", "type": "Function", "lineno": 233}]}, {"nodeid": "test_performance.py", "outcome": "passed", "result": [{"nodeid": "test_performance.py::TestPerformance", "type": "Class"}, {"nodeid": "test_performance.py::TestLoadTesting", "type": "Class"}, {"nodeid": "test_performance.py::TestStressScenarios", "type": "Class"}, {"nodeid": "test_performance.py::TestBoundaryConditions", "type": "Class"}]}, {"nodeid": "__init__.py", "outcome": "passed", "result": [{"nodeid": "test_endpoints.py", "type": "Module"}, {"nodeid": "test_performance.py", "type": "Module"}]}], "tests": [{"nodeid": "test_endpoints.py::TestHealthEndpoint::test_health_check_success", "lineno": 14, "outcome": "passed", "keywords": ["test_health_check_success", "TestHealthEndpoint", "test_endpoints.py", "__init__.py", "api"], "setup": {"duration": 0.008933299999625888, "outcome": "passed", "stdout": "\n\ud83e\uddea Starting BuildingOS API Test Suite\n\ud83c\udf10 Base URL: https://pj4vlvxrg7.execute-api.us-east-1.amazonaws.com/dev\n\ud83c\udff7\ufe0f  Environment: dev\n"}, "call": {"duration": 2.1005475999991177, "outcome": "passed", "stdout": "\n\ud83d\ude80 GET /health\n\ud83d\udcca Status: 200 | \u23f1\ufe0f  Time: 2098.07ms | \ud83d\udce6 Size: 60 bytes\n"}, "teardown": {"duration": 0.0011269999959040433, "outcome": "passed", "stdout": "\n"}}, {"nodeid": "test_endpoints.py::TestHealthEndpoint::test_health_check_performance", "lineno": 23, "outcome": "passed", "keywords": ["test_health_check_performance", "TestHealthEndpoint", "test_endpoints.py", "__init__.py", "api"], "setup": {"duration": 0.000600200000917539, "outcome": "passed"}, "call": {"duration": 0.21004959999845596, "outcome": "passed", "stdout": "\n\ud83d\ude80 GET /health\n\ud83d\udcca Status: 200 | \u23f1\ufe0f  Time: 207.77ms | \ud83d\udce6 Size: 60 bytes\n"}, "teardown": {"duration": 0.0009052000023075379, "outcome": "passed", "stdout": "\n"}}, {"nodeid": "test_endpoints.py::TestDirectorEndpoint::test_director_basic_request", "lineno": 37, "outcome": "failed", "keywords": ["test_director_basic_request", "TestDirectorEndpoint", "test_endpoints.py", "__init__.py", "api"], "setup": {"duration": 0.0005831999951624312, "outcome": "passed"}, "call": {"duration": 128.99216909999814, "outcome": "failed", "crash": {"path": "C:\\Projects\\building-os-platform\\.venv\\Lib\\site-packages\\requests\\adapters.py", "lineno": 519, "message": "requests.exceptions.ConnectionError: HTTPSConnectionPool(host='pj4vlvxrg7.execute-api.us-east-1.amazonaws.com', port=443): Max retries exceeded with url: /dev/director (Caused by ReadTimeoutError(\"HTTPSConnectionPool(host='pj4vlvxrg7.execute-api.us-east-1.amazonaws.com', port=443): Read timed out. (read timeout=30)\"))"}, "stdout": "\n\ud83d\ude80 GET /director\n\u274c Request failed: \nHTTPSConnectionPool(host='pj4vlvxrg7.execute-api.us-east-1.amazonaws.com', \nport=443): Max retries exceeded with url: /dev/director (Caused by \nReadTimeoutError(\"HTTPSConnectionPool(host='pj4vlvxrg7.execute-api.us-east-1.am\nazonaws.com', port=443): Read timed out. (read timeout=30)\"))\n", "log": [{"name": "urllib3.connectionpool", "msg": "Retrying (Retry(total=2, connect=None, read=None, redirect=None, status=None)) after connection broken by 'ReadTimeoutError(\"HTTPSConnectionPool(host='pj4vlvxrg7.execute-api.us-east-1.amazonaws.com', port=443): Read timed out. (read timeout=30)\")': /dev/director", "args": null, "levelname": "WARNING", "levelno": 30, "pathname": "C:\\Projects\\building-os-platform\\.venv\\Lib\\site-packages\\urllib3\\connectionpool.py", "filename": "connectionpool.py", "module": "connectionpool", "exc_info": null, "exc_text": null, "stack_info": null, "lineno": 868, "funcName": "urlopen", "created": 1754782657.8162487, "msecs": 816.0, "relativeCreated": 33613.3919, "thread": 9616, "threadName": "MainThread", "processName": "MainProcess", "process": 3896, "taskName": null}, {"name": "urllib3.connectionpool", "msg": "Retrying (Retry(total=1, connect=None, read=None, redirect=None, status=None)) after connection broken by 'ReadTimeoutError(\"HTTPSConnectionPool(host='pj4vlvxrg7.execute-api.us-east-1.amazonaws.com', port=443): Read timed out. (read timeout=30)\")': /dev/director", "args": null, "levelname": "WARNING", "levelno": 30, "pathname": "C:\\Projects\\building-os-platform\\.venv\\Lib\\site-packages\\urllib3\\connectionpool.py", "filename": "connectionpool.py", "module": "connectionpool", "exc_info": null, "exc_text": null, "stack_info": null, "lineno": 868, "funcName": "urlopen", "created": 1754782690.7600687, "msecs": 760.0, "relativeCreated": 66557.2119, "thread": 9616, "threadName": "MainThread", "processName": "MainProcess", "process": 3896, "taskName": null}, {"name": "urllib3.connectionpool", "msg": "Retrying (Retry(total=0, connect=None, read=None, redirect=None, status=None)) after connection broken by 'ReadTimeoutError(\"HTTPSConnectionPool(host='pj4vlvxrg7.execute-api.us-east-1.amazonaws.com', port=443): Read timed out. (read timeout=30)\")': /dev/director", "args": null, "levelname": "WARNING", "levelno": 30, "pathname": "C:\\Projects\\building-os-platform\\.venv\\Lib\\site-packages\\urllib3\\connectionpool.py", "filename": "connectionpool.py", "module": "connectionpool", "exc_info": null, "exc_text": null, "stack_info": null, "lineno": 868, "funcName": "urlopen", "created": 1754782725.8173823, "msecs": 817.0, "relativeCreated": 101614.5256, "thread": 9616, "threadName": "MainThread", "processName": "MainProcess", "process": 3896, "taskName": null}], "longrepr": "E   TimeoutError: The read operation timed out\n\nThe above exception was the direct cause of the following exception:\nE   urllib3.exceptions.ReadTimeoutError: HTTPSConnectionPool(host='pj4vlvxrg7.execute-api.us-east-1.amazonaws.com', port=443): Read timed out. (read timeout=30)\n\nThe above exception was the direct cause of the following exception:\nE   urllib3.exceptions.MaxRetryError: HTTPSConnectionPool(host='pj4vlvxrg7.execute-api.us-east-1.amazonaws.com', port=443): Max retries exceeded with url: /dev/director (Caused by ReadTimeoutError(\"HTTPSConnectionPool(host='pj4vlvxrg7.execute-api.us-east-1.amazonaws.com', port=443): Read timed out. (read timeout=30)\"))\n\nDuring handling of the above exception, another exception occurred:\nE   requests.exceptions.ConnectionError: HTTPSConnectionPool(host='pj4vlvxrg7.execute-api.us-east-1.amazonaws.com', port=443): Max retries exceeded with url: /dev/director (Caused by ReadTimeoutError(\"HTTPSConnectionPool(host='pj4vlvxrg7.execute-api.us-east-1.amazonaws.com', port=443): Read timed out. (read timeout=30)\"))"}, "teardown": {"duration": 0.0010118999998667277, "outcome": "passed", "stdout": "\n"}}, {"nodeid": "test_endpoints.py::TestDirectorEndpoint::test_director_with_user_request", "lineno": 46, "outcome": "failed", "keywords": ["test_director_with_user_request", "TestDirectorEndpoint", "test_endpoints.py", "__init__.py", "api"], "setup": {"duration": 0.0005534000010811724, "outcome": "passed"}, "call": {"duration": 130.00519910000003, "outcome": "failed", "crash": {"path": "C:\\Projects\\building-os-platform\\.venv\\Lib\\site-packages\\requests\\adapters.py", "lineno": 519, "message": "requests.exceptions.ConnectionError: HTTPSConnectionPool(host='pj4vlvxrg7.execute-api.us-east-1.amazonaws.com', port=443): Max retries exceeded with url: /dev/director?user_request=Test%20mission%20from%20Python%20API%20tests (Caused by ReadTimeoutError(\"HTTPSConnectionPool(host='pj4vlvxrg7.execute-api.us-east-1.amazonaws.com', port=443): Read timed out. (read timeout=30)\"))"}, "stdout": "\n\ud83d\ude80 GET /director?user_request=Test mission from Python API tests\n\u274c Request failed: \nHTTPSConnectionPool(host='pj4vlvxrg7.execute-api.us-east-1.amazonaws.com', \nport=443): Max retries exceeded with url: \n/dev/director?user_request=Test%20mission%20from%20Python%20API%20tests (Caused\nby \nReadTimeoutError(\"HTTPSConnectionPool(host='pj4vlvxrg7.execute-api.us-east-1.am\nazonaws.com', port=443): Read timed out. (read timeout=30)\"))\n", "log": [{"name": "urllib3.connectionpool", "msg": "Retrying (Retry(total=2, connect=None, read=None, redirect=None, status=None)) after connection broken by 'ReadTimeoutError(\"HTTPSConnectionPool(host='pj4vlvxrg7.execute-api.us-east-1.amazonaws.com', port=443): Read timed out. (read timeout=30)\")': /dev/director?user_request=Test%20mission%20from%20Python%20API%20tests", "args": null, "levelname": "WARNING", "levelno": 30, "pathname": "C:\\Projects\\building-os-platform\\.venv\\Lib\\site-packages\\urllib3\\connectionpool.py", "filename": "connectionpool.py", "module": "connectionpool", "exc_info": null, "exc_text": null, "stack_info": null, "lineno": 868, "funcName": "urlopen", "created": 1754782787.8228235, "msecs": 822.0, "relativeCreated": 163619.9668, "thread": 9616, "threadName": "MainThread", "processName": "MainProcess", "process": 3896, "taskName": null}, {"name": "urllib3.connectionpool", "msg": "Retrying (Retry(total=1, connect=None, read=None, redirect=None, status=None)) after connection broken by 'ReadTimeoutError(\"HTTPSConnectionPool(host='pj4vlvxrg7.execute-api.us-east-1.amazonaws.com', port=443): Read timed out. (read timeout=30)\")': /dev/director?user_request=Test%20mission%20from%20Python%20API%20tests", "args": null, "levelname": "WARNING", "levelno": 30, "pathname": "C:\\Projects\\building-os-platform\\.venv\\Lib\\site-packages\\urllib3\\connectionpool.py", "filename": "connectionpool.py", "module": "connectionpool", "exc_info": null, "exc_text": null, "stack_info": null, "lineno": 868, "funcName": "urlopen", "created": 1754782820.7559078, "msecs": 755.0, "relativeCreated": 196553.0511, "thread": 9616, "threadName": "MainThread", "processName": "MainProcess", "process": 3896, "taskName": null}, {"name": "urllib3.connectionpool", "msg": "Retrying (Retry(total=0, connect=None, read=None, redirect=None, status=None)) after connection broken by 'ReadTimeoutError(\"HTTPSConnectionPool(host='pj4vlvxrg7.execute-api.us-east-1.amazonaws.com', port=443): Read timed out. (read timeout=30)\")': /dev/director?user_request=Test%20mission%20from%20Python%20API%20tests", "args": null, "levelname": "WARNING", "levelno": 30, "pathname": "C:\\Projects\\building-os-platform\\.venv\\Lib\\site-packages\\urllib3\\connectionpool.py", "filename": "connectionpool.py", "module": "connectionpool", "exc_info": null, "exc_text": null, "stack_info": null, "lineno": 868, "funcName": "urlopen", "created": 1754782855.80208, "msecs": 802.0, "relativeCreated": 231599.2234, "thread": 9616, "threadName": "MainThread", "processName": "MainProcess", "process": 3896, "taskName": null}], "longrepr": "E   TimeoutError: The read operation timed out\n\nThe above exception was the direct cause of the following exception:\nE   urllib3.exceptions.ReadTimeoutError: HTTPSConnectionPool(host='pj4vlvxrg7.execute-api.us-east-1.amazonaws.com', port=443): Read timed out. (read timeout=30)\n\nThe above exception was the direct cause of the following exception:\nE   urllib3.exceptions.MaxRetryError: HTTPSConnectionPool(host='pj4vlvxrg7.execute-api.us-east-1.amazonaws.com', port=443): Max retries exceeded with url: /dev/director?user_request=Test%20mission%20from%20Python%20API%20tests (Caused by ReadTimeoutError(\"HTTPSConnectionPool(host='pj4vlvxrg7.execute-api.us-east-1.amazonaws.com', port=443): Read timed out. (read timeout=30)\"))\n\nDuring handling of the above exception, another exception occurred:\nE   requests.exceptions.ConnectionError: HTTPSConnectionPool(host='pj4vlvxrg7.execute-api.us-east-1.amazonaws.com', port=443): Max retries exceeded with url: /dev/director?user_request=Test%20mission%20from%20Python%20API%20tests (Caused by ReadTimeoutError(\"HTTPSConnectionPool(host='pj4vlvxrg7.execute-api.us-east-1.amazonaws.com', port=443): Read timed out. (read timeout=30)\"))"}, "teardown": {"duration": 0.0012713000032817945, "outcome": "passed", "stdout": "\n"}}, {"nodeid": "test_endpoints.py::TestDirectorEndpoint::test_director_with_user_id", "lineno": 56, "outcome": "failed", "keywords": ["test_director_with_user_id", "TestDirectorEndpoint", "test_endpoints.py", "__init__.py", "api"], "setup": {"duration": 0.0006931000025360845, "outcome": "passed"}, "call": {"duration": 132.95650419999583, "outcome": "failed", "crash": {"path": "C:\\Projects\\building-os-platform\\.venv\\Lib\\site-packages\\requests\\adapters.py", "lineno": 519, "message": "requests.exceptions.ConnectionError: HTTPSConnectionPool(host='pj4vlvxrg7.execute-api.us-east-1.amazonaws.com', port=443): Max retries exceeded with url: /dev/director?user_id=api-test-user (Caused by ReadTimeoutError(\"HTTPSConnectionPool(host='pj4vlvxrg7.execute-api.us-east-1.amazonaws.com', port=443): Read timed out. (read timeout=30)\"))"}, "stdout": "\n\ud83d\ude80 GET /director?user_id=api-test-user\n\u274c Request failed: \nHTTPSConnectionPool(host='pj4vlvxrg7.execute-api.us-east-1.amazonaws.com', \nport=443): Max retries exceeded with url: /dev/director?user_id=api-test-user \n(Caused by \nReadTimeoutError(\"HTTPSConnectionPool(host='pj4vlvxrg7.execute-api.us-east-1.am\nazonaws.com', port=443): Read timed out. (read timeout=30)\"))\n", "log": [{"name": "urllib3.connectionpool", "msg": "Retrying (Retry(total=2, connect=None, read=None, redirect=None, status=None)) after connection broken by 'ReadTimeoutError(\"HTTPSConnectionPool(host='pj4vlvxrg7.execute-api.us-east-1.amazonaws.com', port=443): Read timed out. (read timeout=30)\")': /dev/director?user_id=api-test-user", "args": null, "levelname": "WARNING", "levelno": 30, "pathname": "C:\\Projects\\building-os-platform\\.venv\\Lib\\site-packages\\urllib3\\connectionpool.py", "filename": "connectionpool.py", "module": "connectionpool", "exc_info": null, "exc_text": null, "stack_info": null, "lineno": 868, "funcName": "urlopen", "created": 1754782918.840902, "msecs": 840.0, "relativeCreated": 294638.0454, "thread": 9616, "threadName": "MainThread", "processName": "MainProcess", "process": 3896, "taskName": null}, {"name": "urllib3.connectionpool", "msg": "Retrying (Retry(total=1, connect=None, read=None, redirect=None, status=None)) after connection broken by 'ReadTimeoutError(\"HTTPSConnectionPool(host='pj4vlvxrg7.execute-api.us-east-1.amazonaws.com', port=443): Read timed out. (read timeout=30)\")': /dev/director?user_id=api-test-user", "args": null, "levelname": "WARNING", "levelno": 30, "pathname": "C:\\Projects\\building-os-platform\\.venv\\Lib\\site-packages\\urllib3\\connectionpool.py", "filename": "connectionpool.py", "module": "connectionpool", "exc_info": null, "exc_text": null, "stack_info": null, "lineno": 868, "funcName": "urlopen", "created": 1754782951.7702231, "msecs": 770.0, "relativeCreated": 327567.3663, "thread": 9616, "threadName": "MainThread", "processName": "MainProcess", "process": 3896, "taskName": null}, {"name": "urllib3.connectionpool", "msg": "Retrying (Retry(total=0, connect=None, read=None, redirect=None, status=None)) after connection broken by 'ReadTimeoutError(\"HTTPSConnectionPool(host='pj4vlvxrg7.execute-api.us-east-1.amazonaws.com', port=443): Read timed out. (read timeout=30)\")': /dev/director?user_id=api-test-user", "args": null, "levelname": "WARNING", "levelno": 30, "pathname": "C:\\Projects\\building-os-platform\\.venv\\Lib\\site-packages\\urllib3\\connectionpool.py", "filename": "connectionpool.py", "module": "connectionpool", "exc_info": null, "exc_text": null, "stack_info": null, "lineno": 868, "funcName": "urlopen", "created": 1754782986.7282674, "msecs": 728.0, "relativeCreated": 362525.4108, "thread": 9616, "threadName": "MainThread", "processName": "MainProcess", "process": 3896, "taskName": null}], "longrepr": "E   TimeoutError: The read operation timed out\n\nThe above exception was the direct cause of the following exception:\nE   urllib3.exceptions.ReadTimeoutError: HTTPSConnectionPool(host='pj4vlvxrg7.execute-api.us-east-1.amazonaws.com', port=443): Read timed out. (read timeout=30)\n\nThe above exception was the direct cause of the following exception:\nE   urllib3.exceptions.MaxRetryError: HTTPSConnectionPool(host='pj4vlvxrg7.execute-api.us-east-1.amazonaws.com', port=443): Max retries exceeded with url: /dev/director?user_id=api-test-user (Caused by ReadTimeoutError(\"HTTPSConnectionPool(host='pj4vlvxrg7.execute-api.us-east-1.amazonaws.com', port=443): Read timed out. (read timeout=30)\"))\n\nDuring handling of the above exception, another exception occurred:\nE   requests.exceptions.ConnectionError: HTTPSConnectionPool(host='pj4vlvxrg7.execute-api.us-east-1.amazonaws.com', port=443): Max retries exceeded with url: /dev/director?user_id=api-test-user (Caused by ReadTimeoutError(\"HTTPSConnectionPool(host='pj4vlvxrg7.execute-api.us-east-1.amazonaws.com', port=443): Read timed out. (read timeout=30)\"))"}, "teardown": {"duration": 0.0009805000008782372, "outcome": "passed", "stdout": "\n"}}, {"nodeid": "test_endpoints.py::TestPersonaEndpoint::test_persona_valid_message", "lineno": 68, "outcome": "failed", "keywords": ["test_persona_valid_message", "TestPersonaEndpoint", "test_endpoints.py", "__init__.py", "api"], "setup": {"duration": 0.0006002999944030307, "outcome": "passed"}, "call": {"duration": 8.666361100003996, "outcome": "failed", "crash": {"path": "C:\\Projects\\building-os-platform\\.venv\\Lib\\site-packages\\requests\\adapters.py", "lineno": 510, "message": "requests.exceptions.RetryError: HTTPSConnectionPool(host='pj4vlvxrg7.execute-api.us-east-1.amazonaws.com', port=443): Max retries exceeded with url: /dev/persona (Caused by ResponseError('too many 500 error responses'))"}, "stdout": "\n\ud83d\ude80 POST /persona\n\u274c Request failed: \nHTTPSConnectionPool(host='pj4vlvxrg7.execute-api.us-east-1.amazonaws.com', \nport=443): Max retries exceeded with url: /dev/persona (Caused by \nResponseError('too many 500 error responses'))\n", "longrepr": "urllib3.exceptions.ResponseError: too many 500 error responses\n\nThe above exception was the direct cause of the following exception:\nE   urllib3.exceptions.MaxRetryError: HTTPSConnectionPool(host='pj4vlvxrg7.execute-api.us-east-1.amazonaws.com', port=443): Max retries exceeded with url: /dev/persona (Caused by ResponseError('too many 500 error responses'))\n\nDuring handling of the above exception, another exception occurred:\nE   requests.exceptions.RetryError: HTTPSConnectionPool(host='pj4vlvxrg7.execute-api.us-east-1.amazonaws.com', port=443): Max retries exceeded with url: /dev/persona (Caused by ResponseError('too many 500 error responses'))"}, "teardown": {"duration": 0.0008945000008679926, "outcome": "passed", "stdout": "\n"}}, {"nodeid": "test_endpoints.py::TestPersonaEndpoint::test_persona_missing_user_id", "lineno": 81, "outcome": "passed", "keywords": ["test_persona_missing_user_id", "TestPersonaEndpoint", "test_endpoints.py", "__init__.py", "api"], "setup": {"duration": 0.0007078999988152646, "outcome": "passed"}, "call": {"duration": 0.19801169999846024, "outcome": "passed", "stdout": "\n\ud83d\ude80 POST /persona\n\ud83d\udcca Status: 400 | \u23f1\ufe0f  Time: 195.39ms | \ud83d\udce6 Size: 45 bytes\n"}, "teardown": {"duration": 0.0008134000017889775, "outcome": "passed", "stdout": "\n"}}, {"nodeid": "test_endpoints.py::TestPersonaEndpoint::test_persona_missing_message", "lineno": 89, "outcome": "passed", "keywords": ["test_persona_missing_message", "TestPersonaEndpoint", "test_endpoints.py", "__init__.py", "api"], "setup": {"duration": 0.000573899997107219, "outcome": "passed"}, "call": {"duration": 0.18954669999948237, "outcome": "passed", "stdout": "\n\ud83d\ude80 POST /persona\n\ud83d\udcca Status: 400 | \u23f1\ufe0f  Time: 187.14ms | \ud83d\udce6 Size: 45 bytes\n"}, "teardown": {"duration": 0.000883699998666998, "outcome": "passed", "stdout": "\n"}}, {"nodeid": "test_endpoints.py::TestPersonaEndpoint::test_persona_conversations", "lineno": 97, "outcome": "passed", "keywords": ["test_persona_conversations", "TestPersonaEndpoint", "test_endpoints.py", "__init__.py", "api"], "setup": {"duration": 0.0005384999967645854, "outcome": "passed"}, "call": {"duration": 0.22663319999992382, "outcome": "passed", "stdout": "\n\ud83d\ude80 GET /persona/conversations?user_id=api-test-user\n\ud83d\udcca Status: 200 | \u23f1\ufe0f  Time: 224.26ms | \ud83d\udce6 Size: 64 bytes\n"}, "teardown": {"duration": 0.0009565999935148284, "outcome": "passed", "stdout": "\n"}}, {"nodeid": "test_endpoints.py::TestElevatorEndpoint::test_elevator_call_basic", "lineno": 109, "outcome": "passed", "keywords": ["test_elevator_call_basic", "TestElevatorEndpoint", "test_endpoints.py", "__init__.py", "api"], "setup": {"duration": 0.00047649999760324135, "outcome": "passed"}}], "warnings": [{"message": "Unknown pytest.mark.slow - is this a typo?  You can register custom marks to avoid this warning - for details, see https://docs.pytest.org/en/stable/how-to/mark.html", "category": "PytestUnknownMarkWarning", "when": "collect", "filename": "c:\\Projects\\building-os-platform\\tests\\api\\test_performance.py", "lineno": 73}, {"message": "Unknown pytest.mark.slow - is this a typo?  You can register custom marks to avoid this warning - for details, see https://docs.pytest.org/en/stable/how-to/mark.html", "category": "PytestUnknownMarkWarning", "when": "collect", "filename": "c:\\Projects\\building-os-platform\\tests\\api\\test_performance.py", "lineno": 245}, {"message": "Unknown pytest.mark.load - is this a typo?  You can register custom marks to avoid this warning - for details, see https://docs.pytest.org/en/stable/how-to/mark.html", "category": "PytestUnknownMarkWarning", "when": "collect", "filename": "c:\\Projects\\building-os-platform\\tests\\api\\test_performance.py", "lineno": 246}]}