{"created": 1754835904.5156977, "duration": 147.54083037376404, "exitcode": 1, "root": "C:\\Projects\\building-os-platform\\tests\\api", "environment": {}, "summary": {"passed": 16, "failed": 17, "total": 33, "collected": 33}, "collectors": [{"nodeid": "", "outcome": "passed", "result": [{"nodeid": "__init__.py", "type": "Package"}]}, {"nodeid": "test_endpoints.py::TestPayloads", "outcome": "passed", "result": []}, {"nodeid": "test_endpoints.py::TestHealthEndpoint", "outcome": "passed", "result": [{"nodeid": "test_endpoints.py::TestHealthEndpoint::test_health_check_success", "type": "Function", "lineno": 14}, {"nodeid": "test_endpoints.py::TestHealthEndpoint::test_health_check_performance", "type": "Function", "lineno": 23}]}, {"nodeid": "test_endpoints.py::TestDirectorEndpoint", "outcome": "passed", "result": [{"nodeid": "test_endpoints.py::TestDirectorEndpoint::test_director_basic_request", "type": "Function", "lineno": 37}, {"nodeid": "test_endpoints.py::TestDirectorEndpoint::test_director_with_user_request", "type": "Function", "lineno": 46}, {"nodeid": "test_endpoints.py::TestDirectorEndpoint::test_director_with_user_id", "type": "Function", "lineno": 56}]}, {"nodeid": "test_endpoints.py::TestPersonaEndpoint", "outcome": "passed", "result": [{"nodeid": "test_endpoints.py::TestPersonaEndpoint::test_persona_valid_message", "type": "Function", "lineno": 68}, {"nodeid": "test_endpoints.py::TestPersonaEndpoint::test_persona_missing_user_id", "type": "Function", "lineno": 81}, {"nodeid": "test_endpoints.py::TestPersonaEndpoint::test_persona_missing_message", "type": "Function", "lineno": 89}, {"nodeid": "test_endpoints.py::TestPersonaEndpoint::test_persona_conversations", "type": "Function", "lineno": 97}]}, {"nodeid": "test_endpoints.py::TestElevatorEndpoint", "outcome": "passed", "result": [{"nodeid": "test_endpoints.py::TestElevatorEndpoint::test_elevator_call_basic", "type": "Function", "lineno": 109}, {"nodeid": "test_endpoints.py::TestElevatorEndpoint::test_elevator_missing_mission_id", "type": "Function", "lineno": 120}]}, {"nodeid": "test_endpoints.py::TestPSIMEndpoint", "outcome": "passed", "result": [{"nodeid": "test_endpoints.py::TestPSIMEndpoint::test_psim_search_basic", "type": "Function", "lineno": 132}, {"nodeid": "test_endpoints.py::TestPSIMEndpoint::test_psim_search_with_custom_query", "type": "Function", "lineno": 142}]}, {"nodeid": "test_endpoints.py::TestCoordinatorEndpoint", "outcome": "passed", "result": [{"nodeid": "test_endpoints.py::TestCoordinatorEndpoint::test_coordinator_mission_status", "type": "Function", "lineno": 155}, {"nodeid": "test_endpoints.py::TestCoordinatorEndpoint::test_coordinator_different_mission_id", "type": "Function", "lineno": 166}]}, {"nodeid": "test_endpoints.py::TestCORSHeaders", "outcome": "passed", "result": [{"nodeid": "test_endpoints.py::TestCORSHeaders::test_cors_headers_present[/health]", "type": "Function", "lineno": 178}, {"nodeid": "test_endpoints.py::TestCORSHeaders::test_cors_headers_present[/director]", "type": "Function", "lineno": 178}, {"nodeid": "test_endpoints.py::TestCORSHeaders::test_cors_headers_present[/persona]", "type": "Function", "lineno": 178}, {"nodeid": "test_endpoints.py::TestCORSHeaders::test_cors_headers_present[/elevator/call]", "type": "Function", "lineno": 178}, {"nodeid": "test_endpoints.py::TestCORSHeaders::test_cors_headers_present[/psim/search]", "type": "Function", "lineno": 178}, {"nodeid": "test_endpoints.py::TestCORSHeaders::test_cors_headers_present[/coordinator/missions/test-123]", "type": "Function", "lineno": 178}]}, {"nodeid": "test_endpoints.py::TestErrorHandling", "outcome": "passed", "result": [{"nodeid": "test_endpoints.py::TestErrorHandling::test_invalid_endpoint", "type": "Function", "lineno": 220}, {"nodeid": "test_endpoints.py::TestErrorHandling::test_invalid_method", "type": "Function", "lineno": 225}, {"nodeid": "test_endpoints.py::TestErrorHandling::test_malformed_json", "type": "Function", "lineno": 235}]}, {"nodeid": "test_endpoints.py", "outcome": "passed", "result": [{"nodeid": "test_endpoints.py::TestPayloads", "type": "Class"}, {"nodeid": "test_endpoints.py::TestHealthEndpoint", "type": "Class"}, {"nodeid": "test_endpoints.py::TestDirectorEndpoint", "type": "Class"}, {"nodeid": "test_endpoints.py::TestPersonaEndpoint", "type": "Class"}, {"nodeid": "test_endpoints.py::TestElevatorEndpoint", "type": "Class"}, {"nodeid": "test_endpoints.py::TestPSIMEndpoint", "type": "Class"}, {"nodeid": "test_endpoints.py::TestCoordinatorEndpoint", "type": "Class"}, {"nodeid": "test_endpoints.py::TestCORSHeaders", "type": "Class"}, {"nodeid": "test_endpoints.py::TestErrorHandling", "type": "Class"}]}, {"nodeid": "test_performance.py::TestPerformance", "outcome": "passed", "result": [{"nodeid": "test_performance.py::TestPerformance::test_response_time_under_threshold", "type": "Function", "lineno": 18}, {"nodeid": "test_performance.py::TestPerformance::test_concurrent_health_checks", "type": "Function", "lineno": 45}]}, {"nodeid": "test_performance.py::TestLoadTesting", "outcome": "passed", "result": [{"nodeid": "test_performance.py::TestLoadTesting::test_sustained_load_health_endpoint", "type": "Function", "lineno": 72}]}, {"nodeid": "test_performance.py::TestStressScenarios", "outcome": "passed", "result": [{"nodeid": "test_performance.py::TestStressScenarios::test_large_payload_persona", "type": "Function", "lineno": 149}, {"nodeid": "test_performance.py::TestStressScenarios::test_rapid_successive_requests", "type": "Function", "lineno": 163}, {"nodeid": "test_performance.py::TestStressScenarios::test_special_characters_in_requests", "type": "Function", "lineno": 189}]}, {"nodeid": "test_performance.py::TestBoundaryConditions", "outcome": "passed", "result": [{"nodeid": "test_performance.py::TestBoundaryConditions::test_empty_payloads", "type": "Function", "lineno": 213}, {"nodeid": "test_performance.py::TestBoundaryConditions::test_null_values_in_payload", "type": "Function", "lineno": 224}, {"nodeid": "test_performance.py::TestBoundaryConditions::test_extremely_long_mission_id", "type": "Function", "lineno": 233}]}, {"nodeid": "test_performance.py", "outcome": "passed", "result": [{"nodeid": "test_performance.py::TestPerformance", "type": "Class"}, {"nodeid": "test_performance.py::TestLoadTesting", "type": "Class"}, {"nodeid": "test_performance.py::TestStressScenarios", "type": "Class"}, {"nodeid": "test_performance.py::TestBoundaryConditions", "type": "Class"}]}, {"nodeid": "__init__.py", "outcome": "passed", "result": [{"nodeid": "test_endpoints.py", "type": "Module"}, {"nodeid": "test_performance.py", "type": "Module"}]}], "tests": [{"nodeid": "test_endpoints.py::TestHealthEndpoint::test_health_check_success", "lineno": 14, "outcome": "passed", "keywords": ["test_health_check_success", "TestHealthEndpoint", "test_endpoints.py", "__init__.py", "api"], "setup": {"duration": 0.01212630000009085, "outcome": "passed", "stdout": "\n\ud83e\uddea Starting BuildingOS API Test Suite\n\ud83c\udf10 Base URL: https://pj4vlvxrg7.execute-api.us-east-1.amazonaws.com/dev\n\ud83c\udff7\ufe0f  Environment: dev\n"}, "call": {"duration": 3.805470300000252, "outcome": "passed", "stdout": "\n\ud83d\ude80 GET /health\n\ud83d\udcca Status: 200 | \u23f1\ufe0f  Time: 3802.82ms | \ud83d\udce6 Size: 60 bytes\n"}, "teardown": {"duration": 0.0008695000001353037, "outcome": "passed", "stdout": "\n"}}, {"nodeid": "test_endpoints.py::TestHealthEndpoint::test_health_check_performance", "lineno": 23, "outcome": "passed", "keywords": ["test_health_check_performance", "TestHealthEndpoint", "test_endpoints.py", "__init__.py", "api"], "setup": {"duration": 0.0005241999997451785, "outcome": "passed"}, "call": {"duration": 0.21130300000004354, "outcome": "passed", "stdout": "\n\ud83d\ude80 GET /health\n\ud83d\udcca Status: 200 | \u23f1\ufe0f  Time: 209.04ms | \ud83d\udce6 Size: 60 bytes\n"}, "teardown": {"duration": 0.000843799999984185, "outcome": "passed", "stdout": "\n"}}, {"nodeid": "test_endpoints.py::TestDirectorEndpoint::test_director_basic_request", "lineno": 37, "outcome": "passed", "keywords": ["test_director_basic_request", "TestDirectorEndpoint", "test_endpoints.py", "__init__.py", "api"], "setup": {"duration": 0.000561300000299525, "outcome": "passed"}, "call": {"duration": 3.7202016999999614, "outcome": "passed", "stdout": "\n\ud83d\ude80 GET /director\n\ud83d\udcca Status: 200 | \u23f1\ufe0f  Time: 3717.71ms | \ud83d\udce6 Size: 128 bytes\n"}, "teardown": {"duration": 0.0016300000002047454, "outcome": "passed", "stdout": "\n"}}, {"nodeid": "test_endpoints.py::TestDirectorEndpoint::test_director_with_user_request", "lineno": 46, "outcome": "passed", "keywords": ["test_director_with_user_request", "TestDirectorEndpoint", "test_endpoints.py", "__init__.py", "api"], "setup": {"duration": 0.0006134999998721469, "outcome": "passed"}, "call": {"duration": 7.39527790000011, "outcome": "passed", "stdout": "\n\ud83d\ude80 GET /director?user_request=Test mission from Python API tests\n\ud83d\udcca Status: 200 | \u23f1\ufe0f  Time: 7392.65ms | \ud83d\udce6 Size: 128 bytes\n"}, "teardown": {"duration": 0.0009828999995988852, "outcome": "passed", "stdout": "\n"}}, {"nodeid": "test_endpoints.py::TestDirectorEndpoint::test_director_with_user_id", "lineno": 56, "outcome": "passed", "keywords": ["test_director_with_user_id", "TestDirectorEndpoint", "test_endpoints.py", "__init__.py", "api"], "setup": {"duration": 0.0006175000003167952, "outcome": "passed"}, "call": {"duration": 3.515739200000098, "outcome": "passed", "stdout": "\n\ud83d\ude80 GET /director?user_id=api-test-user\n\ud83d\udcca Status: 200 | \u23f1\ufe0f  Time: 3513.32ms | \ud83d\udce6 Size: 128 bytes\n"}, "teardown": {"duration": 0.0011537999998836312, "outcome": "passed", "stdout": "\n"}}, {"nodeid": "test_endpoints.py::TestPersonaEndpoint::test_persona_valid_message", "lineno": 68, "outcome": "failed", "keywords": ["test_persona_valid_message", "TestPersonaEndpoint", "test_endpoints.py", "__init__.py", "api"], "setup": {"duration": 0.0005416999997578387, "outcome": "passed"}, "call": {"duration": 7.534472600000299, "outcome": "failed", "crash": {"path": "C:\\Projects\\building-os-platform\\.venv\\Lib\\site-packages\\requests\\adapters.py", "lineno": 510, "message": "requests.exceptions.RetryError: HTTPSConnectionPool(host='pj4vlvxrg7.execute-api.us-east-1.amazonaws.com', port=443): Max retries exceeded with url: /dev/persona (Caused by ResponseError('too many 500 error responses'))"}, "stdout": "\n\ud83d\ude80 POST /persona\n\u274c Request failed: \nHTTPSConnectionPool(host='pj4vlvxrg7.execute-api.us-east-1.amazonaws.com', \nport=443): Max retries exceeded with url: /dev/persona (Caused by \nResponseError('too many 500 error responses'))\n", "longrepr": "urllib3.exceptions.ResponseError: too many 500 error responses\n\nThe above exception was the direct cause of the following exception:\nE   urllib3.exceptions.MaxRetryError: HTTPSConnectionPool(host='pj4vlvxrg7.execute-api.us-east-1.amazonaws.com', port=443): Max retries exceeded with url: /dev/persona (Caused by ResponseError('too many 500 error responses'))\n\nDuring handling of the above exception, another exception occurred:\nE   requests.exceptions.RetryError: HTTPSConnectionPool(host='pj4vlvxrg7.execute-api.us-east-1.amazonaws.com', port=443): Max retries exceeded with url: /dev/persona (Caused by ResponseError('too many 500 error responses'))"}, "teardown": {"duration": 0.001166400000329304, "outcome": "passed", "stdout": "\n"}}, {"nodeid": "test_endpoints.py::TestPersonaEndpoint::test_persona_missing_user_id", "lineno": 81, "outcome": "passed", "keywords": ["test_persona_missing_user_id", "TestPersonaEndpoint", "test_endpoints.py", "__init__.py", "api"], "setup": {"duration": 0.0005831999997099047, "outcome": "passed"}, "call": {"duration": 0.17973309999979392, "outcome": "passed", "stdout": "\n\ud83d\ude80 POST /persona\n\ud83d\udcca Status: 400 | \u23f1\ufe0f  Time: 177.37ms | \ud83d\udce6 Size: 45 bytes\n"}, "teardown": {"duration": 0.0008838999997351493, "outcome": "passed", "stdout": "\n"}}, {"nodeid": "test_endpoints.py::TestPersonaEndpoint::test_persona_missing_message", "lineno": 89, "outcome": "passed", "keywords": ["test_persona_missing_message", "TestPersonaEndpoint", "test_endpoints.py", "__init__.py", "api"], "setup": {"duration": 0.00048339999966628966, "outcome": "passed"}, "call": {"duration": 0.1949760000002243, "outcome": "passed", "stdout": "\n\ud83d\ude80 POST /persona\n\ud83d\udcca Status: 400 | \u23f1\ufe0f  Time: 191.87ms | \ud83d\udce6 Size: 45 bytes\n"}, "teardown": {"duration": 0.0010777999996207654, "outcome": "passed", "stdout": "\n"}}, {"nodeid": "test_endpoints.py::TestPersonaEndpoint::test_persona_conversations", "lineno": 97, "outcome": "failed", "keywords": ["test_persona_conversations", "TestPersonaEndpoint", "test_endpoints.py", "__init__.py", "api"], "setup": {"duration": 0.0005181000001357461, "outcome": "passed"}, "call": {"duration": 6.800163500000053, "outcome": "failed", "crash": {"path": "C:\\Projects\\building-os-platform\\.venv\\Lib\\site-packages\\requests\\adapters.py", "lineno": 510, "message": "requests.exceptions.RetryError: HTTPSConnectionPool(host='pj4vlvxrg7.execute-api.us-east-1.amazonaws.com', port=443): Max retries exceeded with url: /dev/persona/conversations?user_id=api-test-user (Caused by ResponseError('too many 500 error responses'))"}, "stdout": "\n\ud83d\ude80 GET /persona/conversations?user_id=api-test-user\n\u274c Request failed: \nHTTPSConnectionPool(host='pj4vlvxrg7.execute-api.us-east-1.amazonaws.com', \nport=443): Max retries exceeded with url: \n/dev/persona/conversations?user_id=api-test-user (Caused by ResponseError('too \nmany 500 error responses'))\n", "longrepr": "urllib3.exceptions.ResponseError: too many 500 error responses\n\nThe above exception was the direct cause of the following exception:\nE   urllib3.exceptions.MaxRetryError: HTTPSConnectionPool(host='pj4vlvxrg7.execute-api.us-east-1.amazonaws.com', port=443): Max retries exceeded with url: /dev/persona/conversations?user_id=api-test-user (Caused by ResponseError('too many 500 error responses'))\n\nDuring handling of the above exception, another exception occurred:\nE   requests.exceptions.RetryError: HTTPSConnectionPool(host='pj4vlvxrg7.execute-api.us-east-1.amazonaws.com', port=443): Max retries exceeded with url: /dev/persona/conversations?user_id=api-test-user (Caused by ResponseError('too many 500 error responses'))"}, "teardown": {"duration": 0.0010542999998506275, "outcome": "passed", "stdout": "\n"}}, {"nodeid": "test_endpoints.py::TestElevatorEndpoint::test_elevator_call_basic", "lineno": 109, "outcome": "failed", "keywords": ["test_elevator_call_basic", "TestElevatorEndpoint", "test_endpoints.py", "__init__.py", "api"], "setup": {"duration": 0.0005713000000469037, "outcome": "passed"}, "call": {"duration": 8.187157599999864, "outcome": "failed", "crash": {"path": "C:\\Projects\\building-os-platform\\.venv\\Lib\\site-packages\\requests\\adapters.py", "lineno": 510, "message": "requests.exceptions.RetryError: HTTPSConnectionPool(host='pj4vlvxrg7.execute-api.us-east-1.amazonaws.com', port=443): Max retries exceeded with url: /dev/elevator/call (Caused by ResponseError('too many 500 error responses'))"}, "stdout": "\n\ud83d\ude80 POST /elevator/call\n\u274c Request failed: \nHTTPSConnectionPool(host='pj4vlvxrg7.execute-api.us-east-1.amazonaws.com', \nport=443): Max retries exceeded with url: /dev/elevator/call (Caused by \nResponseError('too many 500 error responses'))\n", "longrepr": "urllib3.exceptions.ResponseError: too many 500 error responses\n\nThe above exception was the direct cause of the following exception:\nE   urllib3.exceptions.MaxRetryError: HTTPSConnectionPool(host='pj4vlvxrg7.execute-api.us-east-1.amazonaws.com', port=443): Max retries exceeded with url: /dev/elevator/call (Caused by ResponseError('too many 500 error responses'))\n\nDuring handling of the above exception, another exception occurred:\nE   requests.exceptions.RetryError: HTTPSConnectionPool(host='pj4vlvxrg7.execute-api.us-east-1.amazonaws.com', port=443): Max retries exceeded with url: /dev/elevator/call (Caused by ResponseError('too many 500 error responses'))"}, "teardown": {"duration": 0.0009433000000171887, "outcome": "passed", "stdout": "\n"}}, {"nodeid": "test_endpoints.py::TestElevatorEndpoint::test_elevator_missing_mission_id", "lineno": 120, "outcome": "failed", "keywords": ["test_elevator_missing_mission_id", "TestElevatorEndpoint", "test_endpoints.py", "__init__.py", "api"], "setup": {"duration": 0.0005427000000963744, "outcome": "passed"}, "call": {"duration": 6.960480400000051, "outcome": "failed", "crash": {"path": "C:\\Projects\\building-os-platform\\.venv\\Lib\\site-packages\\requests\\adapters.py", "lineno": 510, "message": "requests.exceptions.RetryError: HTTPSConnectionPool(host='pj4vlvxrg7.execute-api.us-east-1.amazonaws.com', port=443): Max retries exceeded with url: /dev/elevator/call (Caused by ResponseError('too many 500 error responses'))"}, "stdout": "\n\ud83d\ude80 POST /elevator/call\n\u274c Request failed: \nHTTPSConnectionPool(host='pj4vlvxrg7.execute-api.us-east-1.amazonaws.com', \nport=443): Max retries exceeded with url: /dev/elevator/call (Caused by \nResponseError('too many 500 error responses'))\n", "longrepr": "urllib3.exceptions.ResponseError: too many 500 error responses\n\nThe above exception was the direct cause of the following exception:\nE   urllib3.exceptions.MaxRetryError: HTTPSConnectionPool(host='pj4vlvxrg7.execute-api.us-east-1.amazonaws.com', port=443): Max retries exceeded with url: /dev/elevator/call (Caused by ResponseError('too many 500 error responses'))\n\nDuring handling of the above exception, another exception occurred:\nE   requests.exceptions.RetryError: HTTPSConnectionPool(host='pj4vlvxrg7.execute-api.us-east-1.amazonaws.com', port=443): Max retries exceeded with url: /dev/elevator/call (Caused by ResponseError('too many 500 error responses'))"}, "teardown": {"duration": 0.0009444999996048864, "outcome": "passed", "stdout": "\n"}}, {"nodeid": "test_endpoints.py::TestPSIMEndpoint::test_psim_search_basic", "lineno": 132, "outcome": "passed", "keywords": ["test_psim_search_basic", "TestPSIMEndpoint", "test_endpoints.py", "__init__.py", "api"], "setup": {"duration": 0.000517299999955867, "outcome": "passed"}, "call": {"duration": 1.794986400000198, "outcome": "passed", "stdout": "\n\ud83d\ude80 POST /psim/search\n\ud83d\udcca Status: 200 | \u23f1\ufe0f  Time: 1792.74ms | \ud83d\udce6 Size: 223 bytes\n"}, "teardown": {"duration": 0.0007563999997728388, "outcome": "passed", "stdout": "\n"}}, {"nodeid": "test_endpoints.py::TestPSIMEndpoint::test_psim_search_with_custom_query", "lineno": 142, "outcome": "passed", "keywords": ["test_psim_search_with_custom_query", "TestPSIMEndpoint", "test_endpoints.py", "__init__.py", "api"], "setup": {"duration": 0.0005490000003192108, "outcome": "passed"}, "call": {"duration": 0.3202774000001227, "outcome": "passed", "stdout": "\n\ud83d\ude80 POST /psim/search\n\ud83d\udcca Status: 200 | \u23f1\ufe0f  Time: 318.02ms | \ud83d\udce6 Size: 223 bytes\n"}, "teardown": {"duration": 0.000892900000053487, "outcome": "passed", "stdout": "\n"}}, {"nodeid": "test_endpoints.py::TestCoordinatorEndpoint::test_coordinator_mission_status", "lineno": 155, "outcome": "failed", "keywords": ["test_coordinator_mission_status", "TestCoordinatorEndpoint", "test_endpoints.py", "__init__.py", "api"], "setup": {"duration": 0.0004659999999603315, "outcome": "passed"}, "call": {"duration": 6.820013999999901, "outcome": "failed", "crash": {"path": "C:\\Projects\\building-os-platform\\.venv\\Lib\\site-packages\\requests\\adapters.py", "lineno": 510, "message": "requests.exceptions.RetryError: HTTPSConnectionPool(host='pj4vlvxrg7.execute-api.us-east-1.amazonaws.com', port=443): Max retries exceeded with url: /dev/coordinator/missions/test-mission-123 (Caused by ResponseError('too many 500 error responses'))"}, "stdout": "\n\ud83d\ude80 GET /coordinator/missions/test-mission-123\n\u274c Request failed: \nHTTPSConnectionPool(host='pj4vlvxrg7.execute-api.us-east-1.amazonaws.com', \nport=443): Max retries exceeded with url: \n/dev/coordinator/missions/test-mission-123 (Caused by ResponseError('too many \n500 error responses'))\n", "longrepr": "urllib3.exceptions.ResponseError: too many 500 error responses\n\nThe above exception was the direct cause of the following exception:\nE   urllib3.exceptions.MaxRetryError: HTTPSConnectionPool(host='pj4vlvxrg7.execute-api.us-east-1.amazonaws.com', port=443): Max retries exceeded with url: /dev/coordinator/missions/test-mission-123 (Caused by ResponseError('too many 500 error responses'))\n\nDuring handling of the above exception, another exception occurred:\nE   requests.exceptions.RetryError: HTTPSConnectionPool(host='pj4vlvxrg7.execute-api.us-east-1.amazonaws.com', port=443): Max retries exceeded with url: /dev/coordinator/missions/test-mission-123 (Caused by ResponseError('too many 500 error responses'))"}, "teardown": {"duration": 0.0009360999997625186, "outcome": "passed", "stdout": "\n"}}, {"nodeid": "test_endpoints.py::TestCoordinatorEndpoint::test_coordinator_different_mission_id", "lineno": 166, "outcome": "failed", "keywords": ["test_coordinator_different_mission_id", "TestCoordinatorEndpoint", "test_endpoints.py", "__init__.py", "api"], "setup": {"duration": 0.0005032999997638399, "outcome": "passed"}, "call": {"duration": 6.7972514000002775, "outcome": "failed", "crash": {"path": "C:\\Projects\\building-os-platform\\.venv\\Lib\\site-packages\\requests\\adapters.py", "lineno": 510, "message": "requests.exceptions.RetryError: HTTPSConnectionPool(host='pj4vlvxrg7.execute-api.us-east-1.amazonaws.com', port=443): Max retries exceeded with url: /dev/coordinator/missions/python-test-1754835816 (Caused by ResponseError('too many 500 error responses'))"}, "stdout": "\n\ud83d\ude80 GET /coordinator/missions/python-test-1754835816\n\u274c Request failed: \nHTTPSConnectionPool(host='pj4vlvxrg7.execute-api.us-east-1.amazonaws.com', \nport=443): Max retries exceeded with url: \n/dev/coordinator/missions/python-test-1754835816 (Caused by ResponseError('too \nmany 500 error responses'))\n", "longrepr": "urllib3.exceptions.ResponseError: too many 500 error responses\n\nThe above exception was the direct cause of the following exception:\nE   urllib3.exceptions.MaxRetryError: HTTPSConnectionPool(host='pj4vlvxrg7.execute-api.us-east-1.amazonaws.com', port=443): Max retries exceeded with url: /dev/coordinator/missions/python-test-1754835816 (Caused by ResponseError('too many 500 error responses'))\n\nDuring handling of the above exception, another exception occurred:\nE   requests.exceptions.RetryError: HTTPSConnectionPool(host='pj4vlvxrg7.execute-api.us-east-1.amazonaws.com', port=443): Max retries exceeded with url: /dev/coordinator/missions/python-test-1754835816 (Caused by ResponseError('too many 500 error responses'))"}, "teardown": {"duration": 0.0009571000000505592, "outcome": "passed", "stdout": "\n"}}, {"nodeid": "test_endpoints.py::TestCORSHeaders::test_cors_headers_present[/health]", "lineno": 178, "outcome": "failed", "keywords": ["test_cors_headers_present[/health]", "parametrize", "pytestmark", "/health", "TestCORSHeaders", "test_endpoints.py", "__init__.py", "api"], "setup": {"duration": 0.0006229000000530505, "outcome": "passed"}, "call": {"duration": 0.19096069999977772, "outcome": "failed", "crash": {"path": "c:\\Projects\\building-os-platform\\tests\\api\\test_endpoints.py", "lineno": 215, "message": "AssertionError: No CORS headers found in response for /health\nassert False"}, "stdout": "\n\ud83d\ude80 GET /health\n\ud83d\udcca Status: 200 | \u23f1\ufe0f  Time: 188.48ms | \ud83d\udce6 Size: 60 bytes\n", "longrepr": "E   AssertionError: No CORS headers found in response for /health\n    assert False"}, "teardown": {"duration": 0.0010258999996040075, "outcome": "passed", "stdout": "\n"}}, {"nodeid": "test_endpoints.py::TestCORSHeaders::test_cors_headers_present[/director]", "lineno": 178, "outcome": "failed", "keywords": ["test_cors_headers_present[/director]", "parametrize", "pytestmark", "/director", "TestCORSHeaders", "test_endpoints.py", "__init__.py", "api"], "setup": {"duration": 0.0005648999999721127, "outcome": "passed"}, "call": {"duration": 3.7756030999998984, "outcome": "failed", "crash": {"path": "c:\\Projects\\building-os-platform\\tests\\api\\test_endpoints.py", "lineno": 215, "message": "AssertionError: No CORS headers found in response for /director\nassert False"}, "stdout": "\n\ud83d\ude80 GET /director\n\ud83d\udcca Status: 200 | \u23f1\ufe0f  Time: 3773.22ms | \ud83d\udce6 Size: 128 bytes\n", "longrepr": "E   AssertionError: No CORS headers found in response for /director\n    assert False"}, "teardown": {"duration": 0.0009482000000389235, "outcome": "passed", "stdout": "\n"}}, {"nodeid": "test_endpoints.py::TestCORSHeaders::test_cors_headers_present[/persona]", "lineno": 178, "outcome": "failed", "keywords": ["test_cors_headers_present[/persona]", "parametrize", "pytestmark", "/persona", "TestCORSHeaders", "test_endpoints.py", "__init__.py", "api"], "setup": {"duration": 0.0005639000000883243, "outcome": "passed"}, "call": {"duration": 0.20985269999982847, "outcome": "failed", "crash": {"path": "c:\\Projects\\building-os-platform\\tests\\api\\test_endpoints.py", "lineno": 215, "message": "AssertionError: No CORS headers found in response for /persona\nassert False"}, "stdout": "\n\ud83d\ude80 POST /persona\n\ud83d\udcca Status: 400 | \u23f1\ufe0f  Time: 207.61ms | \ud83d\udce6 Size: 45 bytes\n", "longrepr": "E   AssertionError: No CORS headers found in response for /persona\n    assert False"}, "teardown": {"duration": 0.0009392000001753331, "outcome": "passed", "stdout": "\n"}}, {"nodeid": "test_endpoints.py::TestCORSHeaders::test_cors_headers_present[/elevator/call]", "lineno": 178, "outcome": "failed", "keywords": ["test_cors_headers_present[/elevator/call]", "parametrize", "pytestmark", "/elevator/call", "TestCORSHeaders", "test_endpoints.py", "__init__.py", "api"], "setup": {"duration": 0.0006106999999246909, "outcome": "passed"}, "call": {"duration": 7.038264499999968, "outcome": "failed", "crash": {"path": "C:\\Projects\\building-os-platform\\.venv\\Lib\\site-packages\\requests\\adapters.py", "lineno": 510, "message": "requests.exceptions.RetryError: HTTPSConnectionPool(host='pj4vlvxrg7.execute-api.us-east-1.amazonaws.com', port=443): Max retries exceeded with url: /dev/elevator/call (Caused by ResponseError('too many 500 error responses'))"}, "stdout": "\n\ud83d\ude80 POST /elevator/call\n\u274c Request failed: \nHTTPSConnectionPool(host='pj4vlvxrg7.execute-api.us-east-1.amazonaws.com', \nport=443): Max retries exceeded with url: /dev/elevator/call (Caused by \nResponseError('too many 500 error responses'))\n", "longrepr": "urllib3.exceptions.ResponseError: too many 500 error responses\n\nThe above exception was the direct cause of the following exception:\nE   urllib3.exceptions.MaxRetryError: HTTPSConnectionPool(host='pj4vlvxrg7.execute-api.us-east-1.amazonaws.com', port=443): Max retries exceeded with url: /dev/elevator/call (Caused by ResponseError('too many 500 error responses'))\n\nDuring handling of the above exception, another exception occurred:\nE   requests.exceptions.RetryError: HTTPSConnectionPool(host='pj4vlvxrg7.execute-api.us-east-1.amazonaws.com', port=443): Max retries exceeded with url: /dev/elevator/call (Caused by ResponseError('too many 500 error responses'))"}, "teardown": {"duration": 0.0009542000002511486, "outcome": "passed", "stdout": "\n"}}, {"nodeid": "test_endpoints.py::TestCORSHeaders::test_cors_headers_present[/psim/search]", "lineno": 178, "outcome": "failed", "keywords": ["test_cors_headers_present[/psim/search]", "parametrize", "pytestmark", "/psim/search", "TestCORSHeaders", "test_endpoints.py", "__init__.py", "api"], "setup": {"duration": 0.0006077000002733257, "outcome": "passed"}, "call": {"duration": 0.17762539999966975, "outcome": "failed", "crash": {"path": "c:\\Projects\\building-os-platform\\tests\\api\\test_endpoints.py", "lineno": 215, "message": "AssertionError: No CORS headers found in response for /psim/search\nassert False"}, "stdout": "\n\ud83d\ude80 POST /psim/search\n\ud83d\udcca Status: 400 | \u23f1\ufe0f  Time: 175.32ms | \ud83d\udce6 Size: 43 bytes\n", "longrepr": "E   AssertionError: No CORS headers found in response for /psim/search\n    assert False"}, "teardown": {"duration": 0.0009684000001470849, "outcome": "passed", "stdout": "\n"}}, {"nodeid": "test_endpoints.py::TestCORSHeaders::test_cors_headers_present[/coordinator/missions/test-123]", "lineno": 178, "outcome": "failed", "keywords": ["test_cors_headers_present[/coordinator/missions/test-123]", "parametrize", "pytestmark", "/coordinator/missions/test-123", "TestCORSHeaders", "test_endpoints.py", "__init__.py", "api"], "setup": {"duration": 0.0006225999995876919, "outcome": "passed"}, "call": {"duration": 6.810831499999949, "outcome": "failed", "crash": {"path": "C:\\Projects\\building-os-platform\\.venv\\Lib\\site-packages\\requests\\adapters.py", "lineno": 510, "message": "requests.exceptions.RetryError: HTTPSConnectionPool(host='pj4vlvxrg7.execute-api.us-east-1.amazonaws.com', port=443): Max retries exceeded with url: /dev/coordinator/missions/test-123 (Caused by ResponseError('too many 500 error responses'))"}, "stdout": "\n\ud83d\ude80 GET /coordinator/missions/test-123\n\u274c Request failed: \nHTTPSConnectionPool(host='pj4vlvxrg7.execute-api.us-east-1.amazonaws.com', \nport=443): Max retries exceeded with url: /dev/coordinator/missions/test-123 \n(Caused by ResponseError('too many 500 error responses'))\n", "longrepr": "urllib3.exceptions.ResponseError: too many 500 error responses\n\nThe above exception was the direct cause of the following exception:\nE   urllib3.exceptions.MaxRetryError: HTTPSConnectionPool(host='pj4vlvxrg7.execute-api.us-east-1.amazonaws.com', port=443): Max retries exceeded with url: /dev/coordinator/missions/test-123 (Caused by ResponseError('too many 500 error responses'))\n\nDuring handling of the above exception, another exception occurred:\nE   requests.exceptions.RetryError: HTTPSConnectionPool(host='pj4vlvxrg7.execute-api.us-east-1.amazonaws.com', port=443): Max retries exceeded with url: /dev/coordinator/missions/test-123 (Caused by ResponseError('too many 500 error responses'))"}, "teardown": {"duration": 0.0016696999996383965, "outcome": "passed", "stdout": "\n"}}, {"nodeid": "test_endpoints.py::TestErrorHandling::test_invalid_endpoint", "lineno": 220, "outcome": "passed", "keywords": ["test_invalid_endpoint", "TestErrorHandling", "test_endpoints.py", "__init__.py", "api"], "setup": {"duration": 0.0006002000000080443, "outcome": "passed"}, "call": {"duration": 0.16211000000021158, "outcome": "passed", "stdout": "\n\ud83d\ude80 GET /invalid-endpoint\n\ud83d\udcca Status: 404 | \u23f1\ufe0f  Time: 159.78ms | \ud83d\udce6 Size: 23 bytes\n"}, "teardown": {"duration": 0.0014992999999776657, "outcome": "passed", "stdout": "\n"}}, {"nodeid": "test_endpoints.py::TestErrorHandling::test_invalid_method", "lineno": 225, "outcome": "passed", "keywords": ["test_invalid_method", "TestErrorHandling", "test_endpoints.py", "__init__.py", "api"], "setup": {"duration": 0.000641399999949499, "outcome": "passed"}, "call": {"duration": 0.17197669999995924, "outcome": "passed", "stdout": "\n\ud83d\ude80 DELETE /health\n\ud83d\udcca Status: 404 | \u23f1\ufe0f  Time: 169.33ms | \ud83d\udce6 Size: 23 bytes\n"}, "teardown": {"duration": 0.001061800000115909, "outcome": "passed", "stdout": "\n"}}, {"nodeid": "test_endpoints.py::TestErrorHandling::test_malformed_json", "lineno": 235, "outcome": "passed", "keywords": ["test_malformed_json", "TestErrorHandling", "test_endpoints.py", "__init__.py", "api"], "setup": {"duration": 0.0006133000001682376, "outcome": "passed"}, "call": {"duration": 6.756827900000189, "outcome": "passed"}, "teardown": {"duration": 0.000991500000054657, "outcome": "passed", "stdout": "\n"}}, {"nodeid": "test_performance.py::TestPerformance::test_response_time_under_threshold", "lineno": 18, "outcome": "failed", "keywords": ["test_response_time_under_threshold", "TestPerformance", "test_performance.py", "__init__.py", "api"], "setup": {"duration": 0.0004321999999774562, "outcome": "passed"}, "call": {"duration": 9.821597600000132, "outcome": "failed", "crash": {"path": "C:\\Projects\\building-os-platform\\.venv\\Lib\\site-packages\\requests\\adapters.py", "lineno": 510, "message": "requests.exceptions.RetryError: HTTPSConnectionPool(host='pj4vlvxrg7.execute-api.us-east-1.amazonaws.com', port=443): Max retries exceeded with url: /dev/persona (Caused by ResponseError('too many 500 error responses'))"}, "stdout": "\n\ud83d\ude80 GET /health\n\ud83d\udcca Status: 200 | \u23f1\ufe0f  Time: 190.55ms | \ud83d\udce6 Size: 60 bytes\n\n\ud83d\ude80 GET /director\n\ud83d\udcca Status: 200 | \u23f1\ufe0f  Time: 2834.51ms | \ud83d\udce6 Size: 128 bytes\n\n\ud83d\ude80 POST /persona\n\u274c Request failed: \nHTTPSConnectionPool(host='pj4vlvxrg7.execute-api.us-east-1.amazonaws.com', \nport=443): Max retries exceeded with url: /dev/persona (Caused by \nResponseError('too many 500 error responses'))\n", "longrepr": "urllib3.exceptions.ResponseError: too many 500 error responses\n\nThe above exception was the direct cause of the following exception:\nE   urllib3.exceptions.MaxRetryError: HTTPSConnectionPool(host='pj4vlvxrg7.execute-api.us-east-1.amazonaws.com', port=443): Max retries exceeded with url: /dev/persona (Caused by ResponseError('too many 500 error responses'))\n\nDuring handling of the above exception, another exception occurred:\nE   requests.exceptions.RetryError: HTTPSConnectionPool(host='pj4vlvxrg7.execute-api.us-east-1.amazonaws.com', port=443): Max retries exceeded with url: /dev/persona (Caused by ResponseError('too many 500 error responses'))"}, "teardown": {"duration": 0.0004737000003842695, "outcome": "passed"}}, {"nodeid": "test_performance.py::TestPerformance::test_concurrent_health_checks", "lineno": 45, "outcome": "passed", "keywords": ["test_concurrent_health_checks", "TestPerformance", "test_performance.py", "__init__.py", "api"], "setup": {"duration": 0.000419899999997142, "outcome": "passed"}, "call": {"duration": 1.8903247999996893, "outcome": "passed", "stdout": "\n\ud83d\ude80 GET /health\n\n\ud83d\ude80 GET /health\n\n\ud83d\ude80 GET /health\n\n\ud83d\ude80 GET /health\n\n\ud83d\ude80 GET /health\n\ud83d\udcca Status: 200 | \u23f1\ufe0f  Time: 196.55ms | \ud83d\udce6 Size: 60 bytes\n\ud83d\udcca Status: 200 | \u23f1\ufe0f  Time: 1631.89ms | \ud83d\udce6 Size: 60 bytes\n\ud83d\udcca Status: 200 | \u23f1\ufe0f  Time: 1875.02ms | \ud83d\udce6 Size: 60 bytes\n\ud83d\udcca Status: 200 | \u23f1\ufe0f  Time: 1881.53ms | \ud83d\udce6 Size: 60 bytes\n\ud83d\udcca Status: 200 | \u23f1\ufe0f  Time: 1881.09ms | \ud83d\udce6 Size: 60 bytes\n"}, "teardown": {"duration": 0.0005307999999786261, "outcome": "passed"}}, {"nodeid": "test_performance.py::TestLoadTesting::test_sustained_load_health_endpoint", "lineno": 72, "outcome": "passed", "keywords": ["test_sustained_load_health_endpoint", "slow", "pytestmark", "TestLoadTesting", "test_performance.py", "__init__.py", "api"], "setup": {"duration": 0.00043120000009366777, "outcome": "passed"}, "call": {"duration": 13.19920030000003, "outcome": "passed", "stdout": "\n\ud83d\udd25 Running sustained load test...\n\n\ud83d\ude80 GET /health\n\ud83d\udcca Status: 200 | \u23f1\ufe0f  Time: 187.57ms | \ud83d\udce6 Size: 60 bytes\n\n\ud83d\ude80 GET /health\n\ud83d\udcca Status: 200 | \u23f1\ufe0f  Time: 188.90ms | \ud83d\udce6 Size: 60 bytes\n\n\ud83d\ude80 GET /health\n\ud83d\udcca Status: 200 | \u23f1\ufe0f  Time: 188.11ms | \ud83d\udce6 Size: 60 bytes\n\n\ud83d\ude80 GET /health\n\ud83d\udcca Status: 200 | \u23f1\ufe0f  Time: 185.38ms | \ud83d\udce6 Size: 60 bytes\n\n\ud83d\ude80 GET /health\n\ud83d\udcca Status: 200 | \u23f1\ufe0f  Time: 173.21ms | \ud83d\udce6 Size: 60 bytes\n\n\ud83d\ude80 GET /health\n\ud83d\udcca Status: 200 | \u23f1\ufe0f  Time: 205.63ms | \ud83d\udce6 Size: 60 bytes\n\n\ud83d\ude80 GET /health\n\ud83d\udcca Status: 200 | \u23f1\ufe0f  Time: 181.67ms | \ud83d\udce6 Size: 60 bytes\n\n\ud83d\ude80 GET /health\n\ud83d\udcca Status: 200 | \u23f1\ufe0f  Time: 182.17ms | \ud83d\udce6 Size: 60 bytes\n\n\ud83d\ude80 GET /health\n\ud83d\udcca Status: 200 | \u23f1\ufe0f  Time: 179.46ms | \ud83d\udce6 Size: 60 bytes\n\n\ud83d\ude80 GET /health\n\ud83d\udcca Status: 200 | \u23f1\ufe0f  Time: 179.38ms | \ud83d\udce6 Size: 60 bytes\n\n\ud83d\ude80 GET /health\n\ud83d\udcca Status: 200 | \u23f1\ufe0f  Time: 183.83ms | \ud83d\udce6 Size: 60 bytes\n\n\ud83d\ude80 GET /health\n\ud83d\udcca Status: 200 | \u23f1\ufe0f  Time: 182.74ms | \ud83d\udce6 Size: 60 bytes\n\n\ud83d\ude80 GET /health\n\ud83d\udcca Status: 200 | \u23f1\ufe0f  Time: 165.72ms | \ud83d\udce6 Size: 60 bytes\n\n\ud83d\ude80 GET /health\n\ud83d\udcca Status: 200 | \u23f1\ufe0f  Time: 189.48ms | \ud83d\udce6 Size: 60 bytes\n\n\ud83d\ude80 GET /health\n\ud83d\udcca Status: 200 | \u23f1\ufe0f  Time: 174.02ms | \ud83d\udce6 Size: 60 bytes\n\n\ud83d\ude80 GET /health\n\ud83d\udcca Status: 200 | \u23f1\ufe0f  Time: 184.01ms | \ud83d\udce6 Size: 60 bytes\n\n\ud83d\ude80 GET /health\n\ud83d\udcca Status: 200 | \u23f1\ufe0f  Time: 175.60ms | \ud83d\udce6 Size: 60 bytes\n\n\ud83d\ude80 GET /health\n\ud83d\udcca Status: 200 | \u23f1\ufe0f  Time: 170.45ms | \ud83d\udce6 Size: 60 bytes\n\n\ud83d\ude80 GET /health\n\ud83d\udcca Status: 200 | \u23f1\ufe0f  Time: 183.67ms | \ud83d\udce6 Size: 60 bytes\n\n\ud83d\ude80 GET /health\n\ud83d\udcca Status: 200 | \u23f1\ufe0f  Time: 182.44ms | \ud83d\udce6 Size: 60 bytes\n  Making 20 requests... 0:00:13\n\u2705 Success rate: 100.0% (20/20)\n\u23f1\ufe0f  Avg response: 184.06ms\n\ud83d\udc0c Max response: 207.46ms\n\u26a1 Min response: 167.48ms\n"}, "teardown": {"duration": 0.00040859999990061624, "outcome": "passed"}}, {"nodeid": "test_performance.py::TestStressScenarios::test_large_payload_persona", "lineno": 149, "outcome": "failed", "keywords": ["test_large_payload_persona", "TestStressScenarios", "test_performance.py", "__init__.py", "api"], "setup": {"duration": 0.0006356999997478852, "outcome": "passed"}, "call": {"duration": 6.779267800000071, "outcome": "failed", "crash": {"path": "C:\\Projects\\building-os-platform\\.venv\\Lib\\site-packages\\requests\\adapters.py", "lineno": 510, "message": "requests.exceptions.RetryError: HTTPSConnectionPool(host='pj4vlvxrg7.execute-api.us-east-1.amazonaws.com', port=443): Max retries exceeded with url: /dev/persona (Caused by ResponseError('too many 500 error responses'))"}, "stdout": "\n\ud83d\ude80 POST /persona\n\u274c Request failed: \nHTTPSConnectionPool(host='pj4vlvxrg7.execute-api.us-east-1.amazonaws.com', \nport=443): Max retries exceeded with url: /dev/persona (Caused by \nResponseError('too many 500 error responses'))\n", "longrepr": "urllib3.exceptions.ResponseError: too many 500 error responses\n\nThe above exception was the direct cause of the following exception:\nE   urllib3.exceptions.MaxRetryError: HTTPSConnectionPool(host='pj4vlvxrg7.execute-api.us-east-1.amazonaws.com', port=443): Max retries exceeded with url: /dev/persona (Caused by ResponseError('too many 500 error responses'))\n\nDuring handling of the above exception, another exception occurred:\nE   requests.exceptions.RetryError: HTTPSConnectionPool(host='pj4vlvxrg7.execute-api.us-east-1.amazonaws.com', port=443): Max retries exceeded with url: /dev/persona (Caused by ResponseError('too many 500 error responses'))"}, "teardown": {"duration": 0.0004725999997390318, "outcome": "passed"}}, {"nodeid": "test_performance.py::TestStressScenarios::test_rapid_successive_requests", "lineno": 163, "outcome": "passed", "keywords": ["test_rapid_successive_requests", "TestStressScenarios", "test_performance.py", "__init__.py", "api"], "setup": {"duration": 0.0005411000001913635, "outcome": "passed"}, "call": {"duration": 1.8410193000004256, "outcome": "passed", "stdout": "\n\ud83d\ude80 GET /health\n\ud83d\udcca Status: 200 | \u23f1\ufe0f  Time: 179.41ms | \ud83d\udce6 Size: 60 bytes\n\n\ud83d\ude80 GET /health\n\ud83d\udcca Status: 200 | \u23f1\ufe0f  Time: 183.42ms | \ud83d\udce6 Size: 60 bytes\n\n\ud83d\ude80 GET /health\n\ud83d\udcca Status: 200 | \u23f1\ufe0f  Time: 173.75ms | \ud83d\udce6 Size: 60 bytes\n\n\ud83d\ude80 GET /health\n\ud83d\udcca Status: 200 | \u23f1\ufe0f  Time: 174.74ms | \ud83d\udce6 Size: 60 bytes\n\n\ud83d\ude80 GET /health\n\ud83d\udcca Status: 200 | \u23f1\ufe0f  Time: 187.37ms | \ud83d\udce6 Size: 60 bytes\n\n\ud83d\ude80 GET /health\n\ud83d\udcca Status: 200 | \u23f1\ufe0f  Time: 184.09ms | \ud83d\udce6 Size: 60 bytes\n\n\ud83d\ude80 GET /health\n\ud83d\udcca Status: 200 | \u23f1\ufe0f  Time: 182.32ms | \ud83d\udce6 Size: 60 bytes\n\n\ud83d\ude80 GET /health\n\ud83d\udcca Status: 200 | \u23f1\ufe0f  Time: 182.53ms | \ud83d\udce6 Size: 60 bytes\n\n\ud83d\ude80 GET /health\n\ud83d\udcca Status: 200 | \u23f1\ufe0f  Time: 177.32ms | \ud83d\udce6 Size: 60 bytes\n\n\ud83d\ude80 GET /health\n\ud83d\udcca Status: 200 | \u23f1\ufe0f  Time: 197.22ms | \ud83d\udce6 Size: 60 bytes\n\ud83d\ude80 Rapid requests: 10 in 1.84s\n\u2705 Success rate: 100.0%\n"}, "teardown": {"duration": 0.0005355999996936589, "outcome": "passed"}}, {"nodeid": "test_performance.py::TestStressScenarios::test_special_characters_in_requests", "lineno": 189, "outcome": "failed", "keywords": ["test_special_characters_in_requests", "TestStressScenarios", "test_performance.py", "__init__.py", "api"], "setup": {"duration": 0.00045709999994869577, "outcome": "passed"}, "call": {"duration": 6.753185900000062, "outcome": "failed", "crash": {"path": "C:\\Projects\\building-os-platform\\.venv\\Lib\\site-packages\\requests\\adapters.py", "lineno": 510, "message": "requests.exceptions.RetryError: HTTPSConnectionPool(host='pj4vlvxrg7.execute-api.us-east-1.amazonaws.com', port=443): Max retries exceeded with url: /dev/persona (Caused by ResponseError('too many 500 error responses'))"}, "stdout": "\n\ud83d\ude80 POST /persona\n\u274c Request failed: \nHTTPSConnectionPool(host='pj4vlvxrg7.execute-api.us-east-1.amazonaws.com', \nport=443): Max retries exceeded with url: /dev/persona (Caused by \nResponseError('too many 500 error responses'))\n", "longrepr": "urllib3.exceptions.ResponseError: too many 500 error responses\n\nThe above exception was the direct cause of the following exception:\nE   urllib3.exceptions.MaxRetryError: HTTPSConnectionPool(host='pj4vlvxrg7.execute-api.us-east-1.amazonaws.com', port=443): Max retries exceeded with url: /dev/persona (Caused by ResponseError('too many 500 error responses'))\n\nDuring handling of the above exception, another exception occurred:\nE   requests.exceptions.RetryError: HTTPSConnectionPool(host='pj4vlvxrg7.execute-api.us-east-1.amazonaws.com', port=443): Max retries exceeded with url: /dev/persona (Caused by ResponseError('too many 500 error responses'))"}, "teardown": {"duration": 0.0004658000002564222, "outcome": "passed"}}, {"nodeid": "test_performance.py::TestBoundaryConditions::test_empty_payloads", "lineno": 213, "outcome": "failed", "keywords": ["test_empty_payloads", "TestBoundaryConditions", "test_performance.py", "__init__.py", "api"], "setup": {"duration": 0.0003575000000637374, "outcome": "passed"}, "call": {"duration": 8.309020099999998, "outcome": "failed", "crash": {"path": "C:\\Projects\\building-os-platform\\.venv\\Lib\\site-packages\\requests\\adapters.py", "lineno": 510, "message": "requests.exceptions.RetryError: HTTPSConnectionPool(host='pj4vlvxrg7.execute-api.us-east-1.amazonaws.com', port=443): Max retries exceeded with url: /dev/elevator/call (Caused by ResponseError('too many 500 error responses'))"}, "stdout": "\n\ud83d\ude80 POST /persona\n\ud83d\udcca Status: 400 | \u23f1\ufe0f  Time: 1426.50ms | \ud83d\udce6 Size: 45 bytes\n\n\ud83d\ude80 POST /elevator/call\n\u274c Request failed: \nHTTPSConnectionPool(host='pj4vlvxrg7.execute-api.us-east-1.amazonaws.com', \nport=443): Max retries exceeded with url: /dev/elevator/call (Caused by \nResponseError('too many 500 error responses'))\n", "longrepr": "urllib3.exceptions.ResponseError: too many 500 error responses\n\nThe above exception was the direct cause of the following exception:\nE   urllib3.exceptions.MaxRetryError: HTTPSConnectionPool(host='pj4vlvxrg7.execute-api.us-east-1.amazonaws.com', port=443): Max retries exceeded with url: /dev/elevator/call (Caused by ResponseError('too many 500 error responses'))\n\nDuring handling of the above exception, another exception occurred:\nE   requests.exceptions.RetryError: HTTPSConnectionPool(host='pj4vlvxrg7.execute-api.us-east-1.amazonaws.com', port=443): Max retries exceeded with url: /dev/elevator/call (Caused by ResponseError('too many 500 error responses'))"}, "teardown": {"duration": 0.00048050000032162643, "outcome": "passed"}}, {"nodeid": "test_performance.py::TestBoundaryConditions::test_null_values_in_payload", "lineno": 224, "outcome": "passed", "keywords": ["test_null_values_in_payload", "TestBoundaryConditions", "test_performance.py", "__init__.py", "api"], "setup": {"duration": 0.000461399999949208, "outcome": "passed"}, "call": {"duration": 0.1750291000003017, "outcome": "passed", "stdout": "\n\ud83d\ude80 POST /persona\n\ud83d\udcca Status: 400 | \u23f1\ufe0f  Time: 172.28ms | \ud83d\udce6 Size: 45 bytes\n"}, "teardown": {"duration": 0.0005617000001620909, "outcome": "passed"}}, {"nodeid": "test_performance.py::TestBoundaryConditions::test_extremely_long_mission_id", "lineno": 233, "outcome": "failed", "keywords": ["test_extremely_long_mission_id", "TestBoundaryConditions", "test_performance.py", "__init__.py", "api"], "setup": {"duration": 0.00046750000001338776, "outcome": "passed"}, "call": {"duration": 6.8082909999998265, "outcome": "failed", "crash": {"path": "C:\\Projects\\building-os-platform\\.venv\\Lib\\site-packages\\requests\\adapters.py", "lineno": 510, "message": "requests.exceptions.RetryError: HTTPSConnectionPool(host='pj4vlvxrg7.execute-api.us-east-1.amazonaws.com', port=443): Max retries exceeded with url: /dev/coordinator/missions/xxxxxxxxxxxxxxxxxxxxxxxxxxxxxxxxxxxxxxxxxxxxxxxxxxxxxxxxxxxxxxxxxxxxxxxxxxxxxxxxxxxxxxxxxxxxxxxxxxxxxxxxxxxxxxxxxxxxxxxxxxxxxxxxxxxxxxxxxxxxxxxxxxxxxxxxxxxxxxxxxxxxxxxxxxxxxxxxxxxxxxxxxxxxxxxxxxxxxxxxxxxxxxxxxxxxxxxxxxxxxxxxxxxxxxxxxxxxxxxxxxxxxxxxxxxxxxxxxxxxxxxxxxxxxxxxxxxxxxxxxxxxxxxxxxxxxxxxxxxxxxxxxxxxxxxxxxxxxxxxxxxxxxxxxxxxxxxxxxxxxxxxxxxxxxxxxxxxxxxxxxxxxxxxxxxxxxxxxxxxxxxxxxxxxxxxxxxxxxxxxxxxxxxxxxxxxxxxxxxxxxxxxxxxxxxxxxxxxxxxxxxxxxxxxxxxxxxxxxxxxxxxxxxxxxxxxxxxxxxxxxxxxxxxxxxxxxxxxxxxxxxxxxxxxxxxxxxxxxxxxxxxxxxxxxxxxxxxxxxxxxxxxxxxxxxxxxxxxxxxxxxxxxxxxxxxxxxxxxxxxxxxxxxxxxxxxxxxxxxxxxxxxxxxxxxxxxxxxxxxxxxxxxxxxxxxxxxxxxxxxxxxxxxxxxxxxxxxxxxxxxxxxxxxxxxxxxxxxxxxxxxxxxxxxxxxxxxxxxxxxxxxxxxxxxxxxxxxxxxxxxxxxxxxxxxxxxxxxxxxxxxxxxxxxxxxxxxxxxxxxxxxxxxxxxxxxxxxxxxxxxxxxxxxxxxxxxxxxxxxxxxxxxxxxxxxxxxxxxxxxxxxxxxxxxxxxxxxxxxxxxxxxxxxxxxxxxxxxxxxxxxxxxxxxxxxxxxxxxxxxxxxxxxxxxxxxxxxxxxxxxxxxxxxxxxxxxxxxxxxxxxxxxxxxxxxxxxxxxxxxxxxxxxxxxxxxxxxxxxxxxxxxxxxxxxxxxxxxxxxxxxxxxxxxxxxxxxxxxxx (Caused by ResponseError('too many 500 error responses'))"}, "stdout": "\n\ud83d\ude80 GET \n/coordinator/missions/xxxxxxxxxxxxxxxxxxxxxxxxxxxxxxxxxxxxxxxxxxxxxxxxxxxxxxxxx\nxxxxxxxxxxxxxxxxxxxxxxxxxxxxxxxxxxxxxxxxxxxxxxxxxxxxxxxxxxxxxxxxxxxxxxxxxxxxxxx\nxxxxxxxxxxxxxxxxxxxxxxxxxxxxxxxxxxxxxxxxxxxxxxxxxxxxxxxxxxxxxxxxxxxxxxxxxxxxxxx\nxxxxxxxxxxxxxxxxxxxxxxxxxxxxxxxxxxxxxxxxxxxxxxxxxxxxxxxxxxxxxxxxxxxxxxxxxxxxxxx\nxxxxxxxxxxxxxxxxxxxxxxxxxxxxxxxxxxxxxxxxxxxxxxxxxxxxxxxxxxxxxxxxxxxxxxxxxxxxxxx\nxxxxxxxxxxxxxxxxxxxxxxxxxxxxxxxxxxxxxxxxxxxxxxxxxxxxxxxxxxxxxxxxxxxxxxxxxxxxxxx\nxxxxxxxxxxxxxxxxxxxxxxxxxxxxxxxxxxxxxxxxxxxxxxxxxxxxxxxxxxxxxxxxxxxxxxxxxxxxxxx\nxxxxxxxxxxxxxxxxxxxxxxxxxxxxxxxxxxxxxxxxxxxxxxxxxxxxxxxxxxxxxxxxxxxxxxxxxxxxxxx\nxxxxxxxxxxxxxxxxxxxxxxxxxxxxxxxxxxxxxxxxxxxxxxxxxxxxxxxxxxxxxxxxxxxxxxxxxxxxxxx\nxxxxxxxxxxxxxxxxxxxxxxxxxxxxxxxxxxxxxxxxxxxxxxxxxxxxxxxxxxxxxxxxxxxxxxxxxxxxxxx\nxxxxxxxxxxxxxxxxxxxxxxxxxxxxxxxxxxxxxxxxxxxxxxxxxxxxxxxxxxxxxxxxxxxxxxxxxxxxxxx\nxxxxxxxxxxxxxxxxxxxxxxxxxxxxxxxxxxxxxxxxxxxxxxxxxxxxxxxxxxxxxxxxxxxxxxxxxxxxxxx\nxxxxxxxxxxxxxxxxxxxxxxxxxxxxxxxxxxxxxxxxxxxxxxxxxxxxxxxxxxxxxxxxxxxxxxxxxx\n\u274c Request failed: \nHTTPSConnectionPool(host='pj4vlvxrg7.execute-api.us-east-1.amazonaws.com', \nport=443): Max retries exceeded with url: \n/dev/coordinator/missions/xxxxxxxxxxxxxxxxxxxxxxxxxxxxxxxxxxxxxxxxxxxxxxxxxxxxx\nxxxxxxxxxxxxxxxxxxxxxxxxxxxxxxxxxxxxxxxxxxxxxxxxxxxxxxxxxxxxxxxxxxxxxxxxxxxxxxx\nxxxxxxxxxxxxxxxxxxxxxxxxxxxxxxxxxxxxxxxxxxxxxxxxxxxxxxxxxxxxxxxxxxxxxxxxxxxxxxx\nxxxxxxxxxxxxxxxxxxxxxxxxxxxxxxxxxxxxxxxxxxxxxxxxxxxxxxxxxxxxxxxxxxxxxxxxxxxxxxx\nxxxxxxxxxxxxxxxxxxxxxxxxxxxxxxxxxxxxxxxxxxxxxxxxxxxxxxxxxxxxxxxxxxxxxxxxxxxxxxx\nxxxxxxxxxxxxxxxxxxxxxxxxxxxxxxxxxxxxxxxxxxxxxxxxxxxxxxxxxxxxxxxxxxxxxxxxxxxxxxx\nxxxxxxxxxxxxxxxxxxxxxxxxxxxxxxxxxxxxxxxxxxxxxxxxxxxxxxxxxxxxxxxxxxxxxxxxxxxxxxx\nxxxxxxxxxxxxxxxxxxxxxxxxxxxxxxxxxxxxxxxxxxxxxxxxxxxxxxxxxxxxxxxxxxxxxxxxxxxxxxx\nxxxxxxxxxxxxxxxxxxxxxxxxxxxxxxxxxxxxxxxxxxxxxxxxxxxxxxxxxxxxxxxxxxxxxxxxxxxxxxx\nxxxxxxxxxxxxxxxxxxxxxxxxxxxxxxxxxxxxxxxxxxxxxxxxxxxxxxxxxxxxxxxxxxxxxxxxxxxxxxx\nxxxxxxxxxxxxxxxxxxxxxxxxxxxxxxxxxxxxxxxxxxxxxxxxxxxxxxxxxxxxxxxxxxxxxxxxxxxxxxx\nxxxxxxxxxxxxxxxxxxxxxxxxxxxxxxxxxxxxxxxxxxxxxxxxxxxxxxxxxxxxxxxxxxxxxxxxxxxxxxx\nxxxxxxxxxxxxxxxxxxxxxxxxxxxxxxxxxxxxxxxxxxxxxxxxxxxxxxxxxxxxxxxxxxxxxxxxxxxxxx \n(Caused by ResponseError('too many 500 error responses'))\n", "longrepr": "urllib3.exceptions.ResponseError: too many 500 error responses\n\nThe above exception was the direct cause of the following exception:\nE   urllib3.exceptions.MaxRetryError: HTTPSConnectionPool(host='pj4vlvxrg7.execute-api.us-east-1.amazonaws.com', port=443): Max retries exceeded with url: /dev/coordinator/missions/xxxxxxxxxxxxxxxxxxxxxxxxxxxxxxxxxxxxxxxxxxxxxxxxxxxxxxxxxxxxxxxxxxxxxxxxxxxxxxxxxxxxxxxxxxxxxxxxxxxxxxxxxxxxxxxxxxxxxxxxxxxxxxxxxxxxxxxxxxxxxxxxxxxxxxxxxxxxxxxxxxxxxxxxxxxxxxxxxxxxxxxxxxxxxxxxxxxxxxxxxxxxxxxxxxxxxxxxxxxxxxxxxxxxxxxxxxxxxxxxxxxxxxxxxxxxxxxxxxxxxxxxxxxxxxxxxxxxxxxxxxxxxxxxxxxxxxxxxxxxxxxxxxxxxxxxxxxxxxxxxxxxxxxxxxxxxxxxxxxxxxxxxxxxxxxxxxxxxxxxxxxxxxxxxxxxxxxxxxxxxxxxxxxxxxxxxxxxxxxxxxxxxxxxxxxxxxxxxxxxxxxxxxxxxxxxxxxxxxxxxxxxxxxxxxxxxxxxxxxxxxxxxxxxxxxxxxxxxxxxxxxxxxxxxxxxxxxxxxxxxxxxxxxxxxxxxxxxxxxxxxxxxxxxxxxxxxxxxxxxxxxxxxxxxxxxxxxxxxxxxxxxxxxxxxxxxxxxxxxxxxxxxxxxxxxxxxxxxxxxxxxxxxxxxxxxxxxxxxxxxxxxxxxxxxxxxxxxxxxxxxxxxxxxxxxxxxxxxxxxxxxxxxxxxxxxxxxxxxxxxxxxxxxxxxxxxxxxxxxxxxxxxxxxxxxxxxxxxxxxxxxxxxxxxxxxxxxxxxxxxxxxxxxxxxxxxxxxxxxxxxxxxxxxxxxxxxxxxxxxxxxxxxxxxxxxxxxxxxxxxxxxxxxxxxxxxxxxxxxxxxxxxxxxxxxxxxxxxxxxxxxxxxxxxxxxxxxxxxxxxxxxxxxxxxxxxxxxxxxxxxxxxxxxxxxxxxxxxxxxxxxxxxxxxxxxxxxxxxxxxxxxxxxxxxxxxxxxxxxxxxxxxxxxxxxxxxxxxxxxxxxxxxxxxxxxxxxxxxxxxxxxxxxxxxxxxxxxxxxx (Caused by ResponseError('too many 500 error responses'))\n\nDuring handling of the above exception, another exception occurred:\nE   requests.exceptions.RetryError: HTTPSConnectionPool(host='pj4vlvxrg7.execute-api.us-east-1.amazonaws.com', port=443): Max retries exceeded with url: /dev/coordinator/missions/xxxxxxxxxxxxxxxxxxxxxxxxxxxxxxxxxxxxxxxxxxxxxxxxxxxxxxxxxxxxxxxxxxxxxxxxxxxxxxxxxxxxxxxxxxxxxxxxxxxxxxxxxxxxxxxxxxxxxxxxxxxxxxxxxxxxxxxxxxxxxxxxxxxxxxxxxxxxxxxxxxxxxxxxxxxxxxxxxxxxxxxxxxxxxxxxxxxxxxxxxxxxxxxxxxxxxxxxxxxxxxxxxxxxxxxxxxxxxxxxxxxxxxxxxxxxxxxxxxxxxxxxxxxxxxxxxxxxxxxxxxxxxxxxxxxxxxxxxxxxxxxxxxxxxxxxxxxxxxxxxxxxxxxxxxxxxxxxxxxxxxxxxxxxxxxxxxxxxxxxxxxxxxxxxxxxxxxxxxxxxxxxxxxxxxxxxxxxxxxxxxxxxxxxxxxxxxxxxxxxxxxxxxxxxxxxxxxxxxxxxxxxxxxxxxxxxxxxxxxxxxxxxxxxxxxxxxxxxxxxxxxxxxxxxxxxxxxxxxxxxxxxxxxxxxxxxxxxxxxxxxxxxxxxxxxxxxxxxxxxxxxxxxxxxxxxxxxxxxxxxxxxxxxxxxxxxxxxxxxxxxxxxxxxxxxxxxxxxxxxxxxxxxxxxxxxxxxxxxxxxxxxxxxxxxxxxxxxxxxxxxxxxxxxxxxxxxxxxxxxxxxxxxxxxxxxxxxxxxxxxxxxxxxxxxxxxxxxxxxxxxxxxxxxxxxxxxxxxxxxxxxxxxxxxxxxxxxxxxxxxxxxxxxxxxxxxxxxxxxxxxxxxxxxxxxxxxxxxxxxxxxxxxxxxxxxxxxxxxxxxxxxxxxxxxxxxxxxxxxxxxxxxxxxxxxxxxxxxxxxxxxxxxxxxxxxxxxxxxxxxxxxxxxxxxxxxxxxxxxxxxxxxxxxxxxxxxxxxxxxxxxxxxxxxxxxxxxxxxxxxxxxxxxxxxxxxxxxxxxxxxxxxxxxxxxxxxxxxxxxxxxxxxxxxxxxxxxxxxxxxxxxxxxxxxxxxxxxxxxx (Caused by ResponseError('too many 500 error responses'))"}, "teardown": {"duration": 0.18598709999969287, "outcome": "passed", "stdout": "\n\ud83d\udcca Test Session Complete\n                              \ud83d\udd0d Request Summary                               \n\u250c\u2500\u2500\u2500\u2500\u2500\u2500\u2500\u2500\u252c\u2500\u2500\u2500\u2500\u2500\u2500\u2500\u2500\u2500\u2500\u2500\u2500\u2500\u2500\u2500\u2500\u2500\u2500\u2500\u2500\u2500\u2500\u2500\u2500\u2500\u2500\u2500\u2500\u2500\u2500\u2500\u2500\u2500\u2500\u2500\u2500\u2500\u252c\u2500\u2500\u2500\u2500\u2500\u2500\u2500\u2500\u252c\u2500\u2500\u2500\u2500\u2500\u2500\u2500\u2500\u2500\u2500\u2500\u252c\u2500\u2500\u2500\u2500\u2500\u2500\u2500\u2500\u2500\u2510\n\u2502 Method \u2502 Endpoint                            \u2502 Status \u2502 Time (ms) \u2502 Success \u2502\n\u251c\u2500\u2500\u2500\u2500\u2500\u2500\u2500\u2500\u253c\u2500\u2500\u2500\u2500\u2500\u2500\u2500\u2500\u2500\u2500\u2500\u2500\u2500\u2500\u2500\u2500\u2500\u2500\u2500\u2500\u2500\u2500\u2500\u2500\u2500\u2500\u2500\u2500\u2500\u2500\u2500\u2500\u2500\u2500\u2500\u2500\u2500\u253c\u2500\u2500\u2500\u2500\u2500\u2500\u2500\u2500\u253c\u2500\u2500\u2500\u2500\u2500\u2500\u2500\u2500\u2500\u2500\u2500\u253c\u2500\u2500\u2500\u2500\u2500\u2500\u2500\u2500\u2500\u2524\n\u2502 GET    \u2502 /health                             \u2502 200    \u2502 3802.82   \u2502 \u2705      \u2502\n\u2502 GET    \u2502 /health                             \u2502 200    \u2502 209.04    \u2502 \u2705      \u2502\n\u2502 GET    \u2502 /director                           \u2502 200    \u2502 3717.71   \u2502 \u2705      \u2502\n\u2502 GET    \u2502 /director?user_request=Test mission \u2502 200    \u2502 7392.65   \u2502 \u2705      \u2502\n\u2502        \u2502 from Python API tests               \u2502        \u2502           \u2502         \u2502\n\u2502 GET    \u2502 /director?user_id=api-test-user     \u2502 200    \u2502 3513.32   \u2502 \u2705      \u2502\n\u2502 POST   \u2502 /persona                            \u2502 0      \u2502 7531.49   \u2502 \u274c      \u2502\n\u2502 POST   \u2502 /persona                            \u2502 400    \u2502 177.37    \u2502 \u274c      \u2502\n\u2502 POST   \u2502 /persona                            \u2502 400    \u2502 191.87    \u2502 \u274c      \u2502\n\u2502 GET    \u2502 /persona/conversations?user_id=api\u2026 \u2502 0      \u2502 6797.02   \u2502 \u274c      \u2502\n\u2502 POST   \u2502 /elevator/call                      \u2502 0      \u2502 8184.36   \u2502 \u274c      \u2502\n\u2502 POST   \u2502 /elevator/call                      \u2502 0      \u2502 6957.76   \u2502 \u274c      \u2502\n\u2502 POST   \u2502 /psim/search                        \u2502 200    \u2502 1792.74   \u2502 \u2705      \u2502\n\u2502 POST   \u2502 /psim/search                        \u2502 200    \u2502 318.02    \u2502 \u2705      \u2502\n\u2502 GET    \u2502 /coordinator/missions/test-mission\u2026 \u2502 0      \u2502 6817.3    \u2502 \u274c      \u2502\n\u2502 GET    \u2502 /coordinator/missions/python-test-\u2026 \u2502 0      \u2502 6794.43   \u2502 \u274c      \u2502\n\u2502 GET    \u2502 /health                             \u2502 200    \u2502 188.48    \u2502 \u2705      \u2502\n\u2502 GET    \u2502 /director                           \u2502 200    \u2502 3773.22   \u2502 \u2705      \u2502\n\u2502 POST   \u2502 /persona                            \u2502 400    \u2502 207.61    \u2502 \u274c      \u2502\n\u2502 POST   \u2502 /elevator/call                      \u2502 0      \u2502 7034.97   \u2502 \u274c      \u2502\n\u2502 POST   \u2502 /psim/search                        \u2502 400    \u2502 175.32    \u2502 \u274c      \u2502\n\u2502 GET    \u2502 /coordinator/missions/test-123      \u2502 0      \u2502 6808.18   \u2502 \u274c      \u2502\n\u2502 GET    \u2502 /invalid-endpoint                   \u2502 404    \u2502 159.78    \u2502 \u274c      \u2502\n\u2502 DELETE \u2502 /health                             \u2502 404    \u2502 169.33    \u2502 \u274c      \u2502\n\u2502 GET    \u2502 /health                             \u2502 200    \u2502 190.55    \u2502 \u2705      \u2502\n\u2502 GET    \u2502 /director                           \u2502 200    \u2502 2834.51   \u2502 \u2705      \u2502\n\u2502 POST   \u2502 /persona                            \u2502 0      \u2502 6790.55   \u2502 \u274c      \u2502\n\u2502 GET    \u2502 /health                             \u2502 200    \u2502 196.55    \u2502 \u2705      \u2502\n\u2502 GET    \u2502 /health                             \u2502 200    \u2502 1631.89   \u2502 \u2705      \u2502\n\u2502 GET    \u2502 /health                             \u2502 200    \u2502 1875.02   \u2502 \u2705      \u2502\n\u2502 GET    \u2502 /health                             \u2502 200    \u2502 1881.53   \u2502 \u2705      \u2502\n\u2502 GET    \u2502 /health                             \u2502 200    \u2502 1881.09   \u2502 \u2705      \u2502\n\u2502 GET    \u2502 /health                             \u2502 200    \u2502 187.57    \u2502 \u2705      \u2502\n\u2502 GET    \u2502 /health                             \u2502 200    \u2502 188.9     \u2502 \u2705      \u2502\n\u2502 GET    \u2502 /health                             \u2502 200    \u2502 188.11    \u2502 \u2705      \u2502\n\u2502 GET    \u2502 /health                             \u2502 200    \u2502 185.38    \u2502 \u2705      \u2502\n\u2502 GET    \u2502 /health                             \u2502 200    \u2502 173.21    \u2502 \u2705      \u2502\n\u2502 GET    \u2502 /health                             \u2502 200    \u2502 205.63    \u2502 \u2705      \u2502\n\u2502 GET    \u2502 /health                             \u2502 200    \u2502 181.67    \u2502 \u2705      \u2502\n\u2502 GET    \u2502 /health                             \u2502 200    \u2502 182.17    \u2502 \u2705      \u2502\n\u2502 GET    \u2502 /health                             \u2502 200    \u2502 179.46    \u2502 \u2705      \u2502\n\u2502 GET    \u2502 /health                             \u2502 200    \u2502 179.38    \u2502 \u2705      \u2502\n\u2502 GET    \u2502 /health                             \u2502 200    \u2502 183.83    \u2502 \u2705      \u2502\n\u2502 GET    \u2502 /health                             \u2502 200    \u2502 182.74    \u2502 \u2705      \u2502\n\u2502 GET    \u2502 /health                             \u2502 200    \u2502 165.72    \u2502 \u2705      \u2502\n\u2502 GET    \u2502 /health                             \u2502 200    \u2502 189.48    \u2502 \u2705      \u2502\n\u2502 GET    \u2502 /health                             \u2502 200    \u2502 174.02    \u2502 \u2705      \u2502\n\u2502 GET    \u2502 /health                             \u2502 200    \u2502 184.01    \u2502 \u2705      \u2502\n\u2502 GET    \u2502 /health                             \u2502 200    \u2502 175.6     \u2502 \u2705      \u2502\n\u2502 GET    \u2502 /health                             \u2502 200    \u2502 170.45    \u2502 \u2705      \u2502\n\u2502 GET    \u2502 /health                             \u2502 200    \u2502 183.67    \u2502 \u2705      \u2502\n\u2502 GET    \u2502 /health                             \u2502 200    \u2502 182.44    \u2502 \u2705      \u2502\n\u2502 POST   \u2502 /persona                            \u2502 0      \u2502 6776.43   \u2502 \u274c      \u2502\n\u2502 GET    \u2502 /health                             \u2502 200    \u2502 179.41    \u2502 \u2705      \u2502\n\u2502 GET    \u2502 /health                             \u2502 200    \u2502 183.42    \u2502 \u2705      \u2502\n\u2502 GET    \u2502 /health                             \u2502 200    \u2502 173.75    \u2502 \u2705      \u2502\n\u2502 GET    \u2502 /health                             \u2502 200    \u2502 174.74    \u2502 \u2705      \u2502\n\u2502 GET    \u2502 /health                             \u2502 200    \u2502 187.37    \u2502 \u2705      \u2502\n\u2502 GET    \u2502 /health                             \u2502 200    \u2502 184.09    \u2502 \u2705      \u2502\n\u2502 GET    \u2502 /health                             \u2502 200    \u2502 182.32    \u2502 \u2705      \u2502\n\u2502 GET    \u2502 /health                             \u2502 200    \u2502 182.53    \u2502 \u2705      \u2502\n\u2502 GET    \u2502 /health                             \u2502 200    \u2502 177.32    \u2502 \u2705      \u2502\n\u2502 GET    \u2502 /health                             \u2502 200    \u2502 197.22    \u2502 \u2705      \u2502\n\u2502 POST   \u2502 /persona                            \u2502 0      \u2502 6750.39   \u2502 \u274c      \u2502\n\u2502 POST   \u2502 /persona                            \u2502 400    \u2502 1426.5    \u2502 \u274c      \u2502\n\u2502 POST   \u2502 /elevator/call                      \u2502 0      \u2502 6878.43   \u2502 \u274c      \u2502\n\u2502 POST   \u2502 /persona                            \u2502 400    \u2502 172.28    \u2502 \u274c      \u2502\n\u2502 GET    \u2502 /coordinator/missions/xxxxxxxxxxxx\u2026 \u2502 0      \u2502 6799.58   \u2502 \u274c      \u2502\n\u2514\u2500\u2500\u2500\u2500\u2500\u2500\u2500\u2500\u2534\u2500\u2500\u2500\u2500\u2500\u2500\u2500\u2500\u2500\u2500\u2500\u2500\u2500\u2500\u2500\u2500\u2500\u2500\u2500\u2500\u2500\u2500\u2500\u2500\u2500\u2500\u2500\u2500\u2500\u2500\u2500\u2500\u2500\u2500\u2500\u2500\u2500\u2534\u2500\u2500\u2500\u2500\u2500\u2500\u2500\u2500\u2534\u2500\u2500\u2500\u2500\u2500\u2500\u2500\u2500\u2500\u2500\u2500\u2534\u2500\u2500\u2500\u2500\u2500\u2500\u2500\u2500\u2500\u2518\n\u250c\u2500\u2500\u2500\u2500\u2500\u2500\u2500\u2500\u2500\u2500\u2500\u2500\u2500\u2500\u2500\u2500\u2500\u2500\u2500\u2500\u2500\u2500\u2500\u2500\u2500\u2500\u2500\u2500 Performance Metrics \u2500\u2500\u2500\u2500\u2500\u2500\u2500\u2500\u2500\u2500\u2500\u2500\u2500\u2500\u2500\u2500\u2500\u2500\u2500\u2500\u2500\u2500\u2500\u2500\u2500\u2500\u2500\u2500\u2510\n\u2502 \ud83d\udcc8 Avg: 884.02ms | \u26a1 Min: 165.72ms | \ud83d\udc0c Max: 7392.65ms                     \u2502\n\u2514\u2500\u2500\u2500\u2500\u2500\u2500\u2500\u2500\u2500\u2500\u2500\u2500\u2500\u2500\u2500\u2500\u2500\u2500\u2500\u2500\u2500\u2500\u2500\u2500\u2500\u2500\u2500\u2500\u2500\u2500\u2500\u2500\u2500\u2500\u2500\u2500\u2500\u2500\u2500\u2500\u2500\u2500\u2500\u2500\u2500\u2500\u2500\u2500\u2500\u2500\u2500\u2500\u2500\u2500\u2500\u2500\u2500\u2500\u2500\u2500\u2500\u2500\u2500\u2500\u2500\u2500\u2500\u2500\u2500\u2500\u2500\u2500\u2500\u2500\u2500\u2500\u2500\u2518\n\ud83d\udcbe Results exported to: api-test-results-20250810-112504.json\n"}}], "warnings": [{"message": "Unknown pytest.mark.slow - is this a typo?  You can register custom marks to avoid this warning - for details, see https://docs.pytest.org/en/stable/how-to/mark.html", "category": "PytestUnknownMarkWarning", "when": "collect", "filename": "c:\\Projects\\building-os-platform\\tests\\api\\test_performance.py", "lineno": 73}, {"message": "Unknown pytest.mark.slow - is this a typo?  You can register custom marks to avoid this warning - for details, see https://docs.pytest.org/en/stable/how-to/mark.html", "category": "PytestUnknownMarkWarning", "when": "collect", "filename": "c:\\Projects\\building-os-platform\\tests\\api\\test_performance.py", "lineno": 245}, {"message": "Unknown pytest.mark.load - is this a typo?  You can register custom marks to avoid this warning - for details, see https://docs.pytest.org/en/stable/how-to/mark.html", "category": "PytestUnknownMarkWarning", "when": "collect", "filename": "c:\\Projects\\building-os-platform\\tests\\api\\test_performance.py", "lineno": 246}]}